Author: Bo3 BulkEdit

Description: Converted Schematic - Modified by Bo3BulkEdit

Version: 3

SettingsMode: WriteDisable

IsOTGPlus: false
Tree: false
Frequency: 1
Rarity: 100
RotateRandomly: false
SpawnHeight: randomY
MaxBranchDepth: 10
ExcludedBiomes: All

MinHeight: 0
MaxHeight: 256

SourceBlocks: AIR
MaxPercentageOutsideSourceBlock: 100
OutsideSourceBlock: placeAnyway

B(0,0,0,STONEBRICK:0)
B(1,0,0,STONEBRICK:0)
B(2,0,0,STONEBRICK:0)
B(3,0,0,STONEBRICK:0)
B(4,0,0,STONEBRICK:0)
B(5,0,0,STONEBRICK:0)
B(6,0,0,STONEBRICK:0)
B(7,0,0,STONEBRICK:0)
B(0,0,1,STONEBRICK:0)
B(1,0,1,STONEBRICK:0)
B(2,0,1,STONEBRICK:0)
B(3,0,1,STONEBRICK:0)
B(4,0,1,STONEBRICK:0)
B(5,0,1,STONEBRICK:0)
B(6,0,1,STONEBRICK:0)
B(7,0,1,STONEBRICK:0)
B(0,0,2,STONEBRICK:0)
B(1,0,2,STONEBRICK:0)
B(2,0,2,STONEBRICK:0)
B(3,0,2,STONEBRICK:0)
B(4,0,2,STONEBRICK:0)
B(5,0,2,STONEBRICK:0)
B(6,0,2,STONEBRICK:0)
B(7,0,2,STONEBRICK:0)
B(0,0,3,STONEBRICK:0)
B(1,0,3,STONEBRICK:0)
B(2,0,3,STONEBRICK:0)
B(3,0,3,STONEBRICK:0)
B(4,0,3,STONEBRICK:0)
B(5,0,3,STONEBRICK:0)
B(6,0,3,STONEBRICK:0)
B(7,0,3,STONEBRICK:0)
B(0,0,4,STONEBRICK:0)
B(1,0,4,STONEBRICK:0)
B(2,0,4,STONEBRICK:0)
B(3,0,4,STONEBRICK:0)
B(4,0,4,STONEBRICK:0)
B(5,0,4,STONEBRICK:0)
B(6,0,4,STONEBRICK:0)
B(7,0,4,STONEBRICK:0)
B(0,0,5,STONEBRICK:0)
B(1,0,5,STONEBRICK:0)
B(2,0,5,STONEBRICK:0)
B(3,0,5,STONEBRICK:0)
B(4,0,5,STONEBRICK:0)
B(5,0,5,STONEBRICK:0)
B(6,0,5,STONEBRICK:0)
B(7,0,5,STONEBRICK:0)
B(0,0,6,STONEBRICK:0)
B(1,0,6,STONEBRICK:0)
B(2,0,6,STONEBRICK:0)
B(3,0,6,STONEBRICK:0)
B(4,0,6,STONEBRICK:0)
B(5,0,6,STONEBRICK:0)
B(6,0,6,STONEBRICK:0)
B(7,0,6,STONEBRICK:0)
B(0,0,7,STONEBRICK:0)
B(1,0,7,STONEBRICK:0)
B(2,0,7,STONEBRICK:0)
B(3,0,7,STONEBRICK:0)
B(4,0,7,STONEBRICK:0)
B(5,0,7,STONEBRICK:0)
B(6,0,7,STONEBRICK:0)
B(7,0,7,STONEBRICK:0)
B(0,1,0,chisel:basalt2:7)
B(1,1,0,chisel:basalt2:7)
B(2,1,0,chisel:basalt2:7)
B(3,1,0,chisel:basalt2:7)
B(4,1,0,chisel:basalt2:7)
B(5,1,0,chisel:basalt2:7)
B(6,1,0,chisel:basalt2:7)
B(7,1,0,STONEBRICK:0)
B(0,1,1,chisel:basalt2:7)
B(1,1,1,chisel:basalt2:7)
B(2,1,1,chisel:basalt2:7)
B(3,1,1,chisel:basalt2:7)
B(4,1,1,chisel:basalt2:7)
B(5,1,1,chisel:basalt2:7)
B(6,1,1,chisel:basalt2:7)
B(7,1,1,STONEBRICK:0)
B(0,1,2,chisel:basalt2:7)
B(1,1,2,chisel:basalt2:7)
B(2,1,2,chisel:basalt2:7)
B(3,1,2,chisel:basalt2:7)
B(4,1,2,chisel:basalt2:7)
B(5,1,2,chisel:basalt2:7)
B(6,1,2,chisel:basalt2:7)
B(7,1,2,STONEBRICK:0)
B(0,1,3,chisel:basalt2:7)
B(1,1,3,chisel:basalt2:7)
B(2,1,3,chisel:basalt2:7)
B(3,1,3,chisel:basalt2:7)
B(4,1,3,chisel:basalt2:7)
B(5,1,3,chisel:basalt2:7)
B(6,1,3,chisel:basalt2:7)
B(7,1,3,STONEBRICK:0)
B(0,1,4,chisel:basalt2:7)
B(1,1,4,chisel:basalt2:7)
B(2,1,4,chisel:basalt2:7)
B(3,1,4,chisel:basalt2:7)
B(4,1,4,chisel:basalt2:7)
B(5,1,4,chisel:basalt2:7)
B(6,1,4,chisel:basalt2:7)
B(7,1,4,STONEBRICK:0)
B(0,1,5,chisel:basalt2:7)
B(1,1,5,chisel:basalt2:7)
B(2,1,5,chisel:basalt2:7)
B(3,1,5,chisel:basalt2:7)
B(4,1,5,chisel:basalt2:7)
B(5,1,5,chisel:basalt2:7)
B(6,1,5,chisel:basalt2:7)
B(7,1,5,STONEBRICK:0)
B(0,1,6,chisel:basalt2:7)
B(1,1,6,chisel:basalt2:7)
B(2,1,6,chisel:basalt2:7)
B(3,1,6,chisel:basalt2:7)
B(4,1,6,chisel:basalt2:7)
B(5,1,6,chisel:basalt2:7)
B(6,1,6,chisel:basalt2:7)
B(7,1,6,STONEBRICK:0)
B(0,1,7,STONEBRICK:0)
B(1,1,7,STONEBRICK:0)
B(2,1,7,STONEBRICK:0)
B(3,1,7,STONEBRICK:0)
B(4,1,7,STONEBRICK:0)
B(5,1,7,STONEBRICK:0)
B(6,1,7,STONEBRICK:0)
B(7,1,7,STONEBRICK:0)
B(0,2,0,chisel:basalt2:7)
B(1,2,0,chisel:basalt2:7)
B(2,2,0,chisel:basalt2:7)
B(3,2,0,chisel:basalt2:7)
B(4,2,0,chisel:basalt2:7)
B(5,2,0,chisel:basalt2:7)
B(6,2,0,chisel:basalt2:7)
B(7,2,0,STONEBRICK:0)
B(0,2,1,chisel:basalt2:7)
B(1,2,1,chisel:basalt2:7)
B(2,2,1,chisel:basalt2:7)
B(3,2,1,chisel:basalt2:7)
B(4,2,1,chisel:basalt2:7)
B(5,2,1,chisel:basalt2:7)
B(6,2,1,chisel:basalt2:7)
B(7,2,1,STONEBRICK:0)
B(0,2,2,chisel:basalt2:7)
B(1,2,2,chisel:basalt2:7)
B(2,2,2,chisel:basalt2:7)
B(3,2,2,chisel:basalt2:7)
B(4,2,2,chisel:basalt2:7)
B(5,2,2,chisel:basalt2:7)
B(6,2,2,chisel:basalt2:7)
B(7,2,2,STONEBRICK:0)
B(0,2,3,chisel:basalt2:7)
B(1,2,3,chisel:basalt2:7)
B(2,2,3,chisel:basalt2:7)
B(3,2,3,chisel:basalt2:7)
B(4,2,3,chisel:basalt2:7)
B(5,2,3,chisel:basalt2:7)
B(6,2,3,chisel:basalt2:7)
B(7,2,3,STONEBRICK:0)
B(0,2,4,chisel:basalt2:7)
B(1,2,4,chisel:basalt2:7)
B(2,2,4,chisel:basalt2:7)
B(3,2,4,chisel:basalt2:7)
B(4,2,4,chisel:basalt2:7)
B(5,2,4,chisel:basalt2:7)
B(6,2,4,chisel:basalt2:7)
B(7,2,4,STONEBRICK:0)
B(0,2,5,chisel:basalt2:7)
B(1,2,5,chisel:basalt2:7)
B(2,2,5,chisel:basalt2:7)
B(3,2,5,chisel:basalt2:7)
B(4,2,5,chisel:basalt2:7)
B(5,2,5,chisel:basalt2:7)
B(6,2,5,chisel:basalt2:7)
B(7,2,5,STONEBRICK:0)
B(0,2,6,chisel:basalt2:7)
B(1,2,6,chisel:basalt2:7)
B(2,2,6,chisel:basalt2:7)
B(3,2,6,chisel:basalt2:7)
B(4,2,6,chisel:basalt2:7)
B(5,2,6,chisel:basalt2:7)
B(6,2,6,chisel:basalt2:7)
B(7,2,6,STONEBRICK:0)
B(0,2,7,STONEBRICK:0)
B(1,2,7,STONEBRICK:0)
B(2,2,7,STONEBRICK:0)
B(3,2,7,STONEBRICK:0)
B(4,2,7,STONEBRICK:0)
B(5,2,7,STONEBRICK:0)
B(6,2,7,STONEBRICK:0)
B(7,2,7,STONEBRICK:0)
B(0,3,0,chisel:basalt2:7)
B(1,3,0,chisel:basalt2:7)
B(2,3,0,chisel:basalt2:7)
B(3,3,0,chisel:basalt2:7)
B(4,3,0,chisel:basalt2:7)
B(5,3,0,chisel:basalt2:7)
B(6,3,0,chisel:basalt2:7)
B(7,3,0,STONEBRICK:0)
B(0,3,1,chisel:basalt2:7)
B(1,3,1,chisel:basalt2:7)
B(2,3,1,chisel:basalt2:7)
B(3,3,1,chisel:basalt2:7)
B(4,3,1,chisel:basalt2:7)
B(5,3,1,chisel:basalt2:7)
B(6,3,1,chisel:basalt2:7)
B(7,3,1,STONEBRICK:0)
B(0,3,2,chisel:basalt2:7)
B(1,3,2,chisel:basalt2:7)
B(2,3,2,chisel:basalt2:7)
B(3,3,2,chisel:basalt2:7)
B(4,3,2,chisel:basalt2:7)
B(5,3,2,chisel:basalt2:7)
B(6,3,2,chisel:basalt2:7)
B(7,3,2,STONEBRICK:0)
B(0,3,3,chisel:basalt2:7)
B(1,3,3,chisel:basalt2:7)
B(2,3,3,chisel:basalt2:7)
B(3,3,3,chisel:basalt2:7)
B(4,3,3,chisel:basalt2:7)
B(5,3,3,chisel:basalt2:7)
B(6,3,3,chisel:basalt2:7)
B(7,3,3,STONEBRICK:0)
B(0,3,4,chisel:basalt2:7)
B(1,3,4,chisel:basalt2:7)
B(2,3,4,chisel:basalt2:7)
B(3,3,4,chisel:basalt2:7)
B(4,3,4,chisel:basalt2:7)
B(5,3,4,chisel:basalt2:7)
B(6,3,4,chisel:basalt2:7)
B(7,3,4,STONEBRICK:0)
B(0,3,5,chisel:basalt2:7)
B(1,3,5,chisel:basalt2:7)
B(2,3,5,chisel:basalt2:7)
B(3,3,5,chisel:basalt2:7)
B(4,3,5,chisel:basalt2:7)
B(5,3,5,chisel:basalt2:7)
B(6,3,5,chisel:basalt2:7)
B(7,3,5,STONEBRICK:0)
B(0,3,6,chisel:basalt2:7)
B(1,3,6,chisel:basalt2:7)
B(2,3,6,chisel:basalt2:7)
B(3,3,6,chisel:basalt2:7)
B(4,3,6,chisel:basalt2:7)
B(5,3,6,chisel:basalt2:7)
B(6,3,6,chisel:basalt2:7)
B(7,3,6,STONEBRICK:0)
B(0,3,7,STONEBRICK:0)
B(1,3,7,STONEBRICK:0)
B(2,3,7,STONEBRICK:0)
B(3,3,7,STONEBRICK:0)
B(4,3,7,STONEBRICK:0)
B(5,3,7,STONEBRICK:0)
B(6,3,7,STONEBRICK:0)
B(7,3,7,STONEBRICK:0)
B(0,4,0,chisel:basalt2:7)
B(1,4,0,chisel:basalt2:7)
B(2,4,0,chisel:basalt2:7)
B(3,4,0,chisel:basalt2:7)
B(4,4,0,chisel:basalt2:7)
B(5,4,0,chisel:basalt2:7)
B(6,4,0,chisel:basalt2:7)
B(7,4,0,STONEBRICK:0)
B(0,4,1,chisel:basalt2:7)
B(1,4,1,chisel:basalt2:7)
B(2,4,1,chisel:basalt2:7)
B(3,4,1,chisel:basalt2:7)
B(4,4,1,chisel:basalt2:7)
B(5,4,1,chisel:basalt2:7)
B(6,4,1,chisel:basalt2:7)
B(7,4,1,STONEBRICK:0)
B(0,4,2,chisel:basalt2:7)
B(1,4,2,chisel:basalt2:7)
B(2,4,2,chisel:basalt2:7)
B(3,4,2,chisel:basalt2:7)
B(4,4,2,chisel:basalt2:7)
B(5,4,2,chisel:basalt2:7)
B(6,4,2,chisel:basalt2:7)
B(7,4,2,STONEBRICK:0)
B(0,4,3,chisel:basalt2:7)
B(1,4,3,chisel:basalt2:7)
B(2,4,3,chisel:basalt2:7)
B(3,4,3,chisel:basalt2:7)
B(4,4,3,chisel:basalt2:7)
B(5,4,3,chisel:basalt2:7)
B(6,4,3,chisel:basalt2:7)
B(7,4,3,STONEBRICK:0)
B(0,4,4,chisel:basalt2:7)
B(1,4,4,chisel:basalt2:7)
B(2,4,4,chisel:basalt2:7)
B(3,4,4,chisel:basalt2:7)
B(4,4,4,chisel:basalt2:7)
B(5,4,4,chisel:basalt2:7)
B(6,4,4,chisel:basalt2:7)
B(7,4,4,STONEBRICK:0)
B(0,4,5,chisel:basalt2:7)
B(1,4,5,chisel:basalt2:7)
B(2,4,5,chisel:basalt2:7)
B(3,4,5,chisel:basalt2:7)
B(4,4,5,chisel:basalt2:7)
B(5,4,5,chisel:basalt2:7)
B(6,4,5,chisel:basalt2:7)
B(7,4,5,STONEBRICK:0)
B(0,4,6,chisel:basalt2:7)
B(1,4,6,chisel:basalt2:7)
B(2,4,6,chisel:basalt2:7)
B(3,4,6,chisel:basalt2:7)
B(4,4,6,chisel:basalt2:7)
B(5,4,6,chisel:basalt2:7)
B(6,4,6,chisel:basalt2:7)
B(7,4,6,STONEBRICK:0)
B(0,4,7,STONEBRICK:0)
B(1,4,7,STONEBRICK:0)
B(2,4,7,STONEBRICK:0)
B(3,4,7,STONEBRICK:0)
B(4,4,7,STONEBRICK:0)
B(5,4,7,STONEBRICK:0)
B(6,4,7,STONEBRICK:0)
B(7,4,7,STONEBRICK:0)
B(0,5,0,chisel:basalt2:7)
B(1,5,0,chisel:basalt2:7)
B(2,5,0,chisel:basalt2:7)
B(3,5,0,chisel:basalt2:7)
B(4,5,0,chisel:basalt2:7)
B(5,5,0,chisel:basalt2:7)
B(6,5,0,chisel:basalt2:7)
B(7,5,0,STONEBRICK:0)
B(0,5,1,chisel:basalt2:7)
B(1,5,1,chisel:basalt2:7)
B(2,5,1,chisel:basalt2:7)
B(3,5,1,chisel:basalt2:7)
B(4,5,1,chisel:basalt2:7)
B(5,5,1,chisel:basalt2:7)
B(6,5,1,chisel:basalt2:7)
B(7,5,1,STONEBRICK:0)
B(0,5,2,chisel:basalt2:7)
B(1,5,2,chisel:basalt2:7)
B(2,5,2,chisel:basalt2:7)
B(3,5,2,chisel:basalt2:7)
B(4,5,2,chisel:basalt2:7)
B(5,5,2,chisel:basalt2:7)
B(6,5,2,chisel:basalt2:7)
B(7,5,2,STONEBRICK:0)
B(0,5,3,chisel:basalt2:7)
B(1,5,3,chisel:basalt2:7)
B(2,5,3,chisel:basalt2:7)
B(3,5,3,chisel:basalt2:7)
B(4,5,3,chisel:basalt2:7)
B(5,5,3,chisel:basalt2:7)
B(6,5,3,chisel:basalt2:7)
B(7,5,3,STONEBRICK:0)
B(0,5,4,chisel:basalt2:7)
B(1,5,4,chisel:basalt2:7)
B(2,5,4,chisel:basalt2:7)
B(3,5,4,chisel:basalt2:7)
B(4,5,4,chisel:basalt2:7)
B(5,5,4,chisel:basalt2:7)
B(6,5,4,chisel:basalt2:7)
B(7,5,4,STONEBRICK:0)
B(0,5,5,chisel:basalt2:7)
B(1,5,5,chisel:basalt2:7)
B(2,5,5,chisel:basalt2:7)
B(3,5,5,chisel:basalt2:7)
B(4,5,5,chisel:basalt2:7)
B(5,5,5,chisel:basalt2:7)
B(6,5,5,chisel:basalt2:7)
B(7,5,5,STONEBRICK:0)
B(0,5,6,chisel:basalt2:7)
B(1,5,6,chisel:basalt2:7)
B(2,5,6,chisel:basalt2:7)
B(3,5,6,chisel:basalt2:7)
B(4,5,6,chisel:basalt2:7)
B(5,5,6,chisel:basalt2:7)
B(6,5,6,chisel:basalt2:7)
B(7,5,6,STONEBRICK:0)
B(0,5,7,STONEBRICK:0)
B(1,5,7,STONEBRICK:0)
B(2,5,7,STONEBRICK:0)
B(3,5,7,STONEBRICK:0)
B(4,5,7,STONEBRICK:0)
B(5,5,7,STONEBRICK:0)
B(6,5,7,STONEBRICK:0)
B(7,5,7,STONEBRICK:0)
B(0,6,0,chisel:basalt2:7)
B(1,6,0,chisel:basalt2:7)
B(2,6,0,chisel:basalt2:7)
B(3,6,0,chisel:basalt2:7)
B(4,6,0,chisel:basalt2:7)
B(5,6,0,chisel:basalt2:7)
B(6,6,0,chisel:basalt2:7)
B(7,6,0,STONEBRICK:0)
B(0,6,1,chisel:basalt2:7)
B(1,6,1,chisel:basalt2:7)
B(2,6,1,chisel:basalt2:7)
B(3,6,1,chisel:basalt2:7)
B(4,6,1,chisel:basalt2:7)
B(5,6,1,chisel:basalt2:7)
B(6,6,1,chisel:basalt2:7)
B(7,6,1,STONEBRICK:0)
B(0,6,2,chisel:basalt2:7)
B(1,6,2,chisel:basalt2:7)
B(2,6,2,chisel:basalt2:7)
B(3,6,2,chisel:basalt2:7)
B(4,6,2,chisel:basalt2:7)
B(5,6,2,chisel:basalt2:7)
B(6,6,2,chisel:basalt2:7)
B(7,6,2,STONEBRICK:0)
B(0,6,3,chisel:basalt2:7)
B(1,6,3,chisel:basalt2:7)
B(2,6,3,chisel:basalt2:7)
B(3,6,3,chisel:basalt2:7)
B(4,6,3,chisel:basalt2:7)
B(5,6,3,chisel:basalt2:7)
B(6,6,3,chisel:basalt2:7)
B(7,6,3,STONEBRICK:0)
B(0,6,4,chisel:basalt2:7)
B(1,6,4,chisel:basalt2:7)
B(2,6,4,chisel:basalt2:7)
B(3,6,4,chisel:basalt2:7)
B(4,6,4,chisel:basalt2:7)
B(5,6,4,chisel:basalt2:7)
B(6,6,4,chisel:basalt2:7)
B(7,6,4,STONEBRICK:0)
B(0,6,5,chisel:basalt2:7)
B(1,6,5,chisel:basalt2:7)
B(2,6,5,chisel:basalt2:7)
B(3,6,5,chisel:basalt2:7)
B(4,6,5,chisel:basalt2:7)
B(5,6,5,chisel:basalt2:7)
B(6,6,5,chisel:basalt2:7)
B(7,6,5,STONEBRICK:0)
B(0,6,6,chisel:basalt2:7)
B(1,6,6,chisel:basalt2:7)
B(2,6,6,chisel:basalt2:7)
B(3,6,6,chisel:basalt2:7)
B(4,6,6,chisel:basalt2:7)
B(5,6,6,chisel:basalt2:7)
B(6,6,6,chisel:basalt2:7)
B(7,6,6,STONEBRICK:0)
B(0,6,7,STONEBRICK:0)
B(1,6,7,STONEBRICK:0)
B(2,6,7,STONEBRICK:0)
B(3,6,7,STONEBRICK:0)
B(4,6,7,STONEBRICK:0)
B(5,6,7,STONEBRICK:0)
B(6,6,7,STONEBRICK:0)
B(7,6,7,STONEBRICK:0)
B(0,7,0,chisel:basalt2:7)
B(1,7,0,chisel:basalt2:7)
B(2,7,0,chisel:basalt2:7)
B(3,7,0,chisel:basalt2:7)
B(4,7,0,chisel:basalt2:7)
B(5,7,0,chisel:basalt2:7)
B(6,7,0,chisel:basalt2:7)
B(7,7,0,STONEBRICK:0)
B(0,7,1,chisel:basalt2:7)
B(1,7,1,chisel:basalt2:7)
B(2,7,1,chisel:basalt2:7)
B(3,7,1,chisel:basalt2:7)
B(4,7,1,chisel:basalt2:7)
B(5,7,1,chisel:basalt2:7)
B(6,7,1,chisel:basalt2:7)
B(7,7,1,STONEBRICK:0)
B(0,7,2,chisel:basalt2:7)
B(1,7,2,chisel:basalt2:7)
B(2,7,2,chisel:basalt2:7)
B(3,7,2,chisel:basalt2:7)
B(4,7,2,chisel:basalt2:7)
B(5,7,2,chisel:basalt2:7)
B(6,7,2,chisel:basalt2:7)
B(7,7,2,STONEBRICK:0)
B(0,7,3,chisel:basalt2:7)
B(1,7,3,chisel:basalt2:7)
B(2,7,3,chisel:basalt2:7)
B(3,7,3,chisel:basalt2:7)
B(4,7,3,chisel:basalt2:7)
B(5,7,3,chisel:basalt2:7)
B(6,7,3,chisel:basalt2:7)
B(7,7,3,STONEBRICK:0)
B(0,7,4,chisel:basalt2:7)
B(1,7,4,chisel:basalt2:7)
B(2,7,4,chisel:basalt2:7)
B(3,7,4,chisel:basalt2:7)
B(4,7,4,chisel:basalt2:7)
B(5,7,4,chisel:basalt2:7)
B(6,7,4,chisel:basalt2:7)
B(7,7,4,STONEBRICK:0)
B(0,7,5,chisel:basalt2:7)
B(1,7,5,chisel:basalt2:7)
B(2,7,5,chisel:basalt2:7)
B(3,7,5,chisel:basalt2:7)
B(4,7,5,chisel:basalt2:7)
B(5,7,5,chisel:basalt2:7)
B(6,7,5,chisel:basalt2:7)
B(7,7,5,STONEBRICK:0)
B(0,7,6,chisel:basalt2:7)
B(1,7,6,chisel:basalt2:7)
B(2,7,6,chisel:basalt2:7)
B(3,7,6,chisel:basalt2:7)
B(4,7,6,chisel:basalt2:7)
B(5,7,6,chisel:basalt2:7)
B(6,7,6,chisel:basalt2:7)
B(7,7,6,STONEBRICK:0)
B(0,7,7,STONEBRICK:0)
B(1,7,7,STONEBRICK:0)
B(2,7,7,STONEBRICK:0)
B(3,7,7,STONEBRICK:0)
B(4,7,7,STONEBRICK:0)
B(5,7,7,STONEBRICK:0)
B(6,7,7,STONEBRICK:0)
B(7,7,7,STONEBRICK:0)
B(0,8,0,chisel:basalt2:7)
B(1,8,0,chisel:basalt2:7)
B(2,8,0,chisel:basalt2:7)
B(3,8,0,chisel:basalt2:7)
B(4,8,0,chisel:basalt2:7)
B(5,8,0,chisel:basalt2:7)
B(6,8,0,chisel:basalt2:7)
B(7,8,0,STONEBRICK:0)
B(0,8,1,chisel:basalt2:7)
B(1,8,1,chisel:basalt2:7)
B(2,8,1,chisel:basalt2:7)
B(3,8,1,chisel:basalt2:7)
B(4,8,1,chisel:basalt2:7)
B(5,8,1,chisel:basalt2:7)
B(6,8,1,chisel:basalt2:7)
B(7,8,1,STONEBRICK:0)
B(0,8,2,chisel:basalt2:7)
B(1,8,2,chisel:basalt2:7)
B(2,8,2,chisel:basalt2:7)
B(3,8,2,chisel:basalt2:7)
B(4,8,2,chisel:basalt2:7)
B(5,8,2,chisel:basalt2:7)
B(6,8,2,chisel:basalt2:7)
B(7,8,2,STONEBRICK:0)
B(0,8,3,chisel:basalt2:7)
B(1,8,3,chisel:basalt2:7)
B(2,8,3,chisel:basalt2:7)
B(3,8,3,chisel:basalt2:7)
B(4,8,3,chisel:basalt2:7)
B(5,8,3,chisel:basalt2:7)
B(6,8,3,chisel:basalt2:7)
B(7,8,3,STONEBRICK:0)
B(0,8,4,chisel:basalt2:7)
B(1,8,4,chisel:basalt2:7)
B(2,8,4,chisel:basalt2:7)
B(3,8,4,chisel:basalt2:7)
B(4,8,4,chisel:basalt2:7)
B(5,8,4,chisel:basalt2:7)
B(6,8,4,chisel:basalt2:7)
B(7,8,4,STONEBRICK:0)
B(0,8,5,chisel:basalt2:7)
B(1,8,5,chisel:basalt2:7)
B(2,8,5,chisel:basalt2:7)
B(3,8,5,chisel:basalt2:7)
B(4,8,5,chisel:basalt2:7)
B(5,8,5,chisel:basalt2:7)
B(6,8,5,chisel:basalt2:7)
B(7,8,5,STONEBRICK:0)
B(0,8,6,chisel:basalt2:7)
B(1,8,6,chisel:basalt2:7)
B(2,8,6,chisel:basalt2:7)
B(3,8,6,chisel:basalt2:7)
B(4,8,6,chisel:basalt2:7)
B(5,8,6,chisel:basalt2:7)
B(6,8,6,chisel:basalt2:7)
B(7,8,6,STONEBRICK:0)
B(0,8,7,STONEBRICK:0)
B(1,8,7,STONEBRICK:0)
B(2,8,7,STONEBRICK:0)
B(3,8,7,STONEBRICK:0)
B(4,8,7,STONEBRICK:0)
B(5,8,7,STONEBRICK:0)
B(6,8,7,STONEBRICK:0)
B(7,8,7,STONEBRICK:0)
B(0,9,0,chisel:basalt2:7)
B(1,9,0,chisel:basalt2:7)
B(2,9,0,chisel:basalt2:7)
B(3,9,0,chisel:basalt2:7)
B(4,9,0,chisel:basalt2:7)
B(5,9,0,chisel:basalt2:7)
B(6,9,0,chisel:basalt2:7)
B(7,9,0,STONEBRICK:0)
B(0,9,1,chisel:basalt2:7)
B(1,9,1,chisel:basalt2:7)
B(2,9,1,chisel:basalt2:7)
B(3,9,1,chisel:basalt2:7)
B(4,9,1,chisel:basalt2:7)
B(5,9,1,chisel:basalt2:7)
B(6,9,1,chisel:basalt2:7)
B(7,9,1,STONEBRICK:0)
B(0,9,2,chisel:basalt2:7)
B(1,9,2,chisel:basalt2:7)
B(2,9,2,chisel:basalt2:7)
B(3,9,2,chisel:basalt2:7)
B(4,9,2,chisel:basalt2:7)
B(5,9,2,chisel:basalt2:7)
B(6,9,2,chisel:basalt2:7)
B(7,9,2,STONEBRICK:0)
B(0,9,3,chisel:basalt2:7)
B(1,9,3,chisel:basalt2:7)
B(2,9,3,chisel:basalt2:7)
B(3,9,3,chisel:basalt2:7)
B(4,9,3,chisel:basalt2:7)
B(5,9,3,chisel:basalt2:7)
B(6,9,3,chisel:basalt2:7)
B(7,9,3,STONEBRICK:0)
B(0,9,4,chisel:basalt2:7)
B(1,9,4,chisel:basalt2:7)
B(2,9,4,chisel:basalt2:7)
B(3,9,4,chisel:basalt2:7)
B(4,9,4,chisel:basalt2:7)
B(5,9,4,chisel:basalt2:7)
B(6,9,4,chisel:basalt2:7)
B(7,9,4,STONEBRICK:0)
B(0,9,5,chisel:basalt2:7)
B(1,9,5,chisel:basalt2:7)
B(2,9,5,chisel:basalt2:7)
B(3,9,5,chisel:basalt2:7)
B(4,9,5,chisel:basalt2:7)
B(5,9,5,chisel:basalt2:7)
B(6,9,5,chisel:basalt2:7)
B(7,9,5,STONEBRICK:0)
B(0,9,6,chisel:basalt2:7)
B(1,9,6,chisel:basalt2:7)
B(2,9,6,chisel:basalt2:7)
B(3,9,6,chisel:basalt2:7)
B(4,9,6,chisel:basalt2:7)
B(5,9,6,chisel:basalt2:7)
B(6,9,6,chisel:basalt2:7)
B(7,9,6,STONEBRICK:0)
B(0,9,7,STONEBRICK:0)
B(1,9,7,STONEBRICK:0)
B(2,9,7,STONEBRICK:0)
B(3,9,7,STONEBRICK:0)
B(4,9,7,STONEBRICK:0)
B(5,9,7,STONEBRICK:0)
B(6,9,7,STONEBRICK:0)
B(7,9,7,STONEBRICK:0)
B(0,10,0,chisel:basalt2:7)
B(1,10,0,chisel:basalt2:7)
B(2,10,0,chisel:basalt2:7)
B(3,10,0,chisel:basalt2:7)
B(4,10,0,chisel:basalt2:7)
B(5,10,0,chisel:basalt2:7)
B(6,10,0,chisel:basalt2:7)
B(7,10,0,STONEBRICK:0)
B(0,10,1,chisel:basalt2:7)
B(1,10,1,chisel:basalt2:7)
B(2,10,1,chisel:basalt2:7)
B(3,10,1,chisel:basalt2:7)
B(4,10,1,chisel:basalt2:7)
B(5,10,1,chisel:basalt2:7)
B(6,10,1,chisel:basalt2:7)
B(7,10,1,STONEBRICK:0)
B(0,10,2,chisel:basalt2:7)
B(1,10,2,chisel:basalt2:7)
B(2,10,2,chisel:basalt2:7)
B(3,10,2,chisel:basalt2:7)
B(4,10,2,chisel:basalt2:7)
B(5,10,2,chisel:basalt2:7)
B(6,10,2,chisel:basalt2:7)
B(7,10,2,STONEBRICK:0)
B(0,10,3,chisel:basalt2:7)
B(1,10,3,chisel:basalt2:7)
B(2,10,3,chisel:basalt2:7)
B(3,10,3,chisel:basalt2:7)
B(4,10,3,chisel:basalt2:7)
B(5,10,3,chisel:basalt2:7)
B(6,10,3,chisel:basalt2:7)
B(7,10,3,STONEBRICK:0)
B(0,10,4,chisel:basalt2:7)
B(1,10,4,chisel:basalt2:7)
B(2,10,4,chisel:basalt2:7)
B(3,10,4,chisel:basalt2:7)
B(4,10,4,chisel:basalt2:7)
B(5,10,4,chisel:basalt2:7)
B(6,10,4,chisel:basalt2:7)
B(7,10,4,STONEBRICK:0)
B(0,10,5,chisel:basalt2:7)
B(1,10,5,chisel:basalt2:7)
B(2,10,5,chisel:basalt2:7)
B(3,10,5,chisel:basalt2:7)
B(4,10,5,chisel:basalt2:7)
B(5,10,5,chisel:basalt2:7)
B(6,10,5,chisel:basalt2:7)
B(7,10,5,STONEBRICK:0)
B(0,10,6,chisel:basalt2:7)
B(1,10,6,chisel:basalt2:7)
B(2,10,6,chisel:basalt2:7)
B(3,10,6,chisel:basalt2:7)
B(4,10,6,chisel:basalt2:7)
B(5,10,6,chisel:basalt2:7)
B(6,10,6,chisel:basalt2:7)
B(7,10,6,STONEBRICK:0)
B(0,10,7,STONEBRICK:0)
B(1,10,7,STONEBRICK:0)
B(2,10,7,STONEBRICK:0)
B(3,10,7,STONEBRICK:0)
B(4,10,7,STONEBRICK:0)
B(5,10,7,STONEBRICK:0)
B(6,10,7,STONEBRICK:0)
B(7,10,7,STONEBRICK:0)
B(0,11,0,chisel:basalt2:7)
B(1,11,0,chisel:basalt2:7)
B(2,11,0,chisel:basalt2:7)
B(3,11,0,chisel:basalt2:7)
B(4,11,0,chisel:basalt2:7)
B(5,11,0,chisel:basalt2:7)
B(6,11,0,chisel:basalt2:7)
B(7,11,0,STONEBRICK:0)
B(0,11,1,chisel:basalt2:7)
B(1,11,1,chisel:basalt2:7)
B(2,11,1,chisel:basalt2:7)
B(3,11,1,chisel:basalt2:7)
B(4,11,1,chisel:basalt2:7)
B(5,11,1,chisel:basalt2:7)
B(6,11,1,chisel:basalt2:7)
B(7,11,1,STONEBRICK:0)
B(0,11,2,chisel:basalt2:7)
B(1,11,2,chisel:basalt2:7)
B(2,11,2,chisel:basalt2:7)
B(3,11,2,chisel:basalt2:7)
B(4,11,2,chisel:basalt2:7)
B(5,11,2,chisel:basalt2:7)
B(6,11,2,chisel:basalt2:7)
B(7,11,2,STONEBRICK:0)
B(0,11,3,chisel:basalt2:7)
B(1,11,3,chisel:basalt2:7)
B(2,11,3,chisel:basalt2:7)
B(3,11,3,chisel:basalt2:7)
B(4,11,3,chisel:basalt2:7)
B(5,11,3,chisel:basalt2:7)
B(6,11,3,chisel:basalt2:7)
B(7,11,3,STONEBRICK:0)
B(0,11,4,chisel:basalt2:7)
B(1,11,4,chisel:basalt2:7)
B(2,11,4,chisel:basalt2:7)
B(3,11,4,chisel:basalt2:7)
B(4,11,4,chisel:basalt2:7)
B(5,11,4,chisel:basalt2:7)
B(6,11,4,chisel:basalt2:7)
B(7,11,4,STONEBRICK:0)
B(0,11,5,chisel:basalt2:7)
B(1,11,5,chisel:basalt2:7)
B(2,11,5,chisel:basalt2:7)
B(3,11,5,chisel:basalt2:7)
B(4,11,5,chisel:basalt2:7)
B(5,11,5,chisel:basalt2:7)
B(6,11,5,chisel:basalt2:7)
B(7,11,5,STONEBRICK:0)
B(0,11,6,chisel:basalt2:7)
B(1,11,6,chisel:basalt2:7)
B(2,11,6,chisel:basalt2:7)
B(3,11,6,chisel:basalt2:7)
B(4,11,6,chisel:basalt2:7)
B(5,11,6,chisel:basalt2:7)
B(6,11,6,chisel:basalt2:7)
B(7,11,6,STONEBRICK:0)
B(0,11,7,STONEBRICK:0)
B(1,11,7,STONEBRICK:0)
B(2,11,7,STONEBRICK:0)
B(3,11,7,STONEBRICK:0)
B(4,11,7,STONEBRICK:0)
B(5,11,7,STONEBRICK:0)
B(6,11,7,STONEBRICK:0)
B(7,11,7,STONEBRICK:0)
B(0,12,0,chisel:basalt2:7)
B(1,12,0,chisel:basalt2:7)
B(2,12,0,chisel:basalt2:7)
B(3,12,0,chisel:basalt2:7)
B(4,12,0,chisel:basalt2:7)
B(5,12,0,chisel:basalt2:7)
B(6,12,0,chisel:basalt2:7)
B(7,12,0,STONEBRICK:0)
B(0,12,1,chisel:basalt2:7)
B(1,12,1,chisel:basalt2:7)
B(2,12,1,chisel:basalt2:7)
B(3,12,1,chisel:basalt2:7)
B(4,12,1,chisel:basalt2:7)
B(5,12,1,chisel:basalt2:7)
B(6,12,1,chisel:basalt2:7)
B(7,12,1,STONEBRICK:0)
B(0,12,2,chisel:basalt2:7)
B(1,12,2,chisel:basalt2:7)
B(2,12,2,chisel:basalt2:7)
B(3,12,2,chisel:basalt2:7)
B(4,12,2,chisel:basalt2:7)
B(5,12,2,chisel:basalt2:7)
B(6,12,2,chisel:basalt2:7)
B(7,12,2,STONEBRICK:0)
B(0,12,3,chisel:basalt2:7)
B(1,12,3,chisel:basalt2:7)
B(2,12,3,chisel:basalt2:7)
B(3,12,3,chisel:basalt2:7)
B(4,12,3,chisel:basalt2:7)
B(5,12,3,chisel:basalt2:7)
B(6,12,3,chisel:basalt2:7)
B(7,12,3,STONEBRICK:0)
B(0,12,4,chisel:basalt2:7)
B(1,12,4,chisel:basalt2:7)
B(2,12,4,chisel:basalt2:7)
B(3,12,4,chisel:basalt2:7)
B(4,12,4,chisel:basalt2:7)
B(5,12,4,chisel:basalt2:7)
B(6,12,4,chisel:basalt2:7)
B(7,12,4,STONEBRICK:0)
B(0,12,5,chisel:basalt2:7)
B(1,12,5,chisel:basalt2:7)
B(2,12,5,chisel:basalt2:7)
B(3,12,5,chisel:basalt2:7)
B(4,12,5,chisel:basalt2:7)
B(5,12,5,chisel:basalt2:7)
B(6,12,5,chisel:basalt2:7)
B(7,12,5,STONEBRICK:0)
B(0,12,6,chisel:basalt2:7)
B(1,12,6,chisel:basalt2:7)
B(2,12,6,chisel:basalt2:7)
B(3,12,6,chisel:basalt2:7)
B(4,12,6,chisel:basalt2:7)
B(5,12,6,chisel:basalt2:7)
B(6,12,6,chisel:basalt2:7)
B(7,12,6,STONEBRICK:0)
B(0,12,7,STONEBRICK:0)
B(1,12,7,STONEBRICK:0)
B(2,12,7,STONEBRICK:0)
B(3,12,7,STONEBRICK:0)
B(4,12,7,STONEBRICK:0)
B(5,12,7,STONEBRICK:0)
B(6,12,7,STONEBRICK:0)
B(7,12,7,STONEBRICK:0)
B(0,13,0,chisel:basalt2:7)
B(1,13,0,chisel:basalt2:7)
B(2,13,0,chisel:basalt2:7)
B(3,13,0,chisel:basalt2:7)
B(4,13,0,chisel:basalt2:7)
B(5,13,0,chisel:basalt2:7)
B(6,13,0,chisel:basalt2:7)
B(7,13,0,STONEBRICK:0)
B(0,13,1,chisel:basalt2:7)
B(1,13,1,chisel:basalt2:7)
B(2,13,1,chisel:basalt2:7)
B(3,13,1,chisel:basalt2:7)
B(4,13,1,chisel:basalt2:7)
B(5,13,1,chisel:basalt2:7)
B(6,13,1,chisel:basalt2:7)
B(7,13,1,STONEBRICK:0)
B(0,13,2,chisel:basalt2:7)
B(1,13,2,chisel:basalt2:7)
B(2,13,2,chisel:basalt2:7)
B(3,13,2,chisel:basalt2:7)
B(4,13,2,chisel:basalt2:7)
B(5,13,2,chisel:basalt2:7)
B(6,13,2,chisel:basalt2:7)
B(7,13,2,STONEBRICK:0)
B(0,13,3,chisel:basalt2:7)
B(1,13,3,chisel:basalt2:7)
B(2,13,3,chisel:basalt2:7)
B(3,13,3,chisel:basalt2:7)
B(4,13,3,chisel:basalt2:7)
B(5,13,3,chisel:basalt2:7)
B(6,13,3,chisel:basalt2:7)
B(7,13,3,STONEBRICK:0)
B(0,13,4,chisel:basalt2:7)
B(1,13,4,chisel:basalt2:7)
B(2,13,4,chisel:basalt2:7)
B(3,13,4,chisel:basalt2:7)
B(4,13,4,chisel:basalt2:7)
B(5,13,4,chisel:basalt2:7)
B(6,13,4,chisel:basalt2:7)
B(7,13,4,STONEBRICK:0)
B(0,13,5,chisel:basalt2:7)
B(1,13,5,chisel:basalt2:7)
B(2,13,5,chisel:basalt2:7)
B(3,13,5,chisel:basalt2:7)
B(4,13,5,chisel:basalt2:7)
B(5,13,5,chisel:basalt2:7)
B(6,13,5,chisel:basalt2:7)
B(7,13,5,STONEBRICK:0)
B(0,13,6,chisel:basalt2:7)
B(1,13,6,chisel:basalt2:7)
B(2,13,6,chisel:basalt2:7)
B(3,13,6,chisel:basalt2:7)
B(4,13,6,chisel:basalt2:7)
B(5,13,6,chisel:basalt2:7)
B(6,13,6,chisel:basalt2:7)
B(7,13,6,STONEBRICK:0)
B(0,13,7,STONEBRICK:0)
B(1,13,7,STONEBRICK:0)
B(2,13,7,STONEBRICK:0)
B(3,13,7,STONEBRICK:0)
B(4,13,7,STONEBRICK:0)
B(5,13,7,STONEBRICK:0)
B(6,13,7,STONEBRICK:0)
B(7,13,7,STONEBRICK:0)
B(0,14,0,chisel:basalt2:7)
B(1,14,0,chisel:basalt2:7)
B(2,14,0,chisel:basalt2:7)
B(3,14,0,chisel:basalt2:7)
B(4,14,0,chisel:basalt2:7)
B(5,14,0,chisel:basalt2:7)
B(6,14,0,chisel:basalt2:7)
B(7,14,0,STONEBRICK:0)
B(0,14,1,chisel:basalt2:7)
B(1,14,1,chisel:basalt2:7)
B(2,14,1,chisel:basalt2:7)
B(3,14,1,chisel:basalt2:7)
B(4,14,1,chisel:basalt2:7)
B(5,14,1,chisel:basalt2:7)
B(6,14,1,chisel:basalt2:7)
B(7,14,1,STONEBRICK:0)
B(0,14,2,chisel:basalt2:7)
B(1,14,2,chisel:basalt2:7)
B(2,14,2,chisel:basalt2:7)
B(3,14,2,chisel:basalt2:7)
B(4,14,2,chisel:basalt2:7)
B(5,14,2,chisel:basalt2:7)
B(6,14,2,chisel:basalt2:7)
B(7,14,2,STONEBRICK:0)
B(0,14,3,chisel:basalt2:7)
B(1,14,3,chisel:basalt2:7)
B(2,14,3,chisel:basalt2:7)
B(3,14,3,chisel:basalt2:7)
B(4,14,3,chisel:basalt2:7)
B(5,14,3,chisel:basalt2:7)
B(6,14,3,chisel:basalt2:7)
B(7,14,3,STONEBRICK:0)
B(0,14,4,chisel:basalt2:7)
B(1,14,4,chisel:basalt2:7)
B(2,14,4,chisel:basalt2:7)
B(3,14,4,chisel:basalt2:7)
B(4,14,4,chisel:basalt2:7)
B(5,14,4,chisel:basalt2:7)
B(6,14,4,chisel:basalt2:7)
B(7,14,4,STONEBRICK:0)
B(0,14,5,chisel:basalt2:7)
B(1,14,5,chisel:basalt2:7)
B(2,14,5,chisel:basalt2:7)
B(3,14,5,chisel:basalt2:7)
B(4,14,5,chisel:basalt2:7)
B(5,14,5,chisel:basalt2:7)
B(6,14,5,chisel:basalt2:7)
B(7,14,5,STONEBRICK:0)
B(0,14,6,chisel:basalt2:7)
B(1,14,6,chisel:basalt2:7)
B(2,14,6,chisel:basalt2:7)
B(3,14,6,chisel:basalt2:7)
B(4,14,6,chisel:basalt2:7)
B(5,14,6,chisel:basalt2:7)
B(6,14,6,chisel:basalt2:7)
B(7,14,6,STONEBRICK:0)
B(0,14,7,STONEBRICK:0)
B(1,14,7,STONEBRICK:0)
B(2,14,7,STONEBRICK:0)
B(3,14,7,STONEBRICK:0)
B(4,14,7,STONEBRICK:0)
B(5,14,7,STONEBRICK:0)
B(6,14,7,STONEBRICK:0)
B(7,14,7,STONEBRICK:0)
B(0,15,0,chisel:basalt2:7)
B(1,15,0,chisel:basalt2:7)
B(2,15,0,chisel:basalt2:7)
B(3,15,0,chisel:basalt2:7)
B(4,15,0,chisel:basalt2:7)
B(5,15,0,chisel:basalt2:7)
B(6,15,0,chisel:basalt2:7)
B(7,15,0,STONEBRICK:0)
B(0,15,1,chisel:basalt2:7)
B(1,15,1,chisel:basalt2:7)
B(2,15,1,chisel:basalt2:7)
B(3,15,1,chisel:basalt2:7)
B(4,15,1,chisel:basalt2:7)
B(5,15,1,chisel:basalt2:7)
B(6,15,1,chisel:basalt2:7)
B(7,15,1,STONEBRICK:0)
B(0,15,2,chisel:basalt2:7)
B(1,15,2,chisel:basalt2:7)
B(2,15,2,chisel:basalt2:7)
B(3,15,2,chisel:basalt2:7)
B(4,15,2,chisel:basalt2:7)
B(5,15,2,chisel:basalt2:7)
B(6,15,2,chisel:basalt2:7)
B(7,15,2,STONEBRICK:0)
B(0,15,3,chisel:basalt2:7)
B(1,15,3,chisel:basalt2:7)
B(2,15,3,chisel:basalt2:7)
B(3,15,3,chisel:basalt2:7)
B(4,15,3,chisel:basalt2:7)
B(5,15,3,chisel:basalt2:7)
B(6,15,3,chisel:basalt2:7)
B(7,15,3,STONEBRICK:0)
B(0,15,4,chisel:basalt2:7)
B(1,15,4,chisel:basalt2:7)
B(2,15,4,chisel:basalt2:7)
B(3,15,4,chisel:basalt2:7)
B(4,15,4,chisel:basalt2:7)
B(5,15,4,chisel:basalt2:7)
B(6,15,4,chisel:basalt2:7)
B(7,15,4,STONEBRICK:0)
B(0,15,5,chisel:basalt2:7)
B(1,15,5,chisel:basalt2:7)
B(2,15,5,chisel:basalt2:7)
B(3,15,5,chisel:basalt2:7)
B(4,15,5,chisel:basalt2:7)
B(5,15,5,chisel:basalt2:7)
B(6,15,5,chisel:basalt2:7)
B(7,15,5,STONEBRICK:0)
B(0,15,6,chisel:basalt2:7)
B(1,15,6,chisel:basalt2:7)
B(2,15,6,chisel:basalt2:7)
B(3,15,6,chisel:basalt2:7)
B(4,15,6,chisel:basalt2:7)
B(5,15,6,chisel:basalt2:7)
B(6,15,6,chisel:basalt2:7)
B(7,15,6,STONEBRICK:0)
B(0,15,7,STONEBRICK:0)
B(1,15,7,STONEBRICK:0)
B(2,15,7,STONEBRICK:0)
B(3,15,7,STONEBRICK:0)
B(4,15,7,STONEBRICK:0)
B(5,15,7,STONEBRICK:0)
B(6,15,7,STONEBRICK:0)
B(7,15,7,STONEBRICK:0)
B(0,16,0,chisel:basalt2:7)
B(1,16,0,chisel:basalt2:7)
B(2,16,0,chisel:basalt2:7)
B(3,16,0,chisel:basalt2:7)
B(4,16,0,chisel:basalt2:7)
B(5,16,0,chisel:basalt2:7)
B(6,16,0,chisel:basalt2:7)
B(7,16,0,STONEBRICK:0)
B(0,16,1,chisel:basalt2:7)
B(1,16,1,chisel:basalt2:7)
B(2,16,1,chisel:basalt2:7)
B(3,16,1,chisel:basalt2:7)
B(4,16,1,chisel:basalt2:7)
B(5,16,1,chisel:basalt2:7)
B(6,16,1,chisel:basalt2:7)
B(7,16,1,STONEBRICK:0)
B(0,16,2,chisel:basalt2:7)
B(1,16,2,chisel:basalt2:7)
B(2,16,2,chisel:basalt2:7)
B(3,16,2,chisel:basalt2:7)
B(4,16,2,chisel:basalt2:7)
B(5,16,2,chisel:basalt2:7)
B(6,16,2,chisel:basalt2:7)
B(7,16,2,STONEBRICK:0)
B(0,16,3,chisel:basalt2:7)
B(1,16,3,chisel:basalt2:7)
B(2,16,3,chisel:basalt2:7)
B(3,16,3,chisel:basalt2:7)
B(4,16,3,chisel:basalt2:7)
B(5,16,3,chisel:basalt2:7)
B(6,16,3,chisel:basalt2:7)
B(7,16,3,STONEBRICK:0)
B(0,16,4,chisel:basalt2:7)
B(1,16,4,chisel:basalt2:7)
B(2,16,4,chisel:basalt2:7)
B(3,16,4,chisel:basalt2:7)
B(4,16,4,chisel:basalt2:7)
B(5,16,4,chisel:basalt2:7)
B(6,16,4,chisel:basalt2:7)
B(7,16,4,STONEBRICK:0)
B(0,16,5,chisel:basalt2:7)
B(1,16,5,chisel:basalt2:7)
B(2,16,5,chisel:basalt2:7)
B(3,16,5,chisel:basalt2:7)
B(4,16,5,chisel:basalt2:7)
B(5,16,5,chisel:basalt2:7)
B(6,16,5,chisel:basalt2:7)
B(7,16,5,STONEBRICK:0)
B(0,16,6,chisel:basalt2:7)
B(1,16,6,chisel:basalt2:7)
B(2,16,6,chisel:basalt2:7)
B(3,16,6,chisel:basalt2:7)
B(4,16,6,chisel:basalt2:7)
B(5,16,6,chisel:basalt2:7)
B(6,16,6,chisel:basalt2:7)
B(7,16,6,STONEBRICK:0)
B(0,16,7,STONEBRICK:0)
B(1,16,7,STONEBRICK:0)
B(2,16,7,STONEBRICK:0)
B(3,16,7,STONEBRICK:0)
B(4,16,7,STONEBRICK:0)
B(5,16,7,STONEBRICK:0)
B(6,16,7,STONEBRICK:0)
B(7,16,7,STONEBRICK:0)
B(0,17,0,chisel:basalt2:7)
B(1,17,0,chisel:basalt2:7)
B(2,17,0,chisel:basalt2:7)
B(3,17,0,chisel:basalt2:7)
B(4,17,0,chisel:basalt2:7)
B(5,17,0,chisel:basalt2:7)
B(6,17,0,chisel:basalt2:7)
B(7,17,0,STONEBRICK:0)
B(0,17,1,chisel:basalt2:7)
B(1,17,1,chisel:basalt2:7)
B(2,17,1,chisel:basalt2:7)
B(3,17,1,chisel:basalt2:7)
B(4,17,1,chisel:basalt2:7)
B(5,17,1,chisel:basalt2:7)
B(6,17,1,chisel:basalt2:7)
B(7,17,1,STONEBRICK:0)
B(0,17,2,chisel:basalt2:7)
B(1,17,2,chisel:basalt2:7)
B(2,17,2,chisel:basalt2:7)
B(3,17,2,chisel:basalt2:7)
B(4,17,2,chisel:basalt2:7)
B(5,17,2,chisel:basalt2:7)
B(6,17,2,chisel:basalt2:7)
B(7,17,2,STONEBRICK:0)
B(0,17,3,chisel:basalt2:7)
B(1,17,3,chisel:basalt2:7)
B(2,17,3,chisel:basalt2:7)
B(3,17,3,chisel:basalt2:7)
B(4,17,3,chisel:basalt2:7)
B(5,17,3,chisel:basalt2:7)
B(6,17,3,chisel:basalt2:7)
B(7,17,3,STONEBRICK:0)
B(0,17,4,chisel:basalt2:7)
B(1,17,4,chisel:basalt2:7)
B(2,17,4,chisel:basalt2:7)
B(3,17,4,chisel:basalt2:7)
B(4,17,4,chisel:basalt2:7)
B(5,17,4,chisel:basalt2:7)
B(6,17,4,chisel:basalt2:7)
B(7,17,4,STONEBRICK:0)
B(0,17,5,chisel:basalt2:7)
B(1,17,5,chisel:basalt2:7)
B(2,17,5,chisel:basalt2:7)
B(3,17,5,chisel:basalt2:7)
B(4,17,5,chisel:basalt2:7)
B(5,17,5,chisel:basalt2:7)
B(6,17,5,chisel:basalt2:7)
B(7,17,5,STONEBRICK:0)
B(0,17,6,chisel:basalt2:7)
B(1,17,6,chisel:basalt2:7)
B(2,17,6,chisel:basalt2:7)
B(3,17,6,chisel:basalt2:7)
B(4,17,6,chisel:basalt2:7)
B(5,17,6,chisel:basalt2:7)
B(6,17,6,chisel:basalt2:7)
B(7,17,6,STONEBRICK:0)
B(0,17,7,STONEBRICK:0)
B(1,17,7,STONEBRICK:0)
B(2,17,7,STONEBRICK:0)
B(3,17,7,STONEBRICK:0)
B(4,17,7,STONEBRICK:0)
B(5,17,7,STONEBRICK:0)
B(6,17,7,STONEBRICK:0)
B(7,17,7,STONEBRICK:0)
B(0,18,0,chisel:basalt2:7)
B(1,18,0,chisel:basalt2:7)
B(2,18,0,chisel:basalt2:7)
B(3,18,0,chisel:basalt2:7)
B(4,18,0,chisel:basalt2:7)
B(5,18,0,chisel:basalt2:7)
B(6,18,0,chisel:basalt2:7)
B(7,18,0,STONEBRICK:0)
B(0,18,1,chisel:basalt2:7)
B(1,18,1,chisel:basalt2:7)
B(2,18,1,chisel:basalt2:7)
B(3,18,1,chisel:basalt2:7)
B(4,18,1,chisel:basalt2:7)
B(5,18,1,chisel:basalt2:7)
B(6,18,1,chisel:basalt2:7)
B(7,18,1,STONEBRICK:0)
B(0,18,2,chisel:basalt2:7)
B(1,18,2,chisel:basalt2:7)
B(2,18,2,chisel:basalt2:7)
B(3,18,2,chisel:basalt2:7)
B(4,18,2,chisel:basalt2:7)
B(5,18,2,chisel:basalt2:7)
B(6,18,2,chisel:basalt2:7)
B(7,18,2,STONEBRICK:0)
B(0,18,3,chisel:basalt2:7)
B(1,18,3,chisel:basalt2:7)
B(2,18,3,chisel:basalt2:7)
B(3,18,3,chisel:basalt2:7)
B(4,18,3,chisel:basalt2:7)
B(5,18,3,chisel:basalt2:7)
B(6,18,3,chisel:basalt2:7)
B(7,18,3,STONEBRICK:0)
B(0,18,4,chisel:basalt2:7)
B(1,18,4,chisel:basalt2:7)
B(2,18,4,chisel:basalt2:7)
B(3,18,4,chisel:basalt2:7)
B(4,18,4,chisel:basalt2:7)
B(5,18,4,chisel:basalt2:7)
B(6,18,4,chisel:basalt2:7)
B(7,18,4,STONEBRICK:0)
B(0,18,5,chisel:basalt2:7)
B(1,18,5,chisel:basalt2:7)
B(2,18,5,chisel:basalt2:7)
B(3,18,5,chisel:basalt2:7)
B(4,18,5,chisel:basalt2:7)
B(5,18,5,chisel:basalt2:7)
B(6,18,5,chisel:basalt2:7)
B(7,18,5,STONEBRICK:0)
B(0,18,6,chisel:basalt2:7)
B(1,18,6,chisel:basalt2:7)
B(2,18,6,chisel:basalt2:7)
B(3,18,6,chisel:basalt2:7)
B(4,18,6,chisel:basalt2:7)
B(5,18,6,chisel:basalt2:7)
B(6,18,6,chisel:basalt2:7)
B(7,18,6,STONEBRICK:0)
B(0,18,7,STONEBRICK:0)
B(1,18,7,STONEBRICK:0)
B(2,18,7,STONEBRICK:0)
B(3,18,7,STONEBRICK:0)
B(4,18,7,STONEBRICK:0)
B(5,18,7,STONEBRICK:0)
B(6,18,7,STONEBRICK:0)
B(7,18,7,STONEBRICK:0)
B(0,19,0,chisel:basalt2:7)
B(1,19,0,chisel:basalt2:7)
B(2,19,0,chisel:basalt2:7)
B(3,19,0,chisel:basalt2:7)
B(4,19,0,chisel:basalt2:7)
B(5,19,0,chisel:basalt2:7)
B(6,19,0,chisel:basalt2:7)
B(7,19,0,STONEBRICK:0)
B(0,19,1,chisel:basalt2:7)
B(1,19,1,chisel:basalt2:7)
B(2,19,1,chisel:basalt2:7)
B(3,19,1,chisel:basalt2:7)
B(4,19,1,chisel:basalt2:7)
B(5,19,1,chisel:basalt2:7)
B(6,19,1,chisel:basalt2:7)
B(7,19,1,STONEBRICK:0)
B(0,19,2,chisel:basalt2:7)
B(1,19,2,chisel:basalt2:7)
B(2,19,2,chisel:basalt2:7)
B(3,19,2,chisel:basalt2:7)
B(4,19,2,chisel:basalt2:7)
B(5,19,2,chisel:basalt2:7)
B(6,19,2,chisel:basalt2:7)
B(7,19,2,STONEBRICK:0)
B(0,19,3,chisel:basalt2:7)
B(1,19,3,chisel:basalt2:7)
B(2,19,3,chisel:basalt2:7)
B(3,19,3,chisel:basalt2:7)
B(4,19,3,chisel:basalt2:7)
B(5,19,3,chisel:basalt2:7)
B(6,19,3,chisel:basalt2:7)
B(7,19,3,STONEBRICK:0)
B(0,19,4,chisel:basalt2:7)
B(1,19,4,chisel:basalt2:7)
B(2,19,4,chisel:basalt2:7)
B(3,19,4,chisel:basalt2:7)
B(4,19,4,chisel:basalt2:7)
B(5,19,4,chisel:basalt2:7)
B(6,19,4,chisel:basalt2:7)
B(7,19,4,STONEBRICK:0)
B(0,19,5,chisel:basalt2:7)
B(1,19,5,chisel:basalt2:7)
B(2,19,5,chisel:basalt2:7)
B(3,19,5,chisel:basalt2:7)
B(4,19,5,chisel:basalt2:7)
B(5,19,5,chisel:basalt2:7)
B(6,19,5,chisel:basalt2:7)
B(7,19,5,STONEBRICK:0)
B(0,19,6,chisel:basalt2:7)
B(1,19,6,chisel:basalt2:7)
B(2,19,6,chisel:basalt2:7)
B(3,19,6,chisel:basalt2:7)
B(4,19,6,chisel:basalt2:7)
B(5,19,6,chisel:basalt2:7)
B(6,19,6,chisel:basalt2:7)
B(7,19,6,STONEBRICK:0)
B(0,19,7,STONEBRICK:0)
B(1,19,7,STONEBRICK:0)
B(2,19,7,STONEBRICK:0)
B(3,19,7,STONEBRICK:0)
B(4,19,7,STONEBRICK:0)
B(5,19,7,STONEBRICK:0)
B(6,19,7,STONEBRICK:0)
B(7,19,7,STONEBRICK:0)
B(0,20,0,chisel:basalt2:7)
B(1,20,0,chisel:basalt2:7)
B(2,20,0,chisel:basalt2:7)
B(3,20,0,chisel:basalt2:7)
B(4,20,0,chisel:basalt2:7)
B(5,20,0,chisel:basalt2:7)
B(6,20,0,chisel:basalt2:7)
B(7,20,0,STONEBRICK:0)
B(0,20,1,chisel:basalt2:7)
B(1,20,1,chisel:basalt2:7)
B(2,20,1,chisel:basalt2:7)
B(3,20,1,chisel:basalt2:7)
B(4,20,1,chisel:basalt2:7)
B(5,20,1,chisel:basalt2:7)
B(6,20,1,chisel:basalt2:7)
B(7,20,1,STONEBRICK:0)
B(0,20,2,chisel:basalt2:7)
B(1,20,2,chisel:basalt2:7)
B(2,20,2,chisel:basalt2:7)
B(3,20,2,chisel:basalt2:7)
B(4,20,2,chisel:basalt2:7)
B(5,20,2,chisel:basalt2:7)
B(6,20,2,chisel:basalt2:7)
B(7,20,2,STONEBRICK:0)
B(0,20,3,chisel:basalt2:7)
B(1,20,3,chisel:basalt2:7)
B(2,20,3,chisel:basalt2:7)
B(3,20,3,chisel:basalt2:7)
B(4,20,3,chisel:basalt2:7)
B(5,20,3,chisel:basalt2:7)
B(6,20,3,chisel:basalt2:7)
B(7,20,3,STONEBRICK:0)
B(0,20,4,chisel:basalt2:7)
B(1,20,4,chisel:basalt2:7)
B(2,20,4,chisel:basalt2:7)
B(3,20,4,chisel:basalt2:7)
B(4,20,4,chisel:basalt2:7)
B(5,20,4,chisel:basalt2:7)
B(6,20,4,chisel:basalt2:7)
B(7,20,4,STONEBRICK:0)
B(0,20,5,chisel:basalt2:7)
B(1,20,5,chisel:basalt2:7)
B(2,20,5,chisel:basalt2:7)
B(3,20,5,chisel:basalt2:7)
B(4,20,5,chisel:basalt2:7)
B(5,20,5,chisel:basalt2:7)
B(6,20,5,chisel:basalt2:7)
B(7,20,5,STONEBRICK:0)
B(0,20,6,chisel:basalt2:7)
B(1,20,6,chisel:basalt2:7)
B(2,20,6,chisel:basalt2:7)
B(3,20,6,chisel:basalt2:7)
B(4,20,6,chisel:basalt2:7)
B(5,20,6,chisel:basalt2:7)
B(6,20,6,chisel:basalt2:7)
B(7,20,6,STONEBRICK:0)
B(0,20,7,STONEBRICK:0)
B(1,20,7,STONEBRICK:0)
B(2,20,7,STONEBRICK:0)
B(3,20,7,STONEBRICK:0)
B(4,20,7,STONEBRICK:0)
B(5,20,7,STONEBRICK:0)
B(6,20,7,STONEBRICK:0)
B(7,20,7,STONEBRICK:0)
B(0,21,0,chisel:basalt2:7)
B(1,21,0,chisel:basalt2:7)
B(2,21,0,chisel:basalt2:7)
B(3,21,0,chisel:basalt2:7)
B(4,21,0,chisel:basalt2:7)
B(5,21,0,chisel:basalt2:7)
B(6,21,0,chisel:basalt2:7)
B(7,21,0,STONEBRICK:0)
B(0,21,1,chisel:basalt2:7)
B(1,21,1,chisel:basalt2:7)
B(2,21,1,chisel:basalt2:7)
B(3,21,1,chisel:basalt2:7)
B(4,21,1,chisel:basalt2:7)
B(5,21,1,chisel:basalt2:7)
B(6,21,1,chisel:basalt2:7)
B(7,21,1,STONEBRICK:0)
B(0,21,2,chisel:basalt2:7)
B(1,21,2,chisel:basalt2:7)
B(2,21,2,chisel:basalt2:7)
B(3,21,2,chisel:basalt2:7)
B(4,21,2,chisel:basalt2:7)
B(5,21,2,chisel:basalt2:7)
B(6,21,2,chisel:basalt2:7)
B(7,21,2,STONEBRICK:0)
B(0,21,3,chisel:basalt2:7)
B(1,21,3,chisel:basalt2:7)
B(2,21,3,chisel:basalt2:7)
B(3,21,3,chisel:basalt2:7)
B(4,21,3,chisel:basalt2:7)
B(5,21,3,chisel:basalt2:7)
B(6,21,3,chisel:basalt2:7)
B(7,21,3,STONEBRICK:0)
B(0,21,4,chisel:basalt2:7)
B(1,21,4,chisel:basalt2:7)
B(2,21,4,chisel:basalt2:7)
B(3,21,4,chisel:basalt2:7)
B(4,21,4,chisel:basalt2:7)
B(5,21,4,chisel:basalt2:7)
B(6,21,4,chisel:basalt2:7)
B(7,21,4,STONEBRICK:0)
B(0,21,5,chisel:basalt2:7)
B(1,21,5,chisel:basalt2:7)
B(2,21,5,chisel:basalt2:7)
B(3,21,5,chisel:basalt2:7)
B(4,21,5,chisel:basalt2:7)
B(5,21,5,chisel:basalt2:7)
B(6,21,5,chisel:basalt2:7)
B(7,21,5,STONEBRICK:0)
B(0,21,6,chisel:basalt2:7)
B(1,21,6,chisel:basalt2:7)
B(2,21,6,chisel:basalt2:7)
B(3,21,6,chisel:basalt2:7)
B(4,21,6,chisel:basalt2:7)
B(5,21,6,chisel:basalt2:7)
B(6,21,6,chisel:basalt2:7)
B(7,21,6,STONEBRICK:0)
B(0,21,7,STONEBRICK:0)
B(1,21,7,STONEBRICK:0)
B(2,21,7,STONEBRICK:0)
B(3,21,7,STONEBRICK:0)
B(4,21,7,STONEBRICK:0)
B(5,21,7,STONEBRICK:0)
B(6,21,7,STONEBRICK:0)
B(7,21,7,STONEBRICK:0)
B(0,22,0,chisel:basalt2:7)
B(1,22,0,chisel:basalt2:7)
B(2,22,0,chisel:basalt2:7)
B(3,22,0,chisel:basalt2:7)
B(4,22,0,chisel:basalt2:7)
B(5,22,0,chisel:basalt2:7)
B(6,22,0,chisel:basalt2:7)
B(7,22,0,STONEBRICK:0)
B(0,22,1,chisel:basalt2:7)
B(1,22,1,chisel:basalt2:7)
B(2,22,1,chisel:basalt2:7)
B(3,22,1,chisel:basalt2:7)
B(4,22,1,chisel:basalt2:7)
B(5,22,1,chisel:basalt2:7)
B(6,22,1,chisel:basalt2:7)
B(7,22,1,STONEBRICK:0)
B(0,22,2,chisel:basalt2:7)
B(1,22,2,chisel:basalt2:7)
B(2,22,2,chisel:basalt2:7)
B(3,22,2,chisel:basalt2:7)
B(4,22,2,chisel:basalt2:7)
B(5,22,2,chisel:basalt2:7)
B(6,22,2,chisel:basalt2:7)
B(7,22,2,STONEBRICK:0)
B(0,22,3,chisel:basalt2:7)
B(1,22,3,chisel:basalt2:7)
B(2,22,3,chisel:basalt2:7)
B(3,22,3,chisel:basalt2:7)
B(4,22,3,chisel:basalt2:7)
B(5,22,3,chisel:basalt2:7)
B(6,22,3,chisel:basalt2:7)
B(7,22,3,STONEBRICK:0)
B(0,22,4,chisel:basalt2:7)
B(1,22,4,chisel:basalt2:7)
B(2,22,4,chisel:basalt2:7)
B(3,22,4,chisel:basalt2:7)
B(4,22,4,chisel:basalt2:7)
B(5,22,4,chisel:basalt2:7)
B(6,22,4,chisel:basalt2:7)
B(7,22,4,STONEBRICK:0)
B(0,22,5,chisel:basalt2:7)
B(1,22,5,chisel:basalt2:7)
B(2,22,5,chisel:basalt2:7)
B(3,22,5,chisel:basalt2:7)
B(4,22,5,chisel:basalt2:7)
B(5,22,5,chisel:basalt2:7)
B(6,22,5,chisel:basalt2:7)
B(7,22,5,STONEBRICK:0)
B(0,22,6,chisel:basalt2:7)
B(1,22,6,chisel:basalt2:7)
B(2,22,6,chisel:basalt2:7)
B(3,22,6,chisel:basalt2:7)
B(4,22,6,chisel:basalt2:7)
B(5,22,6,chisel:basalt2:7)
B(6,22,6,chisel:basalt2:7)
B(7,22,6,STONEBRICK:0)
B(0,22,7,STONEBRICK:0)
B(1,22,7,STONEBRICK:0)
B(2,22,7,STONEBRICK:0)
B(3,22,7,STONEBRICK:0)
B(4,22,7,STONEBRICK:0)
B(5,22,7,STONEBRICK:0)
B(6,22,7,STONEBRICK:0)
B(7,22,7,STONEBRICK:0)
B(0,23,0,chisel:basalt2:7)
B(1,23,0,chisel:basalt2:7)
B(2,23,0,chisel:basalt2:7)
B(3,23,0,chisel:basalt2:7)
B(4,23,0,chisel:basalt2:7)
B(5,23,0,chisel:basalt2:7)
B(6,23,0,chisel:basalt2:7)
B(7,23,0,STONEBRICK:0)
B(0,23,1,chisel:basalt2:7)
B(1,23,1,chisel:basalt2:7)
B(2,23,1,chisel:basalt2:7)
B(3,23,1,chisel:basalt2:7)
B(4,23,1,chisel:basalt2:7)
B(5,23,1,chisel:basalt2:7)
B(6,23,1,chisel:basalt2:7)
B(7,23,1,STONEBRICK:0)
B(0,23,2,chisel:basalt2:7)
B(1,23,2,chisel:basalt2:7)
B(2,23,2,chisel:basalt2:7)
B(3,23,2,chisel:basalt2:7)
B(4,23,2,chisel:basalt2:7)
B(5,23,2,chisel:basalt2:7)
B(6,23,2,chisel:basalt2:7)
B(7,23,2,STONEBRICK:0)
B(0,23,3,chisel:basalt2:7)
B(1,23,3,chisel:basalt2:7)
B(2,23,3,chisel:basalt2:7)
B(3,23,3,chisel:basalt2:7)
B(4,23,3,chisel:basalt2:7)
B(5,23,3,chisel:basalt2:7)
B(6,23,3,chisel:basalt2:7)
B(7,23,3,STONEBRICK:0)
B(0,23,4,chisel:basalt2:7)
B(1,23,4,chisel:basalt2:7)
B(2,23,4,chisel:basalt2:7)
B(3,23,4,chisel:basalt2:7)
B(4,23,4,chisel:basalt2:7)
B(5,23,4,chisel:basalt2:7)
B(6,23,4,chisel:basalt2:7)
B(7,23,4,STONEBRICK:0)
B(0,23,5,chisel:basalt2:7)
B(1,23,5,chisel:basalt2:7)
B(2,23,5,chisel:basalt2:7)
B(3,23,5,chisel:basalt2:7)
B(4,23,5,chisel:basalt2:7)
B(5,23,5,chisel:basalt2:7)
B(6,23,5,chisel:basalt2:7)
B(7,23,5,STONEBRICK:0)
B(0,23,6,chisel:basalt2:7)
B(1,23,6,chisel:basalt2:7)
B(2,23,6,chisel:basalt2:7)
B(3,23,6,chisel:basalt2:7)
B(4,23,6,chisel:basalt2:7)
B(5,23,6,chisel:basalt2:7)
B(6,23,6,chisel:basalt2:7)
B(7,23,6,STONEBRICK:0)
B(0,23,7,STONEBRICK:0)
B(1,23,7,STONEBRICK:0)
B(2,23,7,STONEBRICK:0)
B(3,23,7,STONEBRICK:0)
B(4,23,7,STONEBRICK:0)
B(5,23,7,STONEBRICK:0)
B(6,23,7,STONEBRICK:0)
B(7,23,7,STONEBRICK:0)
B(0,24,0,chisel:basalt2:7)
B(1,24,0,chisel:basalt2:7)
B(2,24,0,chisel:basalt2:7)
B(3,24,0,chisel:basalt2:7)
B(4,24,0,chisel:basalt2:7)
B(5,24,0,chisel:basalt2:7)
B(6,24,0,chisel:basalt2:7)
B(7,24,0,STONEBRICK:0)
B(0,24,1,chisel:basalt2:7)
B(1,24,1,chisel:basalt2:7)
B(2,24,1,chisel:basalt2:7)
B(3,24,1,chisel:basalt2:7)
B(4,24,1,chisel:basalt2:7)
B(5,24,1,chisel:basalt2:7)
B(6,24,1,chisel:basalt2:7)
B(7,24,1,STONEBRICK:0)
B(0,24,2,chisel:basalt2:7)
B(1,24,2,chisel:basalt2:7)
B(2,24,2,chisel:basalt2:7)
B(3,24,2,chisel:basalt2:7)
B(4,24,2,chisel:basalt2:7)
B(5,24,2,chisel:basalt2:7)
B(6,24,2,chisel:basalt2:7)
B(7,24,2,STONEBRICK:0)
B(0,24,3,chisel:basalt2:7)
B(1,24,3,chisel:basalt2:7)
B(2,24,3,chisel:basalt2:7)
B(3,24,3,chisel:basalt2:7)
B(4,24,3,chisel:basalt2:7)
B(5,24,3,chisel:basalt2:7)
B(6,24,3,chisel:basalt2:7)
B(7,24,3,STONEBRICK:0)
B(0,24,4,chisel:basalt2:7)
B(1,24,4,chisel:basalt2:7)
B(2,24,4,chisel:basalt2:7)
B(3,24,4,chisel:basalt2:7)
B(4,24,4,chisel:basalt2:7)
B(5,24,4,chisel:basalt2:7)
B(6,24,4,chisel:basalt2:7)
B(7,24,4,STONEBRICK:0)
B(0,24,5,chisel:basalt2:7)
B(1,24,5,chisel:basalt2:7)
B(2,24,5,chisel:basalt2:7)
B(3,24,5,chisel:basalt2:7)
B(4,24,5,chisel:basalt2:7)
B(5,24,5,chisel:basalt2:7)
B(6,24,5,chisel:basalt2:7)
B(7,24,5,STONEBRICK:0)
B(0,24,6,chisel:basalt2:7)
B(1,24,6,chisel:basalt2:7)
B(2,24,6,chisel:basalt2:7)
B(3,24,6,chisel:basalt2:7)
B(4,24,6,chisel:basalt2:7)
B(5,24,6,chisel:basalt2:7)
B(6,24,6,chisel:basalt2:7)
B(7,24,6,STONEBRICK:0)
B(0,24,7,STONEBRICK:0)
B(1,24,7,STONEBRICK:0)
B(2,24,7,STONEBRICK:0)
B(3,24,7,STONEBRICK:0)
B(4,24,7,STONEBRICK:0)
B(5,24,7,STONEBRICK:0)
B(6,24,7,STONEBRICK:0)
B(7,24,7,STONEBRICK:0)
B(0,25,0,chisel:basalt2:7)
B(1,25,0,chisel:basalt2:7)
B(2,25,0,chisel:basalt2:7)
B(3,25,0,chisel:basalt2:7)
B(4,25,0,chisel:basalt2:7)
B(5,25,0,chisel:basalt2:7)
B(6,25,0,chisel:basalt2:7)
B(7,25,0,STONEBRICK:0)
B(0,25,1,chisel:basalt2:7)
B(1,25,1,chisel:basalt2:7)
B(2,25,1,chisel:basalt2:7)
B(3,25,1,chisel:basalt2:7)
B(4,25,1,chisel:basalt2:7)
B(5,25,1,chisel:basalt2:7)
B(6,25,1,chisel:basalt2:7)
B(7,25,1,STONEBRICK:0)
B(0,25,2,chisel:basalt2:7)
B(1,25,2,chisel:basalt2:7)
B(2,25,2,chisel:basalt2:7)
B(3,25,2,chisel:basalt2:7)
B(4,25,2,chisel:basalt2:7)
B(5,25,2,chisel:basalt2:7)
B(6,25,2,chisel:basalt2:7)
B(7,25,2,STONEBRICK:0)
B(0,25,3,chisel:basalt2:7)
B(1,25,3,chisel:basalt2:7)
B(2,25,3,chisel:basalt2:7)
B(3,25,3,chisel:basalt2:7)
B(4,25,3,chisel:basalt2:7)
B(5,25,3,chisel:basalt2:7)
B(6,25,3,chisel:basalt2:7)
B(7,25,3,STONEBRICK:0)
B(0,25,4,chisel:basalt2:7)
B(1,25,4,chisel:basalt2:7)
B(2,25,4,chisel:basalt2:7)
B(3,25,4,chisel:basalt2:7)
B(4,25,4,chisel:basalt2:7)
B(5,25,4,chisel:basalt2:7)
B(6,25,4,chisel:basalt2:7)
B(7,25,4,STONEBRICK:0)
B(0,25,5,chisel:basalt2:7)
B(1,25,5,chisel:basalt2:7)
B(2,25,5,chisel:basalt2:7)
B(3,25,5,chisel:basalt2:7)
B(4,25,5,chisel:basalt2:7)
B(5,25,5,chisel:basalt2:7)
B(6,25,5,chisel:basalt2:7)
B(7,25,5,STONEBRICK:0)
B(0,25,6,chisel:basalt2:7)
B(1,25,6,chisel:basalt2:7)
B(2,25,6,chisel:basalt2:7)
B(3,25,6,chisel:basalt2:7)
B(4,25,6,chisel:basalt2:7)
B(5,25,6,chisel:basalt2:7)
B(6,25,6,chisel:basalt2:7)
B(7,25,6,STONEBRICK:0)
B(0,25,7,STONEBRICK:0)
B(1,25,7,STONEBRICK:0)
B(2,25,7,STONEBRICK:0)
B(3,25,7,STONEBRICK:0)
B(4,25,7,STONEBRICK:0)
B(5,25,7,STONEBRICK:0)
B(6,25,7,STONEBRICK:0)
B(7,25,7,STONEBRICK:0)
B(0,26,0,REDSTONE_WIRE:0)
B(1,26,0,chisel:basalt2:7)
B(2,26,0,chisel:basalt2:7)
B(3,26,0,chisel:basalt2:7)
B(4,26,0,chisel:basalt2:7)
B(5,26,0,chisel:basalt2:7)
B(6,26,0,chisel:basalt2:7)
B(7,26,0,STONEBRICK:0)
B(0,26,1,REDSTONE_WIRE:0)
B(1,26,1,chisel:basalt2:7)
B(2,26,1,chisel:basalt2:7)
B(3,26,1,chisel:basalt2:7)
B(4,26,1,chisel:basalt2:7)
B(5,26,1,chisel:basalt2:7)
B(6,26,1,chisel:basalt2:7)
B(7,26,1,STONEBRICK:0)
B(0,26,2,REDSTONE_WIRE:0)
B(1,26,2,chisel:basalt2:7)
B(2,26,2,chisel:basalt2:7)
B(3,26,2,chisel:basalt2:7)
B(4,26,2,chisel:basalt2:7)
B(5,26,2,chisel:basalt2:7)
B(6,26,2,chisel:basalt2:7)
B(7,26,2,STONEBRICK:0)
B(0,26,3,REDSTONE_WIRE:0)
B(1,26,3,chisel:basalt2:7)
B(2,26,3,chisel:basalt2:7)
B(3,26,3,chisel:basalt2:7)
B(4,26,3,chisel:basalt2:7)
B(5,26,3,chisel:basalt2:7)
B(6,26,3,chisel:basalt2:7)
B(7,26,3,STONEBRICK:0)
B(0,26,4,REDSTONE_WIRE:0)
B(1,26,4,chisel:basalt2:7)
B(2,26,4,chisel:basalt2:7)
B(3,26,4,chisel:basalt2:7)
B(4,26,4,chisel:basalt2:7)
B(5,26,4,chisel:basalt2:7)
B(6,26,4,chisel:basalt2:7)
B(7,26,4,STONEBRICK:0)
B(0,26,5,REDSTONE_WIRE:0)
B(1,26,5,chisel:basalt2:7)
B(2,26,5,chisel:basalt2:7)
B(3,26,5,chisel:basalt2:7)
B(4,26,5,chisel:basalt2:7)
B(5,26,5,chisel:basalt2:7)
B(6,26,5,chisel:basalt2:7)
B(7,26,5,STONEBRICK:0)
B(0,26,6,chisel:basalt2:7)
B(1,26,6,chisel:basalt2:7)
B(2,26,6,chisel:basalt2:7)
B(3,26,6,chisel:basalt2:7)
B(4,26,6,chisel:basalt2:7)
B(5,26,6,chisel:basalt2:7)
B(6,26,6,chisel:basalt2:7)
B(7,26,6,STONEBRICK:0)
B(0,26,7,STONEBRICK:0)
B(1,26,7,STONEBRICK:0)
B(2,26,7,STONEBRICK:0)
B(3,26,7,STONEBRICK:0)
B(4,26,7,STONEBRICK:0)
B(5,26,7,STONEBRICK:0)
B(6,26,7,STONEBRICK:0)
B(7,26,7,STONEBRICK:0)
B(0,27,0,chisel:basalt2:7)
B(1,27,0,chisel:basalt2:7)
B(2,27,0,chisel:basalt2:7)
B(3,27,0,chisel:basalt2:7)
B(4,27,0,chisel:basalt2:7)
B(5,27,0,chisel:basalt2:7)
B(6,27,0,chisel:basalt2:7)
B(7,27,0,STONEBRICK:0)
B(0,27,1,chisel:basalt2:7)
B(1,27,1,chisel:basalt2:7)
B(2,27,1,chisel:basalt2:7)
B(3,27,1,chisel:basalt2:7)
B(4,27,1,chisel:basalt2:7)
B(5,27,1,chisel:basalt2:7)
B(6,27,1,chisel:basalt2:7)
B(7,27,1,STONEBRICK:0)
B(0,27,2,chisel:basalt2:7)
B(1,27,2,chisel:basalt2:7)
B(2,27,2,chisel:basalt2:7)
B(3,27,2,chisel:basalt2:7)
B(4,27,2,chisel:basalt2:7)
B(5,27,2,chisel:basalt2:7)
B(6,27,2,chisel:basalt2:7)
B(7,27,2,STONEBRICK:0)
B(0,27,3,chisel:basalt2:7)
B(1,27,3,chisel:basalt2:7)
B(2,27,3,chisel:basalt2:7)
B(3,27,3,chisel:basalt2:7)
B(4,27,3,chisel:basalt2:7)
B(5,27,3,chisel:basalt2:7)
B(6,27,3,chisel:basalt2:7)
B(7,27,3,STONEBRICK:0)
B(0,27,4,chisel:basalt2:7)
B(1,27,4,chisel:basalt2:7)
B(2,27,4,chisel:basalt2:7)
B(3,27,4,chisel:basalt2:7)
B(4,27,4,chisel:basalt2:7)
B(5,27,4,chisel:basalt2:7)
B(6,27,4,chisel:basalt2:7)
B(7,27,4,STONEBRICK:0)
B(0,27,5,chisel:basalt2:7)
B(1,27,5,chisel:basalt2:7)
B(2,27,5,chisel:basalt2:7)
B(3,27,5,chisel:basalt2:7)
B(4,27,5,chisel:basalt2:7)
B(5,27,5,chisel:basalt2:7)
B(6,27,5,chisel:basalt2:7)
B(7,27,5,STONEBRICK:0)
B(0,27,6,chisel:basalt2:7)
B(1,27,6,chisel:basalt2:7)
B(2,27,6,chisel:basalt2:7)
B(3,27,6,chisel:basalt2:7)
B(4,27,6,chisel:basalt2:7)
B(5,27,6,chisel:basalt2:7)
B(6,27,6,chisel:basalt2:7)
B(7,27,6,STONEBRICK:0)
B(0,27,7,STONEBRICK:0)
B(1,27,7,STONEBRICK:0)
B(2,27,7,STONEBRICK:0)
B(3,27,7,STONEBRICK:0)
B(4,27,7,STONEBRICK:0)
B(5,27,7,STONEBRICK:0)
B(6,27,7,STONEBRICK:0)
B(7,27,7,STONEBRICK:0)
B(0,28,0,chisel:basalt2:7)
B(1,28,0,chisel:basalt2:7)
B(2,28,0,chisel:basalt2:7)
B(3,28,0,chisel:basalt2:7)
B(4,28,0,chisel:basalt2:7)
B(5,28,0,chisel:basalt2:7)
B(6,28,0,chisel:basalt2:7)
B(7,28,0,STONEBRICK:0)
B(0,28,1,chisel:basalt2:7)
B(1,28,1,chisel:basalt2:7)
B(2,28,1,chisel:basalt2:7)
B(3,28,1,chisel:basalt2:7)
B(4,28,1,chisel:basalt2:7)
B(5,28,1,chisel:basalt2:7)
B(6,28,1,chisel:basalt2:7)
B(7,28,1,STONEBRICK:0)
B(0,28,2,chisel:basalt2:7)
B(1,28,2,chisel:basalt2:7)
B(2,28,2,chisel:basalt2:7)
B(3,28,2,chisel:basalt2:7)
B(4,28,2,chisel:basalt2:7)
B(5,28,2,chisel:basalt2:7)
B(6,28,2,chisel:basalt2:7)
B(7,28,2,STONEBRICK:0)
B(0,28,3,chisel:basalt2:7)
B(1,28,3,chisel:basalt2:7)
B(2,28,3,chisel:basalt2:7)
B(3,28,3,chisel:basalt2:7)
B(4,28,3,chisel:basalt2:7)
B(5,28,3,chisel:basalt2:7)
B(6,28,3,chisel:basalt2:7)
B(7,28,3,STONEBRICK:0)
B(0,28,4,chisel:basalt2:7)
B(1,28,4,chisel:basalt2:7)
B(2,28,4,chisel:basalt2:7)
B(3,28,4,chisel:basalt2:7)
B(4,28,4,chisel:basalt2:7)
B(5,28,4,chisel:basalt2:7)
B(6,28,4,chisel:basalt2:7)
B(7,28,4,STONEBRICK:0)
B(0,28,5,chisel:basalt2:7)
B(1,28,5,chisel:basalt2:7)
B(2,28,5,chisel:basalt2:7)
B(3,28,5,chisel:basalt2:7)
B(4,28,5,chisel:basalt2:7)
B(5,28,5,chisel:basalt2:7)
B(6,28,5,chisel:basalt2:7)
B(7,28,5,STONEBRICK:0)
B(0,28,6,chisel:basalt2:7)
B(1,28,6,chisel:basalt2:7)
B(2,28,6,chisel:basalt2:7)
B(3,28,6,chisel:basalt2:7)
B(4,28,6,chisel:basalt2:7)
B(5,28,6,chisel:basalt2:7)
B(6,28,6,chisel:basalt2:7)
B(7,28,6,STONEBRICK:0)
B(0,28,7,STONEBRICK:0)
B(1,28,7,STONEBRICK:0)
B(2,28,7,STONEBRICK:0)
B(3,28,7,STONEBRICK:0)
B(4,28,7,STONEBRICK:0)
B(5,28,7,STONEBRICK:0)
B(6,28,7,STONEBRICK:0)
B(7,28,7,STONEBRICK:0)
B(0,29,0,chisel:basalt2:7)
B(1,29,0,chisel:basalt2:7)
B(2,29,0,chisel:basalt2:7)
B(3,29,0,chisel:basalt2:7)
B(4,29,0,chisel:basalt2:7)
B(5,29,0,chisel:basalt2:7)
B(6,29,0,chisel:basalt2:7)
B(7,29,0,STONEBRICK:0)
B(0,29,1,chisel:basalt2:7)
B(1,29,1,chisel:basalt2:7)
B(2,29,1,chisel:basalt2:7)
B(3,29,1,chisel:basalt2:7)
B(4,29,1,chisel:basalt2:7)
B(5,29,1,chisel:basalt2:7)
B(6,29,1,chisel:basalt2:7)
B(7,29,1,STONEBRICK:0)
B(0,29,2,chisel:basalt2:7)
B(1,29,2,chisel:basalt2:7)
B(2,29,2,chisel:basalt2:7)
B(3,29,2,chisel:basalt2:7)
B(4,29,2,chisel:basalt2:7)
B(5,29,2,chisel:basalt2:7)
B(6,29,2,chisel:basalt2:7)
B(7,29,2,STONEBRICK:0)
B(0,29,3,chisel:basalt2:7)
B(1,29,3,chisel:basalt2:7)
B(2,29,3,chisel:basalt2:7)
B(3,29,3,chisel:basalt2:7)
B(4,29,3,chisel:basalt2:7)
B(5,29,3,chisel:basalt2:7)
B(6,29,3,chisel:basalt2:7)
B(7,29,3,STONEBRICK:0)
B(0,29,4,chisel:basalt2:7)
B(1,29,4,chisel:basalt2:7)
B(2,29,4,chisel:basalt2:7)
B(3,29,4,chisel:basalt2:7)
B(4,29,4,chisel:basalt2:7)
B(5,29,4,chisel:basalt2:7)
B(6,29,4,chisel:basalt2:7)
B(7,29,4,STONEBRICK:0)
B(0,29,5,chisel:basalt2:7)
B(1,29,5,chisel:basalt2:7)
B(2,29,5,chisel:basalt2:7)
B(3,29,5,chisel:basalt2:7)
B(4,29,5,chisel:basalt2:7)
B(5,29,5,chisel:basalt2:7)
B(6,29,5,chisel:basalt2:7)
B(7,29,5,STONEBRICK:0)
B(0,29,6,chisel:basalt2:7)
B(1,29,6,chisel:basalt2:7)
B(2,29,6,chisel:basalt2:7)
B(3,29,6,chisel:basalt2:7)
B(4,29,6,chisel:basalt2:7)
B(5,29,6,chisel:basalt2:7)
B(6,29,6,chisel:basalt2:7)
B(7,29,6,STONEBRICK:0)
B(0,29,7,STONEBRICK:0)
B(1,29,7,STONEBRICK:0)
B(2,29,7,STONEBRICK:0)
B(3,29,7,STONEBRICK:0)
B(4,29,7,STONEBRICK:0)
B(5,29,7,STONEBRICK:0)
B(6,29,7,STONEBRICK:0)
B(7,29,7,STONEBRICK:0)
B(0,30,0,chisel:basalt2:7)
B(1,30,0,chisel:basalt2:7)
B(2,30,0,chisel:basalt2:7)
B(3,30,0,chisel:basalt2:7)
B(4,30,0,chisel:basalt2:7)
B(5,30,0,chisel:basalt2:7)
B(6,30,0,chisel:basalt2:7)
B(7,30,0,STONEBRICK:0)
B(0,30,1,chisel:basalt2:7)
B(1,30,1,chisel:basalt2:7)
B(2,30,1,chisel:basalt2:7)
B(3,30,1,chisel:basalt2:7)
B(4,30,1,chisel:basalt2:7)
B(5,30,1,chisel:basalt2:7)
B(6,30,1,chisel:basalt2:7)
B(7,30,1,STONEBRICK:0)
B(0,30,2,chisel:basalt2:7)
B(1,30,2,chisel:basalt2:7)
B(2,30,2,chisel:basalt2:7)
B(3,30,2,chisel:basalt2:7)
B(4,30,2,chisel:basalt2:7)
B(5,30,2,chisel:basalt2:7)
B(6,30,2,chisel:basalt2:7)
B(7,30,2,STONEBRICK:0)
B(0,30,3,chisel:basalt2:7)
B(1,30,3,chisel:basalt2:7)
B(2,30,3,chisel:basalt2:7)
B(3,30,3,chisel:basalt2:7)
B(4,30,3,chisel:basalt2:7)
B(5,30,3,chisel:basalt2:7)
B(6,30,3,chisel:basalt2:7)
B(7,30,3,STONEBRICK:0)
B(0,30,4,chisel:basalt2:7)
B(1,30,4,chisel:basalt2:7)
B(2,30,4,chisel:basalt2:7)
B(3,30,4,chisel:basalt2:7)
B(4,30,4,chisel:basalt2:7)
B(5,30,4,chisel:basalt2:7)
B(6,30,4,chisel:basalt2:7)
B(7,30,4,STONEBRICK:0)
B(0,30,5,chisel:basalt2:7)
B(1,30,5,chisel:basalt2:7)
B(2,30,5,chisel:basalt2:7)
B(3,30,5,chisel:basalt2:7)
B(4,30,5,chisel:basalt2:7)
B(5,30,5,chisel:basalt2:7)
B(6,30,5,chisel:basalt2:7)
B(7,30,5,STONEBRICK:0)
B(0,30,6,chisel:basalt2:7)
B(1,30,6,chisel:basalt2:7)
B(2,30,6,chisel:basalt2:7)
B(3,30,6,chisel:basalt2:7)
B(4,30,6,chisel:basalt2:7)
B(5,30,6,chisel:basalt2:7)
B(6,30,6,chisel:basalt2:7)
B(7,30,6,STONEBRICK:0)
B(0,30,7,STONEBRICK:0)
B(1,30,7,STONEBRICK:0)
B(2,30,7,STONEBRICK:0)
B(3,30,7,STONEBRICK:0)
B(4,30,7,STONEBRICK:0)
B(5,30,7,STONEBRICK:0)
B(6,30,7,STONEBRICK:0)
B(7,30,7,STONEBRICK:0)
B(0,31,0,chisel:basalt2:7)
B(1,31,0,chisel:basalt2:7)
B(2,31,0,chisel:basalt2:7)
B(3,31,0,chisel:basalt2:7)
B(4,31,0,chisel:basalt2:7)
B(5,31,0,chisel:basalt2:7)
B(6,31,0,chisel:basalt2:7)
B(7,31,0,chisel:basalt2:7)
B(0,31,1,chisel:basalt2:7)
B(1,31,1,chisel:basalt2:7)
B(2,31,1,chisel:basalt2:7)
B(3,31,1,chisel:basalt2:7)
B(4,31,1,chisel:basalt2:7)
B(5,31,1,chisel:basalt2:7)
B(6,31,1,chisel:basalt2:7)
B(7,31,1,chisel:basalt2:7)
B(0,31,2,chisel:basalt2:7)
B(1,31,2,chisel:basalt2:7)
B(2,31,2,chisel:basalt2:7)
B(3,31,2,chisel:basalt2:7)
B(4,31,2,chisel:basalt2:7)
B(5,31,2,chisel:basalt2:7)
B(6,31,2,chisel:basalt2:7)
B(7,31,2,chisel:basalt2:7)
B(0,31,3,chisel:basalt2:7)
B(1,31,3,chisel:basalt2:7)
B(2,31,3,chisel:basalt2:7)
B(3,31,3,chisel:basalt2:7)
B(4,31,3,chisel:basalt2:7)
B(5,31,3,chisel:basalt2:7)
B(6,31,3,chisel:basalt2:7)
B(7,31,3,chisel:basalt2:7)
B(0,31,4,chisel:basalt2:7)
B(1,31,4,chisel:basalt2:7)
B(2,31,4,chisel:basalt2:7)
B(3,31,4,chisel:basalt2:7)
B(4,31,4,chisel:basalt2:7)
B(5,31,4,chisel:basalt2:7)
B(6,31,4,chisel:basalt2:7)
B(7,31,4,chisel:basalt2:7)
B(0,31,5,chisel:basalt2:7)
B(1,31,5,chisel:basalt2:7)
B(2,31,5,chisel:basalt2:7)
B(3,31,5,chisel:basalt2:7)
B(4,31,5,chisel:basalt2:7)
B(5,31,5,chisel:basalt2:7)
B(6,31,5,chisel:basalt2:7)
B(7,31,5,chisel:basalt2:7)
B(0,31,6,chisel:basalt2:7)
B(1,31,6,chisel:basalt2:7)
B(2,31,6,chisel:basalt2:7)
B(3,31,6,chisel:basalt2:7)
B(4,31,6,chisel:basalt2:7)
B(5,31,6,chisel:basalt2:7)
B(6,31,6,chisel:basalt2:7)
B(7,31,6,chisel:basalt2:7)
B(0,31,7,chisel:basalt2:7)
B(1,31,7,chisel:basalt2:7)
B(2,31,7,chisel:basalt2:7)
B(3,31,7,chisel:basalt2:7)
B(4,31,7,chisel:basalt2:7)
B(5,31,7,chisel:basalt2:7)
B(6,31,7,chisel:basalt2:7)
B(7,31,7,chisel:basalt2:7)
B(0,32,0,chisel:basalt2:7)
B(1,32,0,chisel:basalt2:7)
B(2,32,0,chisel:basalt2:7)
B(3,32,0,chisel:basalt2:7)
B(4,32,0,chisel:basalt2:7)
B(5,32,0,chisel:basalt2:7)
B(6,32,0,chisel:basalt2:7)
B(7,32,0,chisel:basalt2:7)
B(0,32,1,chisel:basalt2:7)
B(1,32,1,chisel:basalt2:7)
B(2,32,1,chisel:basalt2:7)
B(3,32,1,chisel:basalt2:7)
B(4,32,1,chisel:basalt2:7)
B(5,32,1,chisel:basalt2:7)
B(6,32,1,chisel:basalt2:7)
B(7,32,1,chisel:basalt2:7)
B(0,32,2,chisel:basalt2:7)
B(1,32,2,chisel:basalt2:7)
B(2,32,2,chisel:basalt2:7)
B(3,32,2,chisel:basalt2:7)
B(4,32,2,chisel:basalt2:7)
B(5,32,2,chisel:basalt2:7)
B(6,32,2,chisel:basalt2:7)
B(7,32,2,chisel:basalt2:7)
B(0,32,3,chisel:basalt2:7)
B(1,32,3,chisel:basalt2:7)
B(2,32,3,chisel:basalt2:7)
B(3,32,3,chisel:basalt2:7)
B(4,32,3,chisel:basalt2:7)
B(5,32,3,chisel:basalt2:7)
B(6,32,3,chisel:basalt2:7)
B(7,32,3,chisel:basalt2:7)
B(0,32,4,chisel:basalt2:7)
B(1,32,4,chisel:basalt2:7)
B(2,32,4,chisel:basalt2:7)
B(3,32,4,chisel:basalt2:7)
B(4,32,4,chisel:basalt2:7)
B(5,32,4,chisel:basalt2:7)
B(6,32,4,chisel:basalt2:7)
B(7,32,4,chisel:basalt2:7)
B(0,32,5,chisel:basalt2:7)
B(1,32,5,chisel:basalt2:7)
B(2,32,5,chisel:basalt2:7)
B(3,32,5,chisel:basalt2:7)
B(4,32,5,chisel:basalt2:7)
B(5,32,5,chisel:basalt2:7)
B(6,32,5,chisel:basalt2:7)
B(7,32,5,chisel:basalt2:7)
B(0,32,6,chisel:basalt2:7)
B(1,32,6,chisel:basalt2:7)
B(2,32,6,chisel:basalt2:7)
B(3,32,6,chisel:basalt2:7)
B(4,32,6,chisel:basalt2:7)
B(5,32,6,chisel:basalt2:7)
B(6,32,6,chisel:basalt2:7)
B(7,32,6,chisel:basalt2:7)
B(0,32,7,chisel:basalt2:7)
B(1,32,7,chisel:basalt2:7)
B(2,32,7,chisel:basalt2:7)
B(3,32,7,chisel:basalt2:7)
B(4,32,7,chisel:basalt2:7)
B(5,32,7,chisel:basalt2:7)
B(6,32,7,chisel:basalt2:7)
B(7,32,7,chisel:basalt2:7)
B(0,33,0,chisel:basalt2:7)
B(1,33,0,chisel:basalt2:7)
B(2,33,0,chisel:basalt2:7)
B(3,33,0,chisel:basalt2:7)
B(4,33,0,chisel:basalt2:7)
B(5,33,0,chisel:basalt2:7)
B(6,33,0,chisel:basalt2:7)
B(7,33,0,chisel:basalt2:7)
B(0,33,1,chisel:basalt2:7)
B(1,33,1,chisel:basalt2:7)
B(2,33,1,chisel:basalt2:7)
B(3,33,1,chisel:basalt2:7)
B(4,33,1,chisel:basalt2:7)
B(5,33,1,chisel:basalt2:7)
B(6,33,1,chisel:basalt2:7)
B(7,33,1,chisel:basalt2:7)
B(0,33,2,chisel:basalt2:7)
B(1,33,2,chisel:basalt2:7)
B(2,33,2,chisel:basalt2:7)
B(3,33,2,chisel:basalt2:7)
B(4,33,2,chisel:basalt2:7)
B(5,33,2,chisel:basalt2:7)
B(6,33,2,chisel:basalt2:7)
B(7,33,2,chisel:basalt2:7)
B(0,33,3,chisel:basalt2:7)
B(1,33,3,chisel:basalt2:7)
B(2,33,3,chisel:basalt2:7)
B(3,33,3,chisel:basalt2:7)
B(4,33,3,chisel:basalt2:7)
B(5,33,3,chisel:basalt2:7)
B(6,33,3,chisel:basalt2:7)
B(7,33,3,chisel:basalt2:7)
B(0,33,4,chisel:basalt2:7)
B(1,33,4,chisel:basalt2:7)
B(2,33,4,chisel:basalt2:7)
B(3,33,4,chisel:basalt2:7)
B(4,33,4,chisel:basalt2:7)
B(5,33,4,chisel:basalt2:7)
B(6,33,4,chisel:basalt2:7)
B(7,33,4,chisel:basalt2:7)
B(0,33,5,chisel:basalt2:7)
B(1,33,5,chisel:basalt2:7)
B(2,33,5,chisel:basalt2:7)
B(3,33,5,chisel:basalt2:7)
B(4,33,5,chisel:basalt2:7)
B(5,33,5,chisel:basalt2:7)
B(6,33,5,chisel:basalt2:7)
B(7,33,5,chisel:basalt2:7)
B(0,33,6,chisel:basalt2:7)
B(1,33,6,chisel:basalt2:7)
B(2,33,6,chisel:basalt2:7)
B(3,33,6,chisel:basalt2:7)
B(4,33,6,chisel:basalt2:7)
B(5,33,6,chisel:basalt2:7)
B(6,33,6,chisel:basalt2:7)
B(7,33,6,chisel:basalt2:7)
B(0,33,7,chisel:basalt2:7)
B(1,33,7,chisel:basalt2:7)
B(2,33,7,chisel:basalt2:7)
B(3,33,7,chisel:basalt2:7)
B(4,33,7,chisel:basalt2:7)
B(5,33,7,chisel:basalt2:7)
B(6,33,7,chisel:basalt2:7)
B(7,33,7,chisel:basalt2:7)
B(0,34,0,chisel:basalt2:7)
B(1,34,0,chisel:basalt2:7)
B(2,34,0,chisel:basalt2:7)
B(3,34,0,chisel:basalt2:7)
B(4,34,0,chisel:basalt2:7)
B(5,34,0,chisel:basalt2:7)
B(6,34,0,chisel:basalt2:7)
B(7,34,0,chisel:basalt2:7)
B(0,34,1,chisel:basalt2:7)
B(1,34,1,chisel:basalt2:7)
B(2,34,1,chisel:basalt2:7)
B(3,34,1,chisel:basalt2:7)
B(4,34,1,chisel:basalt2:7)
B(5,34,1,chisel:basalt2:7)
B(6,34,1,chisel:basalt2:7)
B(7,34,1,chisel:basalt2:7)
B(0,34,2,chisel:basalt2:7)
B(1,34,2,chisel:basalt2:7)
B(2,34,2,chisel:basalt2:7)
B(3,34,2,chisel:basalt2:7)
B(4,34,2,chisel:basalt2:7)
B(5,34,2,chisel:basalt2:7)
B(6,34,2,chisel:basalt2:7)
B(7,34,2,chisel:basalt2:7)
B(0,34,3,chisel:basalt2:7)
B(1,34,3,chisel:basalt2:7)
B(2,34,3,chisel:basalt2:7)
B(3,34,3,chisel:basalt2:7)
B(4,34,3,chisel:basalt2:7)
B(5,34,3,chisel:basalt2:7)
B(6,34,3,chisel:basalt2:7)
B(7,34,3,chisel:basalt2:7)
B(0,34,4,chisel:basalt2:7)
B(1,34,4,chisel:basalt2:7)
B(2,34,4,chisel:basalt2:7)
B(3,34,4,chisel:basalt2:7)
B(4,34,4,chisel:basalt2:7)
B(5,34,4,chisel:basalt2:7)
B(6,34,4,chisel:basalt2:7)
B(7,34,4,chisel:basalt2:7)
B(0,34,5,chisel:basalt2:7)
B(1,34,5,chisel:basalt2:7)
B(2,34,5,chisel:basalt2:7)
B(3,34,5,chisel:basalt2:7)
B(4,34,5,chisel:basalt2:7)
B(5,34,5,chisel:basalt2:7)
B(6,34,5,chisel:basalt2:7)
B(7,34,5,chisel:basalt2:7)
B(0,34,6,chisel:basalt2:7)
B(1,34,6,chisel:basalt2:7)
B(2,34,6,chisel:basalt2:7)
B(3,34,6,chisel:basalt2:7)
B(4,34,6,chisel:basalt2:7)
B(5,34,6,chisel:basalt2:7)
B(6,34,6,chisel:basalt2:7)
B(7,34,6,chisel:basalt2:7)
B(0,34,7,chisel:basalt2:7)
B(1,34,7,chisel:basalt2:7)
B(2,34,7,chisel:basalt2:7)
B(3,34,7,chisel:basalt2:7)
B(4,34,7,chisel:basalt2:7)
B(5,34,7,chisel:basalt2:7)
B(6,34,7,chisel:basalt2:7)
B(7,34,7,chisel:basalt2:7)
B(0,35,0,chisel:basalt2:7)
B(1,35,0,chisel:basalt2:7)
B(2,35,0,chisel:basalt2:7)
B(3,35,0,chisel:basalt2:7)
B(4,35,0,chisel:basalt2:7)
B(5,35,0,chisel:basalt2:7)
B(6,35,0,chisel:basalt2:7)
B(7,35,0,chisel:basalt2:7)
B(0,35,1,chisel:basalt2:7)
B(1,35,1,chisel:basalt2:7)
B(2,35,1,chisel:basalt2:7)
B(3,35,1,chisel:basalt2:7)
B(4,35,1,chisel:basalt2:7)
B(5,35,1,chisel:basalt2:7)
B(6,35,1,chisel:basalt2:7)
B(7,35,1,chisel:basalt2:7)
B(0,35,2,chisel:basalt2:7)
B(1,35,2,chisel:basalt2:7)
B(2,35,2,chisel:basalt2:7)
B(3,35,2,chisel:basalt2:7)
B(4,35,2,chisel:basalt2:7)
B(5,35,2,chisel:basalt2:7)
B(6,35,2,chisel:basalt2:7)
B(7,35,2,chisel:basalt2:7)
B(0,35,3,chisel:basalt2:7)
B(1,35,3,chisel:basalt2:7)
B(2,35,3,chisel:basalt2:7)
B(3,35,3,chisel:basalt2:7)
B(4,35,3,chisel:basalt2:7)
B(5,35,3,chisel:basalt2:7)
B(6,35,3,chisel:basalt2:7)
B(7,35,3,chisel:basalt2:7)
B(0,35,4,chisel:basalt2:7)
B(1,35,4,chisel:basalt2:7)
B(2,35,4,chisel:basalt2:7)
B(3,35,4,chisel:basalt2:7)
B(4,35,4,chisel:basalt2:7)
B(5,35,4,chisel:basalt2:7)
B(6,35,4,chisel:basalt2:7)
B(7,35,4,chisel:basalt2:7)
B(0,35,5,chisel:basalt2:7)
B(1,35,5,chisel:basalt2:7)
B(2,35,5,chisel:basalt2:7)
B(3,35,5,chisel:basalt2:7)
B(4,35,5,chisel:basalt2:7)
B(5,35,5,chisel:basalt2:7)
B(6,35,5,chisel:basalt2:7)
B(7,35,5,chisel:basalt2:7)
B(0,35,6,chisel:basalt2:7)
B(1,35,6,chisel:basalt2:7)
B(2,35,6,chisel:basalt2:7)
B(3,35,6,chisel:basalt2:7)
B(4,35,6,chisel:basalt2:7)
B(5,35,6,chisel:basalt2:7)
B(6,35,6,chisel:basalt2:7)
B(7,35,6,chisel:basalt2:7)
B(0,35,7,chisel:basalt2:7)
B(1,35,7,chisel:basalt2:7)
B(2,35,7,chisel:basalt2:7)
B(3,35,7,chisel:basalt2:7)
B(4,35,7,chisel:basalt2:7)
B(5,35,7,chisel:basalt2:7)
B(6,35,7,chisel:basalt2:7)
B(7,35,7,chisel:basalt2:7)
B(0,36,0,chisel:basalt2:7)
B(1,36,0,chisel:basalt2:7)
B(2,36,0,chisel:basalt2:7)
B(3,36,0,chisel:basalt2:7)
B(4,36,0,chisel:basalt2:7)
B(5,36,0,chisel:basalt2:7)
B(6,36,0,chisel:basalt2:7)
B(7,36,0,chisel:basalt2:7)
B(0,36,1,chisel:basalt2:7)
B(1,36,1,chisel:basalt2:7)
B(2,36,1,chisel:basalt2:7)
B(3,36,1,chisel:basalt2:7)
B(4,36,1,chisel:basalt2:7)
B(5,36,1,chisel:basalt2:7)
B(6,36,1,chisel:basalt2:7)
B(7,36,1,chisel:basalt2:7)
B(0,36,2,chisel:basalt2:7)
B(1,36,2,chisel:basalt2:7)
B(2,36,2,chisel:basalt2:7)
B(3,36,2,chisel:basalt2:7)
B(4,36,2,chisel:basalt2:7)
B(5,36,2,chisel:basalt2:7)
B(6,36,2,chisel:basalt2:7)
B(7,36,2,chisel:basalt2:7)
B(0,36,3,chisel:basalt2:7)
B(1,36,3,chisel:basalt2:7)
B(2,36,3,chisel:basalt2:7)
B(3,36,3,chisel:basalt2:7)
B(4,36,3,chisel:basalt2:7)
B(5,36,3,chisel:basalt2:7)
B(6,36,3,chisel:basalt2:7)
B(7,36,3,chisel:basalt2:7)
B(0,36,4,chisel:basalt2:7)
B(1,36,4,chisel:basalt2:7)
B(2,36,4,chisel:basalt2:7)
B(3,36,4,chisel:basalt2:7)
B(4,36,4,chisel:basalt2:7)
B(5,36,4,chisel:basalt2:7)
B(6,36,4,chisel:basalt2:7)
B(7,36,4,chisel:basalt2:7)
B(0,36,5,chisel:basalt2:7)
B(1,36,5,chisel:basalt2:7)
B(2,36,5,chisel:basalt2:7)
B(3,36,5,chisel:basalt2:7)
B(4,36,5,chisel:basalt2:7)
B(5,36,5,chisel:basalt2:7)
B(6,36,5,chisel:basalt2:7)
B(7,36,5,chisel:basalt2:7)
B(0,36,6,chisel:basalt2:7)
B(1,36,6,chisel:basalt2:7)
B(2,36,6,chisel:basalt2:7)
B(3,36,6,chisel:basalt2:7)
B(4,36,6,chisel:basalt2:7)
B(5,36,6,chisel:basalt2:7)
B(6,36,6,chisel:basalt2:7)
B(7,36,6,chisel:basalt2:7)
B(0,36,7,chisel:basalt2:7)
B(1,36,7,chisel:basalt2:7)
B(2,36,7,chisel:basalt2:7)
B(3,36,7,chisel:basalt2:7)
B(4,36,7,chisel:basalt2:7)
B(5,36,7,chisel:basalt2:7)
B(6,36,7,chisel:basalt2:7)
B(7,36,7,chisel:basalt2:7)
B(0,37,0,chisel:basalt2:7)
B(1,37,0,chisel:basalt2:7)
B(2,37,0,chisel:basalt2:7)
B(3,37,0,chisel:basalt2:7)
B(4,37,0,chisel:basalt2:7)
B(5,37,0,chisel:basalt2:7)
B(6,37,0,chisel:basalt2:7)
B(7,37,0,chisel:basalt2:7)
B(0,37,1,chisel:basalt2:7)
B(1,37,1,chisel:basalt2:7)
B(2,37,1,chisel:basalt2:7)
B(3,37,1,chisel:basalt2:7)
B(4,37,1,chisel:basalt2:7)
B(5,37,1,chisel:basalt2:7)
B(6,37,1,chisel:basalt2:7)
B(7,37,1,chisel:basalt2:7)
B(0,37,2,chisel:basalt2:7)
B(1,37,2,chisel:basalt2:7)
B(2,37,2,chisel:basalt2:7)
B(3,37,2,chisel:basalt2:7)
B(4,37,2,chisel:basalt2:7)
B(5,37,2,chisel:basalt2:7)
B(6,37,2,chisel:basalt2:7)
B(7,37,2,chisel:basalt2:7)
B(0,37,3,chisel:basalt2:7)
B(1,37,3,chisel:basalt2:7)
B(2,37,3,chisel:basalt2:7)
B(3,37,3,chisel:basalt2:7)
B(4,37,3,chisel:basalt2:7)
B(5,37,3,chisel:basalt2:7)
B(6,37,3,chisel:basalt2:7)
B(7,37,3,chisel:basalt2:7)
B(0,37,4,chisel:basalt2:7)
B(1,37,4,chisel:basalt2:7)
B(2,37,4,chisel:basalt2:7)
B(3,37,4,chisel:basalt2:7)
B(4,37,4,chisel:basalt2:7)
B(5,37,4,chisel:basalt2:7)
B(6,37,4,chisel:basalt2:7)
B(7,37,4,chisel:basalt2:7)
B(0,37,5,chisel:basalt2:7)
B(1,37,5,chisel:basalt2:7)
B(2,37,5,chisel:basalt2:7)
B(3,37,5,chisel:basalt2:7)
B(4,37,5,chisel:basalt2:7)
B(5,37,5,chisel:basalt2:7)
B(6,37,5,chisel:basalt2:7)
B(7,37,5,chisel:basalt2:7)
B(0,37,6,chisel:basalt2:7)
B(1,37,6,chisel:basalt2:7)
B(2,37,6,chisel:basalt2:7)
B(3,37,6,chisel:basalt2:7)
B(4,37,6,chisel:basalt2:7)
B(5,37,6,chisel:basalt2:7)
B(6,37,6,chisel:basalt2:7)
B(7,37,6,chisel:basalt2:7)
B(0,37,7,chisel:basalt2:7)
B(1,37,7,chisel:basalt2:7)
B(2,37,7,chisel:basalt2:7)
B(3,37,7,chisel:basalt2:7)
B(4,37,7,chisel:basalt2:7)
B(5,37,7,chisel:basalt2:7)
B(6,37,7,chisel:basalt2:7)
B(7,37,7,chisel:basalt2:7)
B(0,38,0,chisel:basalt2:7)
B(1,38,0,chisel:basalt2:7)
B(2,38,0,chisel:basalt2:7)
B(3,38,0,chisel:basalt2:7)
B(4,38,0,chisel:basalt2:7)
B(5,38,0,chisel:basalt2:7)
B(6,38,0,chisel:basalt2:7)
B(7,38,0,chisel:basalt2:7)
B(0,38,1,chisel:basalt2:7)
B(1,38,1,chisel:basalt2:7)
B(2,38,1,chisel:basalt2:7)
B(3,38,1,chisel:basalt2:7)
B(4,38,1,chisel:basalt2:7)
B(5,38,1,chisel:basalt2:7)
B(6,38,1,chisel:basalt2:7)
B(7,38,1,chisel:basalt2:7)
B(0,38,2,chisel:basalt2:7)
B(1,38,2,chisel:basalt2:7)
B(2,38,2,chisel:basalt2:7)
B(3,38,2,chisel:basalt2:7)
B(4,38,2,chisel:basalt2:7)
B(5,38,2,chisel:basalt2:7)
B(6,38,2,chisel:basalt2:7)
B(7,38,2,chisel:basalt2:7)
B(0,38,3,chisel:basalt2:7)
B(1,38,3,chisel:basalt2:7)
B(2,38,3,chisel:basalt2:7)
B(3,38,3,chisel:basalt2:7)
B(4,38,3,chisel:basalt2:7)
B(5,38,3,chisel:basalt2:7)
B(6,38,3,chisel:basalt2:7)
B(7,38,3,chisel:basalt2:7)
B(0,38,4,chisel:basalt2:7)
B(1,38,4,chisel:basalt2:7)
B(2,38,4,chisel:basalt2:7)
B(3,38,4,chisel:basalt2:7)
B(4,38,4,chisel:basalt2:7)
B(5,38,4,chisel:basalt2:7)
B(6,38,4,chisel:basalt2:7)
B(7,38,4,chisel:basalt2:7)
B(0,38,5,chisel:basalt2:7)
B(1,38,5,chisel:basalt2:7)
B(2,38,5,chisel:basalt2:7)
B(3,38,5,chisel:basalt2:7)
B(4,38,5,chisel:basalt2:7)
B(5,38,5,chisel:basalt2:7)
B(6,38,5,chisel:basalt2:7)
B(7,38,5,chisel:basalt2:7)
B(0,38,6,chisel:basalt2:7)
B(1,38,6,chisel:basalt2:7)
B(2,38,6,chisel:basalt2:7)
B(3,38,6,chisel:basalt2:7)
B(4,38,6,chisel:basalt2:7)
B(5,38,6,chisel:basalt2:7)
B(6,38,6,chisel:basalt2:7)
B(7,38,6,chisel:basalt2:7)
B(0,38,7,chisel:basalt2:7)
B(1,38,7,chisel:basalt2:7)
B(2,38,7,chisel:basalt2:7)
B(3,38,7,chisel:basalt2:7)
B(4,38,7,chisel:basalt2:7)
B(5,38,7,chisel:basalt2:7)
B(6,38,7,chisel:basalt2:7)
B(7,38,7,chisel:basalt2:7)
B(0,39,0,chisel:basalt2:7)
B(1,39,0,chisel:basalt2:7)
B(2,39,0,chisel:basalt2:7)
B(3,39,0,chisel:basalt2:7)
B(4,39,0,chisel:basalt2:7)
B(5,39,0,chisel:basalt2:7)
B(6,39,0,chisel:basalt2:7)
B(7,39,0,chisel:basalt2:7)
B(0,39,1,chisel:basalt2:7)
B(1,39,1,chisel:basalt2:7)
B(2,39,1,chisel:basalt2:7)
B(3,39,1,chisel:basalt2:7)
B(4,39,1,chisel:basalt2:7)
B(5,39,1,chisel:basalt2:7)
B(6,39,1,chisel:basalt2:7)
B(7,39,1,chisel:basalt2:7)
B(0,39,2,chisel:basalt2:7)
B(1,39,2,chisel:basalt2:7)
B(2,39,2,chisel:basalt2:7)
B(3,39,2,chisel:basalt2:7)
B(4,39,2,chisel:basalt2:7)
B(5,39,2,chisel:basalt2:7)
B(6,39,2,chisel:basalt2:7)
B(7,39,2,chisel:basalt2:7)
B(0,39,3,chisel:basalt2:7)
B(1,39,3,chisel:basalt2:7)
B(2,39,3,chisel:basalt2:7)
B(3,39,3,chisel:basalt2:7)
B(4,39,3,chisel:basalt2:7)
B(5,39,3,chisel:basalt2:7)
B(6,39,3,chisel:basalt2:7)
B(7,39,3,chisel:basalt2:7)
B(0,39,4,chisel:basalt2:7)
B(1,39,4,chisel:basalt2:7)
B(2,39,4,chisel:basalt2:7)
B(3,39,4,chisel:basalt2:7)
B(4,39,4,chisel:basalt2:7)
B(5,39,4,chisel:basalt2:7)
B(6,39,4,chisel:basalt2:7)
B(7,39,4,chisel:basalt2:7)
B(0,39,5,chisel:basalt2:7)
B(1,39,5,chisel:basalt2:7)
B(2,39,5,chisel:basalt2:7)
B(3,39,5,chisel:basalt2:7)
B(4,39,5,chisel:basalt2:7)
B(5,39,5,chisel:basalt2:7)
B(6,39,5,chisel:basalt2:7)
B(7,39,5,chisel:basalt2:7)
B(0,39,6,chisel:basalt2:7)
B(1,39,6,chisel:basalt2:7)
B(2,39,6,chisel:basalt2:7)
B(3,39,6,chisel:basalt2:7)
B(4,39,6,chisel:basalt2:7)
B(5,39,6,chisel:basalt2:7)
B(6,39,6,chisel:basalt2:7)
B(7,39,6,chisel:basalt2:7)
B(0,39,7,chisel:basalt2:7)
B(1,39,7,chisel:basalt2:7)
B(2,39,7,chisel:basalt2:7)
B(3,39,7,chisel:basalt2:7)
B(4,39,7,chisel:basalt2:7)
B(5,39,7,chisel:basalt2:7)
B(6,39,7,chisel:basalt2:7)
B(7,39,7,chisel:basalt2:7)
B(0,40,0,chisel:basalt2:7)
B(1,40,0,chisel:basalt2:7)
B(2,40,0,chisel:basalt2:7)
B(3,40,0,chisel:basalt2:7)
B(4,40,0,chisel:basalt2:7)
B(5,40,0,chisel:basalt2:7)
B(6,40,0,chisel:basalt2:7)
B(7,40,0,chisel:basalt2:7)
B(0,40,1,chisel:basalt2:7)
B(1,40,1,chisel:basalt2:7)
B(2,40,1,chisel:basalt2:7)
B(3,40,1,chisel:basalt2:7)
B(4,40,1,chisel:basalt2:7)
B(5,40,1,chisel:basalt2:7)
B(6,40,1,chisel:basalt2:7)
B(7,40,1,chisel:basalt2:7)
B(0,40,2,chisel:basalt2:7)
B(1,40,2,chisel:basalt2:7)
B(2,40,2,chisel:basalt2:7)
B(3,40,2,chisel:basalt2:7)
B(4,40,2,chisel:basalt2:7)
B(5,40,2,chisel:basalt2:7)
B(6,40,2,chisel:basalt2:7)
B(7,40,2,chisel:basalt2:7)
B(0,40,3,chisel:basalt2:7)
B(1,40,3,chisel:basalt2:7)
B(2,40,3,chisel:basalt2:7)
B(3,40,3,chisel:basalt2:7)
B(4,40,3,chisel:basalt2:7)
B(5,40,3,chisel:basalt2:7)
B(6,40,3,chisel:basalt2:7)
B(7,40,3,chisel:basalt2:7)
B(0,40,4,chisel:basalt2:7)
B(1,40,4,chisel:basalt2:7)
B(2,40,4,chisel:basalt2:7)
B(3,40,4,chisel:basalt2:7)
B(4,40,4,chisel:basalt2:7)
B(5,40,4,chisel:basalt2:7)
B(6,40,4,chisel:basalt2:7)
B(7,40,4,chisel:basalt2:7)
B(0,40,5,chisel:basalt2:7)
B(1,40,5,chisel:basalt2:7)
B(2,40,5,chisel:basalt2:7)
B(3,40,5,chisel:basalt2:7)
B(4,40,5,chisel:basalt2:7)
B(5,40,5,chisel:basalt2:7)
B(6,40,5,chisel:basalt2:7)
B(7,40,5,chisel:basalt2:7)
B(0,40,6,chisel:basalt2:7)
B(1,40,6,chisel:basalt2:7)
B(2,40,6,chisel:basalt2:7)
B(3,40,6,chisel:basalt2:7)
B(4,40,6,chisel:basalt2:7)
B(5,40,6,chisel:basalt2:7)
B(6,40,6,chisel:basalt2:7)
B(7,40,6,chisel:basalt2:7)
B(0,40,7,chisel:basalt2:7)
B(1,40,7,chisel:basalt2:7)
B(2,40,7,chisel:basalt2:7)
B(3,40,7,chisel:basalt2:7)
B(4,40,7,chisel:basalt2:7)
B(5,40,7,chisel:basalt2:7)
B(6,40,7,chisel:basalt2:7)
B(7,40,7,chisel:basalt2:7)
B(0,41,0,chisel:basalt2:7)
B(1,41,0,chisel:basalt2:7)
B(2,41,0,chisel:basalt2:7)
B(3,41,0,chisel:basalt2:7)
B(4,41,0,chisel:basalt2:7)
B(5,41,0,chisel:basalt2:7)
B(6,41,0,chisel:basalt2:7)
B(7,41,0,chisel:basalt2:7)
B(0,41,1,chisel:basalt2:7)
B(1,41,1,chisel:basalt2:7)
B(2,41,1,chisel:basalt2:7)
B(3,41,1,chisel:basalt2:7)
B(4,41,1,chisel:basalt2:7)
B(5,41,1,chisel:basalt2:7)
B(6,41,1,chisel:basalt2:7)
B(7,41,1,chisel:basalt2:7)
B(0,41,2,chisel:basalt2:7)
B(1,41,2,chisel:basalt2:7)
B(2,41,2,chisel:basalt2:7)
B(3,41,2,chisel:basalt2:7)
B(4,41,2,chisel:basalt2:7)
B(5,41,2,chisel:basalt2:7)
B(6,41,2,chisel:basalt2:7)
B(7,41,2,chisel:basalt2:7)
B(0,41,3,chisel:basalt2:7)
B(1,41,3,chisel:basalt2:7)
B(2,41,3,chisel:basalt2:7)
B(3,41,3,chisel:basalt2:7)
B(4,41,3,chisel:basalt2:7)
B(5,41,3,chisel:basalt2:7)
B(6,41,3,chisel:basalt2:7)
B(7,41,3,chisel:basalt2:7)
B(0,41,4,chisel:basalt2:7)
B(1,41,4,chisel:basalt2:7)
B(2,41,4,chisel:basalt2:7)
B(3,41,4,chisel:basalt2:7)
B(4,41,4,chisel:basalt2:7)
B(5,41,4,chisel:basalt2:7)
B(6,41,4,chisel:basalt2:7)
B(7,41,4,chisel:basalt2:7)
B(0,41,5,chisel:basalt2:7)
B(1,41,5,chisel:basalt2:7)
B(2,41,5,chisel:basalt2:7)
B(3,41,5,chisel:basalt2:7)
B(4,41,5,chisel:basalt2:7)
B(5,41,5,chisel:basalt2:7)
B(6,41,5,chisel:basalt2:7)
B(7,41,5,chisel:basalt2:7)
B(0,41,6,chisel:basalt2:7)
B(1,41,6,chisel:basalt2:7)
B(2,41,6,chisel:basalt2:7)
B(3,41,6,chisel:basalt2:7)
B(4,41,6,chisel:basalt2:7)
B(5,41,6,chisel:basalt2:7)
B(6,41,6,chisel:basalt2:7)
B(7,41,6,chisel:basalt2:7)
B(0,41,7,chisel:basalt2:7)
B(1,41,7,chisel:basalt2:7)
B(2,41,7,chisel:basalt2:7)
B(3,41,7,chisel:basalt2:7)
B(4,41,7,chisel:basalt2:7)
B(5,41,7,chisel:basalt2:7)
B(6,41,7,chisel:basalt2:7)
B(7,41,7,chisel:basalt2:7)
B(0,42,0,chisel:basalt2:7)
B(1,42,0,chisel:basalt2:7)
B(2,42,0,chisel:basalt2:7)
B(3,42,0,chisel:basalt2:7)
B(4,42,0,chisel:basalt2:7)
B(5,42,0,chisel:basalt2:7)
B(6,42,0,chisel:basalt2:7)
B(7,42,0,chisel:basalt2:7)
B(0,42,1,chisel:basalt2:7)
B(1,42,1,chisel:basalt2:7)
B(2,42,1,chisel:basalt2:7)
B(3,42,1,chisel:basalt2:7)
B(4,42,1,chisel:basalt2:7)
B(5,42,1,chisel:basalt2:7)
B(6,42,1,chisel:basalt2:7)
B(7,42,1,chisel:basalt2:7)
B(0,42,2,chisel:basalt2:7)
B(1,42,2,chisel:basalt2:7)
B(2,42,2,chisel:basalt2:7)
B(3,42,2,chisel:basalt2:7)
B(4,42,2,chisel:basalt2:7)
B(5,42,2,chisel:basalt2:7)
B(6,42,2,chisel:basalt2:7)
B(7,42,2,chisel:basalt2:7)
B(0,42,3,chisel:basalt2:7)
B(1,42,3,chisel:basalt2:7)
B(2,42,3,chisel:basalt2:7)
B(3,42,3,chisel:basalt2:7)
B(4,42,3,chisel:basalt2:7)
B(5,42,3,chisel:basalt2:7)
B(6,42,3,chisel:basalt2:7)
B(7,42,3,chisel:basalt2:7)
B(0,42,4,chisel:basalt2:7)
B(1,42,4,chisel:basalt2:7)
B(2,42,4,chisel:basalt2:7)
B(3,42,4,chisel:basalt2:7)
B(4,42,4,chisel:basalt2:7)
B(5,42,4,chisel:basalt2:7)
B(6,42,4,chisel:basalt2:7)
B(7,42,4,chisel:basalt2:7)
B(0,42,5,chisel:basalt2:7)
B(1,42,5,chisel:basalt2:7)
B(2,42,5,chisel:basalt2:7)
B(3,42,5,chisel:basalt2:7)
B(4,42,5,chisel:basalt2:7)
B(5,42,5,chisel:basalt2:7)
B(6,42,5,chisel:basalt2:7)
B(7,42,5,chisel:basalt2:7)
B(0,42,6,chisel:basalt2:7)
B(1,42,6,chisel:basalt2:7)
B(2,42,6,chisel:basalt2:7)
B(3,42,6,chisel:basalt2:7)
B(4,42,6,chisel:basalt2:7)
B(5,42,6,chisel:basalt2:7)
B(6,42,6,chisel:basalt2:7)
B(7,42,6,chisel:basalt2:7)
B(0,42,7,chisel:basalt2:7)
B(1,42,7,chisel:basalt2:7)
B(2,42,7,chisel:basalt2:7)
B(3,42,7,chisel:basalt2:7)
B(4,42,7,chisel:basalt2:7)
B(5,42,7,chisel:basalt2:7)
B(6,42,7,chisel:basalt2:7)
B(7,42,7,chisel:basalt2:7)
B(0,43,0,chisel:basalt2:7)
B(1,43,0,chisel:basalt2:7)
B(2,43,0,chisel:basalt2:7)
B(3,43,0,chisel:basalt2:7)
B(4,43,0,chisel:basalt2:7)
B(5,43,0,chisel:basalt2:7)
B(6,43,0,chisel:basalt2:7)
B(7,43,0,chisel:basalt2:7)
B(0,43,1,chisel:basalt2:7)
B(1,43,1,chisel:basalt2:7)
B(2,43,1,chisel:basalt2:7)
B(3,43,1,chisel:basalt2:7)
B(4,43,1,chisel:basalt2:7)
B(5,43,1,chisel:basalt2:7)
B(6,43,1,chisel:basalt2:7)
B(7,43,1,chisel:basalt2:7)
B(0,43,2,chisel:basalt2:7)
B(1,43,2,chisel:basalt2:7)
B(2,43,2,chisel:basalt2:7)
B(3,43,2,chisel:basalt2:7)
B(4,43,2,chisel:basalt2:7)
B(5,43,2,chisel:basalt2:7)
B(6,43,2,chisel:basalt2:7)
B(7,43,2,chisel:basalt2:7)
B(0,43,3,chisel:basalt2:7)
B(1,43,3,chisel:basalt2:7)
B(2,43,3,chisel:basalt2:7)
B(3,43,3,chisel:basalt2:7)
B(4,43,3,chisel:basalt2:7)
B(5,43,3,chisel:basalt2:7)
B(6,43,3,chisel:basalt2:7)
B(7,43,3,chisel:basalt2:7)
B(0,43,4,chisel:basalt2:7)
B(1,43,4,chisel:basalt2:7)
B(2,43,4,chisel:basalt2:7)
B(3,43,4,chisel:basalt2:7)
B(4,43,4,chisel:basalt2:7)
B(5,43,4,chisel:basalt2:7)
B(6,43,4,chisel:basalt2:7)
B(7,43,4,chisel:basalt2:7)
B(0,43,5,chisel:basalt2:7)
B(1,43,5,chisel:basalt2:7)
B(2,43,5,chisel:basalt2:7)
B(3,43,5,chisel:basalt2:7)
B(4,43,5,chisel:basalt2:7)
B(5,43,5,chisel:basalt2:7)
B(6,43,5,chisel:basalt2:7)
B(7,43,5,chisel:basalt2:7)
B(0,43,6,chisel:basalt2:7)
B(1,43,6,chisel:basalt2:7)
B(2,43,6,chisel:basalt2:7)
B(3,43,6,chisel:basalt2:7)
B(4,43,6,chisel:basalt2:7)
B(5,43,6,chisel:basalt2:7)
B(6,43,6,chisel:basalt2:7)
B(7,43,6,chisel:basalt2:7)
B(0,43,7,chisel:basalt2:7)
B(1,43,7,chisel:basalt2:7)
B(2,43,7,chisel:basalt2:7)
B(3,43,7,chisel:basalt2:7)
B(4,43,7,chisel:basalt2:7)
B(5,43,7,chisel:basalt2:7)
B(6,43,7,chisel:basalt2:7)
B(7,43,7,chisel:basalt2:7)
B(0,44,0,chisel:basalt2:7)
B(1,44,0,chisel:basalt2:7)
B(2,44,0,chisel:basalt2:7)
B(3,44,0,chisel:basalt2:7)
B(4,44,0,chisel:basalt2:7)
B(5,44,0,chisel:basalt2:7)
B(6,44,0,chisel:basalt2:7)
B(7,44,0,chisel:basalt2:7)
B(0,44,1,chisel:basalt2:7)
B(1,44,1,chisel:basalt2:7)
B(2,44,1,chisel:basalt2:7)
B(3,44,1,chisel:basalt2:7)
B(4,44,1,chisel:basalt2:7)
B(5,44,1,chisel:basalt2:7)
B(6,44,1,chisel:basalt2:7)
B(7,44,1,chisel:basalt2:7)
B(0,44,2,chisel:basalt2:7)
B(1,44,2,chisel:basalt2:7)
B(2,44,2,chisel:basalt2:7)
B(3,44,2,chisel:basalt2:7)
B(4,44,2,chisel:basalt2:7)
B(5,44,2,chisel:basalt2:7)
B(6,44,2,chisel:basalt2:7)
B(7,44,2,chisel:basalt2:7)
B(0,44,3,chisel:basalt2:7)
B(1,44,3,chisel:basalt2:7)
B(2,44,3,chisel:basalt2:7)
B(3,44,3,chisel:basalt2:7)
B(4,44,3,chisel:basalt2:7)
B(5,44,3,chisel:basalt2:7)
B(6,44,3,chisel:basalt2:7)
B(7,44,3,chisel:basalt2:7)
B(0,44,4,chisel:basalt2:7)
B(1,44,4,chisel:basalt2:7)
B(2,44,4,chisel:basalt2:7)
B(3,44,4,chisel:basalt2:7)
B(4,44,4,chisel:basalt2:7)
B(5,44,4,chisel:basalt2:7)
B(6,44,4,chisel:basalt2:7)
B(7,44,4,chisel:basalt2:7)
B(0,44,5,chisel:basalt2:7)
B(1,44,5,chisel:basalt2:7)
B(2,44,5,chisel:basalt2:7)
B(3,44,5,chisel:basalt2:7)
B(4,44,5,chisel:basalt2:7)
B(5,44,5,chisel:basalt2:7)
B(6,44,5,chisel:basalt2:7)
B(7,44,5,chisel:basalt2:7)
B(0,44,6,chisel:basalt2:7)
B(1,44,6,chisel:basalt2:7)
B(2,44,6,chisel:basalt2:7)
B(3,44,6,chisel:basalt2:7)
B(4,44,6,chisel:basalt2:7)
B(5,44,6,chisel:basalt2:7)
B(6,44,6,chisel:basalt2:7)
B(7,44,6,chisel:basalt2:7)
B(0,44,7,chisel:basalt2:7)
B(1,44,7,chisel:basalt2:7)
B(2,44,7,chisel:basalt2:7)
B(3,44,7,chisel:basalt2:7)
B(4,44,7,chisel:basalt2:7)
B(5,44,7,chisel:basalt2:7)
B(6,44,7,chisel:basalt2:7)
B(7,44,7,chisel:basalt2:7)
B(0,45,0,chisel:basalt2:7)
B(1,45,0,chisel:basalt2:7)
B(2,45,0,chisel:basalt2:7)
B(3,45,0,chisel:basalt2:7)
B(4,45,0,chisel:basalt2:7)
B(5,45,0,chisel:basalt2:7)
B(6,45,0,chisel:basalt2:7)
B(7,45,0,chisel:basalt2:7)
B(0,45,1,chisel:basalt2:7)
B(1,45,1,chisel:basalt2:7)
B(2,45,1,chisel:basalt2:7)
B(3,45,1,chisel:basalt2:7)
B(4,45,1,chisel:basalt2:7)
B(5,45,1,chisel:basalt2:7)
B(6,45,1,chisel:basalt2:7)
B(7,45,1,chisel:basalt2:7)
B(0,45,2,chisel:basalt2:7)
B(1,45,2,chisel:basalt2:7)
B(2,45,2,chisel:basalt2:7)
B(3,45,2,chisel:basalt2:7)
B(4,45,2,chisel:basalt2:7)
B(5,45,2,chisel:basalt2:7)
B(6,45,2,chisel:basalt2:7)
B(7,45,2,chisel:basalt2:7)
B(0,45,3,chisel:basalt2:7)
B(1,45,3,chisel:basalt2:7)
B(2,45,3,chisel:basalt2:7)
B(3,45,3,chisel:basalt2:7)
B(4,45,3,chisel:basalt2:7)
B(5,45,3,chisel:basalt2:7)
B(6,45,3,chisel:basalt2:7)
B(7,45,3,chisel:basalt2:7)
B(0,45,4,chisel:basalt2:7)
B(1,45,4,chisel:basalt2:7)
B(2,45,4,chisel:basalt2:7)
B(3,45,4,chisel:basalt2:7)
B(4,45,4,chisel:basalt2:7)
B(5,45,4,chisel:basalt2:7)
B(6,45,4,chisel:basalt2:7)
B(7,45,4,chisel:basalt2:7)
B(0,45,5,chisel:basalt2:7)
B(1,45,5,chisel:basalt2:7)
B(2,45,5,chisel:basalt2:7)
B(3,45,5,chisel:basalt2:7)
B(4,45,5,chisel:basalt2:7)
B(5,45,5,chisel:basalt2:7)
B(6,45,5,chisel:basalt2:7)
B(7,45,5,chisel:basalt2:7)
B(0,45,6,chisel:basalt2:7)
B(1,45,6,chisel:basalt2:7)
B(2,45,6,chisel:basalt2:7)
B(3,45,6,chisel:basalt2:7)
B(4,45,6,chisel:basalt2:7)
B(5,45,6,chisel:basalt2:7)
B(6,45,6,chisel:basalt2:7)
B(7,45,6,chisel:basalt2:7)
B(0,45,7,chisel:basalt2:7)
B(1,45,7,chisel:basalt2:7)
B(2,45,7,chisel:basalt2:7)
B(3,45,7,chisel:basalt2:7)
B(4,45,7,chisel:basalt2:7)
B(5,45,7,chisel:basalt2:7)
B(6,45,7,chisel:basalt2:7)
B(7,45,7,chisel:basalt2:7)
B(0,46,0,chisel:basalt2:7)
B(1,46,0,chisel:basalt2:7)
B(2,46,0,chisel:basalt2:7)
B(3,46,0,chisel:basalt2:7)
B(4,46,0,chisel:basalt2:7)
B(5,46,0,chisel:basalt2:7)
B(6,46,0,chisel:basalt2:7)
B(7,46,0,chisel:basalt2:7)
B(0,46,1,chisel:basalt2:7)
B(1,46,1,chisel:basalt2:7)
B(2,46,1,chisel:basalt2:7)
B(3,46,1,chisel:basalt2:7)
B(4,46,1,chisel:basalt2:7)
B(5,46,1,chisel:basalt2:7)
B(6,46,1,chisel:basalt2:7)
B(7,46,1,chisel:basalt2:7)
B(0,46,2,chisel:basalt2:7)
B(1,46,2,chisel:basalt2:7)
B(2,46,2,chisel:basalt2:7)
B(3,46,2,chisel:basalt2:7)
B(4,46,2,chisel:basalt2:7)
B(5,46,2,chisel:basalt2:7)
B(6,46,2,chisel:basalt2:7)
B(7,46,2,chisel:basalt2:7)
B(0,46,3,chisel:basalt2:7)
B(1,46,3,chisel:basalt2:7)
B(2,46,3,chisel:basalt2:7)
B(3,46,3,chisel:basalt2:7)
B(4,46,3,chisel:basalt2:7)
B(5,46,3,chisel:basalt2:7)
B(6,46,3,chisel:basalt2:7)
B(7,46,3,chisel:basalt2:7)
B(0,46,4,chisel:basalt2:7)
B(1,46,4,chisel:basalt2:7)
B(2,46,4,chisel:basalt2:7)
B(3,46,4,chisel:basalt2:7)
B(4,46,4,chisel:basalt2:7)
B(5,46,4,chisel:basalt2:7)
B(6,46,4,chisel:basalt2:7)
B(7,46,4,chisel:basalt2:7)
B(0,46,5,chisel:basalt2:7)
B(1,46,5,chisel:basalt2:7)
B(2,46,5,chisel:basalt2:7)
B(3,46,5,chisel:basalt2:7)
B(4,46,5,chisel:basalt2:7)
B(5,46,5,chisel:basalt2:7)
B(6,46,5,chisel:basalt2:7)
B(7,46,5,chisel:basalt2:7)
B(0,46,6,chisel:basalt2:7)
B(1,46,6,chisel:basalt2:7)
B(2,46,6,chisel:basalt2:7)
B(3,46,6,chisel:basalt2:7)
B(4,46,6,chisel:basalt2:7)
B(5,46,6,chisel:basalt2:7)
B(6,46,6,chisel:basalt2:7)
B(7,46,6,chisel:basalt2:7)
B(0,46,7,chisel:basalt2:7)
B(1,46,7,chisel:basalt2:7)
B(2,46,7,chisel:basalt2:7)
B(3,46,7,chisel:basalt2:7)
B(4,46,7,chisel:basalt2:7)
B(5,46,7,chisel:basalt2:7)
B(6,46,7,chisel:basalt2:7)
B(7,46,7,chisel:basalt2:7)
B(0,47,0,chisel:basalt2:7)
B(1,47,0,chisel:basalt2:7)
B(2,47,0,chisel:basalt2:7)
B(3,47,0,chisel:basalt2:7)
B(4,47,0,chisel:basalt2:7)
B(5,47,0,chisel:basalt2:7)
B(6,47,0,chisel:basalt2:7)
B(7,47,0,chisel:basalt2:7)
B(0,47,1,chisel:basalt2:7)
B(1,47,1,chisel:basalt2:7)
B(2,47,1,chisel:basalt2:7)
B(3,47,1,chisel:basalt2:7)
B(4,47,1,chisel:basalt2:7)
B(5,47,1,chisel:basalt2:7)
B(6,47,1,chisel:basalt2:7)
B(7,47,1,chisel:basalt2:7)
B(0,47,2,chisel:basalt2:7)
B(1,47,2,chisel:basalt2:7)
B(2,47,2,chisel:basalt2:7)
B(3,47,2,chisel:basalt2:7)
B(4,47,2,chisel:basalt2:7)
B(5,47,2,chisel:basalt2:7)
B(6,47,2,chisel:basalt2:7)
B(7,47,2,chisel:basalt2:7)
B(0,47,3,chisel:basalt2:7)
B(1,47,3,chisel:basalt2:7)
B(2,47,3,chisel:basalt2:7)
B(3,47,3,chisel:basalt2:7)
B(4,47,3,chisel:basalt2:7)
B(5,47,3,chisel:basalt2:7)
B(6,47,3,chisel:basalt2:7)
B(7,47,3,chisel:basalt2:7)
B(0,47,4,chisel:basalt2:7)
B(1,47,4,chisel:basalt2:7)
B(2,47,4,chisel:basalt2:7)
B(3,47,4,chisel:basalt2:7)
B(4,47,4,chisel:basalt2:7)
B(5,47,4,chisel:basalt2:7)
B(6,47,4,chisel:basalt2:7)
B(7,47,4,chisel:basalt2:7)
B(0,47,5,chisel:basalt2:7)
B(1,47,5,chisel:basalt2:7)
B(2,47,5,chisel:basalt2:7)
B(3,47,5,chisel:basalt2:7)
B(4,47,5,chisel:basalt2:7)
B(5,47,5,chisel:basalt2:7)
B(6,47,5,chisel:basalt2:7)
B(7,47,5,chisel:basalt2:7)
B(0,47,6,chisel:basalt2:7)
B(1,47,6,chisel:basalt2:7)
B(2,47,6,chisel:basalt2:7)
B(3,47,6,chisel:basalt2:7)
B(4,47,6,chisel:basalt2:7)
B(5,47,6,chisel:basalt2:7)
B(6,47,6,chisel:basalt2:7)
B(7,47,6,chisel:basalt2:7)
B(0,47,7,chisel:basalt2:7)
B(1,47,7,chisel:basalt2:7)
B(2,47,7,chisel:basalt2:7)
B(3,47,7,chisel:basalt2:7)
B(4,47,7,chisel:basalt2:7)
B(5,47,7,chisel:basalt2:7)
B(6,47,7,chisel:basalt2:7)
B(7,47,7,chisel:basalt2:7)
B(0,48,0,chisel:basalt2:7)
B(1,48,0,chisel:basalt2:7)
B(2,48,0,chisel:basalt2:7)
B(3,48,0,chisel:basalt2:7)
B(4,48,0,chisel:basalt2:7)
B(5,48,0,chisel:basalt2:7)
B(6,48,0,chisel:basalt2:7)
B(7,48,0,chisel:basalt2:7)
B(0,48,1,chisel:basalt2:7)
B(1,48,1,chisel:basalt2:7)
B(2,48,1,chisel:basalt2:7)
B(3,48,1,chisel:basalt2:7)
B(4,48,1,chisel:basalt2:7)
B(5,48,1,chisel:basalt2:7)
B(6,48,1,chisel:basalt2:7)
B(7,48,1,chisel:basalt2:7)
B(0,48,2,chisel:basalt2:7)
B(1,48,2,chisel:basalt2:7)
B(2,48,2,chisel:basalt2:7)
B(3,48,2,chisel:basalt2:7)
B(4,48,2,chisel:basalt2:7)
B(5,48,2,chisel:basalt2:7)
B(6,48,2,chisel:basalt2:7)
B(7,48,2,chisel:basalt2:7)
B(0,48,3,chisel:basalt2:7)
B(1,48,3,chisel:basalt2:7)
B(2,48,3,chisel:basalt2:7)
B(3,48,3,chisel:basalt2:7)
B(4,48,3,chisel:basalt2:7)
B(5,48,3,chisel:basalt2:7)
B(6,48,3,chisel:basalt2:7)
B(7,48,3,chisel:basalt2:7)
B(0,48,4,chisel:basalt2:7)
B(1,48,4,chisel:basalt2:7)
B(2,48,4,chisel:basalt2:7)
B(3,48,4,chisel:basalt2:7)
B(4,48,4,chisel:basalt2:7)
B(5,48,4,chisel:basalt2:7)
B(6,48,4,chisel:basalt2:7)
B(7,48,4,chisel:basalt2:7)
B(0,48,5,chisel:basalt2:7)
B(1,48,5,chisel:basalt2:7)
B(2,48,5,chisel:basalt2:7)
B(3,48,5,chisel:basalt2:7)
B(4,48,5,chisel:basalt2:7)
B(5,48,5,chisel:basalt2:7)
B(6,48,5,chisel:basalt2:7)
B(7,48,5,chisel:basalt2:7)
B(0,48,6,chisel:basalt2:7)
B(1,48,6,chisel:basalt2:7)
B(2,48,6,chisel:basalt2:7)
B(3,48,6,chisel:basalt2:7)
B(4,48,6,chisel:basalt2:7)
B(5,48,6,chisel:basalt2:7)
B(6,48,6,chisel:basalt2:7)
B(7,48,6,chisel:basalt2:7)
B(0,48,7,chisel:basalt2:7)
B(1,48,7,chisel:basalt2:7)
B(2,48,7,chisel:basalt2:7)
B(3,48,7,chisel:basalt2:7)
B(4,48,7,chisel:basalt2:7)
B(5,48,7,chisel:basalt2:7)
B(6,48,7,chisel:basalt2:7)
B(7,48,7,chisel:basalt2:7)
B(0,49,0,STONEBRICK:0)
B(1,49,0,STONEBRICK:0)
B(2,49,0,STONEBRICK:0)
B(3,49,0,STONEBRICK:0)
B(4,49,0,STONEBRICK:0)
B(5,49,0,STONEBRICK:0)
B(6,49,0,STONEBRICK:0)
B(7,49,0,chisel:basalt2:7)
B(0,49,1,STONEBRICK:0)
B(1,49,1,STONEBRICK:0)
B(2,49,1,STONEBRICK:0)
B(3,49,1,STONEBRICK:0)
B(4,49,1,STONEBRICK:0)
B(5,49,1,STONEBRICK:0)
B(6,49,1,STONEBRICK:0)
B(7,49,1,chisel:basalt2:7)
B(0,49,2,STONEBRICK:0)
B(1,49,2,STONEBRICK:0)
B(2,49,2,STONEBRICK:0)
B(3,49,2,STONEBRICK:0)
B(4,49,2,STONEBRICK:0)
B(5,49,2,STONEBRICK:0)
B(6,49,2,STONEBRICK:0)
B(7,49,2,chisel:basalt2:7)
B(0,49,3,STONEBRICK:0)
B(1,49,3,STONEBRICK:0)
B(2,49,3,STONEBRICK:0)
B(3,49,3,STONEBRICK:0)
B(4,49,3,STONEBRICK:0)
B(5,49,3,STONEBRICK:0)
B(6,49,3,STONEBRICK:0)
B(7,49,3,chisel:basalt2:7)
B(0,49,4,STONEBRICK:0)
B(1,49,4,STONEBRICK:0)
B(2,49,4,STONEBRICK:0)
B(3,49,4,STONEBRICK:0)
B(4,49,4,STONEBRICK:0)
B(5,49,4,STONEBRICK:0)
B(6,49,4,STONEBRICK:0)
B(7,49,4,chisel:basalt2:7)
B(0,49,5,STONEBRICK:0)
B(1,49,5,STONEBRICK:0)
B(2,49,5,STONEBRICK:0)
B(3,49,5,STONEBRICK:0)
B(4,49,5,STONEBRICK:0)
B(5,49,5,STONEBRICK:0)
B(6,49,5,STONEBRICK:0)
B(7,49,5,chisel:basalt2:7)
B(0,49,6,STONEBRICK:0)
B(1,49,6,STONEBRICK:0)
B(2,49,6,STONEBRICK:0)
B(3,49,6,STONEBRICK:0)
B(4,49,6,STONEBRICK:0)
B(5,49,6,STONEBRICK:0)
B(6,49,6,STONEBRICK:0)
B(7,49,6,chisel:basalt2:7)
B(0,49,7,chisel:basalt2:7)
B(1,49,7,chisel:basalt2:7)
B(2,49,7,chisel:basalt2:7)
B(3,49,7,chisel:basalt2:7)
B(4,49,7,chisel:basalt2:7)
B(5,49,7,chisel:basalt2:7)
B(6,49,7,chisel:basalt2:7)
B(7,49,7,chisel:basalt2:7)
B(0,54,0,STONE:0)
B(1,54,0,STONE:0)
B(2,54,0,STONE:0)
B(3,54,0,STONE:0)
B(4,54,0,STONE:0)
B(5,54,0,STONE:0)
B(6,54,0,STONE:0)
B(7,54,0,STONE:0)
B(0,54,1,STONE:0)
B(1,54,1,STONE:0)
B(2,54,1,STONE:0)
B(3,54,1,STONE:0)
B(4,54,1,STONE:0)
B(5,54,1,STONE:0)
B(6,54,1,STONE:0)
B(7,54,1,STONE:0)
B(0,54,2,STONE:0)
B(1,54,2,STONE:0)
B(2,54,2,STONE:0)
B(3,54,2,STONE:0)
B(4,54,2,STONE:0)
B(5,54,2,STONE:0)
B(6,54,2,STONE:0)
B(7,54,2,STONE:0)
B(0,54,3,STONE:0)
B(1,54,3,STONE:0)
B(2,54,3,STONE:0)
B(3,54,3,STONE:0)
B(4,54,3,STONE:0)
B(5,54,3,STONE:0)
B(6,54,3,STONE:0)
B(7,54,3,STONE:0)
B(0,54,4,STONE:0)
B(1,54,4,STONE:0)
B(2,54,4,STONE:0)
B(3,54,4,STONE:0)
B(4,54,4,STONE:0)
B(5,54,4,STONE:0)
B(6,54,4,STONE:0)
B(7,54,4,STONE:0)
B(0,54,5,STONE:0)
B(1,54,5,STONE:0)
B(2,54,5,STONE:0)
B(3,54,5,STONE:0)
B(4,54,5,STONE:0)
B(5,54,5,STONE:0)
B(6,54,5,STONE:0)
B(7,54,5,STONE:0)
B(0,54,6,STONE:0)
B(1,54,6,STONE:0)
B(2,54,6,STONE:0)
B(3,54,6,STONE:0)
B(4,54,6,STONE:0)
B(5,54,6,STONE:0)
B(6,54,6,STONE:0)
B(7,54,6,STONE:0)
B(0,54,7,STONE:0)
B(1,54,7,STONE:0)
B(2,54,7,STONE:0)
B(3,54,7,STONE:0)
B(4,54,7,STONE:0)
B(5,54,7,STONE:0)
B(6,54,7,STONE:0)
B(7,54,7,STONE:0)
B(0,55,0,STONE:0)
B(1,55,0,STONE:0)
B(2,55,0,STONE:0)
B(3,55,0,STONE:0)
B(4,55,0,STONE:0)
B(5,55,0,STONE:0)
B(6,55,0,STONE:0)
B(7,55,0,STONE:0)
B(0,55,1,STONE:0)
B(1,55,1,STONE:0)
B(2,55,1,STONE:0)
B(3,55,1,STONE:0)
B(4,55,1,STONE:0)
B(5,55,1,STONE:0)
B(6,55,1,STONE:0)
B(7,55,1,STONE:0)
B(0,55,2,STONE:0)
B(1,55,2,STONE:0)
B(2,55,2,STONE:0)
B(3,55,2,STONE:0)
B(4,55,2,STONE:0)
B(5,55,2,STONE:0)
B(6,55,2,STONE:0)
B(7,55,2,STONE:0)
B(0,55,3,STONE:0)
B(1,55,3,STONE:0)
B(2,55,3,STONE:0)
B(3,55,3,STONE:0)
B(4,55,3,STONE:0)
B(5,55,3,STONE:0)
B(6,55,3,STONE:0)
B(7,55,3,STONE:0)
B(0,55,4,DIRT:0)
B(1,55,4,STONE:0)
B(2,55,4,STONE:0)
B(3,55,4,STONE:0)
B(4,55,4,STONE:0)
B(5,55,4,STONE:0)
B(6,55,4,STONE:0)
B(7,55,4,STONE:0)
B(0,55,5,DIRT:0)
B(1,55,5,STONE:0)
B(2,55,5,STONE:0)
B(3,55,5,STONE:0)
B(4,55,5,STONE:0)
B(5,55,5,STONE:0)
B(6,55,5,STONE:0)
B(7,55,5,STONE:0)
B(0,55,6,GRASS:0)
B(1,55,6,STONE:0)
B(2,55,6,STONE:0)
B(3,55,6,STONE:0)
B(4,55,6,STONE:0)
B(5,55,6,STONE:0)
B(6,55,6,DIRT:0)
B(7,55,6,STONE:0)
B(0,55,7,DIRT:0)
B(1,55,7,STONE:0)
B(2,55,7,STONE:0)
B(3,55,7,STONE:0)
B(4,55,7,STONE:0)
B(5,55,7,STONE:0)
B(6,55,7,STONE:0)
B(7,55,7,STONE:0)
B(0,56,0,GRASS:0)
B(1,56,0,DIRT:0)
B(2,56,0,GRASS:0)
B(3,56,0,GRASS:0)
B(4,56,0,DIRT:0)
B(5,56,0,DIRT:0)
B(6,56,0,DIRT:0)
B(7,56,0,STONE:0)
B(0,56,1,DIRT:0)
B(1,56,1,GRASS:0)
B(2,56,1,DIRT:0)
B(3,56,1,DIRT:0)
B(4,56,1,DIRT:0)
B(5,56,1,DIRT:0)
B(6,56,1,DIRT:0)
B(7,56,1,STONE:0)
B(0,56,2,GRASS:0)
B(1,56,2,DIRT:0)
B(2,56,2,DIRT:0)
B(3,56,2,DIRT:0)
B(4,56,2,DIRT:0)
B(5,56,2,GRASS:0)
B(6,56,2,GRASS:0)
B(7,56,2,STONE:0)
B(0,56,3,DIRT:0)
B(1,56,3,GRASS:0)
B(2,56,3,STONE:0)
B(3,56,3,STONE:0)
B(4,56,3,STONE:0)
B(5,56,3,STONE:0)
B(6,56,3,STONE:0)
B(7,56,3,STONE:0)
B(1,56,4,DIRT:0)
B(2,56,4,STONE:0)
B(3,56,4,STONE:0)
B(4,56,4,STONE:0)
B(5,56,4,STONE:0)
B(6,56,4,DIRT:0)
B(7,56,4,GRASS:0)
B(1,56,5,DIRT:0)
B(2,56,5,STONE:0)
B(3,56,5,STONE:0)
B(4,56,5,GRASS:0)
B(5,56,5,DIRT:0)
B(6,56,5,DIRT:0)
B(7,56,5,DIRT:0)
B(1,56,6,DIRT:0)
B(2,56,6,STONE:0)
B(3,56,6,STONE:0)
B(4,56,6,DIRT:0)
B(5,56,6,DIRT:0)
B(1,56,7,DIRT:0)
B(2,56,7,DIRT:0)
B(3,56,7,STONE:0)
B(4,56,7,DIRT:0)
B(5,56,7,GRASS:0)
B(7,57,0,STONE:0)
B(7,57,1,STONE:0)
B(7,57,2,STONE:0)
B(2,57,3,GRASS:0)
B(3,57,3,DIRT:0)
B(4,57,3,GRASS:0)
B(5,57,3,DIRT:0)
B(6,57,3,DIRT:0)
B(7,57,3,STONE:0)
B(2,57,4,DIRT:0)
B(3,57,4,GRASS:0)
B(4,57,4,DIRT:0)
B(5,57,4,GRASS:0)
B(2,57,5,DIRT:0)
B(3,57,5,GRASS:0)
B(2,57,6,GRASS:0)
B(3,57,6,DIRT:0)
B(3,57,7,GRASS:0)
