
#
# +-----------------------------------------------------------------+ #
# |                            BO3 object                           | #
# +-----------------------------------------------------------------+ #
#

Author: NLBlackEagle

Description: Bo3 Created by NLBlackEagle - For Dregora

Version: 3

SettingsMode: WriteDisable


#
# +-----------------------------------------------------------------+ #
# |                          Main settings                          | #
# +-----------------------------------------------------------------+ #
#

Tree: false

Frequency: 2

Rarity: 20.0

RotateRandomly: true

SpawnHeight: randomY

SpawnHeightOffset: 0

SpawnHeightVariance: 0


# Height Limits for the BO3. #


MinHeight: 3

MaxHeight: 6


# Extrusion settings #


ExtrudeMode: None

ExtrudeThroughBlocks: air

MaxBranchDepth: 10

ExcludedBiomes: All


#
# +-----------------------------------------------------------------+ #
# |                      Source block settings                      | #
# +-----------------------------------------------------------------+ #
#

SourceBlocks: air

MaxPercentageOutsideSourceBlock: 100

OutsideSourceBlock: placeAnyway


#
# +-----------------------------------------------------------------+ #
# |                              Blocks                             | #
# +-----------------------------------------------------------------+ #
#

B(-3,0,0,quark:basalt:0)
B(-3,1,0,prismarine)
B(-2,0,-1,quark:basalt:0)
B(-2,0,0,quark:basalt:0)
B(-2,0,1,quark:basalt:0)
B(-2,0,2,quark:basalt:0)
B(-2,1,-1,quark:basalt:0)
B(-2,1,0,quark:basalt:0)
B(-2,1,1,quark:basalt:0)
B(-2,1,2,quark:basalt:0)
B(-2,2,0,prismarine)
B(-2,2,1,quark:basalt:0)
B(-2,3,0,prismarine)
B(-2,3,1,quark:basalt:0)
B(-2,4,0,prismarine)
B(-2,5,0,quark:basalt:0)
B(-2,6,0,quark:basalt:0)
B(-2,7,0,quark:basalt:0)
B(-2,8,0,quark:basalt:0)
B(-1,0,-2,quark:basalt:0)
B(-1,0,-1,quark:basalt:0)
B(-1,0,0,quark:basalt:0)
B(-1,0,1,quark:basalt:0)
B(-1,0,2,quark:basalt:0)
B(-1,0,3,quark:basalt:0)
B(-1,1,-2,quark:basalt:0)
B(-1,1,-1,quark:basalt:0)
B(-1,1,0,quark:basalt:0)
B(-1,1,1,quark:basalt:0)
B(-1,1,2,quark:basalt:0)
B(-1,1,3,quark:basalt:0)
B(-1,2,-1,quark:basalt:0)
B(-1,2,0,quark:basalt:0)
B(-1,2,1,quark:basalt:0)
B(-1,2,2,quark:basalt:0)
B(-1,3,-1,quark:basalt:0)
B(-1,3,0,quark:basalt:0)
B(-1,3,1,quark:basalt:0)
B(-1,3,2,quark:basalt:0)
B(-1,4,-1,quark:basalt:0)
B(-1,4,0,quark:basalt:0)
B(-1,4,1,prismarine)
B(-1,4,2,quark:basalt:0)
B(-1,5,-1,quark:basalt:0)
B(-1,5,0,quark:basalt:0)
B(-1,5,1,prismarine)
B(-1,5,2,quark:basalt:0)
B(-1,6,-1,quark:basalt:0)
B(-1,6,0,quark:basalt:0)
B(-1,6,1,prismarine)
B(-1,6,2,prismarine)
B(-1,7,-1,quark:basalt:0)
B(-1,7,0,quark:basalt:0)
B(-1,7,1,quark:basalt:0)
B(-1,8,-1,quark:basalt:0)
B(-1,8,0,quark:basalt:0)
B(-1,8,1,quark:basalt:0)
B(-1,9,-1,quark:basalt:0)
B(-1,9,0,quark:basalt:0)
B(-1,9,1,quark:basalt:0)
B(-1,10,0,quark:basalt:0)
B(-1,10,1,quark:basalt:0)
B(-1,11,0,prismarine)
B(-1,11,1,quark:basalt:0)
B(-1,12,0,prismarine)
B(-1,13,0,prismarine)
B(-1,14,0,quark:basalt:0)
B(0,0,-2,quark:basalt:0)
B(0,0,-1,quark:basalt:0)
B(0,0,0,quark:basalt:0)
B(0,0,1,quark:basalt:0)
B(0,0,2,quark:basalt:0)
B(0,1,-2,quark:basalt:0)
B(0,1,-1,quark:basalt:0)
B(0,1,0,quark:basalt:0)
B(0,1,1,quark:basalt:0)
B(0,1,2,quark:basalt:0)
B(0,2,-2,quark:basalt:0)
B(0,2,-1,quark:basalt:0)
B(0,2,0,quark:basalt:0)
B(0,2,1,quark:basalt:0)
B(0,2,2,quark:basalt:0)
B(0,3,-1,quark:basalt:0)
B(0,3,0,quark:basalt:0)
B(0,3,1,quark:basalt:0)
B(0,3,2,quark:basalt:0)
B(0,4,-1,quark:basalt:0)
B(0,4,0,quark:basalt:0)
B(0,4,1,quark:basalt:0)
B(0,4,2,quark:basalt:0)
B(0,5,-1,quark:basalt:0)
B(0,5,0,quark:basalt:0)
B(0,5,1,quark:basalt:0)
B(0,5,2,quark:basalt:0)
B(0,6,-1,quark:basalt:0)
B(0,6,0,quark:basalt:0)
B(0,6,1,quark:basalt:0)
B(0,6,2,prismarine)
B(0,7,-1,quark:basalt:0)
B(0,7,0,quark:basalt:0)
B(0,7,1,prismarine)
B(0,7,2,quark:basalt:0)
B(0,8,-1,quark:basalt:0)
B(0,8,0,quark:basalt:0)
B(0,8,1,quark:basalt:0)
B(0,9,-1,prismarine)
B(0,9,0,quark:basalt:0)
B(0,9,1,quark:basalt:0)
B(0,10,-1,prismarine)
B(0,10,0,quark:basalt:0)
B(0,10,1,quark:basalt:0)
B(0,11,-1,quark:basalt:0)
B(0,11,0,quark:basalt:0)
B(0,11,1,quark:basalt:0)
B(0,12,0,quark:basalt:0)
B(0,12,1,quark:basalt:0)
B(0,13,0,quark:basalt:0)
B(0,13,1,quark:basalt:0)
B(0,14,0,quark:basalt:0)
B(0,14,1,prismarine)
B(0,15,0,quark:basalt:0)
B(0,15,1,prismarine)
B(0,16,0,quark:basalt:0)
B(0,16,1,prismarine)
B(0,17,0,quark:basalt:0)
B(0,18,0,quark:basalt:0)
B(0,19,0,prismarine)
B(0,20,0,quark:basalt:0)
B(0,21,0,quark:basalt:0)
B(1,0,-3,quark:basalt:0)
B(1,0,-2,quark:basalt:0)
B(1,0,-1,quark:basalt:0)
B(1,0,0,quark:basalt:0)
B(1,0,1,quark:basalt:0)
B(1,0,2,quark:basalt:0)
B(1,1,-3,quark:basalt:0)
B(1,1,-2,quark:basalt:0)
B(1,1,-1,quark:basalt:0)
B(1,1,0,quark:basalt:0)
B(1,1,1,quark:basalt:0)
B(1,1,2,quark:basalt:0)
B(1,2,-3,quark:basalt:0)
B(1,2,-2,quark:basalt:0)
B(1,2,-1,quark:basalt:0)
B(1,2,0,quark:basalt:0)
B(1,2,1,quark:basalt:0)
B(1,2,2,quark:basalt:0)
B(1,3,-2,quark:basalt:0)
B(1,3,-1,quark:basalt:0)
B(1,3,0,quark:basalt:0)
B(1,3,1,quark:basalt:0)
B(1,3,2,quark:basalt:0)
B(1,4,-2,quark:basalt:0)
B(1,4,-1,quark:basalt:0)
B(1,4,0,quark:basalt:0)
B(1,4,1,quark:basalt:0)
B(1,5,-1,quark:basalt:0)
B(1,5,0,quark:basalt:0)
B(1,5,1,quark:basalt:0)
B(1,6,-1,quark:basalt:0)
B(1,6,0,quark:basalt:0)
B(1,6,1,quark:basalt:0)
B(1,7,-1,quark:basalt:0)
B(1,7,0,quark:basalt:0)
B(1,7,1,prismarine)
B(1,8,-1,quark:basalt:0)
B(1,8,0,prismarine)
B(1,8,1,quark:basalt:0)
B(1,9,0,prismarine)
B(1,9,1,quark:basalt:0)
B(1,10,0,quark:basalt:0)
B(1,10,1,quark:basalt:0)
B(1,11,0,quark:basalt:0)
B(1,12,0,quark:basalt:0)
B(1,13,0,quark:basalt:0)
B(1,14,0,quark:basalt:0)
B(1,15,0,quark:basalt:0)
B(1,16,0,quark:basalt:0)
B(1,17,0,prismarine)
B(1,18,0,prismarine)
B(2,0,-2,quark:basalt:0)
B(2,0,-1,quark:basalt:0)
B(2,0,0,quark:basalt:0)
B(2,0,1,quark:basalt:0)
B(2,1,-2,quark:basalt:0)
B(2,1,-1,quark:basalt:0)
B(2,1,0,quark:basalt:0)
B(2,1,1,quark:basalt:0)
B(2,2,-1,quark:basalt:0)
B(2,2,0,quark:basalt:0)
B(2,3,-1,quark:basalt:0)
B(2,4,-1,quark:basalt:0)
B(2,5,-1,quark:basalt:0)
B(3,0,-1,quark:basalt:0)
B(3,1,-1,quark:basalt:0)
B(3,2,-1,quark:basalt:0)
B(3,3,-1,quark:basalt:0)

#
# +-----------------------------------------------------------------+ #
# |                            BO3 checks                           | #
# +-----------------------------------------------------------------+ #
#

BlockCheck(0,24,0,air)

#
# +-----------------------------------------------------------------+ #
# |                             Branches                            | #
# +-----------------------------------------------------------------+ #
#
