#######################################################################
# +-----------------------------------------------------------------+ #
# |                            BO3 object                           | #
# +-----------------------------------------------------------------+ #
#######################################################################

# This is the config file of a custom object.
# If you add this object correctly to your BiomeConfigs, it will spawn in the world.

# This is the creator of this BO3 object
Author: BO3 BulkEdit (by LanToaster)

# A short description of this BO3 object
Description: This Object was Created with BO3_BulkEdit

# The BO3 version, don't change this! It can be used by external applications to do a version check.
Version: 3

# The settings mode, WriteAll, WriteWithoutComments or WriteDisable. See WorldConfig.
SettingsMode: WriteDisable


#######################################################################
# +-----------------------------------------------------------------+ #
# |                          Main settings                          | #
# +-----------------------------------------------------------------+ #
#######################################################################

# This needs to be set to true to spawn the object in the Tree and Sapling resources.
Tree: false

# The frequency of the BO3 from 1 to 200. Tries this many times to spawn this BO3 when using the CustomObject(...) resource.

Frequency: 10

# The rarity of the BO3 from 0 to 100. Each spawn attempt has rarity% chance to succeed when using the CustomObject(...) resource.

Rarity: 100.0

# If you set this to true, the BO3 will be placed with a random rotation.
RotateRandomly: false

# The spawn height of the BO3 - randomY, highestBlock or highestSolidBlock.
SpawnHeight: randomY

# The height limits for the BO3.
MinHeight: 30

MaxHeight: 60

# Objects can have other objects attacthed to it: branches. Branches can also
# have branches attached to it, which can also have branches, etc. This is the
# maximum branch depth for this objects.
MaxBranchDepth: 10

# When spawned with the UseWorld keyword, this BO3 should NOT spawn in the following biomes.
# If you writer.write the BO3 name directly in the BiomeConfigs, this will be ignored.
ExcludedBiomes: All


#######################################################################
# +-----------------------------------------------------------------+ #
# |                      Source block settings                      | #
# +-----------------------------------------------------------------+ #
#######################################################################

# The block(s) the BO3 should spawn in.
SourceBlocks: AIR

# The maximum percentage of the BO3 that can be outside the SourceBlock.
# The BO3 won't be placed on a location with more blocks outside the SourceBlock than this percentage.
MaxPercentageOutsideSourceBlock: 100

# What to do when a block is about to be placed outside the SourceBlock? (dontPlace, placeAnyway)
OutsideSourceBlock: placeAnyway


#######################################################################
# +-----------------------------------------------------------------+ #
# |                              Blocks                             | #
# +-----------------------------------------------------------------+ #
#######################################################################

# All the blocks used in the BO3 are listed here. Possible blocks:
# Block(x,y,z,id[.data][,nbtfile.nbt)
# RandomBlock(x,y,z,id[:data][,nbtfile.nbt],chance[,id[:data][,nbtfile.nbt],chance[,...]])
# So RandomBlock(0,0,0,CHEST,chest.nbt,50,CHEST,anotherchest.nbt,100) will spawn a chest at
# the BO3 origin, and give it a 50% chance to have the contents of chest.nbt, or, if that
# fails, a 100% percent chance to have the contents of anotherchest.nbt.
RandomBlock(-3,0,-5,quark:basalt:0,50,159:10,100)
RandomBlock(-2,0,-5,quark:basalt:0,50,159:10,100)
RandomBlock(-1,0,-5,quark:basalt:0,50,159:10,100)
RandomBlock(0,0,-5,quark:basalt:0,50,159:10,100)
RandomBlock(1,0,-5,quark:basalt:0,50,159:10,100)
RandomBlock(2,0,-5,quark:basalt:0,50,159:10,100)
RandomBlock(3,0,-5,quark:basalt:0,50,159:10,100)
RandomBlock(-5,0,-4,quark:basalt:0,50,159:10,100)
RandomBlock(-4,0,-4,quark:basalt:0,50,159:10,100)
RandomBlock(-3,0,-4,quark:basalt:0,50,159:10,100)
RandomBlock(-2,0,-4,quark:basalt:0,50,159:10,100)
RandomBlock(-1,0,-4,quark:basalt:0,50,159:10,100)
RandomBlock(0,0,-4,quark:basalt:0,50,159:10,100)
RandomBlock(1,0,-4,quark:basalt:0,50,159:10,100)
RandomBlock(2,0,-4,quark:basalt:0,50,159:10,100)
RandomBlock(3,0,-4,quark:basalt:0,50,159:10,100)
RandomBlock(-6,0,-3,quark:basalt:0,50,159:10,100)
RandomBlock(-5,0,-3,quark:basalt:0,50,159:10,100)
RandomBlock(-4,0,-3,quark:basalt:0,50,159:10,100)
RandomBlock(-3,0,-3,quark:basalt:0,50,159:10,100)
RandomBlock(-2,0,-3,quark:basalt:0,50,159:10,100)
RandomBlock(-1,0,-3,quark:basalt:0,50,159:10,100)
RandomBlock(0,0,-3,quark:basalt:0,50,159:10,100)
RandomBlock(1,0,-3,quark:basalt:0,50,159:10,100)
RandomBlock(2,0,-3,quark:basalt:0,50,159:10,100)
RandomBlock(3,0,-3,quark:basalt:0,50,159:10,100)
RandomBlock(4,0,-3,quark:basalt:0,50,159:10,100)
RandomBlock(-6,0,-2,quark:basalt:0,50,159:10,100)
RandomBlock(-5,0,-2,quark:basalt:0,50,159:10,100)
RandomBlock(-4,0,-2,quark:basalt:0,50,159:10,100)
RandomBlock(-3,0,-2,quark:basalt:0,50,159:10,100)
RandomBlock(-2,0,-2,quark:basalt:0,50,159:10,100)
RandomBlock(-1,0,-2,quark:basalt:0,50,159:10,100)
RandomBlock(0,0,-2,quark:basalt:0,50,159:10,100)
RandomBlock(1,0,-2,quark:basalt:0,50,159:10,100)
RandomBlock(2,0,-2,quark:basalt:0,50,159:10,100)
RandomBlock(3,0,-2,quark:basalt:0,50,159:10,100)
RandomBlock(4,0,-2,quark:basalt:0,50,159:10,100)
RandomBlock(-6,0,-1,quark:basalt:0,50,159:10,100)
RandomBlock(-5,0,-1,quark:basalt:0,50,159:10,100)
RandomBlock(-4,0,-1,quark:basalt:0,50,159:10,100)
RandomBlock(-3,0,-1,quark:basalt:0,50,159:10,100)
RandomBlock(-2,0,-1,quark:basalt:0,50,159:10,100)
RandomBlock(-1,0,-1,quark:basalt:0,50,159:10,100)
RandomBlock(0,0,-1,quark:basalt:0,50,159:10,100)
RandomBlock(1,0,-1,quark:basalt:0,50,159:10,100)
RandomBlock(2,0,-1,quark:basalt:0,50,159:10,100)
RandomBlock(3,0,-1,quark:basalt:0,50,159:10,100)
RandomBlock(4,0,-1,quark:basalt:0,50,159:10,100)
RandomBlock(5,0,-1,quark:basalt:0,50,159:10,100)
RandomBlock(-6,0,0,quark:basalt:0,50,159:10,100)
RandomBlock(-5,0,0,quark:basalt:0,50,159:10,100)
RandomBlock(-4,0,0,quark:basalt:0,50,159:10,100)
RandomBlock(-3,0,0,quark:basalt:0,50,159:10,100)
RandomBlock(-2,0,0,quark:basalt:0,50,159:10,100)
RandomBlock(-1,0,0,quark:basalt:0,50,159:10,100)
RandomBlock(0,0,0,quark:basalt:0,50,159:10,100)
RandomBlock(1,0,0,quark:basalt:0,50,159:10,100)
RandomBlock(2,0,0,quark:basalt:0,50,159:10,100)
RandomBlock(3,0,0,quark:basalt:0,50,159:10,100)
RandomBlock(4,0,0,quark:basalt:0,50,159:10,100)
RandomBlock(5,0,0,quark:basalt:0,50,159:10,100)
RandomBlock(-5,0,1,quark:basalt:0,50,159:10,100)
RandomBlock(-4,0,1,quark:basalt:0,50,159:10,100)
RandomBlock(-3,0,1,quark:basalt:0,50,159:10,100)
RandomBlock(-2,0,1,quark:basalt:0,50,159:10,100)
RandomBlock(-1,0,1,quark:basalt:0,50,159:10,100)
RandomBlock(0,0,1,quark:basalt:0,50,159:10,100)
RandomBlock(1,0,1,quark:basalt:0,50,159:10,100)
RandomBlock(2,0,1,quark:basalt:0,50,159:10,100)
RandomBlock(3,0,1,quark:basalt:0,50,159:10,100)
RandomBlock(4,0,1,quark:basalt:0,50,159:10,100)
RandomBlock(5,0,1,quark:basalt:0,50,159:10,100)
RandomBlock(-4,0,2,quark:basalt:0,50,159:10,100)
RandomBlock(-3,0,2,quark:basalt:0,50,159:10,100)
RandomBlock(-2,0,2,quark:basalt:0,50,159:10,100)
RandomBlock(-1,0,2,quark:basalt:0,50,159:10,100)
RandomBlock(0,0,2,quark:basalt:0,50,159:10,100)
RandomBlock(1,0,2,quark:basalt:0,50,159:10,100)
RandomBlock(2,0,2,quark:basalt:0,50,159:10,100)
RandomBlock(3,0,2,quark:basalt:0,50,159:10,100)
RandomBlock(4,0,2,quark:basalt:0,50,159:10,100)
RandomBlock(5,0,2,quark:basalt:0,50,159:10,100)
RandomBlock(-3,0,3,quark:basalt:0,50,159:10,100)
RandomBlock(-2,0,3,quark:basalt:0,50,159:10,100)
RandomBlock(-1,0,3,quark:basalt:0,50,159:10,100)
RandomBlock(0,0,3,quark:basalt:0,50,159:10,100)
RandomBlock(1,0,3,quark:basalt:0,50,159:10,100)
RandomBlock(2,0,3,quark:basalt:0,50,159:10,100)
RandomBlock(-3,0,4,quark:basalt:0,50,159:10,100)
RandomBlock(-2,0,4,quark:basalt:0,50,159:10,100)
RandomBlock(-1,0,4,quark:basalt:0,50,159:10,100)
RandomBlock(0,0,4,quark:basalt:0,50,159:10,100)
RandomBlock(1,0,4,quark:basalt:0,50,159:10,100)
RandomBlock(-3,1,-5,quark:basalt:0,50,159:10,100)
RandomBlock(-2,1,-5,quark:basalt:0,50,159:10,100)
RandomBlock(-1,1,-5,quark:basalt:0,50,159:10,100)
RandomBlock(0,1,-5,quark:basalt:0,50,159:10,100)
RandomBlock(1,1,-5,quark:basalt:0,50,159:10,100)
RandomBlock(2,1,-5,quark:basalt:0,50,159:10,100)
RandomBlock(3,1,-5,quark:basalt:0,50,159:10,100)
RandomBlock(-5,1,-4,quark:basalt:0,50,159:10,100)
RandomBlock(-4,1,-4,quark:basalt:0,50,159:10,100)
RandomBlock(-3,1,-4,quark:basalt:0,50,159:10,100)
RandomBlock(-2,1,-4,quark:basalt:0,50,159:10,100)
RandomBlock(-1,1,-4,quark:basalt:0,50,159:10,100)
RandomBlock(0,1,-4,quark:basalt:0,50,159:10,100)
RandomBlock(1,1,-4,quark:basalt:0,50,159:10,100)
RandomBlock(2,1,-4,quark:basalt:0,50,159:10,100)
RandomBlock(3,1,-4,quark:basalt:0,50,159:10,100)
RandomBlock(-6,1,-3,quark:basalt:0,50,159:10,100)
RandomBlock(-5,1,-3,quark:basalt:0,50,159:10,100)
RandomBlock(-4,1,-3,quark:basalt:0,50,159:10,100)
RandomBlock(-3,1,-3,quark:basalt:0,50,159:10,100)
RandomBlock(-2,1,-3,quark:basalt:0,50,159:10,100)
RandomBlock(-1,1,-3,quark:basalt:0,50,159:10,100)
RandomBlock(0,1,-3,quark:basalt:0,50,159:10,100)
RandomBlock(1,1,-3,quark:basalt:0,50,159:10,100)
RandomBlock(2,1,-3,quark:basalt:0,50,159:10,100)
RandomBlock(3,1,-3,quark:basalt:0,50,159:10,100)
RandomBlock(4,1,-3,quark:basalt:0,50,159:10,100)
RandomBlock(-6,1,-2,quark:basalt:0,50,159:10,100)
RandomBlock(-5,1,-2,quark:basalt:0,50,159:10,100)
RandomBlock(-4,1,-2,quark:basalt:0,50,159:10,100)
RandomBlock(-3,1,-2,quark:basalt:0,50,159:10,100)
RandomBlock(-2,1,-2,quark:basalt:0,50,159:10,100)
RandomBlock(-1,1,-2,quark:basalt:0,50,159:10,100)
RandomBlock(0,1,-2,quark:basalt:0,50,159:10,100)
RandomBlock(1,1,-2,quark:basalt:0,50,159:10,100)
RandomBlock(2,1,-2,quark:basalt:0,50,159:10,100)
RandomBlock(3,1,-2,quark:basalt:0,50,159:10,100)
RandomBlock(4,1,-2,quark:basalt:0,50,159:10,100)
RandomBlock(-6,1,-1,quark:basalt:0,50,159:10,100)
RandomBlock(-5,1,-1,quark:basalt:0,50,159:10,100)
RandomBlock(-4,1,-1,quark:basalt:0,50,159:10,100)
RandomBlock(-3,1,-1,quark:basalt:0,50,159:10,100)
RandomBlock(-2,1,-1,quark:basalt:0,50,159:10,100)
RandomBlock(-1,1,-1,quark:basalt:0,50,159:10,100)
RandomBlock(0,1,-1,quark:basalt:0,50,159:10,100)
RandomBlock(1,1,-1,quark:basalt:0,50,159:10,100)
RandomBlock(2,1,-1,quark:basalt:0,50,159:10,100)
RandomBlock(3,1,-1,quark:basalt:0,50,159:10,100)
RandomBlock(4,1,-1,quark:basalt:0,50,159:10,100)
RandomBlock(5,1,-1,quark:basalt:0,50,159:10,100)
RandomBlock(-6,1,0,quark:basalt:0,50,159:10,100)
RandomBlock(-5,1,0,quark:basalt:0,50,159:10,100)
RandomBlock(-4,1,0,quark:basalt:0,50,159:10,100)
RandomBlock(-3,1,0,quark:basalt:0,50,159:10,100)
RandomBlock(-2,1,0,quark:basalt:0,50,159:10,100)
RandomBlock(-1,1,0,quark:basalt:0,50,159:10,100)
RandomBlock(0,1,0,quark:basalt:0,50,159:10,100)
RandomBlock(1,1,0,quark:basalt:0,50,159:10,100)
RandomBlock(2,1,0,quark:basalt:0,50,159:10,100)
RandomBlock(3,1,0,quark:basalt:0,50,159:10,100)
RandomBlock(4,1,0,quark:basalt:0,50,159:10,100)
RandomBlock(5,1,0,quark:basalt:0,50,159:10,100)
RandomBlock(-5,1,1,quark:basalt:0,50,159:10,100)
RandomBlock(-4,1,1,quark:basalt:0,50,159:10,100)
RandomBlock(-3,1,1,quark:basalt:0,50,159:10,100)
RandomBlock(-2,1,1,quark:basalt:0,50,159:10,100)
RandomBlock(-1,1,1,quark:basalt:0,50,159:10,100)
RandomBlock(0,1,1,quark:basalt:0,50,159:10,100)
RandomBlock(1,1,1,quark:basalt:0,50,159:10,100)
RandomBlock(2,1,1,quark:basalt:0,50,159:10,100)
RandomBlock(3,1,1,quark:basalt:0,50,159:10,100)
RandomBlock(4,1,1,quark:basalt:0,50,159:10,100)
RandomBlock(5,1,1,quark:basalt:0,50,159:10,100)
RandomBlock(-4,1,2,quark:basalt:0,50,159:10,100)
RandomBlock(-3,1,2,quark:basalt:0,50,159:10,100)
RandomBlock(-2,1,2,quark:basalt:0,50,159:10,100)
RandomBlock(-1,1,2,quark:basalt:0,50,159:10,100)
RandomBlock(0,1,2,quark:basalt:0,50,159:10,100)
RandomBlock(1,1,2,quark:basalt:0,50,159:10,100)
RandomBlock(2,1,2,quark:basalt:0,50,159:10,100)
RandomBlock(3,1,2,quark:basalt:0,50,159:10,100)
RandomBlock(4,1,2,quark:basalt:0,50,159:10,100)
RandomBlock(5,1,2,quark:basalt:0,50,159:10,100)
RandomBlock(-3,1,3,quark:basalt:0,50,159:10,100)
RandomBlock(-2,1,3,quark:basalt:0,50,159:10,100)
RandomBlock(-1,1,3,quark:basalt:0,50,159:10,100)
RandomBlock(0,1,3,quark:basalt:0,50,159:10,100)
RandomBlock(1,1,3,quark:basalt:0,50,159:10,100)
RandomBlock(2,1,3,quark:basalt:0,50,159:10,100)
RandomBlock(-3,1,4,quark:basalt:0,50,159:10,100)
RandomBlock(-2,1,4,quark:basalt:0,50,159:10,100)
RandomBlock(-1,1,4,quark:basalt:0,50,159:10,100)
RandomBlock(0,1,4,quark:basalt:0,50,159:10,100)
RandomBlock(1,1,4,quark:basalt:0,50,159:10,100)
RandomBlock(-3,2,-5,quark:basalt:0,50,159:10,100)
RandomBlock(-2,2,-5,quark:basalt:0,50,159:10,100)
RandomBlock(-1,2,-5,quark:basalt:0,50,159:10,100)
RandomBlock(0,2,-5,quark:basalt:0,50,159:10,100)
RandomBlock(1,2,-5,quark:basalt:0,50,159:10,100)
RandomBlock(2,2,-5,quark:basalt:0,50,159:10,100)
RandomBlock(3,2,-5,quark:basalt:0,50,159:10,100)
RandomBlock(-5,2,-4,quark:basalt:0,50,159:10,100)
RandomBlock(-4,2,-4,quark:basalt:0,50,159:10,100)
RandomBlock(-3,2,-4,quark:basalt:0,50,159:10,100)
RandomBlock(-2,2,-4,quark:basalt:0,50,159:10,100)
RandomBlock(-1,2,-4,quark:basalt:0,50,159:10,100)
RandomBlock(0,2,-4,quark:basalt:0,50,159:10,100)
RandomBlock(1,2,-4,quark:basalt:0,50,159:10,100)
RandomBlock(2,2,-4,quark:basalt:0,50,159:10,100)
RandomBlock(3,2,-4,quark:basalt:0,50,159:10,100)
RandomBlock(-6,2,-3,quark:basalt:0,50,159:10,100)
RandomBlock(-5,2,-3,quark:basalt:0,50,159:10,100)
RandomBlock(-4,2,-3,quark:basalt:0,50,159:10,100)
Block(-3,2,-3,LAVA:0)
Block(-2,2,-3,LAVA:0)
Block(-1,2,-3,LAVA:0)
Block(0,2,-3,LAVA:0)
Block(1,2,-3,LAVA:0)
RandomBlock(2,2,-3,quark:basalt:0,50,159:10,100)
RandomBlock(3,2,-3,quark:basalt:0,50,159:10,100)
RandomBlock(4,2,-3,quark:basalt:0,50,159:10,100)
RandomBlock(-6,2,-2,quark:basalt:0,50,159:10,100)
RandomBlock(-5,2,-2,quark:basalt:0,50,159:10,100)
RandomBlock(-4,2,-2,quark:basalt:0,50,159:10,100)
Block(-3,2,-2,LAVA:0)
Block(-2,2,-2,LAVA:0)
Block(-1,2,-2,LAVA:0)
Block(0,2,-2,LAVA:0)
Block(1,2,-2,LAVA:0)
Block(2,2,-2,LAVA:0)
RandomBlock(3,2,-2,quark:basalt:0,50,159:10,100)
RandomBlock(4,2,-2,quark:basalt:0,50,159:10,100)
RandomBlock(-6,2,-1,quark:basalt:0,50,159:10,100)
RandomBlock(-5,2,-1,quark:basalt:0,50,159:10,100)
RandomBlock(-4,2,-1,quark:basalt:0,50,159:10,100)
Block(-3,2,-1,LAVA:0)
Block(-2,2,-1,LAVA:0)
Block(-1,2,-1,LAVA:0)
Block(0,2,-1,LAVA:0)
Block(1,2,-1,LAVA:0)
Block(2,2,-1,LAVA:0)
RandomBlock(3,2,-1,quark:basalt:0,50,159:10,100)
RandomBlock(4,2,-1,quark:basalt:0,50,159:10,100)
RandomBlock(5,2,-1,quark:basalt:0,50,159:10,100)
RandomBlock(-6,2,0,quark:basalt:0,50,159:10,100)
RandomBlock(-5,2,0,quark:basalt:0,50,159:10,100)
RandomBlock(-4,2,0,quark:basalt:0,50,159:10,100)
Block(-3,2,0,LAVA:0)
Block(-2,2,0,LAVA:0)
Block(-1,2,0,LAVA:0)
Block(0,2,0,LAVA:0)
Block(1,2,0,LAVA:0)
Block(2,2,0,LAVA:0)
RandomBlock(3,2,0,quark:basalt:0,50,159:10,100)
RandomBlock(4,2,0,quark:basalt:0,50,159:10,100)
RandomBlock(5,2,0,quark:basalt:0,50,159:10,100)
RandomBlock(-5,2,1,quark:basalt:0,50,159:10,100)
RandomBlock(-4,2,1,quark:basalt:0,50,159:10,100)
RandomBlock(-3,2,1,quark:basalt:0,50,159:10,100)
Block(-2,2,1,LAVA:0)
Block(-1,2,1,LAVA:0)
Block(0,2,1,LAVA:0)
Block(1,2,1,LAVA:0)
Block(2,2,1,LAVA:0)
RandomBlock(3,2,1,quark:basalt:0,50,159:10,100)
RandomBlock(4,2,1,quark:basalt:0,50,159:10,100)
RandomBlock(5,2,1,quark:basalt:0,50,159:10,100)
RandomBlock(-4,2,2,quark:basalt:0,50,159:10,100)
RandomBlock(-3,2,2,quark:basalt:0,50,159:10,100)
RandomBlock(-2,2,2,quark:basalt:0,50,159:10,100)
RandomBlock(-1,2,2,quark:basalt:0,50,159:10,100)
Block(0,2,2,LAVA:0)
Block(1,2,2,LAVA:0)
Block(2,2,2,LAVA:0)
RandomBlock(3,2,2,quark:basalt:0,50,159:10,100)
RandomBlock(4,2,2,quark:basalt:0,50,159:10,100)
RandomBlock(5,2,2,quark:basalt:0,50,159:10,100)
RandomBlock(-3,2,3,quark:basalt:0,50,159:10,100)
RandomBlock(-2,2,3,quark:basalt:0,50,159:10,100)
RandomBlock(-1,2,3,quark:basalt:0,50,159:10,100)
RandomBlock(0,2,3,quark:basalt:0,50,159:10,100)
RandomBlock(1,2,3,quark:basalt:0,50,159:10,100)
RandomBlock(2,2,3,quark:basalt:0,50,159:10,100)
RandomBlock(-3,2,4,quark:basalt:0,50,159:10,100)
RandomBlock(-2,2,4,quark:basalt:0,50,159:10,100)
RandomBlock(-1,2,4,quark:basalt:0,50,159:10,100)
RandomBlock(0,2,4,quark:basalt:0,50,159:10,100)
RandomBlock(1,2,4,quark:basalt:0,50,159:10,100)
RandomBlock(-3,3,-5,quark:basalt:0,50,159:10,100)
RandomBlock(-2,3,-5,quark:basalt:0,50,159:10,100)
RandomBlock(-1,3,-5,quark:basalt:0,50,159:10,100)
RandomBlock(0,3,-5,quark:basalt:0,50,159:10,100)
RandomBlock(1,3,-5,quark:basalt:0,50,159:10,100)
RandomBlock(2,3,-5,quark:basalt:0,50,159:10,100)
RandomBlock(3,3,-5,quark:basalt:0,50,159:10,100)
RandomBlock(-5,3,-4,quark:basalt:0,50,159:10,100)
RandomBlock(-4,3,-4,quark:basalt:0,50,159:10,100)
RandomBlock(-3,3,-4,quark:basalt:0,50,159:10,100)
RandomBlock(-2,3,-4,quark:basalt:0,50,159:10,100)
RandomBlock(-1,3,-4,quark:basalt:0,50,159:10,100)
RandomBlock(0,3,-4,quark:basalt:0,50,159:10,100)
RandomBlock(1,3,-4,quark:basalt:0,50,159:10,100)
RandomBlock(2,3,-4,quark:basalt:0,50,159:10,100)
RandomBlock(3,3,-4,quark:basalt:0,50,159:10,100)
RandomBlock(-6,3,-3,quark:basalt:0,50,159:10,100)
RandomBlock(-5,3,-3,quark:basalt:0,50,159:10,100)
RandomBlock(-4,3,-3,quark:basalt:0,50,159:10,100)
Block(-3,3,-3,LAVA:0)
Block(-2,3,-3,LAVA:0)
Block(-1,3,-3,LAVA:0)
Block(0,3,-3,LAVA:0)
Block(1,3,-3,LAVA:0)
RandomBlock(2,3,-3,quark:basalt:0,50,159:10,100)
RandomBlock(3,3,-3,quark:basalt:0,50,159:10,100)
RandomBlock(4,3,-3,quark:basalt:0,50,159:10,100)
RandomBlock(-6,3,-2,quark:basalt:0,50,159:10,100)
RandomBlock(-5,3,-2,quark:basalt:0,50,159:10,100)
RandomBlock(-4,3,-2,quark:basalt:0,50,159:10,100)
Block(-3,3,-2,LAVA:2)
Block(-2,3,-2,LAVA:8)
Block(-1,3,-2,LAVA:10)
Block(0,3,-2,LAVA:8)
Block(1,3,-2,LAVA:2)
Block(2,3,-2,LAVA:0)
RandomBlock(3,3,-2,quark:basalt:0,50,159:10,100)
RandomBlock(4,3,-2,quark:basalt:0,50,159:10,100)
RandomBlock(-6,3,-1,quark:basalt:0,50,159:10,100)
RandomBlock(-5,3,-1,quark:basalt:0,50,159:10,100)
RandomBlock(-4,3,-1,quark:basalt:0,50,159:10,100)
Block(-3,3,-1,LAVA:0)
Block(-2,3,-1,LAVA:10)
Block(-1,3,-1,LAVA:8)
Block(0,3,-1,DIAMOND_ORE:0)
Block(1,3,-1,LAVA:8)
Block(2,3,-1,LAVA:0)
RandomBlock(3,3,-1,quark:basalt:0,50,159:10,100)
RandomBlock(5,3,-1,quark:basalt:0,50,159:10,100)
RandomBlock(-6,3,0,quark:basalt:0,50,159:10,100)
RandomBlock(-5,3,0,quark:basalt:0,50,159:10,100)
RandomBlock(-4,3,0,quark:basalt:0,50,159:10,100)
Block(-3,3,0,LAVA:0)
Block(-2,3,0,LAVA:8)
Block(-1,3,0,LAVA:10)
Block(0,3,0,LAVA:10)
Block(1,3,0,LAVA:8)
Block(2,3,0,LAVA:8)
RandomBlock(3,3,0,quark:basalt:0,50,159:10,100)
RandomBlock(5,3,0,quark:basalt:0,50,159:10,100)
RandomBlock(-5,3,1,quark:basalt:0,50,159:10,100)
RandomBlock(-4,3,1,quark:basalt:0,50,159:10,100)
RandomBlock(-3,3,1,quark:basalt:0,50,159:10,100)
Block(-2,3,1,LAVA:0)
Block(-1,3,1,LAVA:8)
Block(0,3,1,LAVA:10)
Block(1,3,1,LAVA:8)
Block(2,3,1,LAVA:0)
RandomBlock(3,3,1,quark:basalt:0,50,159:10,100)
RandomBlock(5,3,1,quark:basalt:0,50,159:10,100)
RandomBlock(-4,3,2,quark:basalt:0,50,159:10,100)
RandomBlock(-3,3,2,quark:basalt:0,50,159:10,100)
RandomBlock(-2,3,2,quark:basalt:0,50,159:10,100)
RandomBlock(-1,3,2,quark:basalt:0,50,159:10,100)
Block(0,3,2,LAVA:0)
Block(1,3,2,LAVA:0)
Block(2,3,2,LAVA:0)
RandomBlock(3,3,2,quark:basalt:0,50,159:10,100)
RandomBlock(4,3,2,quark:basalt:0,50,159:10,100)
RandomBlock(5,3,2,quark:basalt:0,50,159:10,100)
RandomBlock(-3,3,3,quark:basalt:0,50,159:10,100)
RandomBlock(-2,3,3,quark:basalt:0,50,159:10,100)
RandomBlock(-1,3,3,quark:basalt:0,50,159:10,100)
RandomBlock(0,3,3,quark:basalt:0,50,159:10,100)
RandomBlock(1,3,3,quark:basalt:0,50,159:10,100)
RandomBlock(2,3,3,quark:basalt:0,50,159:10,100)
RandomBlock(-3,3,4,quark:basalt:0,50,159:10,100)
RandomBlock(-2,3,4,quark:basalt:0,50,159:10,100)
RandomBlock(-1,3,4,quark:basalt:0,50,159:10,100)
RandomBlock(0,3,4,quark:basalt:0,50,159:10,100)
RandomBlock(1,3,4,quark:basalt:0,50,159:10,100)
RandomBlock(-3,4,-5,quark:basalt:0,50,159:10,100)
RandomBlock(-2,4,-5,quark:basalt:0,50,159:10,100)
RandomBlock(-1,4,-5,quark:basalt:0,50,159:10,100)
RandomBlock(0,4,-5,quark:basalt:0,50,159:10,100)
RandomBlock(1,4,-5,quark:basalt:0,50,159:10,100)
RandomBlock(2,4,-5,quark:basalt:0,50,159:10,100)
RandomBlock(3,4,-5,quark:basalt:0,50,159:10,100)
RandomBlock(-5,4,-4,quark:basalt:0,50,159:10,100)
RandomBlock(-4,4,-4,quark:basalt:0,50,159:10,100)
RandomBlock(-3,4,-4,quark:basalt:0,50,159:10,100)
RandomBlock(-2,4,-4,quark:basalt:0,50,159:10,100)
RandomBlock(-1,4,-4,quark:basalt:0,50,159:10,100)
RandomBlock(0,4,-4,quark:basalt:0,50,159:10,100)
RandomBlock(1,4,-4,quark:basalt:0,50,159:10,100)
RandomBlock(2,4,-4,quark:basalt:0,50,159:10,100)
RandomBlock(3,4,-4,quark:basalt:0,50,159:10,100)
RandomBlock(-6,4,-3,quark:basalt:0,50,159:10,100)
RandomBlock(-5,4,-3,quark:basalt:0,50,159:10,100)
RandomBlock(-3,4,-3,quark:basalt:0,50,159:10,100)
RandomBlock(-2,4,-3,quark:basalt:0,50,159:10,100)
Block(-1,4,-3,LAVA:0)
Block(0,4,-3,LAVA:0)
RandomBlock(1,4,-3,quark:basalt:0,50,159:10,100)
RandomBlock(2,4,-3,quark:basalt:0,50,159:10,100)
RandomBlock(3,4,-3,quark:basalt:0,50,159:10,100)
RandomBlock(4,4,-3,quark:basalt:0,50,159:10,100)
RandomBlock(-6,4,-2,quark:basalt:0,50,159:10,100)
RandomBlock(-5,4,-2,quark:basalt:0,50,159:10,100)
RandomBlock(-4,4,-2,quark:basalt:0,50,159:10,100)
RandomBlock(-3,4,-2,quark:basalt:0,50,159:10,100)
Block(-2,4,-2,LAVA:0)
Block(-1,4,-2,LAVA:10)
Block(0,4,-2,LAVA:0)
RandomBlock(1,4,-2,quark:basalt:0,50,159:10,100)
RandomBlock(2,4,-2,quark:basalt:0,50,159:10,100)
RandomBlock(3,4,-2,quark:basalt:0,50,159:10,100)
RandomBlock(4,4,-2,quark:basalt:0,50,159:10,100)
RandomBlock(-6,4,-1,quark:basalt:0,50,159:10,100)
RandomBlock(-5,4,-1,quark:basalt:0,50,159:10,100)
RandomBlock(-4,4,-1,quark:basalt:0,50,159:10,100)
Block(-3,4,-1,LAVA:8)
Block(-2,4,-1,LAVA:10)
Block(-1,4,-1,LAVA:8)
Block(0,4,-1,LAVA:10)
Block(1,4,-1,LAVA:0)
RandomBlock(2,4,-1,quark:basalt:0,50,159:10,100)
RandomBlock(3,4,-1,quark:basalt:0,50,159:10,100)
RandomBlock(4,4,-1,quark:basalt:0,50,159:10,100)
RandomBlock(5,4,-1,quark:basalt:0,50,159:10,100)
RandomBlock(-6,4,0,quark:basalt:0,50,159:10,100)
RandomBlock(-5,4,0,quark:basalt:0,50,159:10,100)
RandomBlock(-4,4,0,quark:basalt:0,50,159:10,100)
Block(-3,4,0,LAVA:2)
Block(-2,4,0,LAVA:0)
Block(-1,4,0,LAVA:10)
Block(0,4,0,LAVA:10)
Block(1,4,0,LAVA:8)
Block(2,4,0,LAVA:0)
RandomBlock(3,4,0,quark:basalt:0,50,159:10,100)
RandomBlock(4,4,0,quark:basalt:0,50,159:10,100)
RandomBlock(5,4,0,quark:basalt:0,50,159:10,100)
RandomBlock(-5,4,1,quark:basalt:0,50,159:10,100)
RandomBlock(-4,4,1,quark:basalt:0,50,159:10,100)
RandomBlock(-3,4,1,quark:basalt:0,50,159:10,100)
RandomBlock(-2,4,1,quark:basalt:0,50,159:10,100)
Block(-1,4,1,LAVA:8)
Block(0,4,1,LAVA:10)
Block(1,4,1,LAVA:0)
RandomBlock(2,4,1,quark:basalt:0,50,159:10,100)
RandomBlock(3,4,1,quark:basalt:0,50,159:10,100)
RandomBlock(4,4,1,quark:basalt:0,50,159:10,100)
RandomBlock(5,4,1,quark:basalt:0,50,159:10,100)
RandomBlock(-4,4,2,quark:basalt:0,50,159:10,100)
RandomBlock(-3,4,2,quark:basalt:0,50,159:10,100)
RandomBlock(-2,4,2,quark:basalt:0,50,159:10,100)
RandomBlock(-1,4,2,quark:basalt:0,50,159:10,100)
RandomBlock(0,4,2,quark:basalt:0,50,159:10,100)
Block(1,4,2,LAVA:0)
RandomBlock(2,4,2,quark:basalt:0,50,159:10,100)
RandomBlock(3,4,2,quark:basalt:0,50,159:10,100)
RandomBlock(4,4,2,quark:basalt:0,50,159:10,100)
RandomBlock(5,4,2,quark:basalt:0,50,159:10,100)
RandomBlock(-3,4,3,quark:basalt:0,50,159:10,100)
RandomBlock(-2,4,3,quark:basalt:0,50,159:10,100)
RandomBlock(-1,4,3,quark:basalt:0,50,159:10,100)
RandomBlock(0,4,3,quark:basalt:0,50,159:10,100)
RandomBlock(1,4,3,quark:basalt:0,50,159:10,100)
RandomBlock(-3,4,4,quark:basalt:0,50,159:10,100)
RandomBlock(-2,4,4,quark:basalt:0,50,159:10,100)
RandomBlock(-1,4,4,quark:basalt:0,50,159:10,100)
RandomBlock(0,4,4,quark:basalt:0,50,159:10,100)
RandomBlock(1,4,4,quark:basalt:0,50,159:10,100)
RandomBlock(-3,5,-5,quark:basalt:0,50,159:10,100)
RandomBlock(-2,5,-5,quark:basalt:0,50,159:10,100)
RandomBlock(-1,5,-5,quark:basalt:0,50,159:10,100)
RandomBlock(0,5,-5,quark:basalt:0,50,159:10,100)
RandomBlock(1,5,-5,quark:basalt:0,50,159:10,100)
RandomBlock(2,5,-5,quark:basalt:0,50,159:10,100)
RandomBlock(3,5,-5,quark:basalt:0,50,159:10,100)
RandomBlock(-5,5,-4,quark:basalt:0,50,159:10,100)
RandomBlock(-4,5,-4,quark:basalt:0,50,159:10,100)
RandomBlock(-3,5,-4,quark:basalt:0,50,159:10,100)
RandomBlock(-2,5,-4,quark:basalt:0,50,159:10,100)
RandomBlock(-1,5,-4,quark:basalt:0,50,159:10,100)
RandomBlock(0,5,-4,quark:basalt:0,50,159:10,100)
RandomBlock(1,5,-4,quark:basalt:0,50,159:10,100)
RandomBlock(2,5,-4,quark:basalt:0,50,159:10,100)
RandomBlock(3,5,-4,quark:basalt:0,50,159:10,100)
RandomBlock(-6,5,-3,quark:basalt:0,50,159:10,100)
RandomBlock(-5,5,-3,quark:basalt:0,50,159:10,100)
RandomBlock(-4,5,-3,quark:basalt:0,50,159:10,100)
RandomBlock(-3,5,-3,quark:basalt:0,50,159:10,100)
RandomBlock(-2,5,-3,quark:basalt:0,50,159:10,100)
Block(-1,5,-3,LAVA:0)
Block(0,5,-3,LAVA:0)
RandomBlock(1,5,-3,quark:basalt:0,50,159:10,100)
RandomBlock(2,5,-3,quark:basalt:0,50,159:10,100)
RandomBlock(3,5,-3,quark:basalt:0,50,159:10,100)
RandomBlock(4,5,-3,quark:basalt:0,50,159:10,100)
RandomBlock(-6,5,-2,quark:basalt:0,50,159:10,100)
RandomBlock(-5,5,-2,quark:basalt:0,50,159:10,100)
RandomBlock(-4,5,-2,quark:basalt:0,50,159:10,100)
RandomBlock(-3,5,-2,quark:basalt:0,50,159:10,100)
Block(-2,5,-2,LAVA:0)
Block(-1,5,-2,LAVA:2)
Block(0,5,-2,LAVA:2)
RandomBlock(1,5,-2,quark:basalt:0,50,159:10,100)
RandomBlock(2,5,-2,quark:basalt:0,50,159:10,100)
RandomBlock(3,5,-2,quark:basalt:0,50,159:10,100)
RandomBlock(4,5,-2,quark:basalt:0,50,159:10,100)
RandomBlock(-6,5,-1,quark:basalt:0,50,159:10,100)
RandomBlock(-5,5,-1,quark:basalt:0,50,159:10,100)
RandomBlock(-4,5,-1,quark:basalt:0,50,159:10,100)
Block(-3,5,-1,LAVA:0)
Block(-2,5,-1,LAVA:2)
Block(-1,5,-1,LAVA:0)
Block(0,5,-1,LAVA:2)
Block(1,5,-1,LAVA:0)
RandomBlock(2,5,-1,quark:basalt:0,50,159:10,100)
RandomBlock(3,5,-1,quark:basalt:0,50,159:10,100)
RandomBlock(4,5,-1,quark:basalt:0,50,159:10,100)
RandomBlock(5,5,-1,quark:basalt:0,50,159:10,100)
RandomBlock(-6,5,0,quark:basalt:0,50,159:10,100)
RandomBlock(-5,5,0,quark:basalt:0,50,159:10,100)
RandomBlock(-4,5,0,quark:basalt:0,50,159:10,100)
RandomBlock(-3,5,0,quark:basalt:0,50,159:10,100)
Block(-2,5,0,LAVA:0)
Block(-1,5,0,LAVA:2)
Block(0,5,0,LAVA:2)
Block(1,5,0,LAVA:0)
RandomBlock(2,5,0,quark:basalt:0,50,159:10,100)
RandomBlock(3,5,0,quark:basalt:0,50,159:10,100)
RandomBlock(4,5,0,quark:basalt:0,50,159:10,100)
RandomBlock(5,5,0,quark:basalt:0,50,159:10,100)
RandomBlock(-5,5,1,quark:basalt:0,50,159:10,100)
RandomBlock(-4,5,1,quark:basalt:0,50,159:10,100)
RandomBlock(-3,5,1,quark:basalt:0,50,159:10,100)
RandomBlock(-2,5,1,quark:basalt:0,50,159:10,100)
Block(-1,5,1,LAVA:0)
Block(0,5,1,LAVA:2)
Block(1,5,1,LAVA:0)
RandomBlock(2,5,1,quark:basalt:0,50,159:10,100)
RandomBlock(3,5,1,quark:basalt:0,50,159:10,100)
RandomBlock(4,5,1,quark:basalt:0,50,159:10,100)
RandomBlock(5,5,1,quark:basalt:0,50,159:10,100)
RandomBlock(-4,5,2,quark:basalt:0,50,159:10,100)
RandomBlock(-3,5,2,quark:basalt:0,50,159:10,100)
RandomBlock(-2,5,2,quark:basalt:0,50,159:10,100)
RandomBlock(-1,5,2,quark:basalt:0,50,159:10,100)
RandomBlock(0,5,2,quark:basalt:0,50,159:10,100)
Block(1,5,2,LAVA:0)
RandomBlock(2,5,2,quark:basalt:0,50,159:10,100)
RandomBlock(3,5,2,quark:basalt:0,50,159:10,100)
RandomBlock(4,5,2,quark:basalt:0,50,159:10,100)
RandomBlock(5,5,2,quark:basalt:0,50,159:10,100)
RandomBlock(-3,5,3,quark:basalt:0,50,159:10,100)
RandomBlock(-2,5,3,quark:basalt:0,50,159:10,100)
RandomBlock(-1,5,3,quark:basalt:0,50,159:10,100)
RandomBlock(0,5,3,quark:basalt:0,50,159:10,100)
RandomBlock(1,5,3,quark:basalt:0,50,159:10,100)
RandomBlock(2,5,3,quark:basalt:0,50,159:10,100)
RandomBlock(3,5,3,quark:basalt:0,50,159:10,100)
RandomBlock(-3,5,4,quark:basalt:0,50,159:10,100)
RandomBlock(-2,5,4,quark:basalt:0,50,159:10,100)
RandomBlock(-1,5,4,quark:basalt:0,50,159:10,100)
RandomBlock(0,5,4,quark:basalt:0,50,159:10,100)
RandomBlock(1,5,4,quark:basalt:0,50,159:10,100)
RandomBlock(-3,6,-5,quark:basalt:0,50,159:10,100)
RandomBlock(-2,6,-5,quark:basalt:0,50,159:10,100)
RandomBlock(-1,6,-5,quark:basalt:0,50,159:10,100)
RandomBlock(0,6,-5,quark:basalt:0,50,159:10,100)
RandomBlock(1,6,-5,quark:basalt:0,50,159:10,100)
RandomBlock(2,6,-5,quark:basalt:0,50,159:10,100)
RandomBlock(3,6,-5,quark:basalt:0,50,159:10,100)
RandomBlock(-5,6,-4,quark:basalt:0,50,159:10,100)
RandomBlock(-4,6,-4,quark:basalt:0,50,159:10,100)
RandomBlock(-3,6,-4,quark:basalt:0,50,159:10,100)
RandomBlock(-2,6,-4,quark:basalt:0,50,159:10,100)
RandomBlock(-1,6,-4,quark:basalt:0,50,159:10,100)
RandomBlock(0,6,-4,quark:basalt:0,50,159:10,100)
RandomBlock(1,6,-4,quark:basalt:0,50,159:10,100)
RandomBlock(2,6,-4,quark:basalt:0,50,159:10,100)
RandomBlock(3,6,-4,quark:basalt:0,50,159:10,100)
RandomBlock(-6,6,-3,quark:basalt:0,50,159:10,100)
RandomBlock(-5,6,-3,quark:basalt:0,50,159:10,100)
RandomBlock(-4,6,-3,quark:basalt:0,50,159:10,100)
RandomBlock(-3,6,-3,quark:basalt:0,50,159:10,100)
RandomBlock(-2,6,-3,quark:basalt:0,50,159:10,100)
RandomBlock(-1,6,-3,quark:basalt:0,50,159:10,100)
RandomBlock(0,6,-3,quark:basalt:0,50,159:10,100)
RandomBlock(1,6,-3,quark:basalt:0,50,159:10,100)
RandomBlock(2,6,-3,quark:basalt:0,50,159:10,100)
RandomBlock(3,6,-3,quark:basalt:0,50,159:10,100)
RandomBlock(4,6,-3,quark:basalt:0,50,159:10,100)
RandomBlock(-6,6,-2,quark:basalt:0,50,159:10,100)
RandomBlock(-5,6,-2,quark:basalt:0,50,159:10,100)
RandomBlock(-4,6,-2,quark:basalt:0,50,159:10,100)
RandomBlock(-3,6,-2,quark:basalt:0,50,159:10,100)
RandomBlock(-2,6,-2,quark:basalt:0,50,159:10,100)
Block(-1,6,-2,MAGMA:0)
RandomBlock(0,6,-2,quark:basalt:0,50,159:10,100)
RandomBlock(1,6,-2,quark:basalt:0,50,159:10,100)
RandomBlock(2,6,-2,quark:basalt:0,50,159:10,100)
RandomBlock(3,6,-2,quark:basalt:0,50,159:10,100)
RandomBlock(4,6,-2,quark:basalt:0,50,159:10,100)
RandomBlock(-6,6,-1,quark:basalt:0,50,159:10,100)
RandomBlock(-5,6,-1,quark:basalt:0,50,159:10,100)
RandomBlock(-4,6,-1,quark:basalt:0,50,159:10,100)
RandomBlock(-3,6,-1,quark:basalt:0,50,159:10,100)
Block(-2,6,-1,MAGMA:0)
RandomBlock(-1,6,-1,quark:basalt:0,50,159:10,100)
Block(0,6,-1,MAGMA:0)
RandomBlock(1,6,-1,quark:basalt:0,50,159:10,100)
RandomBlock(2,6,-1,quark:basalt:0,50,159:10,100)
RandomBlock(3,6,-1,quark:basalt:0,50,159:10,100)
RandomBlock(4,6,-1,quark:basalt:0,50,159:10,100)
RandomBlock(5,6,-1,quark:basalt:0,50,159:10,100)
RandomBlock(-6,6,0,quark:basalt:0,50,159:10,100)
RandomBlock(-5,6,0,quark:basalt:0,50,159:10,100)
RandomBlock(-4,6,0,quark:basalt:0,50,159:10,100)
RandomBlock(-3,6,0,quark:basalt:0,50,159:10,100)
RandomBlock(-2,6,0,quark:basalt:0,50,159:10,100)
RandomBlock(-1,6,0,quark:basalt:0,50,159:10,100)
RandomBlock(0,6,0,quark:basalt:0,50,159:10,100)
RandomBlock(1,6,0,quark:basalt:0,50,159:10,100)
RandomBlock(2,6,0,quark:basalt:0,50,159:10,100)
RandomBlock(3,6,0,quark:basalt:0,50,159:10,100)
RandomBlock(4,6,0,quark:basalt:0,50,159:10,100)
RandomBlock(5,6,0,quark:basalt:0,50,159:10,100)
RandomBlock(-5,6,1,quark:basalt:0,50,159:10,100)
RandomBlock(-4,6,1,quark:basalt:0,50,159:10,100)
RandomBlock(-3,6,1,quark:basalt:0,50,159:10,100)
RandomBlock(-2,6,1,quark:basalt:0,50,159:10,100)
RandomBlock(-1,6,1,quark:basalt:0,50,159:10,100)
RandomBlock(0,6,1,quark:basalt:0,50,159:10,100)
Block(1,6,1,MAGMA:0)
RandomBlock(2,6,1,quark:basalt:0,50,159:10,100)
RandomBlock(3,6,1,quark:basalt:0,50,159:10,100)
RandomBlock(4,6,1,quark:basalt:0,50,159:10,100)
RandomBlock(5,6,1,quark:basalt:0,50,159:10,100)
RandomBlock(-4,6,2,quark:basalt:0,50,159:10,100)
RandomBlock(-3,6,2,quark:basalt:0,50,159:10,100)
RandomBlock(-2,6,2,quark:basalt:0,50,159:10,100)
RandomBlock(-1,6,2,quark:basalt:0,50,159:10,100)
RandomBlock(0,6,2,quark:basalt:0,50,159:10,100)
RandomBlock(1,6,2,quark:basalt:0,50,159:10,100)
RandomBlock(2,6,2,quark:basalt:0,50,159:10,100)
RandomBlock(3,6,2,quark:basalt:0,50,159:10,100)
RandomBlock(4,6,2,quark:basalt:0,50,159:10,100)
RandomBlock(5,6,2,quark:basalt:0,50,159:10,100)
RandomBlock(-3,6,3,quark:basalt:0,50,159:10,100)
RandomBlock(-2,6,3,quark:basalt:0,50,159:10,100)
RandomBlock(-1,6,3,quark:basalt:0,50,159:10,100)
RandomBlock(0,6,3,quark:basalt:0,50,159:10,100)
RandomBlock(1,6,3,quark:basalt:0,50,159:10,100)
RandomBlock(2,6,3,quark:basalt:0,50,159:10,100)
RandomBlock(3,6,3,quark:basalt:0,50,159:10,100)
RandomBlock(-3,6,4,quark:basalt:0,50,159:10,100)
RandomBlock(-2,6,4,quark:basalt:0,50,159:10,100)
RandomBlock(-1,6,4,quark:basalt:0,50,159:10,100)
RandomBlock(0,6,4,quark:basalt:0,50,159:10,100)
RandomBlock(1,6,4,quark:basalt:0,50,159:10,100)
RandomBlock(-3,7,-5,quark:basalt:0,50,159:10,100)
RandomBlock(-2,7,-5,quark:basalt:0,50,159:10,100)
RandomBlock(-1,7,-5,quark:basalt:0,50,159:10,100)
RandomBlock(0,7,-5,quark:basalt:0,50,159:10,100)
RandomBlock(1,7,-5,quark:basalt:0,50,159:10,100)
RandomBlock(2,7,-5,quark:basalt:0,50,159:10,100)
RandomBlock(3,7,-5,quark:basalt:0,50,159:10,100)
RandomBlock(-5,7,-4,quark:basalt:0,50,159:10,100)
RandomBlock(-4,7,-4,quark:basalt:0,50,159:10,100)
RandomBlock(-3,7,-4,quark:basalt:0,50,159:10,100)
RandomBlock(-2,7,-4,quark:basalt:0,50,159:10,100)
RandomBlock(-1,7,-4,quark:basalt:0,50,159:10,100)
RandomBlock(0,7,-4,quark:basalt:0,50,159:10,100)
RandomBlock(1,7,-4,quark:basalt:0,50,159:10,100)
RandomBlock(2,7,-4,quark:basalt:0,50,159:10,100)
RandomBlock(3,7,-4,quark:basalt:0,50,159:10,100)
RandomBlock(-6,7,-3,quark:basalt:0,50,159:10,100)
RandomBlock(-5,7,-3,quark:basalt:0,50,159:10,100)
RandomBlock(-4,7,-3,quark:basalt:0,50,159:10,100)
RandomBlock(-3,7,-3,quark:basalt:0,50,159:10,100)
RandomBlock(-2,7,-3,quark:basalt:0,50,159:10,100)
RandomBlock(-1,7,-3,quark:basalt:0,50,159:10,100)
RandomBlock(0,7,-3,quark:basalt:0,50,159:10,100)
RandomBlock(1,7,-3,quark:basalt:0,50,159:10,100)
RandomBlock(2,7,-3,quark:basalt:0,50,159:10,100)
RandomBlock(3,7,-3,quark:basalt:0,50,159:10,100)
RandomBlock(4,7,-3,quark:basalt:0,50,159:10,100)
RandomBlock(-6,7,-2,quark:basalt:0,50,159:10,100)
RandomBlock(-5,7,-2,quark:basalt:0,50,159:10,100)
RandomBlock(-4,7,-2,quark:basalt:0,50,159:10,100)
RandomBlock(-3,7,-2,quark:basalt:0,50,159:10,100)
RandomBlock(-2,7,-2,quark:basalt:0,50,159:10,100)
Block(-1,7,-2,MAGMA:0)
RandomBlock(0,7,-2,quark:basalt:0,50,159:10,100)
RandomBlock(1,7,-2,quark:basalt:0,50,159:10,100)
RandomBlock(2,7,-2,quark:basalt:0,50,159:10,100)
RandomBlock(3,7,-2,quark:basalt:0,50,159:10,100)
RandomBlock(4,7,-2,quark:basalt:0,50,159:10,100)
RandomBlock(-6,7,-1,quark:basalt:0,50,159:10,100)
RandomBlock(-5,7,-1,quark:basalt:0,50,159:10,100)
RandomBlock(-4,7,-1,quark:basalt:0,50,159:10,100)
RandomBlock(-3,7,-1,quark:basalt:0,50,159:10,100)
Block(-2,7,-1,MAGMA:0)
RandomBlock(-1,7,-1,quark:basalt:0,50,159:10,100)
Block(0,7,-1,MAGMA:0)
RandomBlock(1,7,-1,quark:basalt:0,50,159:10,100)
RandomBlock(2,7,-1,quark:basalt:0,50,159:10,100)
RandomBlock(3,7,-1,quark:basalt:0,50,159:10,100)
RandomBlock(4,7,-1,quark:basalt:0,50,159:10,100)
RandomBlock(5,7,-1,quark:basalt:0,50,159:10,100)
RandomBlock(-6,7,0,quark:basalt:0,50,159:10,100)
RandomBlock(-5,7,0,quark:basalt:0,50,159:10,100)
RandomBlock(-4,7,0,quark:basalt:0,50,159:10,100)
RandomBlock(-3,7,0,quark:basalt:0,50,159:10,100)
RandomBlock(-2,7,0,quark:basalt:0,50,159:10,100)
RandomBlock(-1,7,0,quark:basalt:0,50,159:10,100)
RandomBlock(0,7,0,quark:basalt:0,50,159:10,100)
RandomBlock(1,7,0,quark:basalt:0,50,159:10,100)
RandomBlock(2,7,0,quark:basalt:0,50,159:10,100)
RandomBlock(3,7,0,quark:basalt:0,50,159:10,100)
RandomBlock(4,7,0,quark:basalt:0,50,159:10,100)
RandomBlock(5,7,0,quark:basalt:0,50,159:10,100)
RandomBlock(-5,7,1,quark:basalt:0,50,159:10,100)
RandomBlock(-4,7,1,quark:basalt:0,50,159:10,100)
RandomBlock(-3,7,1,quark:basalt:0,50,159:10,100)
RandomBlock(-2,7,1,quark:basalt:0,50,159:10,100)
RandomBlock(-1,7,1,quark:basalt:0,50,159:10,100)
RandomBlock(0,7,1,quark:basalt:0,50,159:10,100)
Block(1,7,1,MAGMA:0)
RandomBlock(2,7,1,quark:basalt:0,50,159:10,100)
RandomBlock(3,7,1,quark:basalt:0,50,159:10,100)
RandomBlock(4,7,1,quark:basalt:0,50,159:10,100)
RandomBlock(5,7,1,quark:basalt:0,50,159:10,100)
RandomBlock(-4,7,2,quark:basalt:0,50,159:10,100)
RandomBlock(-3,7,2,quark:basalt:0,50,159:10,100)
RandomBlock(-2,7,2,quark:basalt:0,50,159:10,100)
RandomBlock(-1,7,2,quark:basalt:0,50,159:10,100)
RandomBlock(0,7,2,quark:basalt:0,50,159:10,100)
RandomBlock(1,7,2,quark:basalt:0,50,159:10,100)
RandomBlock(2,7,2,quark:basalt:0,50,159:10,100)
RandomBlock(3,7,2,quark:basalt:0,50,159:10,100)
RandomBlock(4,7,2,quark:basalt:0,50,159:10,100)
RandomBlock(5,7,2,quark:basalt:0,50,159:10,100)
RandomBlock(-3,7,3,quark:basalt:0,50,159:10,100)
RandomBlock(-2,7,3,quark:basalt:0,50,159:10,100)
RandomBlock(-1,7,3,quark:basalt:0,50,159:10,100)
RandomBlock(0,7,3,quark:basalt:0,50,159:10,100)
RandomBlock(1,7,3,quark:basalt:0,50,159:10,100)
RandomBlock(2,7,3,quark:basalt:0,50,159:10,100)
RandomBlock(3,7,3,quark:basalt:0,50,159:10,100)
RandomBlock(-3,7,4,quark:basalt:0,50,159:10,100)
RandomBlock(-2,7,4,quark:basalt:0,50,159:10,100)
RandomBlock(-1,7,4,quark:basalt:0,50,159:10,100)
RandomBlock(0,7,4,quark:basalt:0,50,159:10,100)
RandomBlock(1,7,4,quark:basalt:0,50,159:10,100)
RandomBlock(-3,8,-5,quark:basalt:0,50,159:10,100)
RandomBlock(-2,8,-5,quark:basalt:0,50,159:10,100)
RandomBlock(-1,8,-5,quark:basalt:0,50,159:10,100)
RandomBlock(0,8,-5,quark:basalt:0,50,159:10,100)
RandomBlock(1,8,-5,quark:basalt:0,50,159:10,100)
RandomBlock(2,8,-5,quark:basalt:0,50,159:10,100)
RandomBlock(3,8,-5,quark:basalt:0,50,159:10,100)
RandomBlock(-5,8,-4,quark:basalt:0,50,159:10,100)
RandomBlock(-4,8,-4,quark:basalt:0,50,159:10,100)
RandomBlock(-3,8,-4,quark:basalt:0,50,159:10,100)
RandomBlock(-2,8,-4,quark:basalt:0,50,159:10,100)
RandomBlock(-1,8,-4,quark:basalt:0,50,159:10,100)
RandomBlock(0,8,-4,quark:basalt:0,50,159:10,100)
RandomBlock(1,8,-4,quark:basalt:0,50,159:10,100)
RandomBlock(2,8,-4,quark:basalt:0,50,159:10,100)
RandomBlock(3,8,-4,quark:basalt:0,50,159:10,100)
RandomBlock(-6,8,-3,quark:basalt:0,50,159:10,100)
RandomBlock(-5,8,-3,quark:basalt:0,50,159:10,100)
RandomBlock(-4,8,-3,quark:basalt:0,50,159:10,100)
RandomBlock(-3,8,-3,quark:basalt:0,50,159:10,100)
RandomBlock(-2,8,-3,quark:basalt:0,50,159:10,100)
RandomBlock(-1,8,-3,quark:basalt:0,50,159:10,100)
RandomBlock(0,8,-3,quark:basalt:0,50,159:10,100)
RandomBlock(1,8,-3,quark:basalt:0,50,159:10,100)
RandomBlock(2,8,-3,quark:basalt:0,50,159:10,100)
RandomBlock(3,8,-3,quark:basalt:0,50,159:10,100)
RandomBlock(4,8,-3,quark:basalt:0,50,159:10,100)
RandomBlock(-6,8,-2,quark:basalt:0,50,159:10,100)
RandomBlock(-5,8,-2,quark:basalt:0,50,159:10,100)
RandomBlock(-4,8,-2,quark:basalt:0,50,159:10,100)
RandomBlock(-3,8,-2,quark:basalt:0,50,159:10,100)
RandomBlock(-2,8,-2,quark:basalt:0,50,159:10,100)
Block(-1,8,-2,MAGMA:0)
RandomBlock(0,8,-2,quark:basalt:0,50,159:10,100)
RandomBlock(1,8,-2,quark:basalt:0,50,159:10,100)
RandomBlock(2,8,-2,quark:basalt:0,50,159:10,100)
RandomBlock(3,8,-2,quark:basalt:0,50,159:10,100)
RandomBlock(4,8,-2,quark:basalt:0,50,159:10,100)
RandomBlock(-6,8,-1,quark:basalt:0,50,159:10,100)
RandomBlock(-5,8,-1,quark:basalt:0,50,159:10,100)
RandomBlock(-4,8,-1,quark:basalt:0,50,159:10,100)
RandomBlock(-3,8,-1,quark:basalt:0,50,159:10,100)
Block(-2,8,-1,MAGMA:0)
RandomBlock(-1,8,-1,quark:basalt:0,50,159:10,100)
Block(0,8,-1,MAGMA:0)
RandomBlock(1,8,-1,quark:basalt:0,50,159:10,100)
RandomBlock(2,8,-1,quark:basalt:0,50,159:10,100)
RandomBlock(3,8,-1,quark:basalt:0,50,159:10,100)
RandomBlock(4,8,-1,quark:basalt:0,50,159:10,100)
RandomBlock(5,8,-1,quark:basalt:0,50,159:10,100)
RandomBlock(-6,8,0,quark:basalt:0,50,159:10,100)
RandomBlock(-5,8,0,quark:basalt:0,50,159:10,100)
RandomBlock(-4,8,0,quark:basalt:0,50,159:10,100)
RandomBlock(-3,8,0,quark:basalt:0,50,159:10,100)
RandomBlock(-2,8,0,quark:basalt:0,50,159:10,100)
RandomBlock(-1,8,0,quark:basalt:0,50,159:10,100)
RandomBlock(0,8,0,quark:basalt:0,50,159:10,100)
RandomBlock(1,8,0,quark:basalt:0,50,159:10,100)
RandomBlock(2,8,0,quark:basalt:0,50,159:10,100)
RandomBlock(3,8,0,quark:basalt:0,50,159:10,100)
RandomBlock(4,8,0,quark:basalt:0,50,159:10,100)
RandomBlock(5,8,0,quark:basalt:0,50,159:10,100)
RandomBlock(-5,8,1,quark:basalt:0,50,159:10,100)
RandomBlock(-4,8,1,quark:basalt:0,50,159:10,100)
RandomBlock(-3,8,1,quark:basalt:0,50,159:10,100)
RandomBlock(-2,8,1,quark:basalt:0,50,159:10,100)
RandomBlock(-1,8,1,quark:basalt:0,50,159:10,100)
RandomBlock(0,8,1,quark:basalt:0,50,159:10,100)
Block(1,8,1,MAGMA:0)
RandomBlock(2,8,1,quark:basalt:0,50,159:10,100)
RandomBlock(3,8,1,quark:basalt:0,50,159:10,100)
RandomBlock(4,8,1,quark:basalt:0,50,159:10,100)
RandomBlock(5,8,1,quark:basalt:0,50,159:10,100)
RandomBlock(-4,8,2,quark:basalt:0,50,159:10,100)
RandomBlock(-3,8,2,quark:basalt:0,50,159:10,100)
RandomBlock(-2,8,2,quark:basalt:0,50,159:10,100)
RandomBlock(-1,8,2,quark:basalt:0,50,159:10,100)
RandomBlock(0,8,2,quark:basalt:0,50,159:10,100)
RandomBlock(1,8,2,quark:basalt:0,50,159:10,100)
RandomBlock(2,8,2,quark:basalt:0,50,159:10,100)
RandomBlock(3,8,2,quark:basalt:0,50,159:10,100)
RandomBlock(4,8,2,quark:basalt:0,50,159:10,100)
RandomBlock(5,8,2,quark:basalt:0,50,159:10,100)
RandomBlock(-3,8,3,quark:basalt:0,50,159:10,100)
RandomBlock(-2,8,3,quark:basalt:0,50,159:10,100)
RandomBlock(-1,8,3,quark:basalt:0,50,159:10,100)
RandomBlock(0,8,3,quark:basalt:0,50,159:10,100)
RandomBlock(1,8,3,quark:basalt:0,50,159:10,100)
RandomBlock(2,8,3,quark:basalt:0,50,159:10,100)
RandomBlock(3,8,3,quark:basalt:0,50,159:10,100)
RandomBlock(-3,8,4,quark:basalt:0,50,159:10,100)
RandomBlock(-2,8,4,quark:basalt:0,50,159:10,100)
RandomBlock(-1,8,4,quark:basalt:0,50,159:10,100)
RandomBlock(0,8,4,quark:basalt:0,50,159:10,100)
RandomBlock(1,8,4,quark:basalt:0,50,159:10,100)
RandomBlock(-3,9,-5,quark:basalt:0,50,159:10,100)
RandomBlock(-2,9,-5,quark:basalt:0,50,159:10,100)
RandomBlock(-1,9,-5,quark:basalt:0,50,159:10,100)
RandomBlock(0,9,-5,quark:basalt:0,50,159:10,100)
RandomBlock(1,9,-5,quark:basalt:0,50,159:10,100)
RandomBlock(2,9,-5,quark:basalt:0,50,159:10,100)
RandomBlock(3,9,-5,quark:basalt:0,50,159:10,100)
RandomBlock(-5,9,-4,quark:basalt:0,50,159:10,100)
RandomBlock(-4,9,-4,quark:basalt:0,50,159:10,100)
RandomBlock(-3,9,-4,quark:basalt:0,50,159:10,100)
RandomBlock(-2,9,-4,quark:basalt:0,50,159:10,100)
RandomBlock(-1,9,-4,quark:basalt:0,50,159:10,100)
RandomBlock(0,9,-4,quark:basalt:0,50,159:10,100)
RandomBlock(1,9,-4,quark:basalt:0,50,159:10,100)
RandomBlock(2,9,-4,quark:basalt:0,50,159:10,100)
RandomBlock(3,9,-4,quark:basalt:0,50,159:10,100)
RandomBlock(-6,9,-3,quark:basalt:0,50,159:10,100)
RandomBlock(-5,9,-3,quark:basalt:0,50,159:10,100)
RandomBlock(-4,9,-3,quark:basalt:0,50,159:10,100)
RandomBlock(-3,9,-3,quark:basalt:0,50,159:10,100)
RandomBlock(-2,9,-3,quark:basalt:0,50,159:10,100)
RandomBlock(-1,9,-3,quark:basalt:0,50,159:10,100)
RandomBlock(0,9,-3,quark:basalt:0,50,159:10,100)
RandomBlock(1,9,-3,quark:basalt:0,50,159:10,100)
RandomBlock(2,9,-3,quark:basalt:0,50,159:10,100)
RandomBlock(3,9,-3,quark:basalt:0,50,159:10,100)
RandomBlock(4,9,-3,quark:basalt:0,50,159:10,100)
RandomBlock(-6,9,-2,quark:basalt:0,50,159:10,100)
RandomBlock(-5,9,-2,quark:basalt:0,50,159:10,100)
RandomBlock(-4,9,-2,quark:basalt:0,50,159:10,100)
RandomBlock(-3,9,-2,quark:basalt:0,50,159:10,100)
RandomBlock(-2,9,-2,quark:basalt:0,50,159:10,100)
Block(-1,9,-2,MAGMA:0)
RandomBlock(0,9,-2,quark:basalt:0,50,159:10,100)
RandomBlock(1,9,-2,quark:basalt:0,50,159:10,100)
RandomBlock(2,9,-2,quark:basalt:0,50,159:10,100)
RandomBlock(3,9,-2,quark:basalt:0,50,159:10,100)
RandomBlock(4,9,-2,quark:basalt:0,50,159:10,100)
RandomBlock(-6,9,-1,quark:basalt:0,50,159:10,100)
RandomBlock(-5,9,-1,quark:basalt:0,50,159:10,100)
RandomBlock(-4,9,-1,quark:basalt:0,50,159:10,100)
RandomBlock(-3,9,-1,quark:basalt:0,50,159:10,100)
Block(-2,9,-1,MAGMA:0)
RandomBlock(-1,9,-1,quark:basalt:0,50,159:10,100)
Block(0,9,-1,MAGMA:0)
RandomBlock(1,9,-1,quark:basalt:0,50,159:10,100)
RandomBlock(2,9,-1,quark:basalt:0,50,159:10,100)
RandomBlock(3,9,-1,quark:basalt:0,50,159:10,100)
RandomBlock(4,9,-1,quark:basalt:0,50,159:10,100)
RandomBlock(5,9,-1,quark:basalt:0,50,159:10,100)
RandomBlock(-6,9,0,quark:basalt:0,50,159:10,100)
RandomBlock(-5,9,0,quark:basalt:0,50,159:10,100)
RandomBlock(-4,9,0,quark:basalt:0,50,159:10,100)
RandomBlock(-3,9,0,quark:basalt:0,50,159:10,100)
RandomBlock(-2,9,0,quark:basalt:0,50,159:10,100)
RandomBlock(-1,9,0,quark:basalt:0,50,159:10,100)
RandomBlock(0,9,0,quark:basalt:0,50,159:10,100)
RandomBlock(1,9,0,quark:basalt:0,50,159:10,100)
RandomBlock(2,9,0,quark:basalt:0,50,159:10,100)
RandomBlock(3,9,0,quark:basalt:0,50,159:10,100)
RandomBlock(4,9,0,quark:basalt:0,50,159:10,100)
RandomBlock(5,9,0,quark:basalt:0,50,159:10,100)
RandomBlock(-5,9,1,quark:basalt:0,50,159:10,100)
RandomBlock(-4,9,1,quark:basalt:0,50,159:10,100)
RandomBlock(-3,9,1,quark:basalt:0,50,159:10,100)
RandomBlock(-2,9,1,quark:basalt:0,50,159:10,100)
RandomBlock(-1,9,1,quark:basalt:0,50,159:10,100)
RandomBlock(0,9,1,quark:basalt:0,50,159:10,100)
Block(1,9,1,MAGMA:0)
RandomBlock(2,9,1,quark:basalt:0,50,159:10,100)
RandomBlock(3,9,1,quark:basalt:0,50,159:10,100)
RandomBlock(4,9,1,quark:basalt:0,50,159:10,100)
RandomBlock(5,9,1,quark:basalt:0,50,159:10,100)
RandomBlock(-4,9,2,quark:basalt:0,50,159:10,100)
RandomBlock(-3,9,2,quark:basalt:0,50,159:10,100)
RandomBlock(-2,9,2,quark:basalt:0,50,159:10,100)
RandomBlock(-1,9,2,quark:basalt:0,50,159:10,100)
RandomBlock(0,9,2,quark:basalt:0,50,159:10,100)
RandomBlock(1,9,2,quark:basalt:0,50,159:10,100)
RandomBlock(2,9,2,quark:basalt:0,50,159:10,100)
RandomBlock(3,9,2,quark:basalt:0,50,159:10,100)
RandomBlock(4,9,2,quark:basalt:0,50,159:10,100)
RandomBlock(5,9,2,quark:basalt:0,50,159:10,100)
RandomBlock(-3,9,3,quark:basalt:0,50,159:10,100)
RandomBlock(-2,9,3,quark:basalt:0,50,159:10,100)
RandomBlock(-1,9,3,quark:basalt:0,50,159:10,100)
RandomBlock(0,9,3,quark:basalt:0,50,159:10,100)
RandomBlock(1,9,3,quark:basalt:0,50,159:10,100)
RandomBlock(2,9,3,quark:basalt:0,50,159:10,100)
RandomBlock(3,9,3,quark:basalt:0,50,159:10,100)
RandomBlock(-3,9,4,quark:basalt:0,50,159:10,100)
RandomBlock(-2,9,4,quark:basalt:0,50,159:10,100)
RandomBlock(-1,9,4,quark:basalt:0,50,159:10,100)
RandomBlock(0,9,4,quark:basalt:0,50,159:10,100)
RandomBlock(1,9,4,quark:basalt:0,50,159:10,100)
RandomBlock(-3,10,-5,quark:basalt:0,50,159:10,100)
RandomBlock(-2,10,-5,quark:basalt:0,50,159:10,100)
RandomBlock(-1,10,-5,quark:basalt:0,50,159:10,100)
RandomBlock(0,10,-5,quark:basalt:0,50,159:10,100)
RandomBlock(1,10,-5,quark:basalt:0,50,159:10,100)
RandomBlock(2,10,-5,quark:basalt:0,50,159:10,100)
RandomBlock(3,10,-5,quark:basalt:0,50,159:10,100)
RandomBlock(-5,10,-4,quark:basalt:0,50,159:10,100)
RandomBlock(-4,10,-4,quark:basalt:0,50,159:10,100)
RandomBlock(-3,10,-4,quark:basalt:0,50,159:10,100)
RandomBlock(-2,10,-4,quark:basalt:0,50,159:10,100)
RandomBlock(-1,10,-4,quark:basalt:0,50,159:10,100)
RandomBlock(0,10,-4,quark:basalt:0,50,159:10,100)
RandomBlock(1,10,-4,quark:basalt:0,50,159:10,100)
RandomBlock(2,10,-4,quark:basalt:0,50,159:10,100)
RandomBlock(3,10,-4,quark:basalt:0,50,159:10,100)
RandomBlock(-6,10,-3,quark:basalt:0,50,159:10,100)
RandomBlock(-5,10,-3,quark:basalt:0,50,159:10,100)
RandomBlock(-4,10,-3,quark:basalt:0,50,159:10,100)
RandomBlock(-3,10,-3,quark:basalt:0,50,159:10,100)
RandomBlock(-2,10,-3,quark:basalt:0,50,159:10,100)
RandomBlock(-1,10,-3,quark:basalt:0,50,159:10,100)
RandomBlock(0,10,-3,quark:basalt:0,50,159:10,100)
RandomBlock(1,10,-3,quark:basalt:0,50,159:10,100)
RandomBlock(2,10,-3,quark:basalt:0,50,159:10,100)
RandomBlock(3,10,-3,quark:basalt:0,50,159:10,100)
RandomBlock(4,10,-3,quark:basalt:0,50,159:10,100)
RandomBlock(-6,10,-2,quark:basalt:0,50,159:10,100)
RandomBlock(-5,10,-2,quark:basalt:0,50,159:10,100)
RandomBlock(-4,10,-2,quark:basalt:0,50,159:10,100)
RandomBlock(-3,10,-2,quark:basalt:0,50,159:10,100)
RandomBlock(-2,10,-2,quark:basalt:0,50,159:10,100)
Block(-1,10,-2,MAGMA:0)
RandomBlock(0,10,-2,quark:basalt:0,50,159:10,100)
RandomBlock(1,10,-2,quark:basalt:0,50,159:10,100)
RandomBlock(2,10,-2,quark:basalt:0,50,159:10,100)
RandomBlock(3,10,-2,quark:basalt:0,50,159:10,100)
RandomBlock(4,10,-2,quark:basalt:0,50,159:10,100)
RandomBlock(-6,10,-1,quark:basalt:0,50,159:10,100)
RandomBlock(-5,10,-1,quark:basalt:0,50,159:10,100)
RandomBlock(-4,10,-1,quark:basalt:0,50,159:10,100)
RandomBlock(-3,10,-1,quark:basalt:0,50,159:10,100)
Block(-2,10,-1,MAGMA:0)
RandomBlock(-1,10,-1,quark:basalt:0,50,159:10,100)
Block(0,10,-1,MAGMA:0)
RandomBlock(1,10,-1,quark:basalt:0,50,159:10,100)
RandomBlock(2,10,-1,quark:basalt:0,50,159:10,100)
RandomBlock(3,10,-1,quark:basalt:0,50,159:10,100)
RandomBlock(4,10,-1,quark:basalt:0,50,159:10,100)
RandomBlock(5,10,-1,quark:basalt:0,50,159:10,100)
RandomBlock(-6,10,0,quark:basalt:0,50,159:10,100)
RandomBlock(-5,10,0,quark:basalt:0,50,159:10,100)
RandomBlock(-4,10,0,quark:basalt:0,50,159:10,100)
RandomBlock(-3,10,0,quark:basalt:0,50,159:10,100)
RandomBlock(-2,10,0,quark:basalt:0,50,159:10,100)
RandomBlock(-1,10,0,quark:basalt:0,50,159:10,100)
RandomBlock(0,10,0,quark:basalt:0,50,159:10,100)
RandomBlock(1,10,0,quark:basalt:0,50,159:10,100)
RandomBlock(2,10,0,quark:basalt:0,50,159:10,100)
RandomBlock(3,10,0,quark:basalt:0,50,159:10,100)
RandomBlock(4,10,0,quark:basalt:0,50,159:10,100)
RandomBlock(5,10,0,quark:basalt:0,50,159:10,100)
RandomBlock(-5,10,1,quark:basalt:0,50,159:10,100)
RandomBlock(-4,10,1,quark:basalt:0,50,159:10,100)
RandomBlock(-3,10,1,quark:basalt:0,50,159:10,100)
RandomBlock(-2,10,1,quark:basalt:0,50,159:10,100)
RandomBlock(-1,10,1,quark:basalt:0,50,159:10,100)
RandomBlock(0,10,1,quark:basalt:0,50,159:10,100)
Block(1,10,1,MAGMA:0)
RandomBlock(2,10,1,quark:basalt:0,50,159:10,100)
RandomBlock(3,10,1,quark:basalt:0,50,159:10,100)
RandomBlock(4,10,1,quark:basalt:0,50,159:10,100)
RandomBlock(5,10,1,quark:basalt:0,50,159:10,100)
RandomBlock(-4,10,2,quark:basalt:0,50,159:10,100)
RandomBlock(-3,10,2,quark:basalt:0,50,159:10,100)
RandomBlock(-2,10,2,quark:basalt:0,50,159:10,100)
RandomBlock(-1,10,2,quark:basalt:0,50,159:10,100)
RandomBlock(0,10,2,quark:basalt:0,50,159:10,100)
RandomBlock(1,10,2,quark:basalt:0,50,159:10,100)
RandomBlock(2,10,2,quark:basalt:0,50,159:10,100)
RandomBlock(3,10,2,quark:basalt:0,50,159:10,100)
RandomBlock(4,10,2,quark:basalt:0,50,159:10,100)
RandomBlock(5,10,2,quark:basalt:0,50,159:10,100)
RandomBlock(-3,10,3,quark:basalt:0,50,159:10,100)
RandomBlock(-2,10,3,quark:basalt:0,50,159:10,100)
RandomBlock(-1,10,3,quark:basalt:0,50,159:10,100)
RandomBlock(0,10,3,quark:basalt:0,50,159:10,100)
RandomBlock(1,10,3,quark:basalt:0,50,159:10,100)
RandomBlock(2,10,3,quark:basalt:0,50,159:10,100)
RandomBlock(3,10,3,quark:basalt:0,50,159:10,100)
RandomBlock(-3,10,4,quark:basalt:0,50,159:10,100)
RandomBlock(-2,10,4,quark:basalt:0,50,159:10,100)
RandomBlock(-1,10,4,quark:basalt:0,50,159:10,100)
RandomBlock(0,10,4,quark:basalt:0,50,159:10,100)
RandomBlock(1,10,4,quark:basalt:0,50,159:10,100)
RandomBlock(-3,11,-5,quark:basalt:0,50,159:10,100)
RandomBlock(-2,11,-5,quark:basalt:0,50,159:10,100)
RandomBlock(-1,11,-5,quark:basalt:0,50,159:10,100)
RandomBlock(0,11,-5,quark:basalt:0,50,159:10,100)
RandomBlock(1,11,-5,quark:basalt:0,50,159:10,100)
RandomBlock(2,11,-5,quark:basalt:0,50,159:10,100)
RandomBlock(-5,11,-4,quark:basalt:0,50,159:10,100)
RandomBlock(-4,11,-4,quark:basalt:0,50,159:10,100)
RandomBlock(-3,11,-4,quark:basalt:0,50,159:10,100)
RandomBlock(-2,11,-4,quark:basalt:0,50,159:10,100)
RandomBlock(-1,11,-4,quark:basalt:0,50,159:10,100)
RandomBlock(0,11,-4,quark:basalt:0,50,159:10,100)
RandomBlock(1,11,-4,quark:basalt:0,50,159:10,100)
RandomBlock(2,11,-4,quark:basalt:0,50,159:10,100)
RandomBlock(3,11,-4,quark:basalt:0,50,159:10,100)
RandomBlock(-6,11,-3,quark:basalt:0,50,159:10,100)
RandomBlock(-5,11,-3,quark:basalt:0,50,159:10,100)
RandomBlock(-4,11,-3,quark:basalt:0,50,159:10,100)
RandomBlock(-3,11,-3,quark:basalt:0,50,159:10,100)
RandomBlock(-2,11,-3,quark:basalt:0,50,159:10,100)
RandomBlock(-1,11,-3,quark:basalt:0,50,159:10,100)
RandomBlock(0,11,-3,quark:basalt:0,50,159:10,100)
RandomBlock(1,11,-3,quark:basalt:0,50,159:10,100)
RandomBlock(2,11,-3,quark:basalt:0,50,159:10,100)
RandomBlock(3,11,-3,quark:basalt:0,50,159:10,100)
RandomBlock(4,11,-3,quark:basalt:0,50,159:10,100)
RandomBlock(-6,11,-2,quark:basalt:0,50,159:10,100)
RandomBlock(-5,11,-2,quark:basalt:0,50,159:10,100)
RandomBlock(-4,11,-2,quark:basalt:0,50,159:10,100)
RandomBlock(-3,11,-2,quark:basalt:0,50,159:10,100)
RandomBlock(-2,11,-2,quark:basalt:0,50,159:10,100)
Block(-1,11,-2,MAGMA:0)
RandomBlock(0,11,-2,quark:basalt:0,50,159:10,100)
RandomBlock(1,11,-2,quark:basalt:0,50,159:10,100)
RandomBlock(2,11,-2,quark:basalt:0,50,159:10,100)
RandomBlock(3,11,-2,quark:basalt:0,50,159:10,100)
RandomBlock(4,11,-2,quark:basalt:0,50,159:10,100)
RandomBlock(-6,11,-1,quark:basalt:0,50,159:10,100)
RandomBlock(-5,11,-1,quark:basalt:0,50,159:10,100)
RandomBlock(-4,11,-1,quark:basalt:0,50,159:10,100)
RandomBlock(-3,11,-1,quark:basalt:0,50,159:10,100)
Block(-2,11,-1,MAGMA:0)
RandomBlock(-1,11,-1,quark:basalt:0,50,159:10,100)
Block(0,11,-1,MAGMA:0)
RandomBlock(1,11,-1,quark:basalt:0,50,159:10,100)
RandomBlock(2,11,-1,quark:basalt:0,50,159:10,100)
RandomBlock(3,11,-1,quark:basalt:0,50,159:10,100)
RandomBlock(4,11,-1,quark:basalt:0,50,159:10,100)
RandomBlock(5,11,-1,quark:basalt:0,50,159:10,100)
RandomBlock(-6,11,0,quark:basalt:0,50,159:10,100)
RandomBlock(-5,11,0,quark:basalt:0,50,159:10,100)
RandomBlock(-4,11,0,quark:basalt:0,50,159:10,100)
RandomBlock(-3,11,0,quark:basalt:0,50,159:10,100)
RandomBlock(-2,11,0,quark:basalt:0,50,159:10,100)
RandomBlock(-1,11,0,quark:basalt:0,50,159:10,100)
RandomBlock(0,11,0,quark:basalt:0,50,159:10,100)
RandomBlock(1,11,0,quark:basalt:0,50,159:10,100)
RandomBlock(2,11,0,quark:basalt:0,50,159:10,100)
RandomBlock(3,11,0,quark:basalt:0,50,159:10,100)
RandomBlock(4,11,0,quark:basalt:0,50,159:10,100)
RandomBlock(5,11,0,quark:basalt:0,50,159:10,100)
RandomBlock(-5,11,1,quark:basalt:0,50,159:10,100)
RandomBlock(-4,11,1,quark:basalt:0,50,159:10,100)
RandomBlock(-3,11,1,quark:basalt:0,50,159:10,100)
RandomBlock(-2,11,1,quark:basalt:0,50,159:10,100)
RandomBlock(-1,11,1,quark:basalt:0,50,159:10,100)
RandomBlock(0,11,1,quark:basalt:0,50,159:10,100)
Block(1,11,1,MAGMA:0)
RandomBlock(2,11,1,quark:basalt:0,50,159:10,100)
RandomBlock(3,11,1,quark:basalt:0,50,159:10,100)
RandomBlock(4,11,1,quark:basalt:0,50,159:10,100)
RandomBlock(5,11,1,quark:basalt:0,50,159:10,100)
RandomBlock(-4,11,2,quark:basalt:0,50,159:10,100)
RandomBlock(-3,11,2,quark:basalt:0,50,159:10,100)
RandomBlock(-2,11,2,quark:basalt:0,50,159:10,100)
RandomBlock(-1,11,2,quark:basalt:0,50,159:10,100)
RandomBlock(0,11,2,quark:basalt:0,50,159:10,100)
RandomBlock(1,11,2,quark:basalt:0,50,159:10,100)
RandomBlock(2,11,2,quark:basalt:0,50,159:10,100)
RandomBlock(3,11,2,quark:basalt:0,50,159:10,100)
RandomBlock(4,11,2,quark:basalt:0,50,159:10,100)
RandomBlock(5,11,2,quark:basalt:0,50,159:10,100)
RandomBlock(-3,11,3,quark:basalt:0,50,159:10,100)
RandomBlock(-2,11,3,quark:basalt:0,50,159:10,100)
RandomBlock(-1,11,3,quark:basalt:0,50,159:10,100)
RandomBlock(0,11,3,quark:basalt:0,50,159:10,100)
RandomBlock(1,11,3,quark:basalt:0,50,159:10,100)
RandomBlock(2,11,3,quark:basalt:0,50,159:10,100)
RandomBlock(3,11,3,quark:basalt:0,50,159:10,100)
RandomBlock(-3,11,4,quark:basalt:0,50,159:10,100)
RandomBlock(-2,11,4,quark:basalt:0,50,159:10,100)
RandomBlock(-1,11,4,quark:basalt:0,50,159:10,100)
RandomBlock(0,11,4,quark:basalt:0,50,159:10,100)
RandomBlock(1,11,4,quark:basalt:0,50,159:10,100)
RandomBlock(-3,12,-5,quark:basalt:0,50,159:10,100)
RandomBlock(-2,12,-5,quark:basalt:0,50,159:10,100)
RandomBlock(-1,12,-5,quark:basalt:0,50,159:10,100)
RandomBlock(0,12,-5,quark:basalt:0,50,159:10,100)
RandomBlock(-5,12,-4,quark:basalt:0,50,159:10,100)
RandomBlock(-4,12,-4,quark:basalt:0,50,159:10,100)
RandomBlock(-3,12,-4,quark:basalt:0,50,159:10,100)
RandomBlock(-2,12,-4,quark:basalt:0,50,159:10,100)
RandomBlock(-1,12,-4,quark:basalt:0,50,159:10,100)
RandomBlock(0,12,-4,quark:basalt:0,50,159:10,100)
RandomBlock(1,12,-4,quark:basalt:0,50,159:10,100)
RandomBlock(2,12,-4,quark:basalt:0,50,159:10,100)
RandomBlock(3,12,-4,quark:basalt:0,50,159:10,100)
RandomBlock(-5,12,-3,quark:basalt:0,50,159:10,100)
RandomBlock(-4,12,-3,quark:basalt:0,50,159:10,100)
RandomBlock(-3,12,-3,quark:basalt:0,50,159:10,100)
RandomBlock(-2,12,-3,quark:basalt:0,50,159:10,100)
RandomBlock(-1,12,-3,quark:basalt:0,50,159:10,100)
RandomBlock(0,12,-3,quark:basalt:0,50,159:10,100)
RandomBlock(1,12,-3,quark:basalt:0,50,159:10,100)
RandomBlock(2,12,-3,quark:basalt:0,50,159:10,100)
RandomBlock(3,12,-3,quark:basalt:0,50,159:10,100)
RandomBlock(4,12,-3,quark:basalt:0,50,159:10,100)
RandomBlock(-6,12,-2,quark:basalt:0,50,159:10,100)
RandomBlock(-5,12,-2,quark:basalt:0,50,159:10,100)
RandomBlock(-4,12,-2,quark:basalt:0,50,159:10,100)
RandomBlock(-3,12,-2,quark:basalt:0,50,159:10,100)
RandomBlock(-2,12,-2,quark:basalt:0,50,159:10,100)
Block(-1,12,-2,MAGMA:0)
RandomBlock(0,12,-2,quark:basalt:0,50,159:10,100)
RandomBlock(1,12,-2,quark:basalt:0,50,159:10,100)
RandomBlock(2,12,-2,quark:basalt:0,50,159:10,100)
RandomBlock(3,12,-2,quark:basalt:0,50,159:10,100)
RandomBlock(4,12,-2,quark:basalt:0,50,159:10,100)
RandomBlock(-6,12,-1,quark:basalt:0,50,159:10,100)
RandomBlock(-5,12,-1,quark:basalt:0,50,159:10,100)
RandomBlock(-4,12,-1,quark:basalt:0,50,159:10,100)
RandomBlock(-3,12,-1,quark:basalt:0,50,159:10,100)
Block(-2,12,-1,MAGMA:0)
RandomBlock(-1,12,-1,quark:basalt:0,50,159:10,100)
Block(0,12,-1,MAGMA:0)
RandomBlock(1,12,-1,quark:basalt:0,50,159:10,100)
RandomBlock(2,12,-1,quark:basalt:0,50,159:10,100)
RandomBlock(3,12,-1,quark:basalt:0,50,159:10,100)
RandomBlock(4,12,-1,quark:basalt:0,50,159:10,100)
RandomBlock(5,12,-1,quark:basalt:0,50,159:10,100)
RandomBlock(-5,12,0,quark:basalt:0,50,159:10,100)
RandomBlock(-4,12,0,quark:basalt:0,50,159:10,100)
RandomBlock(-3,12,0,quark:basalt:0,50,159:10,100)
RandomBlock(-2,12,0,quark:basalt:0,50,159:10,100)
RandomBlock(-1,12,0,quark:basalt:0,50,159:10,100)
RandomBlock(0,12,0,quark:basalt:0,50,159:10,100)
RandomBlock(1,12,0,quark:basalt:0,50,159:10,100)
RandomBlock(2,12,0,quark:basalt:0,50,159:10,100)
RandomBlock(3,12,0,quark:basalt:0,50,159:10,100)
RandomBlock(4,12,0,quark:basalt:0,50,159:10,100)
RandomBlock(5,12,0,quark:basalt:0,50,159:10,100)
RandomBlock(-4,12,1,quark:basalt:0,50,159:10,100)
RandomBlock(-3,12,1,quark:basalt:0,50,159:10,100)
RandomBlock(-2,12,1,quark:basalt:0,50,159:10,100)
RandomBlock(-1,12,1,quark:basalt:0,50,159:10,100)
RandomBlock(0,12,1,quark:basalt:0,50,159:10,100)
Block(1,12,1,MAGMA:0)
RandomBlock(2,12,1,quark:basalt:0,50,159:10,100)
RandomBlock(3,12,1,quark:basalt:0,50,159:10,100)
RandomBlock(4,12,1,quark:basalt:0,50,159:10,100)
RandomBlock(-4,12,2,quark:basalt:0,50,159:10,100)
RandomBlock(-3,12,2,quark:basalt:0,50,159:10,100)
RandomBlock(-2,12,2,quark:basalt:0,50,159:10,100)
RandomBlock(-1,12,2,quark:basalt:0,50,159:10,100)
RandomBlock(0,12,2,quark:basalt:0,50,159:10,100)
RandomBlock(1,12,2,quark:basalt:0,50,159:10,100)
RandomBlock(2,12,2,quark:basalt:0,50,159:10,100)
RandomBlock(3,12,2,quark:basalt:0,50,159:10,100)
RandomBlock(4,12,2,quark:basalt:0,50,159:10,100)
RandomBlock(-3,12,3,quark:basalt:0,50,159:10,100)
RandomBlock(-2,12,3,quark:basalt:0,50,159:10,100)
RandomBlock(-1,12,3,quark:basalt:0,50,159:10,100)
RandomBlock(0,12,3,quark:basalt:0,50,159:10,100)
RandomBlock(1,12,3,quark:basalt:0,50,159:10,100)
RandomBlock(2,12,3,quark:basalt:0,50,159:10,100)
RandomBlock(3,12,3,quark:basalt:0,50,159:10,100)
RandomBlock(-3,12,4,quark:basalt:0,50,159:10,100)
RandomBlock(-2,12,4,quark:basalt:0,50,159:10,100)
RandomBlock(-1,12,4,quark:basalt:0,50,159:10,100)
RandomBlock(0,12,4,quark:basalt:0,50,159:10,100)
RandomBlock(1,12,4,quark:basalt:0,50,159:10,100)
RandomBlock(-3,13,-5,quark:basalt:0,50,159:10,100)
RandomBlock(-2,13,-5,quark:basalt:0,50,159:10,100)
RandomBlock(-5,13,-4,quark:basalt:0,50,159:10,100)
RandomBlock(-4,13,-4,quark:basalt:0,50,159:10,100)
RandomBlock(-3,13,-4,quark:basalt:0,50,159:10,100)
RandomBlock(-2,13,-4,quark:basalt:0,50,159:10,100)
RandomBlock(-1,13,-4,quark:basalt:0,50,159:10,100)
RandomBlock(0,13,-4,quark:basalt:0,50,159:10,100)
RandomBlock(1,13,-4,quark:basalt:0,50,159:10,100)
RandomBlock(2,13,-4,quark:basalt:0,50,159:10,100)
RandomBlock(-5,13,-3,quark:basalt:0,50,159:10,100)
RandomBlock(-4,13,-3,quark:basalt:0,50,159:10,100)
RandomBlock(-3,13,-3,quark:basalt:0,50,159:10,100)
RandomBlock(-2,13,-3,quark:basalt:0,50,159:10,100)
RandomBlock(-1,13,-3,quark:basalt:0,50,159:10,100)
RandomBlock(0,13,-3,quark:basalt:0,50,159:10,100)
RandomBlock(1,13,-3,quark:basalt:0,50,159:10,100)
RandomBlock(2,13,-3,quark:basalt:0,50,159:10,100)
RandomBlock(3,13,-3,quark:basalt:0,50,159:10,100)
RandomBlock(-5,13,-2,quark:basalt:0,50,159:10,100)
RandomBlock(-4,13,-2,quark:basalt:0,50,159:10,100)
RandomBlock(-3,13,-2,quark:basalt:0,50,159:10,100)
RandomBlock(-2,13,-2,quark:basalt:0,50,159:10,100)
Block(-1,13,-2,MAGMA:0)
RandomBlock(0,13,-2,quark:basalt:0,50,159:10,100)
RandomBlock(1,13,-2,quark:basalt:0,50,159:10,100)
RandomBlock(2,13,-2,quark:basalt:0,50,159:10,100)
RandomBlock(3,13,-2,quark:basalt:0,50,159:10,100)
RandomBlock(-5,13,-1,quark:basalt:0,50,159:10,100)
RandomBlock(-4,13,-1,quark:basalt:0,50,159:10,100)
RandomBlock(-3,13,-1,quark:basalt:0,50,159:10,100)
Block(-2,13,-1,MAGMA:0)
RandomBlock(-1,13,-1,quark:basalt:0,50,159:10,100)
Block(0,13,-1,MAGMA:0)
RandomBlock(1,13,-1,quark:basalt:0,50,159:10,100)
RandomBlock(2,13,-1,quark:basalt:0,50,159:10,100)
RandomBlock(3,13,-1,quark:basalt:0,50,159:10,100)
RandomBlock(4,13,-1,quark:basalt:0,50,159:10,100)
RandomBlock(-5,13,0,quark:basalt:0,50,159:10,100)
RandomBlock(-4,13,0,quark:basalt:0,50,159:10,100)
RandomBlock(-3,13,0,quark:basalt:0,50,159:10,100)
RandomBlock(-2,13,0,quark:basalt:0,50,159:10,100)
RandomBlock(-1,13,0,quark:basalt:0,50,159:10,100)
RandomBlock(0,13,0,quark:basalt:0,50,159:10,100)
RandomBlock(1,13,0,quark:basalt:0,50,159:10,100)
RandomBlock(2,13,0,quark:basalt:0,50,159:10,100)
RandomBlock(3,13,0,quark:basalt:0,50,159:10,100)
RandomBlock(4,13,0,quark:basalt:0,50,159:10,100)
RandomBlock(-4,13,1,quark:basalt:0,50,159:10,100)
RandomBlock(-3,13,1,quark:basalt:0,50,159:10,100)
RandomBlock(-2,13,1,quark:basalt:0,50,159:10,100)
RandomBlock(-1,13,1,quark:basalt:0,50,159:10,100)
RandomBlock(0,13,1,quark:basalt:0,50,159:10,100)
Block(1,13,1,MAGMA:0)
RandomBlock(2,13,1,quark:basalt:0,50,159:10,100)
RandomBlock(3,13,1,quark:basalt:0,50,159:10,100)
RandomBlock(-3,13,2,quark:basalt:0,50,159:10,100)
RandomBlock(-2,13,2,quark:basalt:0,50,159:10,100)
RandomBlock(-1,13,2,quark:basalt:0,50,159:10,100)
RandomBlock(0,13,2,quark:basalt:0,50,159:10,100)
RandomBlock(1,13,2,quark:basalt:0,50,159:10,100)
RandomBlock(2,13,2,quark:basalt:0,50,159:10,100)
RandomBlock(3,13,2,quark:basalt:0,50,159:10,100)
RandomBlock(-2,13,3,quark:basalt:0,50,159:10,100)
RandomBlock(-1,13,3,quark:basalt:0,50,159:10,100)
RandomBlock(0,13,3,quark:basalt:0,50,159:10,100)
RandomBlock(1,13,3,quark:basalt:0,50,159:10,100)
RandomBlock(-2,13,4,quark:basalt:0,50,159:10,100)
RandomBlock(-1,13,4,quark:basalt:0,50,159:10,100)
RandomBlock(0,13,4,quark:basalt:0,50,159:10,100)
RandomBlock(-2,14,-5,quark:basalt:0,50,159:10,100)
RandomBlock(-1,14,-4,quark:basalt:0,50,159:10,100)
RandomBlock(0,14,-4,quark:basalt:0,50,159:10,100)
RandomBlock(1,14,-4,quark:basalt:0,50,159:10,100)
RandomBlock(2,14,-4,quark:basalt:0,50,159:10,100)
RandomBlock(-4,14,-3,quark:basalt:0,50,159:10,100)
RandomBlock(-3,14,-3,quark:basalt:0,50,159:10,100)
RandomBlock(-2,14,-3,quark:basalt:0,50,159:10,100)
RandomBlock(-1,14,-3,quark:basalt:0,50,159:10,100)
RandomBlock(0,14,-3,quark:basalt:0,50,159:10,100)
RandomBlock(1,14,-3,quark:basalt:0,50,159:10,100)
RandomBlock(2,14,-3,quark:basalt:0,50,159:10,100)
RandomBlock(3,14,-3,quark:basalt:0,50,159:10,100)
RandomBlock(-4,14,-2,quark:basalt:0,50,159:10,100)
RandomBlock(-3,14,-2,quark:basalt:0,50,159:10,100)
RandomBlock(-2,14,-2,quark:basalt:0,50,159:10,100)
Block(-1,14,-2,MAGMA:0)
RandomBlock(0,14,-2,quark:basalt:0,50,159:10,100)
RandomBlock(1,14,-2,quark:basalt:0,50,159:10,100)
RandomBlock(2,14,-2,quark:basalt:0,50,159:10,100)
RandomBlock(3,14,-2,quark:basalt:0,50,159:10,100)
RandomBlock(-4,14,-1,quark:basalt:0,50,159:10,100)
RandomBlock(-3,14,-1,quark:basalt:0,50,159:10,100)
Block(-2,14,-1,MAGMA:0)
RandomBlock(-1,14,-1,quark:basalt:0,50,159:10,100)
Block(0,14,-1,MAGMA:0)
RandomBlock(1,14,-1,quark:basalt:0,50,159:10,100)
RandomBlock(2,14,-1,quark:basalt:0,50,159:10,100)
RandomBlock(3,14,-1,quark:basalt:0,50,159:10,100)
RandomBlock(-3,14,0,quark:basalt:0,50,159:10,100)
RandomBlock(-2,14,0,quark:basalt:0,50,159:10,100)
RandomBlock(-1,14,0,quark:basalt:0,50,159:10,100)
RandomBlock(0,14,0,quark:basalt:0,50,159:10,100)
RandomBlock(1,14,0,quark:basalt:0,50,159:10,100)
RandomBlock(2,14,0,quark:basalt:0,50,159:10,100)
RandomBlock(3,14,0,quark:basalt:0,50,159:10,100)
RandomBlock(4,14,0,quark:basalt:0,50,159:10,100)
RandomBlock(-3,14,1,quark:basalt:0,50,159:10,100)
RandomBlock(-2,14,1,quark:basalt:0,50,159:10,100)
RandomBlock(-1,14,1,quark:basalt:0,50,159:10,100)
RandomBlock(0,14,1,quark:basalt:0,50,159:10,100)
Block(1,14,1,MAGMA:0)
RandomBlock(2,14,1,quark:basalt:0,50,159:10,100)
RandomBlock(3,14,1,quark:basalt:0,50,159:10,100)
RandomBlock(-2,14,2,quark:basalt:0,50,159:10,100)
RandomBlock(-1,14,2,quark:basalt:0,50,159:10,100)
RandomBlock(0,14,2,quark:basalt:0,50,159:10,100)
RandomBlock(1,14,2,quark:basalt:0,50,159:10,100)
RandomBlock(2,14,2,quark:basalt:0,50,159:10,100)
RandomBlock(-2,14,3,quark:basalt:0,50,159:10,100)
RandomBlock(-1,14,3,quark:basalt:0,50,159:10,100)
RandomBlock(0,14,3,quark:basalt:0,50,159:10,100)
RandomBlock(-1,14,4,quark:basalt:0,50,159:10,100)
RandomBlock(-1,15,-4,quark:basalt:0,50,159:10,100)
RandomBlock(2,15,-4,quark:basalt:0,50,159:10,100)
RandomBlock(-2,15,-3,quark:basalt:0,50,159:10,100)
RandomBlock(-1,15,-3,quark:basalt:0,50,159:10,100)
RandomBlock(0,15,-3,quark:basalt:0,50,159:10,100)
RandomBlock(1,15,-3,quark:basalt:0,50,159:10,100)
RandomBlock(2,15,-3,quark:basalt:0,50,159:10,100)
RandomBlock(-3,15,-2,quark:basalt:0,50,159:10,100)
RandomBlock(-2,15,-2,quark:basalt:0,50,159:10,100)
Block(-1,15,-2,MAGMA:0)
RandomBlock(0,15,-2,quark:basalt:0,50,159:10,100)
RandomBlock(1,15,-2,quark:basalt:0,50,159:10,100)
RandomBlock(2,15,-2,quark:basalt:0,50,159:10,100)
RandomBlock(3,15,-2,quark:basalt:0,50,159:10,100)
RandomBlock(-4,15,-1,quark:basalt:0,50,159:10,100)
RandomBlock(-3,15,-1,quark:basalt:0,50,159:10,100)
Block(-2,15,-1,MAGMA:0)
RandomBlock(-1,15,-1,quark:basalt:0,50,159:10,100)
Block(0,15,-1,MAGMA:0)
RandomBlock(1,15,-1,quark:basalt:0,50,159:10,100)
RandomBlock(2,15,-1,quark:basalt:0,50,159:10,100)
RandomBlock(3,15,-1,quark:basalt:0,50,159:10,100)
RandomBlock(-3,15,0,quark:basalt:0,50,159:10,100)
RandomBlock(-2,15,0,quark:basalt:0,50,159:10,100)
RandomBlock(-1,15,0,quark:basalt:0,50,159:10,100)
RandomBlock(0,15,0,quark:basalt:0,50,159:10,100)
RandomBlock(1,15,0,quark:basalt:0,50,159:10,100)
RandomBlock(2,15,0,quark:basalt:0,50,159:10,100)
RandomBlock(3,15,0,quark:basalt:0,50,159:10,100)
RandomBlock(-3,15,1,quark:basalt:0,50,159:10,100)
RandomBlock(-2,15,1,quark:basalt:0,50,159:10,100)
RandomBlock(-1,15,1,quark:basalt:0,50,159:10,100)
RandomBlock(0,15,1,quark:basalt:0,50,159:10,100)
Block(1,15,1,MAGMA:0)
RandomBlock(2,15,1,quark:basalt:0,50,159:10,100)
RandomBlock(-2,15,2,quark:basalt:0,50,159:10,100)
RandomBlock(-1,15,2,quark:basalt:0,50,159:10,100)
RandomBlock(0,15,2,quark:basalt:0,50,159:10,100)
RandomBlock(1,15,2,quark:basalt:0,50,159:10,100)
RandomBlock(-2,15,3,quark:basalt:0,50,159:10,100)
RandomBlock(-1,15,3,quark:basalt:0,50,159:10,100)
RandomBlock(-1,16,-4,quark:basalt:0,50,159:10,100)
RandomBlock(-1,16,-3,quark:basalt:0,50,159:10,100)
RandomBlock(-2,16,-2,quark:basalt:0,50,159:10,100)
Block(-1,16,-2,MAGMA:0)
RandomBlock(0,16,-2,quark:basalt:0,50,159:10,100)
RandomBlock(1,16,-2,quark:basalt:0,50,159:10,100)
RandomBlock(2,16,-2,quark:basalt:0,50,159:10,100)
RandomBlock(-3,16,-1,quark:basalt:0,50,159:10,100)
Block(-2,16,-1,MAGMA:0)
RandomBlock(-1,16,-1,quark:basalt:0,50,159:10,100)
Block(0,16,-1,MAGMA:0)
RandomBlock(1,16,-1,quark:basalt:0,50,159:10,100)
RandomBlock(2,16,-1,quark:basalt:0,50,159:10,100)
RandomBlock(-2,16,0,quark:basalt:0,50,159:10,100)
RandomBlock(-1,16,0,quark:basalt:0,50,159:10,100)
RandomBlock(0,16,0,quark:basalt:0,50,159:10,100)
RandomBlock(1,16,0,quark:basalt:0,50,159:10,100)
RandomBlock(-1,16,1,quark:basalt:0,50,159:10,100)
RandomBlock(0,16,1,quark:basalt:0,50,159:10,100)
RandomBlock(2,16,1,quark:basalt:0,50,159:10,100)
RandomBlock(-1,16,2,quark:basalt:0,50,159:10,100)
RandomBlock(1,16,2,quark:basalt:0,50,159:10,100)
RandomBlock(-1,17,-3,quark:basalt:0,50,159:10,100)
RandomBlock(-2,17,-2,quark:basalt:0,50,159:10,100)
Block(-1,17,-2,MAGMA:0)
RandomBlock(0,17,-2,quark:basalt:0,50,159:10,100)
RandomBlock(1,17,-2,quark:basalt:0,50,159:10,100)
RandomBlock(-3,17,-1,quark:basalt:0,50,159:10,100)
Block(-2,17,-1,MAGMA:0)
RandomBlock(-1,17,-1,quark:basalt:0,50,159:10,100)
Block(0,17,-1,MAGMA:0)
RandomBlock(1,17,-1,quark:basalt:0,50,159:10,100)
RandomBlock(2,17,-1,quark:basalt:0,50,159:10,100)
RandomBlock(-2,17,0,quark:basalt:0,50,159:10,100)
RandomBlock(-1,17,0,quark:basalt:0,50,159:10,100)
RandomBlock(0,17,0,quark:basalt:0,50,159:10,100)
RandomBlock(1,17,0,quark:basalt:0,50,159:10,100)
RandomBlock(-1,17,1,quark:basalt:0,50,159:10,100)
RandomBlock(0,17,1,quark:basalt:0,50,159:10,100)
RandomBlock(2,17,1,quark:basalt:0,50,159:10,100)
RandomBlock(1,17,2,quark:basalt:0,50,159:10,100)
RandomBlock(-1,18,-3,quark:basalt:0,50,159:10,100)
RandomBlock(-2,18,-2,quark:basalt:0,50,159:10,100)
Block(-1,18,-2,MAGMA:0)
RandomBlock(0,18,-2,quark:basalt:0,50,159:10,100)
RandomBlock(1,18,-2,quark:basalt:0,50,159:10,100)
RandomBlock(-3,18,-1,quark:basalt:0,50,159:10,100)
Block(-2,18,-1,MAGMA:0)
RandomBlock(-1,18,-1,quark:basalt:0,50,159:10,100)
Block(0,18,-1,MAGMA:0)
RandomBlock(1,18,-1,quark:basalt:0,50,159:10,100)
RandomBlock(2,18,-1,quark:basalt:0,50,159:10,100)
RandomBlock(-2,18,0,quark:basalt:0,50,159:10,100)
RandomBlock(-1,18,0,quark:basalt:0,50,159:10,100)
RandomBlock(0,18,0,quark:basalt:0,50,159:10,100)
RandomBlock(1,18,0,quark:basalt:0,50,159:10,100)
RandomBlock(-1,18,1,quark:basalt:0,50,159:10,100)
RandomBlock(0,18,1,quark:basalt:0,50,159:10,100)
RandomBlock(-1,19,-3,quark:basalt:0,50,159:10,100)
RandomBlock(-2,19,-2,quark:basalt:0,50,159:10,100)
Block(-1,19,-2,MAGMA:0)
RandomBlock(0,19,-2,quark:basalt:0,50,159:10,100)
RandomBlock(1,19,-2,quark:basalt:0,50,159:10,100)
RandomBlock(-3,19,-1,quark:basalt:0,50,159:10,100)
Block(-2,19,-1,MAGMA:0)
RandomBlock(-1,19,-1,quark:basalt:0,50,159:10,100)
Block(0,19,-1,MAGMA:0)
RandomBlock(1,19,-1,quark:basalt:0,50,159:10,100)
RandomBlock(2,19,-1,quark:basalt:0,50,159:10,100)
RandomBlock(-2,19,0,quark:basalt:0,50,159:10,100)
RandomBlock(-1,19,0,quark:basalt:0,50,159:10,100)
RandomBlock(0,19,0,quark:basalt:0,50,159:10,100)
RandomBlock(1,19,0,quark:basalt:0,50,159:10,100)
RandomBlock(0,19,1,quark:basalt:0,50,159:10,100)
RandomBlock(-1,20,-3,quark:basalt:0,50,159:10,100)
RandomBlock(-2,20,-2,quark:basalt:0,50,159:10,100)
RandomBlock(0,20,-2,quark:basalt:0,50,159:10,100)
RandomBlock(1,20,-2,quark:basalt:0,50,159:10,100)
RandomBlock(-3,20,-1,quark:basalt:0,50,159:10,100)
RandomBlock(-1,20,-1,quark:basalt:0,50,159:10,100)
Block(0,20,-1,MAGMA:0)
RandomBlock(1,20,-1,quark:basalt:0,50,159:10,100)
RandomBlock(2,20,-1,quark:basalt:0,50,159:10,100)
RandomBlock(-2,20,0,quark:basalt:0,50,159:10,100)
RandomBlock(-1,20,0,quark:basalt:0,50,159:10,100)
RandomBlock(0,20,0,quark:basalt:0,50,159:10,100)
RandomBlock(1,20,0,quark:basalt:0,50,159:10,100)
RandomBlock(0,20,1,quark:basalt:0,50,159:10,100)
RandomBlock(-1,21,-3,quark:basalt:0,50,159:10,100)
RandomBlock(-2,21,-2,quark:basalt:0,50,159:10,100)
Block(-1,21,-2,MAGMA:0)
RandomBlock(0,21,-2,quark:basalt:0,50,159:10,100)
RandomBlock(-3,21,-1,quark:basalt:0,50,159:10,100)
RandomBlock(-1,21,-1,quark:basalt:0,50,159:10,100)
Block(0,21,-1,MAGMA:0)
RandomBlock(1,21,-1,quark:basalt:0,50,159:10,100)
RandomBlock(2,21,-1,quark:basalt:0,50,159:10,100)
RandomBlock(-2,21,0,quark:basalt:0,50,159:10,100)
RandomBlock(-1,21,0,quark:basalt:0,50,159:10,100)
RandomBlock(0,21,0,quark:basalt:0,50,159:10,100)
RandomBlock(1,21,0,quark:basalt:0,50,159:10,100)
RandomBlock(-1,22,-3,quark:basalt:0,50,159:10,100)
RandomBlock(-2,22,-2,quark:basalt:0,50,159:10,100)
Block(-1,22,-2,MAGMA:0)
RandomBlock(0,22,-2,quark:basalt:0,50,159:10,100)
RandomBlock(-3,22,-1,quark:basalt:0,50,159:10,100)
RandomBlock(-1,22,-1,quark:basalt:0,50,159:10,100)
Block(0,22,-1,MAGMA:0)
RandomBlock(1,22,-1,quark:basalt:0,50,159:10,100)
RandomBlock(2,22,-1,quark:basalt:0,50,159:10,100)
RandomBlock(0,22,0,quark:basalt:0,50,159:10,100)
RandomBlock(1,22,0,quark:basalt:0,50,159:10,100)
RandomBlock(-1,23,-3,quark:basalt:0,50,159:10,100)
RandomBlock(-2,23,-2,quark:basalt:0,50,159:10,100)
RandomBlock(0,23,-2,quark:basalt:0,50,159:10,100)
RandomBlock(-1,23,-1,quark:basalt:0,50,159:10,100)
Block(0,23,-1,MAGMA:0)
RandomBlock(1,23,-1,quark:basalt:0,50,159:10,100)
RandomBlock(2,23,-1,quark:basalt:0,50,159:10,100)
RandomBlock(0,23,0,quark:basalt:0,50,159:10,100)
RandomBlock(-2,24,-2,quark:basalt:0,50,159:10,100)
RandomBlock(0,24,-2,quark:basalt:0,50,159:10,100)
RandomBlock(-1,24,-1,quark:basalt:0,50,159:10,100)
Block(0,24,-1,MAGMA:0)
RandomBlock(1,24,-1,quark:basalt:0,50,159:10,100)
RandomBlock(0,24,0,quark:basalt:0,50,159:10,100)
RandomBlock(-2,25,-2,quark:basalt:0,50,159:10,100)
RandomBlock(0,25,-2,quark:basalt:0,50,159:10,100)
RandomBlock(-1,25,-1,quark:basalt:0,50,159:10,100)
RandomBlock(1,25,-1,quark:basalt:0,50,159:10,100)
RandomBlock(0,25,0,quark:basalt:0,50,159:10,100)
RandomBlock(0,26,-2,quark:basalt:0,50,159:10,100)
RandomBlock(-1,26,-1,quark:basalt:0,50,159:10,100)
RandomBlock(1,26,-1,quark:basalt:0,50,159:10,100)
RandomBlock(0,26,0,quark:basalt:0,50,159:10,100)
RandomBlock(0,27,-2,quark:basalt:0,50,159:10,100)
RandomBlock(1,27,-1,quark:basalt:0,50,159:10,100)
RandomBlock(0,27,0,quark:basalt:0,50,159:10,100)
RandomBlock(0,28,-2,quark:basalt:0,50,159:10,100)
RandomBlock(1,28,-1,quark:basalt:0,50,159:10,100)
RandomBlock(0,29,-2,quark:basalt:0,50,159:10,100)

#######################################################################
# +-----------------------------------------------------------------+ #
# |                            BO3 checks                           | #
# +-----------------------------------------------------------------+ #
#######################################################################

# Require a condition at a certain location in order for the BO3 to be spawned.
# BlockCheck(x,y,z,BlockName[,BlockName[,...]]) - one of the blocks must be at the location
# BlockCheckNot(x,y,z,BlockName[,BlockName[,...]]) - all the blocks must not be at the location
# LightCheck(x,y,z,minLightLevel,maxLightLevel) - light must be between min and max (inclusive)

# You can use "Solid" as a BlockName for matching all solid blocks or "All" to match all blocks that aren't air.

# Examples:
#   BlockCheck(0,-1,0,GRASS,DIRT)  Require grass or dirt just below the object
#   BlockCheck(0,-1,0,Solid)       Require any solid block just below the object
#   BlockCheck(0,-1,0,WOOL)        Require any type of wool just below the object
#   BlockCheck(0,-1,0,WOOL:0)      Require white wool just below the object
#   BlockCheckNot(0,-1,0,WOOL:0)   Require that there is no white wool below the object
#   LightCheck(0,0,0,0,1)          Require almost complete darkness just below the object
BlockCheck(0,13,-5,quark:basalt:0)
BlockCheck(-6,13,-1,quark:basalt:0)
BlockCheck(5,13,0,quark:basalt:0)
BlockCheck(1,13,4,quark:basalt:0)

#######################################################################
# +-----------------------------------------------------------------+ #
# |                             Branches                            | #
# +-----------------------------------------------------------------+ #
#######################################################################

# Branches are objects that will spawn when this object spawns when it is used in
# the CustomStructure resource. Branches can also have branches, making complex
# structures possible. See the wiki for more details.

# Regular Branches spawn each branch with an independent chance of spawning.
# Branch(x,y,z,branchName,rotation,chance[,anotherBranchName,rotation,chance[,...]][IndividualChance])
# branchName - name of the object to spawn.
# rotation - NORTH, SOUTH, EAST or WEST.
# IndividualChance - The chance each branch has to spawn, assumed to be 100 when left blank

# Weighted Branches spawn branches with a dependent chance of spawning.
# WeightedBranch(x,y,z,branchName,rotation,chance[,anotherBranchName,rotation,chance[,...]][MaxChanceOutOf])
# MaxChanceOutOf - The chance all branches have to spawn out of, assumed to be 100 when left blank
