
#######################################################################
# +-----------------------------------------------------------------+ #
# |                            BO3 object                           | #
# +-----------------------------------------------------------------+ #
#######################################################################

Author: NLBlackEagle

Description: No description given

Version: 3

SettingsMode: WriteDisable


#######################################################################
# +-----------------------------------------------------------------+ #
# |                          Main settings                          | #
# +-----------------------------------------------------------------+ #
#######################################################################

Tree: false

Frequency: 1

Rarity: 10.0

RotateRandomly: true

SpawnHeight: randomY

SpawnHeightOffset: 0

SpawnHeightVariance: 0

##############################
# Height Limits for the BO3. #
##############################

MinHeight: 5

MaxHeight: 5

######################
# Extrusion settings #
######################

ExtrudeMode: None

ExtrudeThroughBlocks: AIR

MaxBranchDepth: 10

ExcludedBiomes: All


#######################################################################
# +-----------------------------------------------------------------+ #
# |                      Source block settings                      | #
# +-----------------------------------------------------------------+ #
#######################################################################

SourceBlocks: AIR

MaxPercentageOutsideSourceBlock: 100

OutsideSourceBlock: placeAnyway

IsOTGPlus: false

InheritBO3: 

InheritBO3Rotation: NORTH

OverrideChildSettings: true

OverrideParentHeight: false

CanOverride: false

BranchFrequency: 0

BranchFrequencyGroup: 

MustBeBelowOther: false

MustBeInside: 

CannotBeInside: 

ReplacesBO3: 

CanSpawnOnWater: true

SpawnOnWaterOnly: false

SpawnUnderWater: false

SpawnAtWaterLevel: false

HeightOffset: 0

RemoveAir: true

ReplaceAbove: 

ReplaceBelow: 

ReplaceWithBiomeBlocks: true

ReplaceWithGroundBlock: DIRT

ReplaceWithSurfaceBlock: GRASS

SmoothRadius: 0

SmoothHeightOffset: 0

SmoothStartTop: false

SmoothStartWood: false

SmoothingSurfaceBlock: 

SmoothingGroundBlock: 

BO3Group: 

IsSpawnPoint: false


#######################################################################
# +-----------------------------------------------------------------+ #
# |                              Blocks                             | #
# +-----------------------------------------------------------------+ #
#######################################################################

Block(-7,0,-2,STONE)
Block(-6,0,-3,STONE)
Block(-6,0,-2,chisel:basalt2:7)
Block(-6,0,-1,STONE)
Block(-6,0,3,STONE)
Block(-6,1,-3,chisel:basalt2:7)
Block(-6,1,-2,chisel:basalt2:7)
Block(-6,26,-4,STONE)
Block(-6,26,-3,STONE)
Block(-6,26,-2,chisel:basalt2:7)
Block(-6,26,-1,chisel:basalt2:7)
Block(-5,0,-4,STONE)
Block(-5,0,-3,STONE)
Block(-5,0,-2,STONE)
Block(-5,0,-1,STONE)
Block(-5,0,2,STONE)
Block(-5,0,3,STONE)
Block(-5,0,4,STONE)
Block(-5,0,5,STONE)
Block(-5,1,-4,STONE)
Block(-5,1,-3,STONE)
Block(-5,1,-2,chisel:basalt2:7)
Block(-5,1,-1,STONE)
Block(-5,2,-3,STONE)
Block(-5,2,-2,chisel:basalt2:7)
Block(-5,3,-3,chisel:basalt2:7)
Block(-5,3,-2,chisel:basalt2:7)
Block(-5,4,-3,chisel:basalt2:7)
Block(-5,23,-3,chisel:basalt2:7)
Block(-5,24,-3,chisel:basalt2:7)
Block(-5,25,-3,chisel:basalt2:7)
Block(-5,25,-2,chisel:basalt2:7)
Block(-5,26,-5,STONE)
Block(-5,26,-4,chisel:basalt2:7)
Block(-5,26,-3,STONE)
Block(-5,26,-2,chisel:basalt2:7)
Block(-5,26,-1,chisel:basalt2:7)
Block(-5,26,0,chisel:basalt2:7)
Block(-4,0,-5,STONE)
Block(-4,0,-4,STONE)
Block(-4,0,-3,STONE)
Block(-4,0,-2,STONE)
Block(-4,0,-1,STONE)
Block(-4,0,0,STONE)
Block(-4,0,1,STONE)
Block(-4,0,2,STONE)
Block(-4,0,3,STONE)
Block(-4,0,4,STONE)
Block(-4,0,5,STONE)
Block(-4,1,-4,STONE)
Block(-4,1,-3,STONE)
Block(-4,1,-2,STONE)
Block(-4,1,-1,STONE)
Block(-4,1,2,STONE)
Block(-4,1,3,STONE)
Block(-4,2,-4,STONE)
Block(-4,2,-3,STONE)
Block(-4,2,-2,chisel:basalt2:7)
Block(-4,2,-1,chisel:basalt2:7)
Block(-4,3,-4,STONE)
Block(-4,3,-3,STONE)
Block(-4,3,-2,chisel:basalt2:7)
Block(-4,3,-1,STONE)
Block(-4,4,-3,chisel:basalt2:7)
Block(-4,4,-2,STONE)
Block(-4,5,-3,STONE)
Block(-4,5,-2,STONE)
Block(-4,6,-3,STONE)
Block(-4,20,-3,STONE)
Block(-4,21,-3,STONE)
Block(-4,22,-3,chisel:basalt2:7)
Block(-4,23,-4,chisel:basalt2:7)
Block(-4,23,-3,chisel:basalt2:7)
Block(-4,23,-2,STONE)
Block(-4,24,-4,STONE)
Block(-4,24,-3,STONE)
Block(-4,24,-2,STONE)
Block(-4,25,-4,chisel:basalt2:7)
Block(-4,25,-3,STONE)
Block(-4,25,-2,STONE)
Block(-4,25,-1,STONE)
Block(-4,25,0,STONE)
Block(-4,26,-6,chisel:basalt2:7)
Block(-4,26,-5,chisel:basalt2:7)
Block(-4,26,-4,chisel:basalt2:7)
Block(-4,26,-3,chisel:basalt2:7)
Block(-4,26,-2,STONE)
Block(-4,26,-1,STONE)
Block(-4,26,0,STONE)
Block(-4,26,1,STONE)
Block(-4,26,2,STONE)
Block(-4,26,3,chisel:basalt2:7)
Block(-3,0,-6,STONE)
Block(-3,0,-5,chisel:basalt2:7)
Block(-3,0,-4,STONE)
Block(-3,0,-3,STONE)
Block(-3,0,-2,STONE)
Block(-3,0,-1,STONE)
Block(-3,0,0,STONE)
Block(-3,0,1,chisel:basalt2:7)
Block(-3,0,2,STONE)
Block(-3,0,3,STONE)
Block(-3,0,4,STONE)
Block(-3,0,5,STONE)
Block(-3,0,6,STONE)
Block(-3,1,-5,chisel:basalt2:7)
Block(-3,1,-4,chisel:basalt2:7)
Block(-3,1,-3,STONE)
Block(-3,1,-2,STONE)
Block(-3,1,-1,STONE)
Block(-3,1,0,STONE)
Block(-3,1,1,STONE)
Block(-3,1,2,STONE)
Block(-3,1,3,STONE)
Block(-3,1,4,STONE)
Block(-3,2,-5,chisel:basalt2:7)
Block(-3,2,-4,STONE)
Block(-3,2,-3,STONE)
Block(-3,2,-2,STONE)
Block(-3,2,-1,chisel:basalt2:7)
Block(-3,2,2,STONE)
Block(-3,2,3,STONE)
Block(-3,3,-5,chisel:basalt2:7)
Block(-3,3,-4,STONE)
Block(-3,3,-3,STONE)
Block(-3,3,-2,STONE)
Block(-3,3,-1,STONE)
Block(-3,4,-4,STONE)
Block(-3,4,-3,STONE)
Block(-3,4,-2,STONE)
Block(-3,4,-1,STONE)
Block(-3,5,-4,STONE)
Block(-3,5,-3,STONE)
Block(-3,5,-2,STONE)
Block(-3,6,-4,STONE)
Block(-3,6,-3,STONE)
Block(-3,6,-2,STONE)
Block(-3,7,-4,STONE)
Block(-3,7,-3,STONE)
Block(-3,7,-2,STONE)
Block(-3,8,-3,STONE)
Block(-3,8,-2,STONE)
Block(-3,9,-3,STONE)
Block(-3,10,-3,STONE)
Block(-3,11,-3,STONE)
Block(-3,12,-3,chisel:basalt2:7)
Block(-3,13,-3,chisel:basalt2:7)
Block(-3,14,-3,STONE)
Block(-3,15,-3,STONE)
Block(-3,16,-3,chisel:basalt2:7)
Block(-3,17,-3,chisel:basalt2:7)
Block(-3,18,-3,STONE)
Block(-3,19,-3,STONE)
Block(-3,20,-3,STONE)
Block(-3,21,-3,chisel:basalt2:7)
Block(-3,22,-4,STONE)
Block(-3,22,-3,STONE)
Block(-3,22,-2,STONE)
Block(-3,23,-4,STONE)
Block(-3,23,-3,STONE)
Block(-3,23,-2,STONE)
Block(-3,23,-1,STONE)
Block(-3,24,-4,STONE)
Block(-3,24,-3,STONE)
Block(-3,24,-2,STONE)
Block(-3,24,-1,STONE)
Block(-3,24,2,STONE)
Block(-3,25,-5,STONE)
Block(-3,25,-4,STONE)
Block(-3,25,-3,STONE)
Block(-3,25,-2,STONE)
Block(-3,25,-1,STONE)
Block(-3,25,0,STONE)
Block(-3,25,1,STONE)
Block(-3,25,2,chisel:basalt2:7)
Block(-3,25,3,chisel:basalt2:7)
Block(-3,26,-6,chisel:basalt2:7)
Block(-3,26,-5,STONE)
Block(-3,26,-4,chisel:basalt2:7)
Block(-3,26,-3,STONE)
Block(-3,26,-2,STONE)
Block(-3,26,-1,STONE)
Block(-3,26,0,STONE)
Block(-3,26,1,STONE)
Block(-3,26,2,STONE)
Block(-3,26,3,chisel:basalt2:7)
Block(-3,26,4,STONE)
Block(-2,0,-5,STONE)
Block(-2,0,-4,STONE)
Block(-2,0,-3,STONE)
Block(-2,0,-2,STONE)
Block(-2,0,-1,STONE)
Block(-2,0,0,STONE)
Block(-2,0,1,STONE)
Block(-2,0,2,STONE)
Block(-2,0,3,STONE)
Block(-2,0,4,STONE)
Block(-2,0,5,STONE)
Block(-2,1,-5,chisel:basalt2:7)
Block(-2,1,-4,STONE)
Block(-2,1,-3,STONE)
Block(-2,1,-2,STONE)
Block(-2,1,-1,STONE)
Block(-2,1,0,STONE)
Block(-2,1,1,STONE)
Block(-2,1,2,STONE)
Block(-2,1,3,STONE)
Block(-2,1,4,chisel:basalt2:7)
Block(-2,2,-5,STONE)
Block(-2,2,-4,STONE)
Block(-2,2,-3,STONE)
Block(-2,2,-2,chisel:basalt2:7)
Block(-2,2,-1,STONE)
Block(-2,2,1,STONE)
Block(-2,2,2,STONE)
Block(-2,2,3,STONE)
Block(-2,2,4,chisel:basalt2:7)
Block(-2,3,-4,STONE)
Block(-2,3,-3,STONE)
Block(-2,3,-2,STONE)
Block(-2,3,-1,STONE)
Block(-2,3,2,STONE)
Block(-2,3,3,chisel:basalt2:7)
Block(-2,4,-4,STONE)
Block(-2,4,-3,STONE)
Block(-2,4,-2,STONE)
Block(-2,4,2,STONE)
Block(-2,5,-4,STONE)
Block(-2,5,-3,STONE)
Block(-2,5,-2,STONE)
Block(-2,5,2,STONE)
Block(-2,6,-3,STONE)
Block(-2,6,-2,STONE)
Block(-2,6,2,STONE)
Block(-2,7,-3,STONE)
Block(-2,7,2,STONE)
Block(-2,8,-3,STONE)
Block(-2,9,-3,STONE)
Block(-2,10,-3,STONE)
Block(-2,21,2,STONE)
Block(-2,22,2,chisel:basalt2:7)
Block(-2,23,-3,STONE)
Block(-2,23,2,STONE)
Block(-2,24,-4,STONE)
Block(-2,24,-3,STONE)
Block(-2,24,-2,STONE)
Block(-2,24,-1,STONE)
Block(-2,24,1,STONE)
Block(-2,24,2,STONE)
Block(-2,24,3,STONE)
Block(-2,25,-4,STONE)
Block(-2,25,-3,STONE)
Block(-2,25,-2,STONE)
Block(-2,25,-1,STONE)
Block(-2,25,0,STONE)
Block(-2,25,1,STONE)
Block(-2,25,2,STONE)
Block(-2,25,3,chisel:basalt2:7)
Block(-2,25,4,STONE)
Block(-2,26,-5,STONE)
Block(-2,26,-4,STONE)
Block(-2,26,-3,STONE)
Block(-2,26,-2,STONE)
Block(-2,26,-1,STONE)
Block(-2,26,0,STONE)
Block(-2,26,1,STONE)
Block(-2,26,2,STONE)
Block(-2,26,3,STONE)
Block(-2,26,4,STONE)
Block(-2,26,5,STONE)
Block(-1,0,-5,STONE)
Block(-1,0,-4,STONE)
Block(-1,0,-3,STONE)
Block(-1,0,-2,STONE)
Block(-1,0,-1,STONE)
Block(-1,0,0,STONE)
Block(-1,0,1,STONE)
Block(-1,0,2,STONE)
Block(-1,0,3,STONE)
Block(-1,0,4,STONE)
Block(-1,1,-4,STONE)
Block(-1,1,-3,STONE)
Block(-1,1,-2,chisel:basalt2:7)
Block(-1,1,-1,STONE)
Block(-1,1,0,STONE)
Block(-1,1,1,STONE)
Block(-1,1,2,STONE)
Block(-1,1,3,STONE)
Block(-1,1,4,chisel:basalt2:7)
Block(-1,2,-4,STONE)
Block(-1,2,-3,chisel:basalt2:7)
Block(-1,2,-2,chisel:basalt2:7)
Block(-1,2,-1,chisel:basalt2:7)
Block(-1,2,1,STONE)
Block(-1,2,2,STONE)
Block(-1,2,3,STONE)
Block(-1,3,-4,STONE)
Block(-1,3,-2,chisel:basalt2:7)
Block(-1,3,1,STONE)
Block(-1,3,2,chisel:basalt2:7)
Block(-1,3,3,chisel:basalt2:7)
Block(-1,4,2,chisel:basalt2:7)
Block(-1,4,3,chisel:basalt2:7)
Block(-1,5,2,STONE)
Block(-1,5,3,chisel:basalt2:7)
Block(-1,6,2,STONE)
Block(-1,6,3,STONE)
Block(-1,7,2,STONE)
Block(-1,8,2,STONE)
Block(-1,9,2,STONE)
Block(-1,10,2,STONE)
Block(-1,11,2,STONE)
Block(-1,16,2,chisel:basalt2:7)
Block(-1,17,2,STONE)
Block(-1,18,2,STONE)
Block(-1,19,2,STONE)
Block(-1,20,2,STONE)
Block(-1,21,2,STONE)
Block(-1,22,1,STONE)
Block(-1,22,2,STONE)
Block(-1,23,0,STONE)
Block(-1,23,1,STONE)
Block(-1,23,2,STONE)
Block(-1,23,3,STONE)
Block(-1,24,0,chisel:basalt2:7)
Block(-1,24,1,STONE)
Block(-1,24,2,STONE)
Block(-1,24,3,STONE)
Block(-1,24,4,STONE)
Block(-1,25,-1,STONE)
Block(-1,25,0,chisel:basalt2:7)
Block(-1,25,1,STONE)
Block(-1,25,2,STONE)
Block(-1,25,3,STONE)
Block(-1,25,4,STONE)
Block(-1,26,-4,STONE)
Block(-1,26,-3,STONE)
Block(-1,26,-2,STONE)
Block(-1,26,-1,STONE)
Block(-1,26,0,STONE)
Block(-1,26,1,STONE)
Block(-1,26,2,STONE)
Block(-1,26,3,STONE)
Block(-1,26,4,STONE)
Block(-1,26,5,STONE)
B(0,0,-4,STONE)
B(0,0,-3,STONE)
B(0,0,-2,STONE)
B(0,0,-1,STONE)
B(0,0,0,STONE)
B(0,0,1,chisel:basalt2:7)
B(0,0,2,STONE)
B(0,0,3,STONE)
B(0,0,4,chisel:basalt2:7)
B(0,1,-4,STONE)
B(0,1,-3,STONE)
B(0,1,-2,STONE)
B(0,1,-1,STONE)
B(0,1,0,chisel:basalt2:7)
B(0,1,1,chisel:basalt2:7)
B(0,1,2,chisel:basalt2:7)
B(0,1,3,chisel:basalt2:7)
B(0,1,4,chisel:basalt2:7)
B(0,2,-1,STONE)
B(0,2,2,chisel:basalt2:7)
B(0,2,3,STONE)
B(0,3,-1,STONE)
B(0,3,2,chisel:basalt2:7)
B(0,3,3,chisel:basalt2:7)
B(0,4,2,chisel:basalt2:7)
B(0,24,-2,STONE)
B(0,24,2,STONE)
B(0,25,-2,STONE)
B(0,25,-1,STONE)
B(0,25,0,STONE)
B(0,25,1,STONE)
B(0,25,2,STONE)
B(0,25,3,STONE)
B(0,25,4,STONE)
B(0,26,-4,STONE)
B(0,26,-3,STONE)
B(0,26,-2,STONE)
B(0,26,-1,STONE)
B(0,26,0,STONE)
B(0,26,1,STONE)
B(0,26,2,STONE)
B(0,26,3,chisel:basalt2:7)
B(0,26,4,STONE)
B(1,0,-4,STONE)
B(1,0,-3,STONE)
B(1,0,-2,STONE)
B(1,0,-1,STONE)
B(1,0,0,STONE)
B(1,0,1,chisel:basalt2:7)
B(1,0,2,STONE)
B(1,0,3,STONE)
B(1,0,4,STONE)
B(1,0,5,chisel:basalt2:7)
B(1,1,-3,STONE)
B(1,1,-2,STONE)
B(1,1,-1,STONE)
B(1,1,0,chisel:basalt2:7)
B(1,1,1,chisel:basalt2:7)
B(1,1,2,chisel:basalt2:7)
B(1,1,3,STONE)
B(1,1,4,chisel:basalt2:7)
B(1,2,-2,STONE)
B(1,2,-1,STONE)
B(1,2,0,STONE)
B(1,2,3,STONE)
B(1,3,-2,chisel:basalt2:7)
B(1,3,-1,chisel:basalt2:7)
B(1,4,-1,chisel:basalt2:7)
B(1,5,-1,chisel:basalt2:7)
B(1,6,-1,chisel:basalt2:7)
B(1,20,-1,STONE)
B(1,21,-1,STONE)
B(1,22,-1,STONE)
B(1,23,-2,STONE)
B(1,23,-1,STONE)
B(1,24,-3,STONE)
B(1,24,-2,STONE)
B(1,24,-1,STONE)
B(1,24,0,STONE)
B(1,25,-3,STONE)
B(1,25,-2,STONE)
B(1,25,-1,STONE)
B(1,25,0,STONE)
B(1,25,1,chisel:basalt2:7)
B(1,26,-4,STONE)
B(1,26,-3,STONE)
B(1,26,-2,STONE)
B(1,26,-1,STONE)
B(1,26,0,STONE)
B(1,26,1,STONE)
B(1,26,2,chisel:basalt2:7)
B(1,26,3,chisel:basalt2:7)
B(2,0,-3,chisel:basalt2:7)
B(2,0,-2,STONE)
B(2,0,-1,STONE)
B(2,0,0,STONE)
B(2,0,1,chisel:basalt2:7)
B(2,0,2,STONE)
B(2,0,3,STONE)
B(2,0,4,chisel:basalt2:7)
B(2,0,5,chisel:basalt2:7)
B(2,0,6,chisel:basalt2:7)
B(2,1,-3,chisel:basalt2:7)
B(2,1,-2,chisel:basalt2:7)
B(2,1,-1,STONE)
B(2,1,0,chisel:basalt2:7)
B(2,1,2,STONE)
B(2,1,3,STONE)
B(2,1,4,STONE)
B(2,1,5,chisel:basalt2:7)
B(2,2,-2,chisel:basalt2:7)
B(2,2,-1,STONE)
B(2,2,0,STONE)
B(2,2,4,STONE)
B(2,3,-2,chisel:basalt2:7)
B(2,3,-1,chisel:basalt2:7)
B(2,3,0,STONE)
B(2,3,4,STONE)
B(2,4,-2,chisel:basalt2:7)
B(2,4,-1,chisel:basalt2:7)
B(2,4,0,STONE)
B(2,5,-2,STONE)
B(2,5,-1,STONE)
B(2,6,-2,STONE)
B(2,6,-1,chisel:basalt2:7)
B(2,7,-2,chisel:basalt2:7)
B(2,7,-1,STONE)
B(2,8,-2,chisel:basalt2:7)
B(2,8,-1,chisel:basalt2:7)
B(2,9,-2,chisel:basalt2:7)
B(2,9,-1,chisel:basalt2:7)
B(2,10,-1,chisel:basalt2:7)
B(2,11,-1,chisel:basalt2:7)
B(2,12,-1,STONE)
B(2,13,-1,STONE)
B(2,14,-1,STONE)
B(2,15,-1,STONE)
B(2,16,-1,chisel:basalt2:7)
B(2,17,-1,chisel:basalt2:7)
B(2,18,-1,chisel:basalt2:7)
B(2,19,-2,chisel:basalt2:7)
B(2,19,-1,chisel:basalt2:7)
B(2,20,-2,STONE)
B(2,20,-1,STONE)
B(2,21,-2,STONE)
B(2,21,-1,STONE)
B(2,22,-2,STONE)
B(2,22,-1,STONE)
B(2,22,0,chisel:basalt2:7)
B(2,23,-2,STONE)
B(2,23,-1,chisel:basalt2:7)
B(2,23,0,chisel:basalt2:7)
B(2,24,-3,STONE)
B(2,24,-2,STONE)
B(2,24,-1,STONE)
B(2,24,0,STONE)
B(2,24,1,STONE)
B(2,25,-3,STONE)
B(2,25,-2,STONE)
B(2,25,-1,STONE)
B(2,25,0,STONE)
B(2,25,1,STONE)
B(2,26,-4,STONE)
B(2,26,-3,STONE)
B(2,26,-2,STONE)
B(2,26,-1,STONE)
B(2,26,0,STONE)
B(2,26,1,chisel:basalt2:7)
B(2,26,2,chisel:basalt2:7)
B(3,0,-3,STONE)
B(3,0,-2,STONE)
B(3,0,-1,STONE)
B(3,0,0,chisel:basalt2:7)
B(3,0,1,chisel:basalt2:7)
B(3,0,2,chisel:basalt2:7)
B(3,0,3,STONE)
B(3,0,4,STONE)
B(3,0,5,chisel:basalt2:7)
B(3,0,6,STONE)
B(3,1,-2,chisel:basalt2:7)
B(3,1,-1,chisel:basalt2:7)
B(3,1,0,chisel:basalt2:7)
B(3,1,3,chisel:basalt2:7)
B(3,1,4,STONE)
B(3,1,5,STONE)
B(3,2,-2,chisel:basalt2:7)
B(3,2,-1,chisel:basalt2:7)
B(3,2,3,STONE)
B(3,2,4,STONE)
B(3,2,5,STONE)
B(3,3,-1,STONE)
B(3,3,3,STONE)
B(3,3,4,STONE)
B(3,3,5,STONE)
B(3,4,3,STONE)
B(3,4,4,STONE)
B(3,5,4,STONE)
B(3,6,4,STONE)
B(3,7,4,STONE)
B(3,20,-1,STONE)
B(3,21,-1,STONE)
B(3,22,-1,STONE)
B(3,23,-2,chisel:basalt2:7)
B(3,23,-1,STONE)
B(3,23,0,chisel:basalt2:7)
B(3,24,-2,STONE)
B(3,24,-1,STONE)
B(3,24,0,STONE)
B(3,25,-3,STONE)
B(3,25,-2,STONE)
B(3,25,-1,STONE)
B(3,25,0,STONE)
B(3,26,-3,STONE)
B(3,26,-2,STONE)
B(3,26,-1,STONE)
B(3,26,0,STONE)
B(3,26,1,STONE)
B(4,0,-2,STONE)
B(4,0,-1,STONE)
B(4,0,0,STONE)
B(4,0,3,chisel:basalt2:7)
B(4,0,4,STONE)
B(4,0,5,STONE)
B(4,1,3,chisel:basalt2:7)
B(4,1,4,chisel:basalt2:7)
B(4,1,5,STONE)
B(4,2,4,STONE)
B(4,24,-1,STONE)
B(4,25,-2,STONE)
B(4,25,-1,STONE)
B(4,26,-3,STONE)
B(4,26,-2,STONE)
B(4,26,-1,chisel:basalt2:7)
B(4,26,0,STONE)
B(5,0,-2,STONE)
B(5,0,4,chisel:basalt2:7)
B(5,0,5,STONE)
B(5,1,4,chisel:basalt2:7)
B(5,26,-2,chisel:basalt2:7)
B(5,26,-1,chisel:basalt2:7)

#######################################################################
# +-----------------------------------------------------------------+ #
# |                            BO3 checks                           | #
# +-----------------------------------------------------------------+ #
#######################################################################


#######################################################################
# +-----------------------------------------------------------------+ #
# |                             Branches                            | #
# +-----------------------------------------------------------------+ #
#######################################################################


#######################################################################
# +-----------------------------------------------------------------+ #
# |                             Entities                            | #
# +-----------------------------------------------------------------+ #
#######################################################################


#######################################################################
# +-----------------------------------------------------------------+ #
# |                            Particles                            | #
# +-----------------------------------------------------------------+ #
#######################################################################


#######################################################################
# +-----------------------------------------------------------------+ #
# |                             Spawners                            | #
# +-----------------------------------------------------------------+ #
#######################################################################


#######################################################################
# +-----------------------------------------------------------------+ #
# |                             ModData                             | #
# +-----------------------------------------------------------------+ #
#######################################################################
