
#######################################################################
# +-----------------------------------------------------------------+ #
# |                            BO3 object                           | #
# +-----------------------------------------------------------------+ #
#######################################################################

Author: NLBlackEagle

Description: No description given

Version: 3

SettingsMode: WriteDisable


#######################################################################
# +-----------------------------------------------------------------+ #
# |                          Main settings                          | #
# +-----------------------------------------------------------------+ #
#######################################################################

Tree: false

Frequency: 4

Rarity: 10.0

RotateRandomly: true

SpawnHeight: randomY

SpawnHeightOffset: 0

SpawnHeightVariance: 0

##############################
# Height Limits for the BO3. #
##############################

MinHeight: 5

MaxHeight: 5

######################
# Extrusion settings #
######################

ExtrudeMode: None

ExtrudeThroughBlocks: AIR

MaxBranchDepth: 10

ExcludedBiomes: All


#######################################################################
# +-----------------------------------------------------------------+ #
# |                      Source block settings                      | #
# +-----------------------------------------------------------------+ #
#######################################################################

SourceBlocks: AIR

MaxPercentageOutsideSourceBlock: 100

OutsideSourceBlock: placeAnyway

IsOTGPlus: false

InheritBO3: 

InheritBO3Rotation: NORTH

OverrideChildSettings: true

OverrideParentHeight: false

CanOverride: false

BranchFrequency: 0

BranchFrequencyGroup: 

MustBeBelowOther: false

MustBeInside: 

CannotBeInside: 

ReplacesBO3: 

CanSpawnOnWater: true

SpawnOnWaterOnly: false

SpawnUnderWater: false

SpawnAtWaterLevel: false

HeightOffset: 0

RemoveAir: true

ReplaceAbove: 

ReplaceBelow: 

ReplaceWithBiomeBlocks: true

ReplaceWithGroundBlock: DIRT

ReplaceWithSurfaceBlock: GRASS

SmoothRadius: 0

SmoothHeightOffset: 0

SmoothStartTop: false

SmoothStartWood: false

SmoothingSurfaceBlock: 

SmoothingGroundBlock: 

BO3Group: 

IsSpawnPoint: false


#######################################################################
# +-----------------------------------------------------------------+ #
# |                              Blocks                             | #
# +-----------------------------------------------------------------+ #
#######################################################################

Block(-14,24,4,Leaves:7)
Block(-13,0,-3,STONE)
Block(-13,0,-2,STONE)
Block(-13,0,-1,STONE)
Block(-13,0,0,STONE)
Block(-13,0,1,STONE)
Block(-13,0,2,STONE)
Block(-13,0,3,STONE)
Block(-13,0,4,STONE)
Block(-13,23,1,quark:basalt:0)
Block(-13,23,2,STONE)
Block(-13,23,3,STONE)
Block(-13,23,4,STONE)
Block(-13,24,-6,STONE)
Block(-13,24,1,quark:basalt:0)
Block(-13,24,2,STONE)
Block(-13,24,3,STONE)
Block(-13,24,4,STONE)
Block(-13,24,5,Leaves:7)
Block(-13,25,-6,STONE)
Block(-13,25,-5,STONE)
Block(-13,25,-4,STONE)
Block(-13,25,-3,STONE)
Block(-13,25,-2,STONE)
Block(-13,25,-1,STONE)
Block(-13,25,0,quark:basalt:0)
Block(-13,25,1,quark:basalt:0)
Block(-13,25,2,quark:basalt:0)
Block(-13,25,3,STONE)
Block(-13,25,4,STONE)
Block(-13,25,5,STONE)
Block(-13,25,6,quark:basalt:0)
Block(-13,26,-6,STONE)
Block(-13,26,-5,STONE)
Block(-13,26,-3,STONE)
Block(-13,26,-1,STONE)
Block(-13,26,0,STONE)
Block(-13,26,1,quark:basalt:0)
Block(-13,26,2,quark:basalt:0)
Block(-13,26,3,STONE)
Block(-13,26,4,STONE)
Block(-13,26,5,STONE)
Block(-13,27,-5,STONE)
Block(-13,27,-3,STONE)
Block(-13,27,-1,STONE)
Block(-13,27,0,STONE)
Block(-13,27,1,quark:basalt:0)
Block(-13,27,3,STONE)
Block(-13,27,4,STONE)
Block(-12,0,-5,STONE)
Block(-12,0,-4,STONE)
Block(-12,0,-3,STONE)
Block(-12,0,-2,STONE)
Block(-12,0,-1,STONE)
Block(-12,0,0,STONE)
Block(-12,0,1,STONE)
Block(-12,0,2,STONE)
Block(-12,0,3,STONE)
Block(-12,0,4,STONE)
Block(-12,0,5,STONE)
Block(-12,0,6,STONE)
Block(-12,1,0,STONE)
Block(-12,1,1,STONE)
Block(-12,1,2,STONE)
Block(-12,1,3,STONE)
Block(-12,2,8,Leaves:7)
Block(-12,22,0,quark:basalt:0)
Block(-12,22,1,STONE)
Block(-12,22,2,STONE)
Block(-12,22,3,STONE)
Block(-12,22,4,STONE)
Block(-12,23,-7,STONE)
Block(-12,23,-6,STONE)
Block(-12,23,-5,STONE)
Block(-12,23,-2,STONE)
Block(-12,23,0,quark:basalt:0)
Block(-12,23,1,quark:basalt:0)
Block(-12,23,2,STONE)
Block(-12,23,3,STONE)
Block(-12,23,4,STONE)
Block(-12,23,6,quark:basalt:0)
Block(-12,24,-7,STONE)
Block(-12,24,-6,STONE)
Block(-12,24,-5,STONE)
Block(-12,24,-4,STONE)
Block(-12,24,-3,STONE)
Block(-12,24,-2,STONE)
Block(-12,24,-1,STONE)
Block(-12,24,0,quark:basalt:0)
Block(-12,24,1,quark:basalt:0)
Block(-12,24,2,quark:basalt:0)
Block(-12,24,3,STONE)
Block(-12,24,4,STONE)
Block(-12,24,5,STONE)
Block(-12,24,6,quark:basalt:0)
Block(-12,24,7,quark:basalt:0)
Block(-12,24,8,STONE)
Block(-12,25,-6,STONE)
Block(-12,25,-5,STONE)
Block(-12,25,-4,STONE)
Block(-12,25,-3,STONE)
Block(-12,25,-2,STONE)
Block(-12,25,-1,STONE)
Block(-12,25,0,STONE)
Block(-12,25,1,quark:basalt:0)
Block(-12,25,2,quark:basalt:0)
Block(-12,25,3,STONE)
Block(-12,25,4,STONE)
Block(-12,25,5,quark:basalt:0)
Block(-12,25,6,quark:basalt:0)
Block(-12,25,7,quark:basalt:0)
Block(-12,26,-7,STONE)
Block(-12,26,-6,STONE)
Block(-12,26,-5,STONE)
Block(-12,26,-4,STONE)
Block(-12,26,-3,STONE)
Block(-12,26,-2,STONE)
Block(-12,26,-1,STONE)
Block(-12,26,0,STONE)
Block(-12,26,1,quark:basalt:0)
Block(-12,26,2,quark:basalt:0)
Block(-12,26,3,STONE)
Block(-12,26,4,STONE)
Block(-12,26,5,STONE)
Block(-12,26,6,quark:basalt:0)
Block(-12,26,7,STONE)
Block(-12,27,-6,STONE)
Block(-12,27,-5,STONE)
Block(-12,27,-4,STONE)
Block(-12,27,-3,STONE)
Block(-12,27,-2,STONE)
Block(-12,27,-1,STONE)
Block(-12,27,0,STONE)
Block(-12,27,1,STONE)
Block(-12,27,2,quark:basalt:0)
Block(-12,27,3,STONE)
Block(-12,27,4,STONE)
Block(-12,27,5,STONE)
Block(-12,27,6,STONE)
Block(-11,0,-7,quark:basalt:0)
Block(-11,0,-6,STONE)
Block(-11,0,-5,STONE)
Block(-11,0,-4,STONE)
Block(-11,0,-3,STONE)
Block(-11,0,-2,STONE)
Block(-11,0,-1,STONE)
Block(-11,0,0,STONE)
Block(-11,0,1,STONE)
Block(-11,0,2,STONE)
Block(-11,0,3,STONE)
Block(-11,0,4,STONE)
Block(-11,0,5,STONE)
Block(-11,0,6,quark:basalt:0)
Block(-11,0,7,quark:basalt:0)
Block(-11,0,8,quark:basalt:0)
Block(-11,0,9,quark:basalt:0)
Block(-11,1,-4,STONE)
Block(-11,1,-3,STONE)
Block(-11,1,-2,STONE)
Block(-11,1,-1,STONE)
Block(-11,1,0,STONE)
Block(-11,1,1,STONE)
Block(-11,1,2,STONE)
Block(-11,1,3,STONE)
Block(-11,1,4,STONE)
Block(-11,1,5,STONE)
Block(-11,1,7,STONE)
Block(-11,1,8,STONE)
Block(-11,1,9,STONE)
Block(-11,2,-4,STONE)
Block(-11,2,-3,STONE)
Block(-11,2,-1,STONE)
Block(-11,2,0,STONE)
Block(-11,2,1,STONE)
Block(-11,2,2,STONE)
Block(-11,2,3,STONE)
Block(-11,2,4,STONE)
Block(-11,2,7,Leaves:7)
Block(-11,2,8,STONE)
Block(-11,2,9,Leaves:7)
Block(-11,3,0,STONE)
Block(-11,3,3,STONE)
Block(-11,3,8,Leaves:7)
Block(-11,21,3,Leaves:7)
Block(-11,21,4,Leaves:7)
Block(-11,22,-4,STONE)
Block(-11,22,-1,quark:basalt:0)
Block(-11,22,0,quark:basalt:0)
Block(-11,22,1,STONE)
Block(-11,22,2,STONE)
Block(-11,22,3,STONE)
Block(-11,22,4,STONE)
Block(-11,22,5,quark:basalt:0)
Block(-11,23,-6,STONE)
Block(-11,23,-5,STONE)
Block(-11,23,-4,STONE)
Block(-11,23,-3,STONE)
Block(-11,23,-2,STONE)
Block(-11,23,-1,STONE)
Block(-11,23,0,quark:basalt:0)
Block(-11,23,1,STONE)
Block(-11,23,2,STONE)
Block(-11,23,3,STONE)
Block(-11,23,4,quark:basalt:0)
Block(-11,23,5,quark:basalt:0)
Block(-11,23,6,quark:basalt:0)
Block(-11,23,7,quark:basalt:0)
Block(-11,24,-9,STONE)
Block(-11,24,-8,STONE)
Block(-11,24,-7,STONE)
Block(-11,24,-6,STONE)
Block(-11,24,-5,STONE)
Block(-11,24,-4,STONE)
Block(-11,24,-3,STONE)
Block(-11,24,-2,STONE)
Block(-11,24,-1,STONE)
Block(-11,24,0,STONE)
Block(-11,24,1,STONE)
Block(-11,24,2,STONE)
Block(-11,24,3,STONE)
Block(-11,24,4,quark:basalt:0)
Block(-11,24,5,STONE)
Block(-11,24,6,quark:basalt:0)
Block(-11,24,7,STONE)
Block(-11,24,8,STONE)
Block(-11,24,9,STONE)
Block(-11,25,-10,STONE)
Block(-11,25,-9,STONE)
Block(-11,25,-8,STONE)
Block(-11,25,-7,STONE)
Block(-11,25,-6,STONE)
Block(-11,25,-5,STONE)
Block(-11,25,-4,STONE)
Block(-11,25,-3,STONE)
Block(-11,25,-2,STONE)
Block(-11,25,-1,STONE)
Block(-11,25,0,STONE)
Block(-11,25,1,STONE)
Block(-11,25,2,STONE)
Block(-11,25,3,STONE)
Block(-11,25,4,STONE)
Block(-11,25,5,STONE)
Block(-11,25,6,STONE)
Block(-11,25,7,STONE)
Block(-11,25,8,STONE)
Block(-11,26,-10,STONE)
Block(-11,26,-9,STONE)
Block(-11,26,-8,STONE)
Block(-11,26,-7,STONE)
Block(-11,26,-6,STONE)
Block(-11,26,-5,STONE)
Block(-11,26,-4,STONE)
Block(-11,26,-3,STONE)
Block(-11,26,-2,STONE)
Block(-11,26,-1,STONE)
Block(-11,26,0,STONE)
Block(-11,26,1,STONE)
Block(-11,26,2,STONE)
Block(-11,26,3,STONE)
Block(-11,26,4,STONE)
Block(-11,26,5,STONE)
Block(-11,26,6,STONE)
Block(-11,26,7,STONE)
Block(-11,26,8,STONE)
Block(-11,27,-8,STONE)
Block(-11,27,-7,STONE)
Block(-11,27,-6,STONE)
Block(-11,27,-5,STONE)
Block(-11,27,-4,STONE)
Block(-11,27,-3,STONE)
Block(-11,27,-2,STONE)
Block(-11,27,-1,STONE)
Block(-11,27,0,STONE)
Block(-11,27,1,STONE)
Block(-11,27,2,STONE)
Block(-11,27,3,STONE)
Block(-11,27,4,STONE)
Block(-11,27,5,STONE)
Block(-11,27,6,STONE)
Block(-11,27,7,STONE)
Block(-11,27,8,STONE)
Block(-10,0,-9,Leaves:7)
Block(-10,0,-8,STONE)
Block(-10,0,-7,quark:basalt:0)
Block(-10,0,-6,quark:basalt:0)
Block(-10,0,-5,STONE)
Block(-10,0,-4,STONE)
Block(-10,0,-3,STONE)
Block(-10,0,-2,STONE)
Block(-10,0,-1,STONE)
Block(-10,0,0,STONE)
Block(-10,0,1,STONE)
Block(-10,0,2,STONE)
Block(-10,0,3,STONE)
Block(-10,0,4,STONE)
Block(-10,0,5,STONE)
Block(-10,0,6,STONE)
Block(-10,0,7,quark:basalt:0)
Block(-10,0,8,quark:basalt:0)
Block(-10,0,9,quark:basalt:0)
Block(-10,1,-7,quark:basalt:0)
Block(-10,1,-6,quark:basalt:0)
Block(-10,1,-5,STONE)
Block(-10,1,-4,STONE)
Block(-10,1,-3,STONE)
Block(-10,1,-2,STONE)
Block(-10,1,-1,STONE)
Block(-10,1,0,STONE)
Block(-10,1,1,STONE)
Block(-10,1,2,STONE)
Block(-10,1,3,STONE)
Block(-10,1,4,STONE)
Block(-10,1,5,STONE)
Block(-10,1,6,quark:basalt:0)
Block(-10,1,7,quark:basalt:0)
Block(-10,1,8,STONE)
Block(-10,1,9,quark:basalt:0)
Block(-10,2,-6,quark:basalt:0)
Block(-10,2,-5,STONE)
Block(-10,2,-4,STONE)
Block(-10,2,-3,STONE)
Block(-10,2,-2,STONE)
Block(-10,2,-1,STONE)
Block(-10,2,0,STONE)
Block(-10,2,1,STONE)
Block(-10,2,2,STONE)
Block(-10,2,3,STONE)
Block(-10,2,4,STONE)
Block(-10,2,5,quark:basalt:0)
Block(-10,2,7,STONE)
Block(-10,2,8,STONE)
Block(-10,2,9,STONE)
Block(-10,3,-4,STONE)
Block(-10,3,-3,STONE)
Block(-10,3,-2,STONE)
Block(-10,3,-1,STONE)
Block(-10,3,0,STONE)
Block(-10,3,1,STONE)
Block(-10,3,2,STONE)
Block(-10,3,3,STONE)
Block(-10,3,4,STONE)
Block(-10,3,5,quark:basalt:0)
Block(-10,3,6,quark:basalt:0)
Block(-10,3,7,quark:basalt:0)
Block(-10,3,8,STONE)
Block(-10,4,-2,STONE)
Block(-10,4,-1,STONE)
Block(-10,4,0,STONE)
Block(-10,4,1,STONE)
Block(-10,4,2,STONE)
Block(-10,4,3,STONE)
Block(-10,4,7,STONE)
Block(-10,4,8,Leaves:7)
Block(-10,5,0,STONE)
Block(-10,5,1,STONE)
Block(-10,20,3,Leaves:7)
Block(-10,21,-1,quark:basalt:0)
Block(-10,21,0,quark:basalt:0)
Block(-10,21,1,STONE)
Block(-10,21,2,STONE)
Block(-10,21,3,STONE)
Block(-10,21,4,quark:basalt:0)
Block(-10,22,-5,STONE)
Block(-10,22,-4,STONE)
Block(-10,22,-2,STONE)
Block(-10,22,-1,quark:basalt:0)
Block(-10,22,0,quark:basalt:0)
Block(-10,22,1,STONE)
Block(-10,22,2,STONE)
Block(-10,22,3,STONE)
Block(-10,22,4,quark:basalt:0)
Block(-10,23,-7,STONE)
Block(-10,23,-6,STONE)
Block(-10,23,-5,STONE)
Block(-10,23,-4,STONE)
Block(-10,23,-3,STONE)
Block(-10,23,-2,STONE)
Block(-10,23,-1,STONE)
Block(-10,23,0,STONE)
Block(-10,23,1,STONE)
Block(-10,23,2,STONE)
Block(-10,23,3,quark:basalt:0)
Block(-10,23,4,STONE)
Block(-10,23,5,quark:basalt:0)
Block(-10,23,6,STONE)
Block(-10,23,7,STONE)
Block(-10,24,-11,STONE)
Block(-10,24,-10,STONE)
Block(-10,24,-9,STONE)
Block(-10,24,-8,STONE)
Block(-10,24,-7,STONE)
Block(-10,24,-6,STONE)
Block(-10,24,-5,STONE)
Block(-10,24,-4,STONE)
Block(-10,24,-3,STONE)
Block(-10,24,-2,STONE)
Block(-10,24,-1,STONE)
Block(-10,24,0,STONE)
Block(-10,24,1,STONE)
Block(-10,24,2,STONE)
Block(-10,24,3,STONE)
Block(-10,24,4,STONE)
Block(-10,24,5,STONE)
Block(-10,24,6,STONE)
Block(-10,24,7,STONE)
Block(-10,24,8,STONE)
Block(-10,24,9,STONE)
Block(-10,24,10,STONE)
Block(-10,25,-11,STONE)
Block(-10,25,-10,STONE)
Block(-10,25,-9,STONE)
Block(-10,25,-8,STONE)
Block(-10,25,-7,STONE)
Block(-10,25,-6,STONE)
Block(-10,25,-5,STONE)
Block(-10,25,-4,STONE)
Block(-10,25,-3,STONE)
Block(-10,25,-2,STONE)
Block(-10,25,-1,STONE)
Block(-10,25,0,STONE)
Block(-10,25,1,STONE)
Block(-10,25,2,STONE)
Block(-10,25,3,STONE)
Block(-10,25,4,STONE)
Block(-10,25,5,STONE)
Block(-10,25,6,STONE)
Block(-10,25,7,STONE)
Block(-10,25,8,STONE)
Block(-10,25,9,STONE)
Block(-10,26,-10,STONE)
Block(-10,26,-9,STONE)
Block(-10,26,-8,STONE)
Block(-10,26,-7,STONE)
Block(-10,26,-6,STONE)
Block(-10,26,-5,STONE)
Block(-10,26,-4,STONE)
Block(-10,26,-3,STONE)
Block(-10,26,-2,STONE)
Block(-10,26,-1,STONE)
Block(-10,26,0,STONE)
Block(-10,26,1,STONE)
Block(-10,26,2,STONE)
Block(-10,26,3,STONE)
Block(-10,26,4,STONE)
Block(-10,26,5,STONE)
Block(-10,26,6,STONE)
Block(-10,26,7,STONE)
Block(-10,26,8,STONE)
Block(-10,26,9,STONE)
Block(-10,27,-9,STONE)
Block(-10,27,-8,STONE)
Block(-10,27,-7,STONE)
Block(-10,27,-6,STONE)
Block(-10,27,-5,STONE)
Block(-10,27,-4,STONE)
Block(-10,27,-3,STONE)
Block(-10,27,-2,STONE)
Block(-10,27,-1,STONE)
Block(-10,27,0,STONE)
Block(-10,27,1,STONE)
Block(-10,27,2,STONE)
Block(-10,27,3,STONE)
Block(-10,27,4,STONE)
Block(-10,27,5,STONE)
Block(-10,27,6,STONE)
Block(-10,27,7,STONE)
Block(-10,27,8,STONE)
Block(-9,0,-9,STONE)
Block(-9,0,-8,STONE)
Block(-9,0,-7,quark:basalt:0)
Block(-9,0,-6,STONE)
Block(-9,0,-5,STONE)
Block(-9,0,-4,STONE)
Block(-9,0,-3,STONE)
Block(-9,0,-2,STONE)
Block(-9,0,-1,STONE)
Block(-9,0,0,STONE)
Block(-9,0,1,STONE)
Block(-9,0,2,STONE)
Block(-9,0,3,STONE)
Block(-9,0,4,STONE)
Block(-9,0,5,STONE)
Block(-9,0,6,STONE)
Block(-9,0,7,STONE)
Block(-9,0,8,quark:basalt:0)
Block(-9,0,9,quark:basalt:0)
Block(-9,0,10,quark:basalt:0)
Block(-9,1,-9,STONE)
Block(-9,1,-8,STONE)
Block(-9,1,-7,quark:basalt:0)
Block(-9,1,-6,quark:basalt:0)
Block(-9,1,-5,STONE)
Block(-9,1,-4,STONE)
Block(-9,1,-3,STONE)
Block(-9,1,-2,STONE)
Block(-9,1,-1,STONE)
Block(-9,1,0,STONE)
Block(-9,1,1,STONE)
Block(-9,1,2,STONE)
Block(-9,1,3,STONE)
Block(-9,1,4,STONE)
Block(-9,1,5,STONE)
Block(-9,1,6,STONE)
Block(-9,1,7,quark:basalt:0)
Block(-9,1,8,quark:basalt:0)
Block(-9,1,9,quark:basalt:0)
Block(-9,2,-9,Leaves:7)
Block(-9,2,-8,STONE)
Block(-9,2,-7,quark:basalt:0)
Block(-9,2,-6,STONE)
Block(-9,2,-5,STONE)
Block(-9,2,-4,STONE)
Block(-9,2,-3,STONE)
Block(-9,2,-2,STONE)
Block(-9,2,-1,STONE)
Block(-9,2,0,STONE)
Block(-9,2,1,STONE)
Block(-9,2,2,STONE)
Block(-9,2,3,STONE)
Block(-9,2,4,STONE)
Block(-9,2,5,STONE)
Block(-9,2,6,quark:basalt:0)
Block(-9,2,7,quark:basalt:0)
Block(-9,2,8,quark:basalt:0)
Block(-9,3,-9,Leaves:7)
Block(-9,3,-8,Leaves:7)
Block(-9,3,-6,quark:basalt:0)
Block(-9,3,-5,STONE)
Block(-9,3,-4,STONE)
Block(-9,3,-3,STONE)
Block(-9,3,-2,STONE)
Block(-9,3,-1,STONE)
Block(-9,3,0,STONE)
Block(-9,3,1,STONE)
Block(-9,3,2,STONE)
Block(-9,3,3,STONE)
Block(-9,3,4,STONE)
Block(-9,3,5,quark:basalt:0)
Block(-9,3,6,quark:basalt:0)
Block(-9,3,7,STONE)
Block(-9,3,8,STONE)
Block(-9,4,-4,STONE)
Block(-9,4,-3,STONE)
Block(-9,4,-2,STONE)
Block(-9,4,-1,STONE)
Block(-9,4,0,STONE)
Block(-9,4,1,STONE)
Block(-9,4,2,STONE)
Block(-9,4,3,STONE)
Block(-9,4,4,STONE)
Block(-9,4,6,STONE)
Block(-9,4,7,STONE)
Block(-9,4,8,STONE)
Block(-9,4,9,Leaves:7)
Block(-9,5,-4,STONE)
Block(-9,5,0,STONE)
Block(-9,5,1,STONE)
Block(-9,5,2,STONE)
Block(-9,5,3,STONE)
Block(-9,5,8,Leaves:7)
Block(-9,6,0,STONE)
Block(-9,20,-2,STONE)
Block(-9,20,-1,STONE)
Block(-9,20,1,STONE)
Block(-9,20,2,STONE)
Block(-9,20,3,Leaves:7)
Block(-9,21,-4,STONE)
Block(-9,21,-3,STONE)
Block(-9,21,-2,STONE)
Block(-9,21,-1,quark:basalt:0)
Block(-9,21,0,quark:basalt:0)
Block(-9,21,1,STONE)
Block(-9,21,2,STONE)
Block(-9,21,3,STONE)
Block(-9,22,-5,STONE)
Block(-9,22,-4,STONE)
Block(-9,22,-3,STONE)
Block(-9,22,-2,STONE)
Block(-9,22,-1,STONE)
Block(-9,22,0,quark:basalt:0)
Block(-9,22,1,STONE)
Block(-9,22,2,STONE)
Block(-9,22,3,quark:basalt:0)
Block(-9,22,4,quark:basalt:0)
Block(-9,23,-11,STONE)
Block(-9,23,-10,STONE)
Block(-9,23,-8,STONE)
Block(-9,23,-7,STONE)
Block(-9,23,-6,STONE)
Block(-9,23,-5,STONE)
Block(-9,23,-4,STONE)
Block(-9,23,-3,STONE)
Block(-9,23,-2,STONE)
Block(-9,23,-1,STONE)
Block(-9,23,0,STONE)
Block(-9,23,1,STONE)
Block(-9,23,2,STONE)
Block(-9,23,3,STONE)
Block(-9,23,4,STONE)
Block(-9,23,5,STONE)
Block(-9,23,6,STONE)
Block(-9,23,7,STONE)
Block(-9,23,8,STONE)
Block(-9,24,-11,STONE)
Block(-9,24,-10,STONE)
Block(-9,24,-9,STONE)
Block(-9,24,-8,STONE)
Block(-9,24,-7,STONE)
Block(-9,24,-6,STONE)
Block(-9,24,-5,STONE)
Block(-9,24,-4,STONE)
Block(-9,24,-3,STONE)
Block(-9,24,-2,STONE)
Block(-9,24,-1,STONE)
Block(-9,24,0,LOG_2:1)
Block(-9,24,1,STONE)
Block(-9,24,2,STONE)
Block(-9,24,3,STONE)
Block(-9,24,4,STONE)
Block(-9,24,5,STONE)
Block(-9,24,6,STONE)
Block(-9,24,7,STONE)
Block(-9,24,8,STONE)
Block(-9,24,9,STONE)
Block(-9,24,10,STONE)
Block(-9,25,-11,STONE)
Block(-9,25,-10,STONE)
Block(-9,25,-9,STONE)
Block(-9,25,-8,STONE)
Block(-9,25,-7,STONE)
Block(-9,25,-6,STONE)
Block(-9,25,-5,STONE)
Block(-9,25,-4,STONE)
Block(-9,25,-3,STONE)
Block(-9,25,-2,STONE)
Block(-9,25,-1,LOG:2)
Block(-9,25,0,LOG:2)
Block(-9,25,1,STONE)
Block(-9,25,2,STONE)
Block(-9,25,3,STONE)
Block(-9,25,4,STONE)
Block(-9,25,5,STONE)
Block(-9,25,6,STONE)
Block(-9,25,7,STONE)
Block(-9,25,8,STONE)
Block(-9,25,9,STONE)
Block(-9,25,10,STONE)
Block(-9,26,-11,STONE)
Block(-9,26,-10,STONE)
Block(-9,26,-9,STONE)
Block(-9,26,-8,STONE)
Block(-9,26,-7,STONE)
Block(-9,26,-6,STONE)
Block(-9,26,-5,STONE)
Block(-9,26,-3,LOG_2:1)
Block(-9,26,-2,STONE)
Block(-9,26,-1,LOG_2)
Block(-9,26,0,LOG)
Block(-9,26,1,STONE)
Block(-9,26,2,STONE)
Block(-9,26,3,LOG_2)
Block(-9,26,4,STONE)
Block(-9,26,5,STONE)
Block(-9,26,6,STONE)
Block(-9,26,7,STONE)
Block(-9,26,8,STONE)
Block(-9,26,9,STONE)
Block(-9,26,10,STONE)
Block(-9,27,-11,STONE)
Block(-9,27,-10,STONE)
Block(-9,27,-9,STONE)
Block(-9,27,-8,STONE)
Block(-9,27,-7,STONE)
Block(-9,27,-6,STONE)
Block(-9,27,-5,STONE)
Block(-9,27,-4,STONE)
Block(-9,27,-3,LOG_2:1)
Block(-9,27,-2,LOG:2)
Block(-9,27,-1,STONE)
Block(-9,27,0,LOG_2:1)
Block(-9,27,1,LOG:2)
Block(-9,27,2,LOG:2)
Block(-9,27,3,STONE)
Block(-9,27,4,STONE)
Block(-9,27,5,STONE)
Block(-9,27,6,STONE)
Block(-9,27,7,STONE)
Block(-9,27,8,STONE)
Block(-9,27,9,STONE)
Block(-8,0,-10,STONE)
Block(-8,0,-9,STONE)
Block(-8,0,-8,STONE)
Block(-8,0,-7,STONE)
Block(-8,0,-6,STONE)
Block(-8,0,-5,STONE)
Block(-8,0,-4,STONE)
Block(-8,0,-3,STONE)
Block(-8,0,-2,STONE)
Block(-8,0,-1,STONE)
Block(-8,0,0,STONE)
Block(-8,0,1,STONE)
Block(-8,0,2,STONE)
Block(-8,0,3,STONE)
Block(-8,0,4,STONE)
Block(-8,0,5,STONE)
Block(-8,0,6,STONE)
Block(-8,0,7,STONE)
Block(-8,0,8,quark:basalt:0)
Block(-8,0,9,quark:basalt:0)
Block(-8,0,10,quark:basalt:0)
Block(-8,0,11,quark:basalt:0)
Block(-8,1,-9,STONE)
Block(-8,1,-8,STONE)
Block(-8,1,-7,STONE)
Block(-8,1,-6,STONE)
Block(-8,1,-5,STONE)
Block(-8,1,-4,STONE)
Block(-8,1,-3,STONE)
Block(-8,1,-2,STONE)
Block(-8,1,-1,STONE)
Block(-8,1,0,STONE)
Block(-8,1,1,STONE)
Block(-8,1,2,STONE)
Block(-8,1,3,STONE)
Block(-8,1,4,STONE)
Block(-8,1,5,STONE)
Block(-8,1,6,STONE)
Block(-8,1,7,STONE)
Block(-8,1,8,quark:basalt:0)
Block(-8,1,9,quark:basalt:0)
Block(-8,2,-9,STONE)
Block(-8,2,-8,STONE)
Block(-8,2,-7,quark:basalt:0)
Block(-8,2,-6,quark:basalt:0)
Block(-8,2,-5,STONE)
Block(-8,2,-4,STONE)
Block(-8,2,-3,STONE)
Block(-8,2,-2,STONE)
Block(-8,2,-1,STONE)
Block(-8,2,0,STONE)
Block(-8,2,1,STONE)
Block(-8,2,2,STONE)
Block(-8,2,3,STONE)
Block(-8,2,4,STONE)
Block(-8,2,5,STONE)
Block(-8,2,6,STONE)
Block(-8,2,7,quark:basalt:0)
Block(-8,2,8,quark:basalt:0)
Block(-8,3,-8,Leaves:7)
Block(-8,3,-7,STONE)
Block(-8,3,-6,quark:basalt:0)
Block(-8,3,-5,STONE)
Block(-8,3,-4,STONE)
Block(-8,3,-3,STONE)
Block(-8,3,-2,STONE)
Block(-8,3,-1,STONE)
Block(-8,3,0,STONE)
Block(-8,3,1,STONE)
Block(-8,3,2,STONE)
Block(-8,3,3,STONE)
Block(-8,3,4,STONE)
Block(-8,3,5,STONE)
Block(-8,3,6,STONE)
Block(-8,3,7,STONE)
Block(-8,3,8,STONE)
Block(-8,4,-6,quark:basalt:0)
Block(-8,4,-5,quark:basalt:0)
Block(-8,4,-4,STONE)
Block(-8,4,-3,STONE)
Block(-8,4,-2,STONE)
Block(-8,4,-1,STONE)
Block(-8,4,0,STONE)
Block(-8,4,1,STONE)
Block(-8,4,2,STONE)
Block(-8,4,3,STONE)
Block(-8,4,4,STONE)
Block(-8,4,5,quark:basalt:0)
Block(-8,4,6,STONE)
Block(-8,4,7,STONE)
Block(-8,4,8,STONE)
Block(-8,5,-5,STONE)
Block(-8,5,-4,STONE)
Block(-8,5,-3,STONE)
Block(-8,5,-2,STONE)
Block(-8,5,-1,STONE)
Block(-8,5,0,STONE)
Block(-8,5,1,STONE)
Block(-8,5,2,STONE)
Block(-8,5,3,STONE)
Block(-8,5,4,quark:basalt:0)
Block(-8,5,5,quark:basalt:0)
Block(-8,5,6,STONE)
Block(-8,6,-4,STONE)
Block(-8,6,-3,STONE)
Block(-8,6,-2,STONE)
Block(-8,6,-1,STONE)
Block(-8,6,0,STONE)
Block(-8,6,1,STONE)
Block(-8,6,2,STONE)
Block(-8,6,3,STONE)
Block(-8,6,4,quark:basalt:0)
Block(-8,6,5,quark:basalt:0)
Block(-8,6,6,Leaves:7)
Block(-8,7,-1,STONE)
Block(-8,7,0,STONE)
Block(-8,7,1,STONE)
Block(-8,7,3,STONE)
Block(-8,8,-2,Leaves:7)
Block(-8,8,1,STONE)
Block(-8,9,1,quark:basalt:0)
Block(-8,19,0,quark:basalt:0)
Block(-8,19,3,Leaves:7)
Block(-8,20,-5,STONE)
Block(-8,20,-4,STONE)
Block(-8,20,-3,STONE)
Block(-8,20,-2,STONE)
Block(-8,20,-1,STONE)
Block(-8,20,0,quark:basalt:0)
Block(-8,20,1,STONE)
Block(-8,20,2,STONE)
Block(-8,20,3,STONE)
Block(-8,20,4,Leaves:7)
Block(-8,21,-6,STONE)
Block(-8,21,-5,STONE)
Block(-8,21,-4,STONE)
Block(-8,21,-3,STONE)
Block(-8,21,-2,STONE)
Block(-8,21,-1,STONE)
Block(-8,21,0,quark:basalt:0)
Block(-8,21,1,quark:basalt:0)
Block(-8,21,2,STONE)
Block(-8,21,3,STONE)
Block(-8,21,4,STONE)
Block(-8,22,-7,STONE)
Block(-8,22,-6,STONE)
Block(-8,22,-5,STONE)
Block(-8,22,-4,STONE)
Block(-8,22,-3,STONE)
Block(-8,22,-2,STONE)
Block(-8,22,-1,STONE)
Block(-8,22,0,STONE)
Block(-8,22,1,STONE)
Block(-8,22,2,STONE)
Block(-8,22,3,quark:basalt:0)
Block(-8,22,4,quark:basalt:0)
Block(-8,22,5,quark:basalt:0)
Block(-8,22,6,quark:basalt:0)
Block(-8,23,-10,STONE)
Block(-8,23,-9,STONE)
Block(-8,23,-8,STONE)
Block(-8,23,-7,STONE)
Block(-8,23,-6,STONE)
Block(-8,23,-5,STONE)
Block(-8,23,-4,STONE)
Block(-8,23,-3,STONE)
Block(-8,23,-2,STONE)
Block(-8,23,-1,STONE)
Block(-8,23,0,STONE)
Block(-8,23,1,STONE)
Block(-8,23,2,STONE)
Block(-8,23,3,STONE)
Block(-8,23,4,STONE)
Block(-8,23,5,STONE)
Block(-8,23,6,quark:basalt:0)
Block(-8,23,7,STONE)
Block(-8,24,-11,STONE)
Block(-8,24,-10,STONE)
Block(-8,24,-9,STONE)
Block(-8,24,-8,STONE)
Block(-8,24,-7,STONE)
Block(-8,24,-6,STONE)
Block(-8,24,-5,STONE)
Block(-8,24,-4,STONE)
Block(-8,24,-3,STONE)
Block(-8,24,-2,STONE)
Block(-8,24,-1,STONE)
Block(-8,24,0,STONE)
Block(-8,24,1,STONE)
Block(-8,24,2,STONE)
Block(-8,24,3,LOG:1)
Block(-8,24,4,STONE)
Block(-8,24,5,STONE)
Block(-8,24,6,STONE)
Block(-8,24,7,STONE)
Block(-8,24,8,STONE)
Block(-8,24,9,STONE)
Block(-8,24,10,STONE)
Block(-8,25,-11,STONE)
Block(-8,25,-10,STONE)
Block(-8,25,-9,STONE)
Block(-8,25,-8,STONE)
Block(-8,25,-7,STONE)
Block(-8,25,-6,STONE)
Block(-8,25,-5,STONE)
Block(-8,25,-4,LOG)
Block(-8,25,-3,STONE)
Block(-8,25,-2,STONE)
Block(-8,25,-1,STONE)
Block(-8,25,0,STONE)
Block(-8,25,1,LOG:1)
Block(-8,25,2,STONE)
Block(-8,25,3,LOG_2)
Block(-8,25,4,LOG_2:1)
Block(-8,25,5,STONE)
Block(-8,25,6,STONE)
Block(-8,25,7,STONE)
Block(-8,25,8,STONE)
Block(-8,25,9,STONE)
Block(-8,25,10,STONE)
Block(-8,26,-12,STONE)
Block(-8,26,-11,STONE)
Block(-8,26,-10,STONE)
Block(-8,26,-9,STONE)
Block(-8,26,-8,STONE)
Block(-8,26,-7,STONE)
Block(-8,26,-6,STONE)
Block(-8,26,-5,STONE)
Block(-8,26,-4,STONE)
Block(-8,26,-3,LOG_2)
Block(-8,26,-2,LOG_2)
Block(-8,26,-1,STONE)
Block(-8,26,0,LOG)
Block(-8,26,1,STONE)
Block(-8,26,2,LOG)
Block(-8,26,3,LOG)
Block(-8,26,4,LOG:1)
Block(-8,26,5,STONE)
Block(-8,26,6,STONE)
Block(-8,26,7,STONE)
Block(-8,26,8,STONE)
Block(-8,26,9,STONE)
Block(-8,26,10,STONE)
Block(-8,27,-10,STONE)
Block(-8,27,-9,STONE)
Block(-8,27,-8,STONE)
Block(-8,27,-7,STONE)
Block(-8,27,-6,STONE)
Block(-8,27,-5,LOG)
Block(-8,27,-4,STONE)
Block(-8,27,-3,STONE)
Block(-8,27,-2,STONE)
Block(-8,27,-1,STONE)
Block(-8,27,0,LOG:2)
Block(-8,27,1,STONE)
Block(-8,27,2,LOG_2)
Block(-8,27,3,STONE)
Block(-8,27,4,STONE)
Block(-8,27,5,STONE)
Block(-8,27,6,STONE)
Block(-8,27,7,STONE)
Block(-8,27,8,STONE)
Block(-8,27,9,STONE)
Block(-8,27,10,STONE)
Block(-7,0,-10,quark:basalt:0)
Block(-7,0,-9,quark:basalt:0)
Block(-7,0,-8,STONE)
Block(-7,0,-7,STONE)
Block(-7,0,-6,STONE)
Block(-7,0,-5,STONE)
Block(-7,0,-4,STONE)
Block(-7,0,-3,STONE)
Block(-7,0,-2,STONE)
Block(-7,0,-1,STONE)
Block(-7,0,0,STONE)
Block(-7,0,1,STONE)
Block(-7,0,2,STONE)
Block(-7,0,3,STONE)
Block(-7,0,4,STONE)
Block(-7,0,5,STONE)
Block(-7,0,6,STONE)
Block(-7,0,7,STONE)
Block(-7,0,8,STONE)
Block(-7,0,9,quark:basalt:0)
Block(-7,0,10,STONE)
Block(-7,0,11,STONE)
Block(-7,1,-9,STONE)
Block(-7,1,-8,quark:basalt:0)
Block(-7,1,-7,STONE)
Block(-7,1,-6,STONE)
Block(-7,1,-5,STONE)
Block(-7,1,-4,STONE)
Block(-7,1,-3,STONE)
Block(-7,1,-2,STONE)
Block(-7,1,-1,STONE)
Block(-7,1,0,STONE)
Block(-7,1,1,STONE)
Block(-7,1,2,STONE)
Block(-7,1,3,STONE)
Block(-7,1,4,STONE)
Block(-7,1,5,STONE)
Block(-7,1,6,STONE)
Block(-7,1,7,STONE)
Block(-7,1,8,quark:basalt:0)
Block(-7,1,9,quark:basalt:0)
Block(-7,1,10,quark:basalt:0)
Block(-7,2,-8,STONE)
Block(-7,2,-7,STONE)
Block(-7,2,-6,STONE)
Block(-7,2,-5,STONE)
Block(-7,2,-4,STONE)
Block(-7,2,-3,STONE)
Block(-7,2,-2,STONE)
Block(-7,2,-1,STONE)
Block(-7,2,0,STONE)
Block(-7,2,1,STONE)
Block(-7,2,2,STONE)
Block(-7,2,3,STONE)
Block(-7,2,4,STONE)
Block(-7,2,5,STONE)
Block(-7,2,6,STONE)
Block(-7,2,7,quark:basalt:0)
Block(-7,2,8,quark:basalt:0)
Block(-7,2,9,quark:basalt:0)
Block(-7,3,-9,Leaves:7)
Block(-7,3,-8,STONE)
Block(-7,3,-7,STONE)
Block(-7,3,-6,quark:basalt:0)
Block(-7,3,-5,quark:basalt:0)
Block(-7,3,-4,STONE)
Block(-7,3,-3,STONE)
Block(-7,3,-2,STONE)
Block(-7,3,-1,STONE)
Block(-7,3,0,STONE)
Block(-7,3,1,STONE)
Block(-7,3,2,STONE)
Block(-7,3,3,STONE)
Block(-7,3,4,STONE)
Block(-7,3,5,STONE)
Block(-7,3,6,STONE)
Block(-7,3,7,STONE)
Block(-7,3,8,quark:basalt:0)
Block(-7,4,-8,Leaves:7)
Block(-7,4,-6,quark:basalt:0)
Block(-7,4,-5,quark:basalt:0)
Block(-7,4,-4,STONE)
Block(-7,4,-3,STONE)
Block(-7,4,-2,STONE)
Block(-7,4,-1,STONE)
Block(-7,4,0,STONE)
Block(-7,4,1,STONE)
Block(-7,4,2,STONE)
Block(-7,4,3,STONE)
Block(-7,4,4,STONE)
Block(-7,4,5,STONE)
Block(-7,4,6,STONE)
Block(-7,4,7,STONE)
Block(-7,5,-6,quark:basalt:0)
Block(-7,5,-5,quark:basalt:0)
Block(-7,5,-4,STONE)
Block(-7,5,-3,STONE)
Block(-7,5,-2,STONE)
Block(-7,5,-1,STONE)
Block(-7,5,0,STONE)
Block(-7,5,1,STONE)
Block(-7,5,2,STONE)
Block(-7,5,3,STONE)
Block(-7,5,4,STONE)
Block(-7,5,5,quark:basalt:0)
Block(-7,5,6,STONE)
Block(-7,5,7,STONE)
Block(-7,6,-5,quark:basalt:0)
Block(-7,6,-4,STONE)
Block(-7,6,-3,STONE)
Block(-7,6,-2,STONE)
Block(-7,6,-1,STONE)
Block(-7,6,0,STONE)
Block(-7,6,1,STONE)
Block(-7,6,2,STONE)
Block(-7,6,3,STONE)
Block(-7,6,4,quark:basalt:0)
Block(-7,6,5,STONE)
Block(-7,6,6,STONE)
Block(-7,6,7,Leaves:7)
Block(-7,7,-3,quark:basalt:0)
Block(-7,7,-2,STONE)
Block(-7,7,-1,STONE)
Block(-7,7,0,STONE)
Block(-7,7,1,STONE)
Block(-7,7,2,STONE)
Block(-7,7,3,STONE)
Block(-7,7,4,quark:basalt:0)
Block(-7,7,6,Leaves:7)
Block(-7,8,-3,Leaves:7)
Block(-7,8,-2,quark:basalt:0)
Block(-7,8,-1,quark:basalt:0)
Block(-7,8,0,quark:basalt:0)
Block(-7,8,1,quark:basalt:0)
Block(-7,8,2,STONE)
Block(-7,8,3,quark:basalt:0)
Block(-7,9,-2,STONE)
Block(-7,9,-1,STONE)
Block(-7,9,0,quark:basalt:0)
Block(-7,9,1,quark:basalt:0)
Block(-7,9,2,quark:basalt:0)
Block(-7,10,-2,STONE)
Block(-7,10,1,quark:basalt:0)
Block(-7,11,-1,Leaves:7)
Block(-7,12,1,Leaves:7)
Block(-7,17,-2,STONE)
Block(-7,17,-1,STONE)
Block(-7,18,-2,STONE)
Block(-7,18,-1,STONE)
Block(-7,18,0,STONE)
Block(-7,18,1,quark:basalt:0)
Block(-7,19,-3,STONE)
Block(-7,19,-2,STONE)
Block(-7,19,-1,STONE)
Block(-7,19,0,STONE)
Block(-7,19,1,quark:basalt:0)
Block(-7,20,-6,STONE)
Block(-7,20,-5,STONE)
Block(-7,20,-4,STONE)
Block(-7,20,-3,STONE)
Block(-7,20,-2,STONE)
Block(-7,20,-1,STONE)
Block(-7,20,0,quark:basalt:0)
Block(-7,20,1,quark:basalt:0)
Block(-7,20,2,STONE)
Block(-7,20,3,STONE)
Block(-7,20,4,STONE)
Block(-7,21,-7,STONE)
Block(-7,21,-6,STONE)
Block(-7,21,-5,STONE)
Block(-7,21,-4,STONE)
Block(-7,21,-3,STONE)
Block(-7,21,-2,STONE)
Block(-7,21,-1,STONE)
Block(-7,21,0,STONE)
Block(-7,21,1,quark:basalt:0)
Block(-7,21,2,STONE)
Block(-7,21,3,STONE)
Block(-7,21,4,STONE)
Block(-7,21,5,STONE)
Block(-7,22,-7,STONE)
Block(-7,22,-6,STONE)
Block(-7,22,-5,STONE)
Block(-7,22,-4,STONE)
Block(-7,22,-3,STONE)
Block(-7,22,-2,STONE)
Block(-7,22,-1,STONE)
Block(-7,22,0,STONE)
Block(-7,22,1,STONE)
Block(-7,22,2,STONE)
Block(-7,22,3,STONE)
Block(-7,22,4,quark:basalt:0)
Block(-7,22,5,quark:basalt:0)
Block(-7,22,6,quark:basalt:0)
Block(-7,22,7,quark:basalt:0)
Block(-7,23,-9,STONE)
Block(-7,23,-8,STONE)
Block(-7,23,-7,STONE)
Block(-7,23,-6,STONE)
Block(-7,23,-5,STONE)
Block(-7,23,-4,STONE)
Block(-7,23,-3,STONE)
Block(-7,23,-2,STONE)
Block(-7,23,-1,STONE)
Block(-7,23,0,STONE)
Block(-7,23,1,STONE)
Block(-7,23,2,STONE)
Block(-7,23,3,LOG_2)
Block(-7,23,4,STONE)
Block(-7,23,5,quark:basalt:0)
Block(-7,23,6,quark:basalt:0)
Block(-7,23,7,quark:basalt:0)
Block(-7,23,8,STONE)
Block(-7,24,-10,STONE)
Block(-7,24,-9,STONE)
Block(-7,24,-8,STONE)
Block(-7,24,-7,STONE)
Block(-7,24,-6,STONE)
Block(-7,24,-5,STONE)
Block(-7,24,-4,STONE)
Block(-7,24,-3,STONE)
Block(-7,24,-2,STONE)
Block(-7,24,-1,STONE)
Block(-7,24,0,STONE)
Block(-7,24,1,STONE)
Block(-7,24,2,LOG:2)
Block(-7,24,3,STONE)
Block(-7,24,4,LOG)
Block(-7,24,5,STONE)
Block(-7,24,6,STONE)
Block(-7,24,7,STONE)
Block(-7,24,8,STONE)
Block(-7,24,9,STONE)
Block(-7,24,10,STONE)
Block(-7,25,-12,STONE)
Block(-7,25,-11,STONE)
Block(-7,25,-10,STONE)
Block(-7,25,-9,STONE)
Block(-7,25,-8,STONE)
Block(-7,25,-7,STONE)
Block(-7,25,-6,STONE)
Block(-7,25,-5,STONE)
Block(-7,25,-4,STONE)
Block(-7,25,-3,STONE)
Block(-7,25,-2,LOG_2:1)
Block(-7,25,-1,LOG_2)
Block(-7,25,0,STONE)
Block(-7,25,1,STONE)
Block(-7,25,2,STONE)
Block(-7,25,3,STONE)
Block(-7,25,4,STONE)
Block(-7,25,5,STONE)
Block(-7,25,6,STONE)
Block(-7,25,7,STONE)
Block(-7,25,8,STONE)
Block(-7,25,9,STONE)
Block(-7,25,10,STONE)
Block(-7,25,11,STONE)
Block(-7,26,-12,STONE)
Block(-7,26,-11,STONE)
Block(-7,26,-10,STONE)
Block(-7,26,-9,STONE)
Block(-7,26,-8,STONE)
Block(-7,26,-7,STONE)
Block(-7,26,-6,STONE)
Block(-7,26,-5,LOG_2)
Block(-7,26,-4,LOG:2)
Block(-7,26,-3,STONE)
Block(-7,26,-2,STONE)
Block(-7,26,-1,STONE)
Block(-7,26,0,STONE)
Block(-7,26,1,STONE)
Block(-7,26,2,STONE)
Block(-7,26,3,LOG_2:1)
Block(-7,26,4,STONE)
Block(-7,26,5,LOG)
Block(-7,26,6,LOG_2:1)
Block(-7,26,7,STONE)
Block(-7,26,8,STONE)
Block(-7,26,9,STONE)
Block(-7,26,10,STONE)
Block(-7,27,-11,STONE)
Block(-7,27,-10,STONE)
Block(-7,27,-9,STONE)
Block(-7,27,-8,STONE)
Block(-7,27,-7,STONE)
Block(-7,27,-6,LOG:1)
Block(-7,27,-5,LOG:2)
Block(-7,27,-4,LOG_2)
Block(-7,27,-3,STONE)
Block(-7,27,-2,STONE)
Block(-7,27,-1,STONE)
Block(-7,27,0,LOG_2:1)
Block(-7,27,1,STONE)
Block(-7,27,2,LOG)
Block(-7,27,3,LOG:2)
Block(-7,27,4,STONE)
Block(-7,27,5,STONE)
Block(-7,27,6,LOG_2:1)
Block(-7,27,7,STONE)
Block(-7,27,8,STONE)
Block(-7,27,9,STONE)
Block(-7,27,10,STONE)
Block(-6,0,-11,quark:basalt:0)
Block(-6,0,-10,quark:basalt:0)
Block(-6,0,-9,quark:basalt:0)
Block(-6,0,-8,quark:basalt:0)
Block(-6,0,-7,STONE)
Block(-6,0,-6,STONE)
Block(-6,0,-5,STONE)
Block(-6,0,-4,STONE)
Block(-6,0,-3,STONE)
Block(-6,0,-2,STONE)
Block(-6,0,-1,STONE)
Block(-6,0,0,STONE)
Block(-6,0,1,STONE)
Block(-6,0,2,STONE)
Block(-6,0,3,STONE)
Block(-6,0,4,STONE)
Block(-6,0,5,STONE)
Block(-6,0,6,STONE)
Block(-6,0,7,STONE)
Block(-6,0,8,STONE)
Block(-6,0,9,STONE)
Block(-6,0,10,STONE)
Block(-6,0,11,STONE)
Block(-6,0,12,STONE)
Block(-6,1,-9,quark:basalt:0)
Block(-6,1,-8,quark:basalt:0)
Block(-6,1,-7,STONE)
Block(-6,1,-6,STONE)
Block(-6,1,-5,STONE)
Block(-6,1,-4,STONE)
Block(-6,1,-3,STONE)
Block(-6,1,-2,STONE)
Block(-6,1,-1,STONE)
Block(-6,1,0,STONE)
Block(-6,1,1,STONE)
Block(-6,1,2,STONE)
Block(-6,1,3,STONE)
Block(-6,1,4,STONE)
Block(-6,1,5,STONE)
Block(-6,1,6,STONE)
Block(-6,1,7,STONE)
Block(-6,1,8,STONE)
Block(-6,1,9,STONE)
Block(-6,1,10,STONE)
Block(-6,2,-9,STONE)
Block(-6,2,-8,STONE)
Block(-6,2,-7,STONE)
Block(-6,2,-6,STONE)
Block(-6,2,-5,STONE)
Block(-6,2,-4,STONE)
Block(-6,2,-3,STONE)
Block(-6,2,-2,STONE)
Block(-6,2,-1,STONE)
Block(-6,2,0,STONE)
Block(-6,2,1,STONE)
Block(-6,2,2,STONE)
Block(-6,2,3,STONE)
Block(-6,2,4,STONE)
Block(-6,2,5,STONE)
Block(-6,2,6,STONE)
Block(-6,2,7,STONE)
Block(-6,2,8,quark:basalt:0)
Block(-6,2,9,STONE)
Block(-6,2,10,STONE)
Block(-6,3,-9,STONE)
Block(-6,3,-8,STONE)
Block(-6,3,-7,STONE)
Block(-6,3,-6,quark:basalt:0)
Block(-6,3,-5,STONE)
Block(-6,3,-4,STONE)
Block(-6,3,-3,STONE)
Block(-6,3,-2,STONE)
Block(-6,3,-1,STONE)
Block(-6,3,0,STONE)
Block(-6,3,1,STONE)
Block(-6,3,2,STONE)
Block(-6,3,3,STONE)
Block(-6,3,4,STONE)
Block(-6,3,5,STONE)
Block(-6,3,6,STONE)
Block(-6,3,7,quark:basalt:0)
Block(-6,3,8,quark:basalt:0)
Block(-6,4,-9,Leaves:7)
Block(-6,4,-8,STONE)
Block(-6,4,-7,quark:basalt:0)
Block(-6,4,-6,quark:basalt:0)
Block(-6,4,-5,quark:basalt:0)
Block(-6,4,-4,STONE)
Block(-6,4,-3,STONE)
Block(-6,4,-2,STONE)
Block(-6,4,-1,STONE)
Block(-6,4,0,STONE)
Block(-6,4,1,LOG:2)
Block(-6,4,2,STONE)
Block(-6,4,3,STONE)
Block(-6,4,4,STONE)
Block(-6,4,5,STONE)
Block(-6,4,6,quark:basalt:0)
Block(-6,4,7,STONE)
Block(-6,4,8,quark:basalt:0)
Block(-6,5,-8,Leaves:7)
Block(-6,5,-7,quark:basalt:0)
Block(-6,5,-6,quark:basalt:0)
Block(-6,5,-5,quark:basalt:0)
Block(-6,5,-4,STONE)
Block(-6,5,-3,STONE)
Block(-6,5,-2,STONE)
Block(-6,5,-1,STONE)
Block(-6,5,0,STONE)
Block(-6,5,1,STONE)
Block(-6,5,2,STONE)
Block(-6,5,3,STONE)
Block(-6,5,4,STONE)
Block(-6,5,5,STONE)
Block(-6,5,6,STONE)
Block(-6,5,7,STONE)
Block(-6,6,-7,Leaves:7)
Block(-6,6,-6,STONE)
Block(-6,6,-5,quark:basalt:0)
Block(-6,6,-4,STONE)
Block(-6,6,-3,STONE)
Block(-6,6,-2,STONE)
Block(-6,6,-1,STONE)
Block(-6,6,0,STONE)
Block(-6,6,1,STONE)
Block(-6,6,2,STONE)
Block(-6,6,3,STONE)
Block(-6,6,4,quark:basalt:0)
Block(-6,6,5,STONE)
Block(-6,6,6,STONE)
Block(-6,7,-5,Leaves:7)
Block(-6,7,-4,quark:basalt:0)
Block(-6,7,-3,STONE)
Block(-6,7,-2,quark:basalt:0)
Block(-6,7,-1,STONE)
Block(-6,7,0,STONE)
Block(-6,7,1,STONE)
Block(-6,7,2,STONE)
Block(-6,7,3,quark:basalt:0)
Block(-6,7,4,quark:basalt:0)
Block(-6,7,5,STONE)
Block(-6,8,-3,STONE)
Block(-6,8,-2,STONE)
Block(-6,8,-1,quark:basalt:0)
Block(-6,8,0,quark:basalt:0)
Block(-6,8,1,STONE)
Block(-6,8,2,STONE)
Block(-6,8,3,quark:basalt:0)
Block(-6,8,4,quark:basalt:0)
Block(-6,8,5,STONE)
Block(-6,8,6,STONE)
Block(-6,9,-3,STONE)
Block(-6,9,-2,STONE)
Block(-6,9,-1,STONE)
Block(-6,9,0,STONE)
Block(-6,9,1,quark:basalt:0)
Block(-6,9,2,quark:basalt:0)
Block(-6,9,3,quark:basalt:0)
Block(-6,9,4,quark:basalt:0)
Block(-6,9,5,STONE)
Block(-6,10,-2,STONE)
Block(-6,10,-1,STONE)
Block(-6,10,0,STONE)
Block(-6,10,1,STONE)
Block(-6,10,2,quark:basalt:0)
Block(-6,10,3,quark:basalt:0)
Block(-6,11,-2,STONE)
Block(-6,11,-1,STONE)
Block(-6,11,0,STONE)
Block(-6,11,1,STONE)
Block(-6,11,2,quark:basalt:0)
Block(-6,12,-1,STONE)
Block(-6,12,0,STONE)
Block(-6,12,1,STONE)
Block(-6,12,2,Leaves:7)
Block(-6,13,-2,quark:basalt:0)
Block(-6,13,-1,quark:basalt:0)
Block(-6,13,0,STONE)
Block(-6,13,1,STONE)
Block(-6,13,2,STONE)
Block(-6,14,0,STONE)
Block(-6,14,1,STONE)
Block(-6,15,0,quark:basalt:0)
Block(-6,16,-2,STONE)
Block(-6,16,-1,STONE)
Block(-6,16,0,quark:basalt:0)
Block(-6,16,1,STONE)
Block(-6,17,-3,STONE)
Block(-6,17,-2,STONE)
Block(-6,17,-1,STONE)
Block(-6,17,0,quark:basalt:0)
Block(-6,17,1,quark:basalt:0)
Block(-6,18,-3,STONE)
Block(-6,18,-2,STONE)
Block(-6,18,-1,STONE)
Block(-6,18,0,STONE)
Block(-6,18,1,quark:basalt:0)
Block(-6,18,2,quark:basalt:0)
Block(-6,18,4,Leaves:7)
Block(-6,19,-3,STONE)
Block(-6,19,-2,STONE)
Block(-6,19,-1,STONE)
Block(-6,19,0,STONE)
Block(-6,19,1,quark:basalt:0)
Block(-6,19,2,STONE)
Block(-6,19,4,Leaves:7)
Block(-6,20,-6,STONE)
Block(-6,20,-5,STONE)
Block(-6,20,-4,STONE)
Block(-6,20,-3,STONE)
Block(-6,20,-2,STONE)
Block(-6,20,-1,STONE)
Block(-6,20,0,STONE)
Block(-6,20,1,quark:basalt:0)
Block(-6,20,2,quark:basalt:0)
Block(-6,20,3,STONE)
Block(-6,20,4,STONE)
Block(-6,20,5,Leaves:7)
Block(-6,21,-7,STONE)
Block(-6,21,-6,STONE)
Block(-6,21,-5,STONE)
Block(-6,21,-4,STONE)
Block(-6,21,-3,STONE)
Block(-6,21,-2,STONE)
Block(-6,21,-1,STONE)
Block(-6,21,0,STONE)
Block(-6,21,1,STONE)
Block(-6,21,2,STONE)
Block(-6,21,3,STONE)
Block(-6,21,4,STONE)
Block(-6,21,5,quark:basalt:0)
Block(-6,22,-7,STONE)
Block(-6,22,-6,STONE)
Block(-6,22,-5,STONE)
Block(-6,22,-4,STONE)
Block(-6,22,-3,STONE)
Block(-6,22,-2,STONE)
Block(-6,22,-1,STONE)
Block(-6,22,0,STONE)
Block(-6,22,1,STONE)
Block(-6,22,2,STONE)
Block(-6,22,3,STONE)
Block(-6,22,4,LOG)
Block(-6,22,5,quark:basalt:0)
Block(-6,22,6,quark:basalt:0)
Block(-6,22,7,quark:basalt:0)
Block(-6,23,-9,STONE)
Block(-6,23,-8,STONE)
Block(-6,23,-7,STONE)
Block(-6,23,-6,STONE)
Block(-6,23,-5,STONE)
Block(-6,23,-4,STONE)
Block(-6,23,-3,STONE)
Block(-6,23,-2,STONE)
Block(-6,23,-1,STONE)
Block(-6,23,0,STONE)
Block(-6,23,1,STONE)
Block(-6,23,2,STONE)
Block(-6,23,3,STONE)
Block(-6,23,4,LOG:1)
Block(-6,23,5,STONE)
Block(-6,23,6,quark:basalt:0)
Block(-6,23,7,quark:basalt:0)
Block(-6,23,8,STONE)
Block(-6,23,9,STONE)
Block(-6,23,10,STONE)
Block(-6,24,-10,STONE)
Block(-6,24,-9,STONE)
Block(-6,24,-8,STONE)
Block(-6,24,-7,STONE)
Block(-6,24,-6,STONE)
Block(-6,24,-5,STONE)
Block(-6,24,-4,STONE)
Block(-6,24,-3,STONE)
Block(-6,24,-2,STONE)
Block(-6,24,-1,STONE)
Block(-6,24,0,STONE)
Block(-6,24,1,STONE)
Block(-6,24,2,STONE)
Block(-6,24,3,STONE)
Block(-6,24,4,STONE)
Block(-6,24,5,STONE)
Block(-6,24,6,STONE)
Block(-6,24,7,STONE)
Block(-6,24,8,STONE)
Block(-6,24,9,STONE)
Block(-6,24,10,STONE)
Block(-6,25,-12,STONE)
Block(-6,25,-11,STONE)
Block(-6,25,-10,STONE)
Block(-6,25,-9,STONE)
Block(-6,25,-8,STONE)
Block(-6,25,-7,STONE)
Block(-6,25,-6,STONE)
Block(-6,25,-5,LOG_2:1)
Block(-6,25,-4,STONE)
Block(-6,25,-3,LOG_2:1)
Block(-6,25,-2,LOG:1)
Block(-6,25,-1,LOG:1)
Block(-6,25,0,STONE)
Block(-6,25,1,STONE)
Block(-6,25,2,LOG:1)
Block(-6,25,3,STONE)
Block(-6,25,4,LOG)
Block(-6,25,5,STONE)
Block(-6,25,6,STONE)
Block(-6,25,7,STONE)
Block(-6,25,8,STONE)
Block(-6,25,9,STONE)
Block(-6,25,10,STONE)
Block(-6,25,11,STONE)
Block(-6,26,-12,STONE)
Block(-6,26,-11,STONE)
Block(-6,26,-10,STONE)
Block(-6,26,-9,STONE)
Block(-6,26,-8,STONE)
Block(-6,26,-7,LOG:2)
Block(-6,26,-6,LOG_2:1)
Block(-6,26,-5,STONE)
Block(-6,26,-4,LOG:1)
Block(-6,26,-3,LOG:1)
Block(-6,26,-2,STONE)
Block(-6,26,-1,STONE)
Block(-6,26,0,STONE)
Block(-6,26,1,STONE)
Block(-6,26,2,LOG)
Block(-6,26,3,STONE)
Block(-6,26,4,LOG)
Block(-6,26,5,LOG)
Block(-6,26,6,STONE)
Block(-6,26,7,STONE)
Block(-6,26,8,STONE)
Block(-6,26,9,STONE)
Block(-6,26,10,STONE)
Block(-6,27,-11,STONE)
Block(-6,27,-10,STONE)
Block(-6,27,-9,STONE)
Block(-6,27,-8,STONE)
Block(-6,27,-7,LOG)
Block(-6,27,-6,STONE)
Block(-6,27,-5,STONE)
Block(-6,27,-4,STONE)
Block(-6,27,-3,STONE)
Block(-6,27,-2,STONE)
Block(-6,27,-1,STONE)
Block(-6,27,0,STONE)
Block(-6,27,1,STONE)
Block(-6,27,2,STONE)
Block(-6,27,3,STONE)
Block(-6,27,4,STONE)
Block(-6,27,5,STONE)
Block(-6,27,6,STONE)
Block(-6,27,7,STONE)
Block(-6,27,8,STONE)
Block(-6,27,9,STONE)
Block(-6,27,10,STONE)
Block(-5,0,-11,quark:basalt:0)
Block(-5,0,-10,quark:basalt:0)
Block(-5,0,-9,quark:basalt:0)
Block(-5,0,-8,STONE)
Block(-5,0,-7,STONE)
Block(-5,0,-6,STONE)
Block(-5,0,-5,STONE)
Block(-5,0,-4,STONE)
Block(-5,0,-3,STONE)
Block(-5,0,-2,STONE)
Block(-5,0,-1,STONE)
Block(-5,0,0,STONE)
Block(-5,0,1,STONE)
Block(-5,0,2,STONE)
Block(-5,0,3,STONE)
Block(-5,0,4,STONE)
Block(-5,0,5,STONE)
Block(-5,0,6,STONE)
Block(-5,0,7,STONE)
Block(-5,0,8,STONE)
Block(-5,0,9,STONE)
Block(-5,0,10,STONE)
Block(-5,0,11,STONE)
Block(-5,0,12,quark:basalt:0)
Block(-5,1,-10,quark:basalt:0)
Block(-5,1,-9,quark:basalt:0)
Block(-5,1,-8,quark:basalt:0)
Block(-5,1,-7,STONE)
Block(-5,1,-6,STONE)
Block(-5,1,-5,STONE)
Block(-5,1,-4,STONE)
Block(-5,1,-3,STONE)
Block(-5,1,-2,STONE)
Block(-5,1,-1,STONE)
Block(-5,1,0,STONE)
Block(-5,1,1,STONE)
Block(-5,1,2,STONE)
Block(-5,1,3,STONE)
Block(-5,1,4,STONE)
Block(-5,1,5,STONE)
Block(-5,1,6,STONE)
Block(-5,1,7,STONE)
Block(-5,1,8,STONE)
Block(-5,1,9,STONE)
Block(-5,1,10,STONE)
Block(-5,2,-9,STONE)
Block(-5,2,-8,STONE)
Block(-5,2,-7,STONE)
Block(-5,2,-6,STONE)
Block(-5,2,-5,STONE)
Block(-5,2,-4,STONE)
Block(-5,2,-3,STONE)
Block(-5,2,-2,STONE)
Block(-5,2,-1,STONE)
Block(-5,2,0,STONE)
Block(-5,2,1,STONE)
Block(-5,2,2,STONE)
Block(-5,2,3,STONE)
Block(-5,2,4,STONE)
Block(-5,2,5,STONE)
Block(-5,2,6,STONE)
Block(-5,2,7,STONE)
Block(-5,2,8,STONE)
Block(-5,2,9,STONE)
Block(-5,3,-9,STONE)
Block(-5,3,-8,STONE)
Block(-5,3,-7,STONE)
Block(-5,3,-6,STONE)
Block(-5,3,-5,LOG_2)
Block(-5,3,-4,LOG_2)
Block(-5,3,-3,STONE)
Block(-5,3,-2,STONE)
Block(-5,3,-1,STONE)
Block(-5,3,0,LOG_2)
Block(-5,3,1,LOG)
Block(-5,3,2,STONE)
Block(-5,3,3,STONE)
Block(-5,3,4,STONE)
Block(-5,3,5,STONE)
Block(-5,3,6,STONE)
Block(-5,3,7,STONE)
Block(-5,3,8,STONE)
Block(-5,4,-9,STONE)
Block(-5,4,-8,STONE)
Block(-5,4,-7,quark:basalt:0)
Block(-5,4,-6,STONE)
Block(-5,4,-5,STONE)
Block(-5,4,-4,STONE)
Block(-5,4,-3,STONE)
Block(-5,4,-2,STONE)
Block(-5,4,-1,STONE)
Block(-5,4,0,STONE)
Block(-5,4,1,STONE)
Block(-5,4,2,STONE)
Block(-5,4,3,STONE)
Block(-5,4,4,STONE)
Block(-5,4,5,STONE)
Block(-5,4,6,STONE)
Block(-5,4,7,quark:basalt:0)
Block(-5,4,8,STONE)
Block(-5,5,-8,STONE)
Block(-5,5,-7,STONE)
Block(-5,5,-6,quark:basalt:0)
Block(-5,5,-5,STONE)
Block(-5,5,-4,STONE)
Block(-5,5,-3,STONE)
Block(-5,5,-2,STONE)
Block(-5,5,-1,STONE)
Block(-5,5,0,STONE)
Block(-5,5,1,LOG_2)
Block(-5,5,2,STONE)
Block(-5,5,3,STONE)
Block(-5,5,4,STONE)
Block(-5,5,5,STONE)
Block(-5,5,6,STONE)
Block(-5,5,7,quark:basalt:0)
Block(-5,5,8,quark:basalt:0)
Block(-5,6,-8,Leaves:7)
Block(-5,6,-7,STONE)
Block(-5,6,-6,STONE)
Block(-5,6,-5,STONE)
Block(-5,6,-4,quark:basalt:0)
Block(-5,6,-3,STONE)
Block(-5,6,-2,STONE)
Block(-5,6,-1,STONE)
Block(-5,6,0,STONE)
Block(-5,6,1,STONE)
Block(-5,6,2,STONE)
Block(-5,6,3,STONE)
Block(-5,6,4,STONE)
Block(-5,6,5,STONE)
Block(-5,6,6,STONE)
Block(-5,6,7,STONE)
Block(-5,7,-7,STONE)
Block(-5,7,-6,STONE)
Block(-5,7,-5,STONE)
Block(-5,7,-4,STONE)
Block(-5,7,-3,STONE)
Block(-5,7,-2,STONE)
Block(-5,7,-1,STONE)
Block(-5,7,0,STONE)
Block(-5,7,1,STONE)
Block(-5,7,2,STONE)
Block(-5,7,3,STONE)
Block(-5,7,4,quark:basalt:0)
Block(-5,7,5,quark:basalt:0)
Block(-5,7,6,STONE)
Block(-5,7,7,quark:basalt:0)
Block(-5,8,-5,Leaves:7)
Block(-5,8,-3,STONE)
Block(-5,8,-2,STONE)
Block(-5,8,-1,STONE)
Block(-5,8,0,STONE)
Block(-5,8,1,LOG_2:1)
Block(-5,8,2,STONE)
Block(-5,8,3,quark:basalt:0)
Block(-5,8,4,quark:basalt:0)
Block(-5,8,5,STONE)
Block(-5,8,6,STONE)
Block(-5,8,7,STONE)
Block(-5,9,-3,STONE)
Block(-5,9,-2,STONE)
Block(-5,9,-1,STONE)
Block(-5,9,0,STONE)
Block(-5,9,1,STONE)
Block(-5,9,2,STONE)
Block(-5,9,3,quark:basalt:0)
Block(-5,9,4,STONE)
Block(-5,9,5,STONE)
Block(-5,9,6,STONE)
Block(-5,10,-2,STONE)
Block(-5,10,-1,STONE)
Block(-5,10,0,STONE)
Block(-5,10,1,STONE)
Block(-5,10,2,quark:basalt:0)
Block(-5,10,3,STONE)
Block(-5,10,4,STONE)
Block(-5,10,5,STONE)
Block(-5,11,-2,quark:basalt:0)
Block(-5,11,-1,STONE)
Block(-5,11,0,STONE)
Block(-5,11,1,STONE)
Block(-5,11,2,quark:basalt:0)
Block(-5,11,3,STONE)
Block(-5,11,4,STONE)
Block(-5,11,5,Leaves:7)
Block(-5,12,-2,quark:basalt:0)
Block(-5,12,-1,quark:basalt:0)
Block(-5,12,0,STONE)
Block(-5,12,1,STONE)
Block(-5,12,2,quark:basalt:0)
Block(-5,12,3,STONE)
Block(-5,12,4,STONE)
Block(-5,13,-2,quark:basalt:0)
Block(-5,13,-1,quark:basalt:0)
Block(-5,13,0,STONE)
Block(-5,13,1,STONE)
Block(-5,13,2,STONE)
Block(-5,13,3,STONE)
Block(-5,14,-1,quark:basalt:0)
Block(-5,14,0,quark:basalt:0)
Block(-5,14,1,STONE)
Block(-5,14,2,STONE)
Block(-5,14,3,STONE)
Block(-5,14,4,STONE)
Block(-5,15,-2,STONE)
Block(-5,15,-1,STONE)
Block(-5,15,0,quark:basalt:0)
Block(-5,15,1,STONE)
Block(-5,15,3,STONE)
Block(-5,15,4,STONE)
Block(-5,16,-3,STONE)
Block(-5,16,-2,STONE)
Block(-5,16,-1,STONE)
Block(-5,16,0,quark:basalt:0)
Block(-5,16,1,STONE)
Block(-5,16,2,STONE)
Block(-5,17,-3,STONE)
Block(-5,17,-2,STONE)
Block(-5,17,-1,STONE)
Block(-5,17,0,STONE)
Block(-5,17,1,STONE)
Block(-5,17,2,STONE)
Block(-5,17,3,STONE)
Block(-5,17,4,Leaves:7)
Block(-5,18,-4,STONE)
Block(-5,18,-3,STONE)
Block(-5,18,-2,STONE)
Block(-5,18,-1,STONE)
Block(-5,18,0,STONE)
Block(-5,18,1,quark:basalt:0)
Block(-5,18,2,STONE)
Block(-5,18,3,STONE)
Block(-5,18,4,STONE)
Block(-5,18,5,Leaves:7)
Block(-5,19,-5,STONE)
Block(-5,19,-4,STONE)
Block(-5,19,-3,STONE)
Block(-5,19,-2,STONE)
Block(-5,19,-1,STONE)
Block(-5,19,0,STONE)
Block(-5,19,1,quark:basalt:0)
Block(-5,19,2,STONE)
Block(-5,19,3,STONE)
Block(-5,19,4,STONE)
Block(-5,20,-6,STONE)
Block(-5,20,-5,STONE)
Block(-5,20,-4,STONE)
Block(-5,20,-3,STONE)
Block(-5,20,-2,STONE)
Block(-5,20,-1,STONE)
Block(-5,20,0,STONE)
Block(-5,20,1,STONE)
Block(-5,20,2,STONE)
Block(-5,20,3,STONE)
Block(-5,20,4,STONE)
Block(-5,21,-7,STONE)
Block(-5,21,-6,STONE)
Block(-5,21,-5,STONE)
Block(-5,21,-4,STONE)
Block(-5,21,-3,STONE)
Block(-5,21,-2,STONE)
Block(-5,21,-1,STONE)
Block(-5,21,0,STONE)
Block(-5,21,1,STONE)
Block(-5,21,2,STONE)
Block(-5,21,3,STONE)
Block(-5,21,4,STONE)
Block(-5,21,5,STONE)
Block(-5,22,-9,STONE)
Block(-5,22,-8,STONE)
Block(-5,22,-7,STONE)
Block(-5,22,-6,STONE)
Block(-5,22,-5,STONE)
Block(-5,22,-4,STONE)
Block(-5,22,-3,STONE)
Block(-5,22,-2,STONE)
Block(-5,22,-1,STONE)
Block(-5,22,0,STONE)
Block(-5,22,1,STONE)
Block(-5,22,2,LOG_2:1)
Block(-5,22,3,STONE)
Block(-5,22,4,STONE)
Block(-5,22,5,quark:basalt:0)
Block(-5,22,6,quark:basalt:0)
Block(-5,22,7,quark:basalt:0)
Block(-5,22,8,STONE)
Block(-5,23,-10,STONE)
Block(-5,23,-9,STONE)
Block(-5,23,-8,STONE)
Block(-5,23,-7,STONE)
Block(-5,23,-6,STONE)
Block(-5,23,-5,STONE)
Block(-5,23,-4,STONE)
Block(-5,23,-3,STONE)
Block(-5,23,-2,STONE)
Block(-5,23,-1,STONE)
Block(-5,23,0,STONE)
Block(-5,23,1,LOG_2:1)
Block(-5,23,2,STONE)
Block(-5,23,3,STONE)
Block(-5,23,4,STONE)
Block(-5,23,5,STONE)
Block(-5,23,6,LOG_2)
Block(-5,23,7,STONE)
Block(-5,23,8,STONE)
Block(-5,23,9,STONE)
Block(-5,23,10,STONE)
Block(-5,24,-10,STONE)
Block(-5,24,-9,STONE)
Block(-5,24,-8,STONE)
Block(-5,24,-7,STONE)
Block(-5,24,-6,STONE)
Block(-5,24,-5,STONE)
Block(-5,24,-4,STONE)
Block(-5,24,-3,STONE)
Block(-5,24,-2,STONE)
Block(-5,24,-1,LOG_2:1)
Block(-5,24,0,STONE)
Block(-5,24,1,STONE)
Block(-5,24,2,STONE)
Block(-5,24,3,STONE)
Block(-5,24,4,STONE)
Block(-5,24,5,STONE)
Block(-5,24,6,STONE)
Block(-5,24,7,STONE)
Block(-5,24,8,STONE)
Block(-5,24,9,STONE)
Block(-5,24,10,STONE)
Block(-5,24,11,quark:basalt:0)
Block(-5,25,-12,STONE)
Block(-5,25,-11,STONE)
Block(-5,25,-10,STONE)
Block(-5,25,-9,STONE)
Block(-5,25,-8,STONE)
Block(-5,25,-7,LOG:2)
Block(-5,25,-6,STONE)
Block(-5,25,-5,LOG)
Block(-5,25,-4,STONE)
Block(-5,25,-3,STONE)
Block(-5,25,-2,STONE)
Block(-5,25,-1,STONE)
Block(-5,25,0,LOG:1)
Block(-5,25,1,STONE)
Block(-5,25,2,LOG)
Block(-5,25,3,STONE)
Block(-5,25,4,LOG:1)
Block(-5,25,5,STONE)
Block(-5,25,6,STONE)
Block(-5,25,7,STONE)
Block(-5,25,8,STONE)
Block(-5,25,9,STONE)
Block(-5,25,10,quark:basalt:0)
Block(-5,25,11,quark:basalt:0)
Block(-5,26,-12,STONE)
Block(-5,26,-11,STONE)
Block(-5,26,-10,STONE)
Block(-5,26,-9,STONE)
Block(-5,26,-8,STONE)
Block(-5,26,-7,LOG)
Block(-5,26,-6,STONE)
Block(-5,26,-5,STONE)
Block(-5,26,-4,STONE)
Block(-5,26,-3,STONE)
Block(-5,26,-2,STONE)
Block(-5,26,-1,STONE)
Block(-5,26,0,STONE)
Block(-5,26,1,STONE)
Block(-5,26,2,STONE)
Block(-5,26,3,LOG)
Block(-5,26,4,STONE)
Block(-5,26,5,STONE)
Block(-5,26,6,STONE)
Block(-5,26,7,STONE)
Block(-5,26,8,STONE)
Block(-5,26,9,STONE)
Block(-5,26,10,STONE)
Block(-5,26,11,quark:basalt:0)
Block(-5,27,-12,STONE)
Block(-5,27,-11,STONE)
Block(-5,27,-10,STONE)
Block(-5,27,-9,STONE)
Block(-5,27,-8,STONE)
Block(-5,27,-7,STONE)
Block(-5,27,-6,STONE)
Block(-5,27,-5,LOG_2:1)
Block(-5,27,-4,STONE)
Block(-5,27,-3,STONE)
Block(-5,27,-2,STONE)
Block(-5,27,-1,STONE)
Block(-5,27,0,STONE)
Block(-5,27,1,LOG)
Block(-5,27,2,STONE)
Block(-5,27,3,LOG_2)
Block(-5,27,4,STONE)
Block(-5,27,5,LOG)
Block(-5,27,6,STONE)
Block(-5,27,7,LOG:2)
Block(-5,27,8,STONE)
Block(-5,27,9,STONE)
Block(-5,27,10,STONE)
Block(-5,27,11,STONE)
Block(-4,0,-12,STONE)
Block(-4,0,-11,STONE)
Block(-4,0,-10,quark:basalt:0)
Block(-4,0,-9,STONE)
Block(-4,0,-8,STONE)
Block(-4,0,-7,STONE)
Block(-4,0,-6,STONE)
Block(-4,0,-5,STONE)
Block(-4,0,-4,STONE)
Block(-4,0,-3,STONE)
Block(-4,0,-2,STONE)
Block(-4,0,-1,STONE)
Block(-4,0,0,STONE)
Block(-4,0,1,STONE)
Block(-4,0,2,STONE)
Block(-4,0,3,STONE)
Block(-4,0,4,STONE)
Block(-4,0,5,STONE)
Block(-4,0,6,STONE)
Block(-4,0,7,STONE)
Block(-4,0,8,STONE)
Block(-4,0,9,STONE)
Block(-4,0,10,STONE)
Block(-4,0,11,quark:basalt:0)
Block(-4,0,12,STONE)
Block(-4,0,13,STONE)
Block(-4,1,-10,quark:basalt:0)
Block(-4,1,-9,quark:basalt:0)
Block(-4,1,-8,STONE)
Block(-4,1,-7,STONE)
Block(-4,1,-6,STONE)
Block(-4,1,-5,STONE)
Block(-4,1,-4,STONE)
Block(-4,1,-3,STONE)
Block(-4,1,-2,STONE)
Block(-4,1,-1,STONE)
Block(-4,1,0,STONE)
Block(-4,1,1,STONE)
Block(-4,1,2,STONE)
Block(-4,1,3,STONE)
Block(-4,1,4,STONE)
Block(-4,1,5,STONE)
Block(-4,1,6,STONE)
Block(-4,1,7,STONE)
Block(-4,1,8,STONE)
Block(-4,1,9,STONE)
Block(-4,1,10,STONE)
Block(-4,1,11,quark:basalt:0)
Block(-4,2,-10,quark:basalt:0)
Block(-4,2,-9,STONE)
Block(-4,2,-8,quark:basalt:0)
Block(-4,2,-7,STONE)
Block(-4,2,-6,STONE)
Block(-4,2,-5,STONE)
Block(-4,2,-4,STONE)
Block(-4,2,-3,STONE)
Block(-4,2,-2,STONE)
Block(-4,2,-1,LOG_2:1)
Block(-4,2,0,LOG:2)
Block(-4,2,1,STONE)
Block(-4,2,2,STONE)
Block(-4,2,3,STONE)
Block(-4,2,4,STONE)
Block(-4,2,5,STONE)
Block(-4,2,6,STONE)
Block(-4,2,7,STONE)
Block(-4,2,8,STONE)
Block(-4,2,9,STONE)
Block(-4,2,10,quark:basalt:0)
Block(-4,2,11,quark:basalt:0)
Block(-4,3,-9,STONE)
Block(-4,3,-8,STONE)
Block(-4,3,-7,STONE)
Block(-4,3,-6,STONE)
Block(-4,3,-5,STONE)
Block(-4,3,-4,STONE)
Block(-4,3,-3,LOG_2)
Block(-4,3,-2,LOG_2:1)
Block(-4,3,-1,LOG_2:1)
Block(-4,3,0,STONE)
Block(-4,3,1,LOG)
Block(-4,3,2,STONE)
Block(-4,3,3,LOG_2)
Block(-4,3,4,STONE)
Block(-4,3,5,LOG:1)
Block(-4,3,6,STONE)
Block(-4,3,7,STONE)
Block(-4,3,8,STONE)
Block(-4,3,9,STONE)
Block(-4,4,-9,STONE)
Block(-4,4,-8,STONE)
Block(-4,4,-7,STONE)
Block(-4,4,-6,STONE)
Block(-4,4,-5,LOG:2)
Block(-4,4,-4,LOG)
Block(-4,4,-3,STONE)
Block(-4,4,-2,STONE)
Block(-4,4,-1,STONE)
Block(-4,4,0,LOG_2)
Block(-4,4,1,LOG:2)
Block(-4,4,2,STONE)
Block(-4,4,3,STONE)
Block(-4,4,4,STONE)
Block(-4,4,5,STONE)
Block(-4,4,6,STONE)
Block(-4,4,7,STONE)
Block(-4,4,8,STONE)
Block(-4,4,9,STONE)
Block(-4,5,-8,STONE)
Block(-4,5,-7,STONE)
Block(-4,5,-6,STONE)
Block(-4,5,-5,STONE)
Block(-4,5,-4,STONE)
Block(-4,5,-3,STONE)
Block(-4,5,-2,STONE)
Block(-4,5,-1,STONE)
Block(-4,5,0,STONE)
Block(-4,5,1,STONE)
Block(-4,5,2,STONE)
Block(-4,5,3,STONE)
Block(-4,5,4,STONE)
Block(-4,5,5,STONE)
Block(-4,5,6,STONE)
Block(-4,5,7,quark:basalt:0)
Block(-4,5,8,STONE)
Block(-4,6,-7,STONE)
Block(-4,6,-6,STONE)
Block(-4,6,-5,quark:basalt:0)
Block(-4,6,-4,STONE)
Block(-4,6,-3,STONE)
Block(-4,6,-2,LOG:2)
Block(-4,6,-1,LOG_2:1)
Block(-4,6,0,LOG_2)
Block(-4,6,1,LOG_2)
Block(-4,6,2,STONE)
Block(-4,6,3,STONE)
Block(-4,6,4,STONE)
Block(-4,6,5,STONE)
Block(-4,6,6,quark:basalt:0)
Block(-4,6,7,quark:basalt:0)
Block(-4,6,8,quark:basalt:0)
Block(-4,7,-7,STONE)
Block(-4,7,-6,STONE)
Block(-4,7,-5,STONE)
Block(-4,7,-4,quark:basalt:0)
Block(-4,7,-3,STONE)
Block(-4,7,-2,STONE)
Block(-4,7,-1,STONE)
Block(-4,7,0,STONE)
Block(-4,7,1,STONE)
Block(-4,7,2,STONE)
Block(-4,7,3,STONE)
Block(-4,7,4,STONE)
Block(-4,7,5,STONE)
Block(-4,7,6,quark:basalt:0)
Block(-4,7,7,quark:basalt:0)
Block(-4,8,-6,STONE)
Block(-4,8,-5,quark:basalt:0)
Block(-4,8,-4,STONE)
Block(-4,8,-3,STONE)
Block(-4,8,-2,STONE)
Block(-4,8,-1,STONE)
Block(-4,8,0,STONE)
Block(-4,8,1,STONE)
Block(-4,8,2,STONE)
Block(-4,8,3,STONE)
Block(-4,8,4,STONE)
Block(-4,8,5,quark:basalt:0)
Block(-4,8,6,quark:basalt:0)
Block(-4,8,7,quark:basalt:0)
Block(-4,9,-6,quark:basalt:0)
Block(-4,9,-5,quark:basalt:0)
Block(-4,9,-4,quark:basalt:0)
Block(-4,9,-3,STONE)
Block(-4,9,-2,quark:basalt:0)
Block(-4,9,-1,STONE)
Block(-4,9,0,STONE)
Block(-4,9,1,STONE)
Block(-4,9,2,STONE)
Block(-4,9,3,STONE)
Block(-4,9,4,STONE)
Block(-4,9,5,STONE)
Block(-4,9,6,quark:basalt:0)
Block(-4,10,-5,quark:basalt:0)
Block(-4,10,-4,quark:basalt:0)
Block(-4,10,-3,quark:basalt:0)
Block(-4,10,-2,quark:basalt:0)
Block(-4,10,-1,LOG)
Block(-4,10,0,STONE)
Block(-4,10,1,STONE)
Block(-4,10,2,STONE)
Block(-4,10,3,STONE)
Block(-4,10,4,STONE)
Block(-4,10,5,STONE)
Block(-4,11,-5,quark:basalt:0)
Block(-4,11,-4,quark:basalt:0)
Block(-4,11,-3,quark:basalt:0)
Block(-4,11,-2,quark:basalt:0)
Block(-4,11,-1,quark:basalt:0)
Block(-4,11,0,STONE)
Block(-4,11,1,STONE)
Block(-4,11,2,quark:basalt:0)
Block(-4,11,3,STONE)
Block(-4,11,4,STONE)
Block(-4,11,5,STONE)
Block(-4,11,6,Leaves:7)
Block(-4,12,-2,quark:basalt:0)
Block(-4,12,-1,quark:basalt:0)
Block(-4,12,0,STONE)
Block(-4,12,1,quark:basalt:0)
Block(-4,12,2,quark:basalt:0)
Block(-4,12,3,STONE)
Block(-4,12,4,STONE)
Block(-4,12,5,STONE)
Block(-4,13,-4,STONE)
Block(-4,13,-3,STONE)
Block(-4,13,-2,quark:basalt:0)
Block(-4,13,-1,STONE)
Block(-4,13,0,STONE)
Block(-4,13,1,STONE)
Block(-4,13,2,STONE)
Block(-4,13,3,STONE)
Block(-4,13,4,STONE)
Block(-4,14,-4,STONE)
Block(-4,14,-3,STONE)
Block(-4,14,-2,STONE)
Block(-4,14,-1,STONE)
Block(-4,14,0,STONE)
Block(-4,14,1,STONE)
Block(-4,14,2,STONE)
Block(-4,14,3,STONE)
Block(-4,14,4,STONE)
Block(-4,15,-4,STONE)
Block(-4,15,-3,STONE)
Block(-4,15,-2,STONE)
Block(-4,15,-1,STONE)
Block(-4,15,0,STONE)
Block(-4,15,1,STONE)
Block(-4,15,2,STONE)
Block(-4,15,3,STONE)
Block(-4,15,4,STONE)
Block(-4,15,5,Leaves:7)
Block(-4,16,-3,STONE)
Block(-4,16,-2,STONE)
Block(-4,16,-1,STONE)
Block(-4,16,0,STONE)
Block(-4,16,1,STONE)
Block(-4,16,2,STONE)
Block(-4,16,3,STONE)
Block(-4,16,4,quark:basalt:0)
Block(-4,17,-3,STONE)
Block(-4,17,-2,STONE)
Block(-4,17,-1,STONE)
Block(-4,17,0,STONE)
Block(-4,17,1,STONE)
Block(-4,17,2,STONE)
Block(-4,17,3,STONE)
Block(-4,17,4,STONE)
Block(-4,18,-4,STONE)
Block(-4,18,-3,STONE)
Block(-4,18,-2,STONE)
Block(-4,18,-1,STONE)
Block(-4,18,0,STONE)
Block(-4,18,1,STONE)
Block(-4,18,2,STONE)
Block(-4,18,3,STONE)
Block(-4,18,4,STONE)
Block(-4,19,-5,STONE)
Block(-4,19,-4,STONE)
Block(-4,19,-3,LOG)
Block(-4,19,-2,STONE)
Block(-4,19,-1,STONE)
Block(-4,19,0,STONE)
Block(-4,19,1,STONE)
Block(-4,19,2,STONE)
Block(-4,19,3,STONE)
Block(-4,19,4,STONE)
Block(-4,19,5,STONE)
Block(-4,20,-6,STONE)
Block(-4,20,-5,STONE)
Block(-4,20,-4,STONE)
Block(-4,20,-3,STONE)
Block(-4,20,-2,LOG_2:1)
Block(-4,20,-1,STONE)
Block(-4,20,0,STONE)
Block(-4,20,1,STONE)
Block(-4,20,2,STONE)
Block(-4,20,3,STONE)
Block(-4,20,4,STONE)
Block(-4,20,5,quark:basalt:0)
Block(-4,21,-7,STONE)
Block(-4,21,-6,STONE)
Block(-4,21,-5,STONE)
Block(-4,21,-4,LOG_2:1)
Block(-4,21,-3,STONE)
Block(-4,21,-2,LOG:2)
Block(-4,21,-1,STONE)
Block(-4,21,0,STONE)
Block(-4,21,1,STONE)
Block(-4,21,2,STONE)
Block(-4,21,3,STONE)
Block(-4,21,4,STONE)
Block(-4,21,5,quark:basalt:0)
Block(-4,21,6,quark:basalt:0)
Block(-4,21,8,STONE)
Block(-4,22,-9,STONE)
Block(-4,22,-8,STONE)
Block(-4,22,-7,STONE)
Block(-4,22,-6,STONE)
Block(-4,22,-5,STONE)
Block(-4,22,-4,STONE)
Block(-4,22,-3,STONE)
Block(-4,22,-2,LOG:1)
Block(-4,22,-1,STONE)
Block(-4,22,0,STONE)
Block(-4,22,1,LOG:2)
Block(-4,22,2,LOG:1)
Block(-4,22,3,STONE)
Block(-4,22,4,STONE)
Block(-4,22,5,STONE)
Block(-4,22,6,STONE)
Block(-4,22,7,STONE)
Block(-4,22,8,quark:basalt:0)
Block(-4,22,9,quark:basalt:0)
Block(-4,23,-9,STONE)
Block(-4,23,-8,STONE)
Block(-4,23,-7,STONE)
Block(-4,23,-6,STONE)
Block(-4,23,-5,STONE)
Block(-4,23,-4,LOG)
Block(-4,23,-3,LOG:1)
Block(-4,23,-2,LOG)
Block(-4,23,-1,STONE)
Block(-4,23,0,STONE)
Block(-4,23,1,LOG_2)
Block(-4,23,2,STONE)
Block(-4,23,3,STONE)
Block(-4,23,4,STONE)
Block(-4,23,5,STONE)
Block(-4,23,6,STONE)
Block(-4,23,7,STONE)
Block(-4,23,8,STONE)
Block(-4,23,9,quark:basalt:0)
Block(-4,23,10,quark:basalt:0)
Block(-4,24,-11,STONE)
Block(-4,24,-10,STONE)
Block(-4,24,-9,STONE)
Block(-4,24,-8,STONE)
Block(-4,24,-7,STONE)
Block(-4,24,-6,STONE)
Block(-4,24,-5,STONE)
Block(-4,24,-4,STONE)
Block(-4,24,-3,LOG:1)
Block(-4,24,-2,STONE)
Block(-4,24,-1,STONE)
Block(-4,24,0,STONE)
Block(-4,24,1,STONE)
Block(-4,24,2,STONE)
Block(-4,24,3,LOG:2)
Block(-4,24,4,STONE)
Block(-4,24,5,STONE)
Block(-4,24,6,STONE)
Block(-4,24,7,STONE)
Block(-4,24,8,STONE)
Block(-4,24,9,STONE)
Block(-4,24,10,quark:basalt:0)
Block(-4,24,11,quark:basalt:0)
Block(-4,25,-13,STONE)
Block(-4,25,-12,STONE)
Block(-4,25,-11,STONE)
Block(-4,25,-10,STONE)
Block(-4,25,-9,STONE)
Block(-4,25,-8,STONE)
Block(-4,25,-7,STONE)
Block(-4,25,-6,STONE)
Block(-4,25,-5,STONE)
Block(-4,25,-4,STONE)
Block(-4,25,-3,STONE)
Block(-4,25,-2,LOG:2)
Block(-4,25,-1,STONE)
Block(-4,25,0,STONE)
Block(-4,25,1,STONE)
Block(-4,25,2,LOG:2)
Block(-4,25,3,STONE)
Block(-4,25,4,LOG)
Block(-4,25,5,LOG_2:1)
Block(-4,25,6,STONE)
Block(-4,25,7,STONE)
Block(-4,25,8,STONE)
Block(-4,25,9,STONE)
Block(-4,25,10,quark:basalt:0)
Block(-4,25,11,quark:basalt:0)
Block(-4,26,-13,STONE)
Block(-4,26,-12,STONE)
Block(-4,26,-11,STONE)
Block(-4,26,-10,STONE)
Block(-4,26,-9,STONE)
Block(-4,26,-8,STONE)
Block(-4,26,-7,STONE)
Block(-4,26,-6,LOG_2:1)
Block(-4,26,-5,STONE)
Block(-4,26,-4,LOG_2)
Block(-4,26,-3,STONE)
Block(-4,26,-2,STONE)
Block(-4,26,-1,STONE)
Block(-4,26,0,LOG_2)
Block(-4,26,1,STONE)
Block(-4,26,2,STONE)
Block(-4,26,3,STONE)
Block(-4,26,4,STONE)
Block(-4,26,5,LOG_2)
Block(-4,26,6,STONE)
Block(-4,26,7,STONE)
Block(-4,26,8,STONE)
Block(-4,26,9,STONE)
Block(-4,26,10,quark:basalt:0)
Block(-4,26,11,quark:basalt:0)
Block(-4,27,-11,STONE)
Block(-4,27,-10,STONE)
Block(-4,27,-9,STONE)
Block(-4,27,-8,STONE)
Block(-4,27,-7,STONE)
Block(-4,27,-6,LOG_2:1)
Block(-4,27,-5,LOG:2)
Block(-4,27,-4,LOG:1)
Block(-4,27,-3,STONE)
Block(-4,27,-2,LOG_2)
Block(-4,27,-1,STONE)
Block(-4,27,0,STONE)
Block(-4,27,1,STONE)
Block(-4,27,2,STONE)
Block(-4,27,3,LOG)
Block(-4,27,4,LOG)
Block(-4,27,5,STONE)
Block(-4,27,6,LOG:2)
Block(-4,27,7,STONE)
Block(-4,27,8,STONE)
Block(-4,27,9,STONE)
Block(-4,27,10,STONE)
Block(-4,27,11,STONE)
Block(-3,0,-12,STONE)
Block(-3,0,-11,STONE)
Block(-3,0,-10,STONE)
Block(-3,0,-9,STONE)
Block(-3,0,-8,STONE)
Block(-3,0,-7,STONE)
Block(-3,0,-6,STONE)
Block(-3,0,-5,STONE)
Block(-3,0,-4,STONE)
Block(-3,0,-3,STONE)
Block(-3,0,-2,STONE)
Block(-3,0,-1,STONE)
Block(-3,0,0,STONE)
Block(-3,0,1,STONE)
Block(-3,0,2,STONE)
Block(-3,0,3,STONE)
Block(-3,0,4,STONE)
Block(-3,0,5,STONE)
Block(-3,0,6,STONE)
Block(-3,0,7,STONE)
Block(-3,0,8,STONE)
Block(-3,0,9,STONE)
Block(-3,0,10,STONE)
Block(-3,0,11,quark:basalt:0)
Block(-3,0,12,STONE)
Block(-3,0,13,STONE)
Block(-3,0,14,Leaves:7)
Block(-3,1,-11,STONE)
Block(-3,1,-10,STONE)
Block(-3,1,-9,STONE)
Block(-3,1,-8,STONE)
Block(-3,1,-7,STONE)
Block(-3,1,-6,STONE)
Block(-3,1,-5,STONE)
Block(-3,1,-4,STONE)
Block(-3,1,-3,STONE)
Block(-3,1,-2,STONE)
Block(-3,1,-1,STONE)
Block(-3,1,0,STONE)
Block(-3,1,1,STONE)
Block(-3,1,2,STONE)
Block(-3,1,3,STONE)
Block(-3,1,4,STONE)
Block(-3,1,5,STONE)
Block(-3,1,6,STONE)
Block(-3,1,7,STONE)
Block(-3,1,8,STONE)
Block(-3,1,9,STONE)
Block(-3,1,10,quark:basalt:0)
Block(-3,1,11,quark:basalt:0)
Block(-3,1,12,STONE)
Block(-3,1,13,Leaves:7)
Block(-3,2,-10,STONE)
Block(-3,2,-9,STONE)
Block(-3,2,-8,STONE)
Block(-3,2,-7,STONE)
Block(-3,2,-6,STONE)
Block(-3,2,-5,STONE)
Block(-3,2,-4,LOG)
Block(-3,2,-3,STONE)
Block(-3,2,-2,LOG:2)
Block(-3,2,-1,STONE)
Block(-3,2,0,STONE)
Block(-3,2,1,LOG)
Block(-3,2,2,STONE)
Block(-3,2,3,STONE)
Block(-3,2,4,STONE)
Block(-3,2,5,LOG_2)
Block(-3,2,6,STONE)
Block(-3,2,7,STONE)
Block(-3,2,8,STONE)
Block(-3,2,9,STONE)
Block(-3,2,10,quark:basalt:0)
Block(-3,2,11,STONE)
Block(-3,3,-10,quark:basalt:0)
Block(-3,3,-9,quark:basalt:0)
Block(-3,3,-8,quark:basalt:0)
Block(-3,3,-7,STONE)
Block(-3,3,-6,LOG:2)
Block(-3,3,-5,STONE)
Block(-3,3,-4,LOG_2)
Block(-3,3,-3,STONE)
Block(-3,3,-2,LOG_2:1)
Block(-3,3,-1,LOG_2)
Block(-3,3,0,STONE)
Block(-3,3,1,LOG:2)
Block(-3,3,2,STONE)
Block(-3,3,3,STONE)
Block(-3,3,4,LOG_2:1)
Block(-3,3,5,STONE)
Block(-3,3,6,STONE)
Block(-3,3,7,STONE)
Block(-3,3,8,STONE)
Block(-3,3,9,STONE)
Block(-3,3,10,quark:basalt:0)
Block(-3,4,-9,quark:basalt:0)
Block(-3,4,-8,STONE)
Block(-3,4,-7,quark:basalt:0)
Block(-3,4,-6,STONE)
Block(-3,4,-5,STONE)
Block(-3,4,-4,STONE)
Block(-3,4,-3,STONE)
Block(-3,4,-2,STONE)
Block(-3,4,-1,LOG)
Block(-3,4,0,STONE)
Block(-3,4,1,LOG:2)
Block(-3,4,2,STONE)
Block(-3,4,3,STONE)
Block(-3,4,4,STONE)
Block(-3,4,5,LOG)
Block(-3,4,6,STONE)
Block(-3,4,7,STONE)
Block(-3,4,8,STONE)
Block(-3,4,9,quark:basalt:0)
Block(-3,5,-8,STONE)
Block(-3,5,-7,STONE)
Block(-3,5,-6,STONE)
Block(-3,5,-5,STONE)
Block(-3,5,-4,STONE)
Block(-3,5,-3,LOG_2:1)
Block(-3,5,-2,STONE)
Block(-3,5,-1,LOG)
Block(-3,5,0,STONE)
Block(-3,5,1,STONE)
Block(-3,5,2,STONE)
Block(-3,5,3,STONE)
Block(-3,5,4,STONE)
Block(-3,5,5,STONE)
Block(-3,5,6,STONE)
Block(-3,5,7,STONE)
Block(-3,5,8,STONE)
Block(-3,5,9,STONE)
Block(-3,6,-8,STONE)
Block(-3,6,-7,STONE)
Block(-3,6,-6,STONE)
Block(-3,6,-5,STONE)
Block(-3,6,-4,STONE)
Block(-3,6,-3,LOG_2:1)
Block(-3,6,-2,LOG_2)
Block(-3,6,-1,LOG_2:1)
Block(-3,6,0,STONE)
Block(-3,6,1,STONE)
Block(-3,6,2,LOG:2)
Block(-3,6,3,LOG_2)
Block(-3,6,4,STONE)
Block(-3,6,5,STONE)
Block(-3,6,6,STONE)
Block(-3,6,7,STONE)
Block(-3,6,8,STONE)
Block(-3,6,9,STONE)
Block(-3,7,-8,Leaves:7)
Block(-3,7,-7,STONE)
Block(-3,7,-6,STONE)
Block(-3,7,-5,LOG_2:1)
Block(-3,7,-4,quark:basalt:0)
Block(-3,7,-3,LOG_2:1)
Block(-3,7,-2,STONE)
Block(-3,7,-1,STONE)
Block(-3,7,0,STONE)
Block(-3,7,1,STONE)
Block(-3,7,2,LOG:1)
Block(-3,7,3,STONE)
Block(-3,7,4,STONE)
Block(-3,7,5,STONE)
Block(-3,7,6,STONE)
Block(-3,7,7,STONE)
Block(-3,8,-7,Leaves:7)
Block(-3,8,-6,STONE)
Block(-3,8,-5,quark:basalt:0)
Block(-3,8,-4,quark:basalt:0)
Block(-3,8,-3,quark:basalt:0)
Block(-3,8,-2,STONE)
Block(-3,8,-1,LOG:2)
Block(-3,8,0,LOG:2)
Block(-3,8,1,STONE)
Block(-3,8,2,STONE)
Block(-3,8,3,STONE)
Block(-3,8,4,STONE)
Block(-3,8,5,STONE)
Block(-3,8,6,quark:basalt:0)
Block(-3,8,7,STONE)
Block(-3,9,-6,quark:basalt:0)
Block(-3,9,-5,quark:basalt:0)
Block(-3,9,-4,quark:basalt:0)
Block(-3,9,-3,quark:basalt:0)
Block(-3,9,-2,STONE)
Block(-3,9,-1,STONE)
Block(-3,9,0,LOG_2:1)
Block(-3,9,1,LOG:2)
Block(-3,9,2,STONE)
Block(-3,9,3,STONE)
Block(-3,9,4,STONE)
Block(-3,9,5,quark:basalt:0)
Block(-3,9,6,quark:basalt:0)
Block(-3,10,-6,quark:basalt:0)
Block(-3,10,-5,quark:basalt:0)
Block(-3,10,-4,quark:basalt:0)
Block(-3,10,-3,quark:basalt:0)
Block(-3,10,-2,quark:basalt:0)
Block(-3,10,-1,LOG)
Block(-3,10,0,STONE)
Block(-3,10,1,STONE)
Block(-3,10,2,STONE)
Block(-3,10,3,STONE)
Block(-3,10,4,STONE)
Block(-3,10,5,STONE)
Block(-3,11,-5,quark:basalt:0)
Block(-3,11,-4,quark:basalt:0)
Block(-3,11,-3,quark:basalt:0)
Block(-3,11,-2,STONE)
Block(-3,11,-1,STONE)
Block(-3,11,0,STONE)
Block(-3,11,1,LOG:2)
Block(-3,11,2,STONE)
Block(-3,11,3,STONE)
Block(-3,11,4,STONE)
Block(-3,11,5,quark:basalt:0)
Block(-3,12,-5,quark:basalt:0)
Block(-3,12,-4,quark:basalt:0)
Block(-3,12,-3,STONE)
Block(-3,12,-2,STONE)
Block(-3,12,-1,STONE)
Block(-3,12,0,STONE)
Block(-3,12,1,LOG)
Block(-3,12,2,STONE)
Block(-3,12,3,STONE)
Block(-3,12,4,quark:basalt:0)
Block(-3,12,5,quark:basalt:0)
Block(-3,13,-4,quark:basalt:0)
Block(-3,13,-3,quark:basalt:0)
Block(-3,13,-2,STONE)
Block(-3,13,-1,STONE)
Block(-3,13,0,STONE)
Block(-3,13,1,STONE)
Block(-3,13,2,STONE)
Block(-3,13,3,quark:basalt:0)
Block(-3,13,4,quark:basalt:0)
Block(-3,13,5,quark:basalt:0)
Block(-3,14,-4,quark:basalt:0)
Block(-3,14,-3,STONE)
Block(-3,14,-2,STONE)
Block(-3,14,-1,STONE)
Block(-3,14,0,STONE)
Block(-3,14,1,STONE)
Block(-3,14,2,STONE)
Block(-3,14,3,quark:basalt:0)
Block(-3,14,4,quark:basalt:0)
Block(-3,15,-4,quark:basalt:0)
Block(-3,15,-3,STONE)
Block(-3,15,-2,STONE)
Block(-3,15,-1,STONE)
Block(-3,15,0,STONE)
Block(-3,15,1,STONE)
Block(-3,15,2,STONE)
Block(-3,15,3,quark:basalt:0)
Block(-3,15,4,quark:basalt:0)
Block(-3,16,-4,STONE)
Block(-3,16,-3,STONE)
Block(-3,16,-2,STONE)
Block(-3,16,-1,STONE)
Block(-3,16,0,STONE)
Block(-3,16,1,STONE)
Block(-3,16,2,STONE)
Block(-3,16,3,quark:basalt:0)
Block(-3,16,4,quark:basalt:0)
Block(-3,16,5,quark:basalt:0)
Block(-3,17,-3,STONE)
Block(-3,17,-2,STONE)
Block(-3,17,-1,STONE)
Block(-3,17,0,STONE)
Block(-3,17,1,STONE)
Block(-3,17,2,STONE)
Block(-3,17,3,quark:basalt:0)
Block(-3,17,4,quark:basalt:0)
Block(-3,17,5,quark:basalt:0)
Block(-3,18,-3,STONE)
Block(-3,18,-2,LOG_2)
Block(-3,18,-1,STONE)
Block(-3,18,0,STONE)
Block(-3,18,1,STONE)
Block(-3,18,2,STONE)
Block(-3,18,3,STONE)
Block(-3,18,4,quark:basalt:0)
Block(-3,18,5,quark:basalt:0)
Block(-3,19,-5,STONE)
Block(-3,19,-4,STONE)
Block(-3,19,-3,STONE)
Block(-3,19,-2,STONE)
Block(-3,19,-1,LOG:2)
Block(-3,19,0,STONE)
Block(-3,19,1,LOG:2)
Block(-3,19,2,STONE)
Block(-3,19,3,STONE)
Block(-3,19,4,quark:basalt:0)
Block(-3,19,5,quark:basalt:0)
Block(-3,19,6,quark:basalt:0)
Block(-3,20,-5,STONE)
Block(-3,20,-4,STONE)
Block(-3,20,-3,LOG:1)
Block(-3,20,-2,LOG)
Block(-3,20,-1,STONE)
Block(-3,20,0,LOG:2)
Block(-3,20,1,STONE)
Block(-3,20,2,STONE)
Block(-3,20,3,STONE)
Block(-3,20,4,quark:basalt:0)
Block(-3,20,5,quark:basalt:0)
Block(-3,20,6,quark:basalt:0)
Block(-3,21,-7,STONE)
Block(-3,21,-6,STONE)
Block(-3,21,-5,STONE)
Block(-3,21,-4,STONE)
Block(-3,21,-3,STONE)
Block(-3,21,-2,STONE)
Block(-3,21,-1,STONE)
Block(-3,21,0,STONE)
Block(-3,21,1,STONE)
Block(-3,21,2,STONE)
Block(-3,21,3,STONE)
Block(-3,21,4,STONE)
Block(-3,21,5,STONE)
Block(-3,21,6,quark:basalt:0)
Block(-3,22,-9,STONE)
Block(-3,22,-8,STONE)
Block(-3,22,-7,STONE)
Block(-3,22,-6,STONE)
Block(-3,22,-5,STONE)
Block(-3,22,-4,STONE)
Block(-3,22,-3,STONE)
Block(-3,22,-2,STONE)
Block(-3,22,-1,STONE)
Block(-3,22,0,STONE)
Block(-3,22,1,STONE)
Block(-3,22,2,STONE)
Block(-3,22,3,STONE)
Block(-3,22,4,LOG)
Block(-3,22,5,STONE)
Block(-3,22,6,STONE)
Block(-3,22,7,STONE)
Block(-3,22,8,quark:basalt:0)
Block(-3,23,-10,STONE)
Block(-3,23,-9,STONE)
Block(-3,23,-8,STONE)
Block(-3,23,-7,STONE)
Block(-3,23,-6,STONE)
Block(-3,23,-5,STONE)
Block(-3,23,-4,STONE)
Block(-3,23,-3,STONE)
Block(-3,23,-2,STONE)
Block(-3,23,-1,STONE)
Block(-3,23,0,STONE)
Block(-3,23,1,STONE)
Block(-3,23,2,STONE)
Block(-3,23,3,LOG_2:1)
Block(-3,23,4,STONE)
Block(-3,23,5,STONE)
Block(-3,23,6,LOG)
Block(-3,23,7,STONE)
Block(-3,23,8,quark:basalt:0)
Block(-3,23,9,quark:basalt:0)
Block(-3,23,10,quark:basalt:0)
Block(-3,24,-13,STONE)
Block(-3,24,-12,STONE)
Block(-3,24,-11,STONE)
Block(-3,24,-10,STONE)
Block(-3,24,-9,STONE)
Block(-3,24,-8,STONE)
Block(-3,24,-7,STONE)
Block(-3,24,-6,STONE)
Block(-3,24,-5,STONE)
Block(-3,24,-4,STONE)
Block(-3,24,-3,STONE)
Block(-3,24,-2,STONE)
Block(-3,24,-1,STONE)
Block(-3,24,0,LOG_2)
Block(-3,24,1,LOG:2)
Block(-3,24,2,STONE)
Block(-3,24,3,LOG_2:1)
Block(-3,24,4,LOG_2)
Block(-3,24,5,STONE)
Block(-3,24,6,STONE)
Block(-3,24,7,STONE)
Block(-3,24,8,STONE)
Block(-3,24,9,quark:basalt:0)
Block(-3,24,10,quark:basalt:0)
Block(-3,24,11,STONE)
Block(-3,25,-13,STONE)
Block(-3,25,-12,STONE)
Block(-3,25,-11,STONE)
Block(-3,25,-10,STONE)
Block(-3,25,-9,STONE)
Block(-3,25,-8,STONE)
Block(-3,25,-7,STONE)
Block(-3,25,-6,STONE)
Block(-3,25,-5,LOG:1)
Block(-3,25,-4,STONE)
Block(-3,25,-3,STONE)
Block(-3,25,-2,LOG:1)
Block(-3,25,-1,LOG_2)
Block(-3,25,0,LOG:1)
Block(-3,25,1,STONE)
Block(-3,25,2,STONE)
Block(-3,25,3,STONE)
Block(-3,25,4,LOG)
Block(-3,25,5,STONE)
Block(-3,25,6,STONE)
Block(-3,25,7,STONE)
Block(-3,25,8,STONE)
Block(-3,25,9,STONE)
Block(-3,25,10,STONE)
Block(-3,25,11,STONE)
Block(-3,26,-13,STONE)
Block(-3,26,-12,STONE)
Block(-3,26,-11,STONE)
Block(-3,26,-10,STONE)
Block(-3,26,-9,STONE)
Block(-3,26,-8,STONE)
Block(-3,26,-7,STONE)
Block(-3,26,-6,STONE)
Block(-3,26,-5,STONE)
Block(-3,26,-4,STONE)
Block(-3,26,-3,LOG)
Block(-3,26,-2,STONE)
Block(-3,26,-1,STONE)
Block(-3,26,0,STONE)
Block(-3,26,1,STONE)
Block(-3,26,2,STONE)
Block(-3,26,3,STONE)
Block(-3,26,4,STONE)
Block(-3,26,5,STONE)
Block(-3,26,6,STONE)
Block(-3,26,7,STONE)
Block(-3,26,8,STONE)
Block(-3,26,9,STONE)
Block(-3,26,10,STONE)
Block(-3,26,11,STONE)
Block(-3,27,-12,STONE)
Block(-3,27,-11,STONE)
Block(-3,27,-10,STONE)
Block(-3,27,-9,STONE)
Block(-3,27,-8,LOG_2)
Block(-3,27,-7,LOG_2:1)
Block(-3,27,-6,STONE)
Block(-3,27,-5,LOG)
Block(-3,27,-4,STONE)
Block(-3,27,-3,STONE)
Block(-3,27,-2,STONE)
Block(-3,27,-1,STONE)
Block(-3,27,0,STONE)
Block(-3,27,1,LOG:1)
Block(-3,27,2,STONE)
Block(-3,27,3,LOG_2)
Block(-3,27,4,LOG)
Block(-3,27,5,STONE)
Block(-3,27,6,STONE)
Block(-3,27,7,LOG_2:1)
Block(-3,27,8,LOG)
Block(-3,27,9,STONE)
Block(-3,27,10,STONE)
Block(-3,27,11,STONE)
Block(-2,0,-12,STONE)
Block(-2,0,-11,STONE)
Block(-2,0,-10,STONE)
Block(-2,0,-9,STONE)
Block(-2,0,-8,STONE)
Block(-2,0,-7,STONE)
Block(-2,0,-6,STONE)
Block(-2,0,-5,STONE)
Block(-2,0,-4,STONE)
Block(-2,0,-3,STONE)
Block(-2,0,-2,STONE)
Block(-2,0,-1,STONE)
Block(-2,0,0,STONE)
Block(-2,0,1,STONE)
Block(-2,0,2,STONE)
Block(-2,0,3,STONE)
Block(-2,0,4,STONE)
Block(-2,0,5,STONE)
Block(-2,0,6,STONE)
Block(-2,0,7,STONE)
Block(-2,0,8,STONE)
Block(-2,0,9,STONE)
Block(-2,0,10,STONE)
Block(-2,0,11,quark:basalt:0)
Block(-2,0,12,STONE)
Block(-2,0,13,STONE)
Block(-2,1,-12,STONE)
Block(-2,1,-11,STONE)
Block(-2,1,-10,STONE)
Block(-2,1,-9,STONE)
Block(-2,1,-8,STONE)
Block(-2,1,-7,STONE)
Block(-2,1,-6,STONE)
Block(-2,1,-5,STONE)
Block(-2,1,-4,STONE)
Block(-2,1,-3,STONE)
Block(-2,1,-2,STONE)
Block(-2,1,-1,STONE)
Block(-2,1,0,STONE)
Block(-2,1,1,STONE)
Block(-2,1,2,STONE)
Block(-2,1,3,STONE)
Block(-2,1,4,STONE)
Block(-2,1,5,STONE)
Block(-2,1,6,STONE)
Block(-2,1,7,STONE)
Block(-2,1,8,STONE)
Block(-2,1,9,STONE)
Block(-2,1,10,STONE)
Block(-2,1,11,STONE)
Block(-2,1,12,STONE)
Block(-2,2,-11,STONE)
Block(-2,2,-10,STONE)
Block(-2,2,-9,STONE)
Block(-2,2,-8,LOG)
Block(-2,2,-7,STONE)
Block(-2,2,-6,STONE)
Block(-2,2,-5,LOG_2:1)
Block(-2,2,-4,STONE)
Block(-2,2,-3,STONE)
Block(-2,2,-2,STONE)
Block(-2,2,-1,LOG:1)
Block(-2,2,0,LOG:1)
Block(-2,2,1,STONE)
Block(-2,2,2,STONE)
Block(-2,2,3,STONE)
Block(-2,2,4,STONE)
Block(-2,2,5,STONE)
Block(-2,2,6,STONE)
Block(-2,2,7,STONE)
Block(-2,2,8,STONE)
Block(-2,2,9,STONE)
Block(-2,2,10,quark:basalt:0)
Block(-2,2,11,STONE)
Block(-2,2,12,STONE)
Block(-2,3,-10,STONE)
Block(-2,3,-9,quark:basalt:0)
Block(-2,3,-8,STONE)
Block(-2,3,-7,STONE)
Block(-2,3,-6,STONE)
Block(-2,3,-5,STONE)
Block(-2,3,-4,LOG_2)
Block(-2,3,-3,STONE)
Block(-2,3,-2,STONE)
Block(-2,3,-1,LOG)
Block(-2,3,0,STONE)
Block(-2,3,1,STONE)
Block(-2,3,2,STONE)
Block(-2,3,3,LOG_2:1)
Block(-2,3,4,STONE)
Block(-2,3,5,STONE)
Block(-2,3,6,STONE)
Block(-2,3,7,STONE)
Block(-2,3,8,STONE)
Block(-2,3,9,quark:basalt:0)
Block(-2,3,10,quark:basalt:0)
Block(-2,3,11,STONE)
Block(-2,4,-10,quark:basalt:0)
Block(-2,4,-9,quark:basalt:0)
Block(-2,4,-8,quark:basalt:0)
Block(-2,4,-7,quark:basalt:0)
Block(-2,4,-6,LOG:2)
Block(-2,4,-5,STONE)
Block(-2,4,-4,STONE)
Block(-2,4,-3,STONE)
Block(-2,4,-2,STONE)
Block(-2,4,-1,STONE)
Block(-2,4,0,STONE)
Block(-2,4,1,STONE)
Block(-2,4,2,STONE)
Block(-2,4,3,LOG_2)
Block(-2,4,4,LOG_2)
Block(-2,4,5,STONE)
Block(-2,4,6,STONE)
Block(-2,4,7,STONE)
Block(-2,4,8,STONE)
Block(-2,4,9,quark:basalt:0)
Block(-2,4,10,quark:basalt:0)
Block(-2,5,-8,STONE)
Block(-2,5,-7,quark:basalt:0)
Block(-2,5,-6,STONE)
Block(-2,5,-5,STONE)
Block(-2,5,-4,STONE)
Block(-2,5,-3,STONE)
Block(-2,5,-2,STONE)
Block(-2,5,-1,LOG:1)
Block(-2,5,0,LOG_2)
Block(-2,5,1,STONE)
Block(-2,5,2,LOG:2)
Block(-2,5,3,STONE)
Block(-2,5,4,STONE)
Block(-2,5,5,STONE)
Block(-2,5,6,STONE)
Block(-2,5,7,STONE)
Block(-2,5,8,STONE)
Block(-2,5,9,quark:basalt:0)
Block(-2,5,10,quark:basalt:0)
Block(-2,6,-8,STONE)
Block(-2,6,-7,STONE)
Block(-2,6,-6,STONE)
Block(-2,6,-5,STONE)
Block(-2,6,-4,STONE)
Block(-2,6,-3,LOG_2)
Block(-2,6,-2,STONE)
Block(-2,6,-1,LOG_2:1)
Block(-2,6,0,STONE)
Block(-2,6,1,STONE)
Block(-2,6,2,LOG)
Block(-2,6,3,STONE)
Block(-2,6,4,STONE)
Block(-2,6,5,STONE)
Block(-2,6,6,STONE)
Block(-2,6,7,STONE)
Block(-2,6,8,STONE)
Block(-2,6,9,STONE)
Block(-2,7,-7,STONE)
Block(-2,7,-6,STONE)
Block(-2,7,-5,STONE)
Block(-2,7,-4,STONE)
Block(-2,7,-3,STONE)
Block(-2,7,-2,LOG)
Block(-2,7,-1,STONE)
Block(-2,7,0,STONE)
Block(-2,7,1,STONE)
Block(-2,7,2,LOG_2)
Block(-2,7,3,STONE)
Block(-2,7,4,STONE)
Block(-2,7,5,STONE)
Block(-2,7,6,STONE)
Block(-2,7,7,STONE)
Block(-2,8,-7,STONE)
Block(-2,8,-6,STONE)
Block(-2,8,-5,STONE)
Block(-2,8,-4,STONE)
Block(-2,8,-3,STONE)
Block(-2,8,-2,STONE)
Block(-2,8,-1,LOG:2)
Block(-2,8,0,LOG:2)
Block(-2,8,1,STONE)
Block(-2,8,2,STONE)
Block(-2,8,3,STONE)
Block(-2,8,4,STONE)
Block(-2,8,5,STONE)
Block(-2,8,6,STONE)
Block(-2,8,7,STONE)
Block(-2,9,-7,Leaves:7)
Block(-2,9,-6,STONE)
Block(-2,9,-5,STONE)
Block(-2,9,-4,STONE)
Block(-2,9,-3,STONE)
Block(-2,9,-2,STONE)
Block(-2,9,-1,LOG_2)
Block(-2,9,0,STONE)
Block(-2,9,1,LOG:2)
Block(-2,9,2,STONE)
Block(-2,9,3,STONE)
Block(-2,9,4,STONE)
Block(-2,9,5,STONE)
Block(-2,9,6,quark:basalt:0)
Block(-2,9,7,STONE)
Block(-2,10,-6,STONE)
Block(-2,10,-5,STONE)
Block(-2,10,-4,quark:basalt:0)
Block(-2,10,-3,STONE)
Block(-2,10,-2,LOG_2:1)
Block(-2,10,-1,STONE)
Block(-2,10,0,STONE)
Block(-2,10,1,STONE)
Block(-2,10,2,STONE)
Block(-2,10,3,STONE)
Block(-2,10,4,quark:basalt:0)
Block(-2,10,5,quark:basalt:0)
Block(-2,10,6,quark:basalt:0)
Block(-2,11,-6,STONE)
Block(-2,11,-5,quark:basalt:0)
Block(-2,11,-4,quark:basalt:0)
Block(-2,11,-3,STONE)
Block(-2,11,-2,STONE)
Block(-2,11,-1,STONE)
Block(-2,11,0,LOG:2)
Block(-2,11,1,STONE)
Block(-2,11,2,LOG_2)
Block(-2,11,3,STONE)
Block(-2,11,4,quark:basalt:0)
Block(-2,11,5,quark:basalt:0)
Block(-2,12,-5,quark:basalt:0)
Block(-2,12,-4,quark:basalt:0)
Block(-2,12,-3,quark:basalt:0)
Block(-2,12,-2,STONE)
Block(-2,12,-1,STONE)
Block(-2,12,0,LOG:2)
Block(-2,12,1,STONE)
Block(-2,12,2,STONE)
Block(-2,12,3,STONE)
Block(-2,12,4,quark:basalt:0)
Block(-2,12,5,quark:basalt:0)
Block(-2,13,-4,quark:basalt:0)
Block(-2,13,-3,quark:basalt:0)
Block(-2,13,-2,STONE)
Block(-2,13,-1,STONE)
Block(-2,13,0,STONE)
Block(-2,13,1,LOG:2)
Block(-2,13,2,STONE)
Block(-2,13,3,STONE)
Block(-2,13,4,quark:basalt:0)
Block(-2,13,5,quark:basalt:0)
Block(-2,14,-4,quark:basalt:0)
Block(-2,14,-3,quark:basalt:0)
Block(-2,14,-2,STONE)
Block(-2,14,-1,STONE)
Block(-2,14,0,STONE)
Block(-2,14,1,STONE)
Block(-2,14,2,STONE)
Block(-2,14,3,quark:basalt:0)
Block(-2,14,4,quark:basalt:0)
Block(-2,15,-5,quark:basalt:0)
Block(-2,15,-4,quark:basalt:0)
Block(-2,15,-3,STONE)
Block(-2,15,-2,STONE)
Block(-2,15,-1,STONE)
Block(-2,15,0,STONE)
Block(-2,15,1,STONE)
Block(-2,15,2,STONE)
Block(-2,15,3,STONE)
Block(-2,15,4,quark:basalt:0)
Block(-2,15,5,quark:basalt:0)
Block(-2,16,-5,quark:basalt:0)
Block(-2,16,-4,quark:basalt:0)
Block(-2,16,-3,STONE)
Block(-2,16,-2,STONE)
Block(-2,16,-1,STONE)
Block(-2,16,0,STONE)
Block(-2,16,1,STONE)
Block(-2,16,2,STONE)
Block(-2,16,3,quark:basalt:0)
Block(-2,16,4,quark:basalt:0)
Block(-2,16,5,quark:basalt:0)
Block(-2,17,-4,STONE)
Block(-2,17,-3,STONE)
Block(-2,17,-2,STONE)
Block(-2,17,-1,LOG_2)
Block(-2,17,0,STONE)
Block(-2,17,1,LOG:1)
Block(-2,17,2,STONE)
Block(-2,17,3,STONE)
Block(-2,17,4,quark:basalt:0)
Block(-2,17,5,quark:basalt:0)
Block(-2,18,-5,STONE)
Block(-2,18,-4,STONE)
Block(-2,18,-3,STONE)
Block(-2,18,-2,LOG_2)
Block(-2,18,-1,STONE)
Block(-2,18,0,STONE)
Block(-2,18,1,STONE)
Block(-2,18,2,STONE)
Block(-2,18,3,STONE)
Block(-2,18,4,quark:basalt:0)
Block(-2,18,5,quark:basalt:0)
Block(-2,19,-5,STONE)
Block(-2,19,-4,STONE)
Block(-2,19,-3,STONE)
Block(-2,19,-2,STONE)
Block(-2,19,-1,STONE)
Block(-2,19,0,STONE)
Block(-2,19,1,STONE)
Block(-2,19,2,STONE)
Block(-2,19,3,STONE)
Block(-2,19,4,quark:basalt:0)
Block(-2,19,5,quark:basalt:0)
Block(-2,19,6,quark:basalt:0)
Block(-2,20,-7,STONE)
Block(-2,20,-6,STONE)
Block(-2,20,-5,STONE)
Block(-2,20,-4,LOG)
Block(-2,20,-3,STONE)
Block(-2,20,-2,LOG:1)
Block(-2,20,-1,STONE)
Block(-2,20,0,LOG_2:1)
Block(-2,20,1,STONE)
Block(-2,20,2,STONE)
Block(-2,20,3,STONE)
Block(-2,20,4,STONE)
Block(-2,20,5,quark:basalt:0)
Block(-2,20,6,STONE)
Block(-2,21,-8,STONE)
Block(-2,21,-7,STONE)
Block(-2,21,-6,STONE)
Block(-2,21,-5,LOG_2)
Block(-2,21,-4,STONE)
Block(-2,21,-3,STONE)
Block(-2,21,-2,LOG_2)
Block(-2,21,-1,STONE)
Block(-2,21,0,STONE)
Block(-2,21,1,LOG)
Block(-2,21,2,STONE)
Block(-2,21,3,STONE)
Block(-2,21,4,STONE)
Block(-2,21,5,STONE)
Block(-2,21,6,STONE)
Block(-2,21,7,STONE)
Block(-2,22,-9,STONE)
Block(-2,22,-8,STONE)
Block(-2,22,-7,STONE)
Block(-2,22,-6,STONE)
Block(-2,22,-5,LOG_2)
Block(-2,22,-4,STONE)
Block(-2,22,-3,STONE)
Block(-2,22,-2,LOG_2:1)
Block(-2,22,-1,STONE)
Block(-2,22,0,STONE)
Block(-2,22,1,STONE)
Block(-2,22,2,LOG_2:1)
Block(-2,22,3,STONE)
Block(-2,22,4,STONE)
Block(-2,22,5,STONE)
Block(-2,22,6,STONE)
Block(-2,22,7,STONE)
Block(-2,22,8,quark:basalt:0)
Block(-2,23,-11,STONE)
Block(-2,23,-10,STONE)
Block(-2,23,-9,STONE)
Block(-2,23,-8,STONE)
Block(-2,23,-7,STONE)
Block(-2,23,-6,STONE)
Block(-2,23,-5,LOG:1)
Block(-2,23,-4,LOG_2:1)
Block(-2,23,-3,STONE)
Block(-2,23,-2,STONE)
Block(-2,23,-1,STONE)
Block(-2,23,0,STONE)
Block(-2,23,1,STONE)
Block(-2,23,2,LOG:1)
Block(-2,23,3,STONE)
Block(-2,23,4,STONE)
Block(-2,23,5,STONE)
Block(-2,23,6,STONE)
Block(-2,23,7,STONE)
Block(-2,23,8,quark:basalt:0)
Block(-2,23,9,quark:basalt:0)
Block(-2,23,10,STONE)
Block(-2,24,-13,STONE)
Block(-2,24,-12,STONE)
Block(-2,24,-11,STONE)
Block(-2,24,-10,STONE)
Block(-2,24,-9,STONE)
Block(-2,24,-8,STONE)
Block(-2,24,-7,STONE)
Block(-2,24,-6,STONE)
Block(-2,24,-5,STONE)
Block(-2,24,-4,STONE)
Block(-2,24,-3,LOG_2:1)
Block(-2,24,-2,STONE)
Block(-2,24,-1,STONE)
Block(-2,24,0,STONE)
Block(-2,24,1,LOG_2)
Block(-2,24,2,STONE)
Block(-2,24,3,LOG_2)
Block(-2,24,4,STONE)
Block(-2,24,5,LOG_2:1)
Block(-2,24,6,LOG:2)
Block(-2,24,7,STONE)
Block(-2,24,8,STONE)
Block(-2,24,9,STONE)
Block(-2,24,10,STONE)
Block(-2,24,11,Leaves:7)
Block(-2,25,-13,STONE)
Block(-2,25,-12,STONE)
Block(-2,25,-11,STONE)
Block(-2,25,-10,STONE)
Block(-2,25,-9,STONE)
Block(-2,25,-8,STONE)
Block(-2,25,-7,STONE)
Block(-2,25,-6,STONE)
Block(-2,25,-5,STONE)
Block(-2,25,-4,STONE)
Block(-2,25,-3,STONE)
Block(-2,25,-2,STONE)
Block(-2,25,-1,LOG:2)
Block(-2,25,0,STONE)
Block(-2,25,1,STONE)
Block(-2,25,2,STONE)
Block(-2,25,3,STONE)
Block(-2,25,4,LOG)
Block(-2,25,5,LOG:1)
Block(-2,25,6,LOG:2)
Block(-2,25,7,STONE)
Block(-2,25,8,STONE)
Block(-2,25,9,STONE)
Block(-2,25,10,STONE)
Block(-2,25,11,STONE)
Block(-2,25,12,Leaves:7)
Block(-2,26,-13,STONE)
Block(-2,26,-12,STONE)
Block(-2,26,-11,STONE)
Block(-2,26,-10,STONE)
Block(-2,26,-9,STONE)
Block(-2,26,-8,STONE)
Block(-2,26,-7,STONE)
Block(-2,26,-6,STONE)
Block(-2,26,-5,LOG:2)
Block(-2,26,-4,STONE)
Block(-2,26,-3,LOG)
Block(-2,26,-2,LOG:2)
Block(-2,26,-1,LOG_2)
Block(-2,26,0,STONE)
Block(-2,26,1,STONE)
Block(-2,26,2,STONE)
Block(-2,26,3,STONE)
Block(-2,26,4,LOG:1)
Block(-2,26,5,LOG_2)
Block(-2,26,6,STONE)
Block(-2,26,7,STONE)
Block(-2,26,8,STONE)
Block(-2,26,9,STONE)
Block(-2,26,10,STONE)
Block(-2,26,11,STONE)
Block(-2,27,-13,STONE)
Block(-2,27,-12,STONE)
Block(-2,27,-11,STONE)
Block(-2,27,-10,STONE)
Block(-2,27,-9,STONE)
Block(-2,27,-8,STONE)
Block(-2,27,-7,STONE)
Block(-2,27,-6,STONE)
Block(-2,27,-5,STONE)
Block(-2,27,-4,STONE)
Block(-2,27,-3,STONE)
Block(-2,27,-2,LOG:1)
Block(-2,27,-1,STONE)
Block(-2,27,0,STONE)
Block(-2,27,1,LOG_2:1)
Block(-2,27,2,LOG:2)
Block(-2,27,3,STONE)
Block(-2,27,4,STONE)
Block(-2,27,5,STONE)
Block(-2,27,6,STONE)
Block(-2,27,7,STONE)
Block(-2,27,8,STONE)
Block(-2,27,9,STONE)
Block(-2,27,10,STONE)
Block(-1,0,-12,STONE)
Block(-1,0,-11,STONE)
Block(-1,0,-10,STONE)
Block(-1,0,-9,STONE)
Block(-1,0,-8,STONE)
Block(-1,0,-7,STONE)
Block(-1,0,-6,STONE)
Block(-1,0,-5,STONE)
Block(-1,0,-4,STONE)
Block(-1,0,-3,STONE)
Block(-1,0,-2,STONE)
Block(-1,0,-1,STONE)
Block(-1,0,0,STONE)
Block(-1,0,1,STONE)
Block(-1,0,2,STONE)
Block(-1,0,3,STONE)
Block(-1,0,4,STONE)
Block(-1,0,5,STONE)
Block(-1,0,6,STONE)
Block(-1,0,7,STONE)
Block(-1,0,8,STONE)
Block(-1,0,9,STONE)
Block(-1,0,10,STONE)
Block(-1,0,11,STONE)
Block(-1,0,12,quark:basalt:0)
Block(-1,0,13,quark:basalt:0)
Block(-1,1,-11,STONE)
Block(-1,1,-10,STONE)
Block(-1,1,-9,STONE)
Block(-1,1,-8,STONE)
Block(-1,1,-7,STONE)
Block(-1,1,-6,STONE)
Block(-1,1,-5,STONE)
Block(-1,1,-4,STONE)
Block(-1,1,-3,STONE)
Block(-1,1,-2,STONE)
Block(-1,1,-1,STONE)
Block(-1,1,0,STONE)
Block(-1,1,1,LOG_2)
Block(-1,1,2,STONE)
Block(-1,1,3,STONE)
Block(-1,1,4,STONE)
Block(-1,1,5,STONE)
Block(-1,1,6,STONE)
Block(-1,1,7,STONE)
Block(-1,1,8,STONE)
Block(-1,1,9,STONE)
Block(-1,1,10,STONE)
Block(-1,1,11,STONE)
Block(-1,1,12,STONE)
Block(-1,2,-10,STONE)
Block(-1,2,-9,STONE)
Block(-1,2,-8,STONE)
Block(-1,2,-7,STONE)
Block(-1,2,-6,STONE)
Block(-1,2,-5,STONE)
Block(-1,2,-4,STONE)
Block(-1,2,-3,STONE)
Block(-1,2,-2,STONE)
Block(-1,2,-1,STONE)
Block(-1,2,0,STONE)
Block(-1,2,1,STONE)
Block(-1,2,2,STONE)
Block(-1,2,3,STONE)
Block(-1,2,4,STONE)
Block(-1,2,5,STONE)
Block(-1,2,6,STONE)
Block(-1,2,7,STONE)
Block(-1,2,8,STONE)
Block(-1,2,9,STONE)
Block(-1,2,10,STONE)
Block(-1,2,11,STONE)
Block(-1,2,12,STONE)
Block(-1,2,13,Leaves:7)
Block(-1,3,-10,STONE)
Block(-1,3,-9,STONE)
Block(-1,3,-8,STONE)
Block(-1,3,-7,LOG_2)
Block(-1,3,-6,STONE)
Block(-1,3,-5,STONE)
Block(-1,3,-4,STONE)
Block(-1,3,-3,STONE)
Block(-1,3,-2,STONE)
Block(-1,3,-1,STONE)
Block(-1,3,0,LOG_2)
Block(-1,3,1,STONE)
Block(-1,3,2,LOG)
Block(-1,3,3,STONE)
Block(-1,3,4,STONE)
Block(-1,3,5,STONE)
Block(-1,3,6,STONE)
Block(-1,3,7,STONE)
Block(-1,3,8,STONE)
Block(-1,3,9,STONE)
Block(-1,3,10,STONE)
Block(-1,3,11,STONE)
Block(-1,3,12,Leaves:7)
Block(-1,4,-10,STONE)
Block(-1,4,-9,STONE)
Block(-1,4,-8,quark:basalt:0)
Block(-1,4,-7,STONE)
Block(-1,4,-6,STONE)
Block(-1,4,-5,STONE)
Block(-1,4,-4,STONE)
Block(-1,4,-3,STONE)
Block(-1,4,-2,STONE)
Block(-1,4,-1,LOG:2)
Block(-1,4,0,STONE)
Block(-1,4,1,STONE)
Block(-1,4,2,STONE)
Block(-1,4,3,LOG:2)
Block(-1,4,4,STONE)
Block(-1,4,5,STONE)
Block(-1,4,6,STONE)
Block(-1,4,7,STONE)
Block(-1,4,8,STONE)
Block(-1,4,9,quark:basalt:0)
Block(-1,4,10,quark:basalt:0)
Block(-1,4,11,STONE)
Block(-1,5,-9,quark:basalt:0)
Block(-1,5,-8,quark:basalt:0)
Block(-1,5,-7,quark:basalt:0)
Block(-1,5,-6,STONE)
Block(-1,5,-5,STONE)
Block(-1,5,-4,STONE)
Block(-1,5,-3,LOG_2:1)
Block(-1,5,-2,STONE)
Block(-1,5,-1,STONE)
Block(-1,5,0,STONE)
Block(-1,5,1,STONE)
Block(-1,5,2,STONE)
Block(-1,5,3,LOG_2:1)
Block(-1,5,4,STONE)
Block(-1,5,5,STONE)
Block(-1,5,6,STONE)
Block(-1,5,7,STONE)
Block(-1,5,8,quark:basalt:0)
Block(-1,5,9,quark:basalt:0)
Block(-1,5,10,quark:basalt:0)
Block(-1,5,11,quark:basalt:0)
Block(-1,6,-8,quark:basalt:0)
Block(-1,6,-7,quark:basalt:0)
Block(-1,6,-6,STONE)
Block(-1,6,-5,STONE)
Block(-1,6,-4,STONE)
Block(-1,6,-3,STONE)
Block(-1,6,-2,STONE)
Block(-1,6,-1,STONE)
Block(-1,6,0,STONE)
Block(-1,6,1,LOG_2:1)
Block(-1,6,2,LOG_2)
Block(-1,6,3,STONE)
Block(-1,6,4,STONE)
Block(-1,6,5,STONE)
Block(-1,6,6,STONE)
Block(-1,6,7,STONE)
Block(-1,6,8,STONE)
Block(-1,6,9,quark:basalt:0)
Block(-1,6,10,quark:basalt:0)
Block(-1,7,-8,quark:basalt:0)
Block(-1,7,-7,STONE)
Block(-1,7,-6,quark:basalt:0)
Block(-1,7,-5,LOG_2:1)
Block(-1,7,-4,LOG_2:1)
Block(-1,7,-3,LOG)
Block(-1,7,-2,STONE)
Block(-1,7,-1,STONE)
Block(-1,7,0,STONE)
Block(-1,7,1,STONE)
Block(-1,7,2,STONE)
Block(-1,7,3,LOG)
Block(-1,7,4,STONE)
Block(-1,7,5,STONE)
Block(-1,7,6,STONE)
Block(-1,7,7,STONE)
Block(-1,7,8,STONE)
Block(-1,8,-8,STONE)
Block(-1,8,-7,STONE)
Block(-1,8,-6,STONE)
Block(-1,8,-5,quark:basalt:0)
Block(-1,8,-4,STONE)
Block(-1,8,-3,LOG)
Block(-1,8,-2,LOG:1)
Block(-1,8,-1,LOG:2)
Block(-1,8,0,STONE)
Block(-1,8,1,STONE)
Block(-1,8,2,LOG:2)
Block(-1,8,3,STONE)
Block(-1,8,4,STONE)
Block(-1,8,5,STONE)
Block(-1,8,6,STONE)
Block(-1,8,7,STONE)
Block(-1,8,8,STONE)
Block(-1,9,-8,Leaves:7)
Block(-1,9,-7,STONE)
Block(-1,9,-6,STONE)
Block(-1,9,-5,STONE)
Block(-1,9,-4,STONE)
Block(-1,9,-3,STONE)
Block(-1,9,-2,LOG:1)
Block(-1,9,-1,STONE)
Block(-1,9,0,STONE)
Block(-1,9,1,STONE)
Block(-1,9,2,STONE)
Block(-1,9,3,LOG)
Block(-1,9,4,STONE)
Block(-1,9,5,quark:basalt:0)
Block(-1,9,6,quark:basalt:0)
Block(-1,9,7,quark:basalt:0)
Block(-1,10,-7,Leaves:7)
Block(-1,10,-6,STONE)
Block(-1,10,-5,STONE)
Block(-1,10,-4,STONE)
Block(-1,10,-3,STONE)
Block(-1,10,-2,LOG:2)
Block(-1,10,-1,STONE)
Block(-1,10,0,STONE)
Block(-1,10,1,STONE)
Block(-1,10,2,LOG:1)
Block(-1,10,3,LOG)
Block(-1,10,4,STONE)
Block(-1,10,5,quark:basalt:0)
Block(-1,10,6,quark:basalt:0)
Block(-1,11,-5,STONE)
Block(-1,11,-4,quark:basalt:0)
Block(-1,11,-3,STONE)
Block(-1,11,-2,STONE)
Block(-1,11,-1,STONE)
Block(-1,11,0,STONE)
Block(-1,11,1,STONE)
Block(-1,11,2,LOG)
Block(-1,11,3,STONE)
Block(-1,11,4,quark:basalt:0)
Block(-1,11,5,STONE)
Block(-1,12,-5,quark:basalt:0)
Block(-1,12,-4,quark:basalt:0)
Block(-1,12,-3,STONE)
Block(-1,12,-2,STONE)
Block(-1,12,-1,STONE)
Block(-1,12,0,STONE)
Block(-1,12,1,STONE)
Block(-1,12,2,LOG:2)
Block(-1,12,3,STONE)
Block(-1,12,4,STONE)
Block(-1,12,5,STONE)
Block(-1,13,-5,STONE)
Block(-1,13,-4,quark:basalt:0)
Block(-1,13,-3,quark:basalt:0)
Block(-1,13,-2,STONE)
Block(-1,13,-1,STONE)
Block(-1,13,0,STONE)
Block(-1,13,1,LOG)
Block(-1,13,2,STONE)
Block(-1,13,3,STONE)
Block(-1,13,4,STONE)
Block(-1,14,-5,STONE)
Block(-1,14,-4,STONE)
Block(-1,14,-3,STONE)
Block(-1,14,-2,STONE)
Block(-1,14,-1,LOG_2:1)
Block(-1,14,0,LOG_2)
Block(-1,14,1,LOG_2:1)
Block(-1,14,2,STONE)
Block(-1,14,3,STONE)
Block(-1,14,4,quark:basalt:0)
Block(-1,14,5,STONE)
Block(-1,15,-5,STONE)
Block(-1,15,-4,quark:basalt:0)
Block(-1,15,-3,STONE)
Block(-1,15,-2,STONE)
Block(-1,15,-1,STONE)
Block(-1,15,0,LOG_2)
Block(-1,15,1,STONE)
Block(-1,15,2,STONE)
Block(-1,15,3,STONE)
Block(-1,15,4,STONE)
Block(-1,15,5,STONE)
Block(-1,16,-5,quark:basalt:0)
Block(-1,16,-4,quark:basalt:0)
Block(-1,16,-3,STONE)
Block(-1,16,-2,LOG)
Block(-1,16,-1,LOG_2)
Block(-1,16,0,STONE)
Block(-1,16,1,STONE)
Block(-1,16,2,STONE)
Block(-1,16,3,STONE)
Block(-1,16,4,STONE)
Block(-1,16,5,STONE)
Block(-1,17,-5,quark:basalt:0)
Block(-1,17,-4,quark:basalt:0)
Block(-1,17,-3,LOG)
Block(-1,17,-2,STONE)
Block(-1,17,-1,STONE)
Block(-1,17,0,LOG_2:1)
Block(-1,17,1,STONE)
Block(-1,17,2,STONE)
Block(-1,17,3,STONE)
Block(-1,17,4,STONE)
Block(-1,17,5,STONE)
Block(-1,17,6,quark:basalt:0)
Block(-1,18,-5,STONE)
Block(-1,18,-4,STONE)
Block(-1,18,-3,STONE)
Block(-1,18,-2,LOG)
Block(-1,18,-1,STONE)
Block(-1,18,0,STONE)
Block(-1,18,1,STONE)
Block(-1,18,2,STONE)
Block(-1,18,3,STONE)
Block(-1,18,4,STONE)
Block(-1,18,5,quark:basalt:0)
Block(-1,18,6,STONE)
Block(-1,19,-6,quark:basalt:0)
Block(-1,19,-5,STONE)
Block(-1,19,-4,LOG:2)
Block(-1,19,-3,LOG_2)
Block(-1,19,-2,STONE)
Block(-1,19,-1,STONE)
Block(-1,19,0,STONE)
Block(-1,19,1,LOG:1)
Block(-1,19,2,STONE)
Block(-1,19,3,STONE)
Block(-1,19,4,STONE)
Block(-1,19,5,STONE)
Block(-1,19,6,STONE)
Block(-1,19,7,STONE)
Block(-1,20,-8,STONE)
Block(-1,20,-7,quark:basalt:0)
Block(-1,20,-6,STONE)
Block(-1,20,-5,STONE)
Block(-1,20,-4,STONE)
Block(-1,20,-3,STONE)
Block(-1,20,-2,STONE)
Block(-1,20,-1,LOG:1)
Block(-1,20,0,STONE)
Block(-1,20,1,LOG:1)
Block(-1,20,2,STONE)
Block(-1,20,3,LOG_2:1)
Block(-1,20,4,STONE)
Block(-1,20,5,STONE)
Block(-1,20,6,STONE)
Block(-1,20,7,STONE)
Block(-1,20,8,quark:basalt:0)
Block(-1,21,-8,STONE)
Block(-1,21,-7,STONE)
Block(-1,21,-6,STONE)
Block(-1,21,-5,LOG)
Block(-1,21,-4,STONE)
Block(-1,21,-3,STONE)
Block(-1,21,-2,LOG:1)
Block(-1,21,-1,STONE)
Block(-1,21,0,STONE)
Block(-1,21,1,STONE)
Block(-1,21,2,LOG:1)
Block(-1,21,3,STONE)
Block(-1,21,4,STONE)
Block(-1,21,5,STONE)
Block(-1,21,6,STONE)
Block(-1,21,7,quark:basalt:0)
Block(-1,21,8,quark:basalt:0)
Block(-1,22,-10,STONE)
Block(-1,22,-9,STONE)
Block(-1,22,-8,STONE)
Block(-1,22,-7,STONE)
Block(-1,22,-6,STONE)
Block(-1,22,-5,STONE)
Block(-1,22,-4,LOG_2:1)
Block(-1,22,-3,STONE)
Block(-1,22,-2,STONE)
Block(-1,22,-1,LOG)
Block(-1,22,0,LOG_2)
Block(-1,22,1,STONE)
Block(-1,22,2,STONE)
Block(-1,22,3,LOG)
Block(-1,22,4,STONE)
Block(-1,22,5,STONE)
Block(-1,22,6,STONE)
Block(-1,22,7,STONE)
Block(-1,22,8,STONE)
Block(-1,23,-11,STONE)
Block(-1,23,-10,STONE)
Block(-1,23,-9,STONE)
Block(-1,23,-8,STONE)
Block(-1,23,-7,STONE)
Block(-1,23,-6,LOG_2:1)
Block(-1,23,-5,STONE)
Block(-1,23,-4,STONE)
Block(-1,23,-3,LOG_2:1)
Block(-1,23,-2,STONE)
Block(-1,23,-1,LOG:2)
Block(-1,23,0,STONE)
Block(-1,23,1,LOG)
Block(-1,23,2,LOG)
Block(-1,23,3,LOG:2)
Block(-1,23,4,STONE)
Block(-1,23,5,STONE)
Block(-1,23,6,STONE)
Block(-1,23,7,STONE)
Block(-1,23,8,STONE)
Block(-1,23,9,STONE)
Block(-1,24,-13,STONE)
Block(-1,24,-12,STONE)
Block(-1,24,-11,STONE)
Block(-1,24,-10,STONE)
Block(-1,24,-9,STONE)
Block(-1,24,-8,STONE)
Block(-1,24,-7,STONE)
Block(-1,24,-6,LOG:2)
Block(-1,24,-5,STONE)
Block(-1,24,-4,STONE)
Block(-1,24,-3,STONE)
Block(-1,24,-2,STONE)
Block(-1,24,-1,STONE)
Block(-1,24,0,STONE)
Block(-1,24,1,LOG:2)
Block(-1,24,2,LOG_2)
Block(-1,24,3,LOG_2:1)
Block(-1,24,4,LOG_2)
Block(-1,24,5,LOG:2)
Block(-1,24,6,STONE)
Block(-1,24,7,STONE)
Block(-1,24,8,STONE)
Block(-1,24,9,STONE)
Block(-1,24,10,STONE)
Block(-1,25,-13,STONE)
Block(-1,25,-12,STONE)
Block(-1,25,-11,STONE)
Block(-1,25,-10,STONE)
Block(-1,25,-9,STONE)
Block(-1,25,-8,STONE)
Block(-1,25,-7,STONE)
Block(-1,25,-6,STONE)
Block(-1,25,-5,STONE)
Block(-1,25,-4,STONE)
Block(-1,25,-3,STONE)
Block(-1,25,-2,STONE)
Block(-1,25,-1,LOG_2)
Block(-1,25,0,STONE)
Block(-1,25,1,STONE)
Block(-1,25,2,STONE)
Block(-1,25,3,STONE)
Block(-1,25,4,STONE)
Block(-1,25,5,LOG_2:1)
Block(-1,25,6,STONE)
Block(-1,25,7,STONE)
Block(-1,25,8,STONE)
Block(-1,25,9,STONE)
Block(-1,25,10,STONE)
Block(-1,25,11,STONE)
Block(-1,26,-13,STONE)
Block(-1,26,-12,STONE)
Block(-1,26,-11,STONE)
Block(-1,26,-10,STONE)
Block(-1,26,-9,STONE)
Block(-1,26,-8,LOG:1)
Block(-1,26,-7,STONE)
Block(-1,26,-6,STONE)
Block(-1,26,-5,STONE)
Block(-1,26,-4,STONE)
Block(-1,26,-3,LOG)
Block(-1,26,-2,STONE)
Block(-1,26,-1,STONE)
Block(-1,26,0,STONE)
Block(-1,26,1,LOG:2)
Block(-1,26,2,STONE)
Block(-1,26,3,STONE)
Block(-1,26,4,STONE)
Block(-1,26,5,STONE)
Block(-1,26,6,STONE)
Block(-1,26,7,STONE)
Block(-1,26,8,STONE)
Block(-1,26,9,STONE)
Block(-1,26,10,STONE)
Block(-1,26,11,STONE)
Block(-1,26,12,quark:basalt:0)
Block(-1,27,-12,STONE)
Block(-1,27,-11,STONE)
Block(-1,27,-10,STONE)
Block(-1,27,-9,STONE)
Block(-1,27,-8,STONE)
Block(-1,27,-7,LOG)
Block(-1,27,-6,STONE)
Block(-1,27,-5,STONE)
Block(-1,27,-4,LOG)
Block(-1,27,-3,LOG_2:1)
Block(-1,27,-2,LOG_2)
Block(-1,27,-1,STONE)
Block(-1,27,0,STONE)
Block(-1,27,1,STONE)
Block(-1,27,2,STONE)
Block(-1,27,3,LOG_2)
Block(-1,27,4,LOG_2)
Block(-1,27,5,STONE)
Block(-1,27,6,STONE)
Block(-1,27,7,LOG_2:1)
Block(-1,27,8,STONE)
Block(-1,27,9,STONE)
Block(-1,27,10,STONE)
Block(-1,27,11,quark:basalt:0)
B(0,0,-12,STONE)
B(0,0,-11,STONE)
B(0,0,-10,STONE)
B(0,0,-9,STONE)
B(0,0,-8,STONE)
B(0,0,-7,STONE)
B(0,0,-6,STONE)
B(0,0,-5,STONE)
B(0,0,-4,STONE)
B(0,0,-3,STONE)
B(0,0,-2,STONE)
B(0,0,-1,STONE)
B(0,0,0,STONE)
B(0,0,1,STONE)
B(0,0,2,STONE)
B(0,0,3,STONE)
B(0,0,4,STONE)
B(0,0,5,STONE)
B(0,0,6,STONE)
B(0,0,7,STONE)
B(0,0,8,STONE)
B(0,0,9,STONE)
B(0,0,10,STONE)
B(0,0,11,STONE)
B(0,0,12,quark:basalt:0)
B(0,0,13,quark:basalt:0)
B(0,1,-11,STONE)
B(0,1,-10,STONE)
B(0,1,-9,STONE)
B(0,1,-8,STONE)
B(0,1,-7,STONE)
B(0,1,-6,STONE)
B(0,1,-5,STONE)
B(0,1,-4,STONE)
B(0,1,-3,STONE)
B(0,1,-2,LOG_2)
B(0,1,-1,LOG_2:1)
B(0,1,0,LOG_2)
B(0,1,1,STONE)
B(0,1,2,STONE)
B(0,1,3,STONE)
B(0,1,4,STONE)
B(0,1,5,STONE)
B(0,1,6,STONE)
B(0,1,7,STONE)
B(0,1,8,STONE)
B(0,1,9,STONE)
B(0,1,10,STONE)
B(0,1,11,quark:basalt:0)
B(0,1,12,quark:basalt:0)
B(0,2,-10,STONE)
B(0,2,-9,STONE)
B(0,2,-8,STONE)
B(0,2,-7,STONE)
B(0,2,-6,STONE)
B(0,2,-5,LOG_2)
B(0,2,-4,LOG:2)
B(0,2,-3,STONE)
B(0,2,-2,LOG_2)
B(0,2,-1,STONE)
B(0,2,0,STONE)
B(0,2,1,STONE)
B(0,2,2,LOG_2:1)
B(0,2,3,LOG_2)
B(0,2,4,STONE)
B(0,2,5,STONE)
B(0,2,6,STONE)
B(0,2,7,STONE)
B(0,2,8,STONE)
B(0,2,9,STONE)
B(0,2,10,STONE)
B(0,2,11,STONE)
B(0,2,12,Leaves:7)
B(0,3,-10,STONE)
B(0,3,-9,STONE)
B(0,3,-8,STONE)
B(0,3,-7,STONE)
B(0,3,-6,STONE)
B(0,3,-5,LOG)
B(0,3,-4,STONE)
B(0,3,-3,LOG:2)
B(0,3,-2,STONE)
B(0,3,-1,STONE)
B(0,3,0,STONE)
B(0,3,1,STONE)
B(0,3,2,STONE)
B(0,3,3,STONE)
B(0,3,4,STONE)
B(0,3,5,STONE)
B(0,3,6,STONE)
B(0,3,7,STONE)
B(0,3,8,STONE)
B(0,3,9,STONE)
B(0,3,10,STONE)
B(0,3,11,STONE)
B(0,3,12,Leaves:7)
B(0,4,-10,STONE)
B(0,4,-9,STONE)
B(0,4,-8,STONE)
B(0,4,-7,STONE)
B(0,4,-6,STONE)
B(0,4,-5,STONE)
B(0,4,-4,STONE)
B(0,4,-3,LOG:2)
B(0,4,-2,STONE)
B(0,4,-1,STONE)
B(0,4,0,LOG_2:1)
B(0,4,1,LOG_2)
B(0,4,2,STONE)
B(0,4,3,LOG:1)
B(0,4,4,STONE)
B(0,4,5,STONE)
B(0,4,6,STONE)
B(0,4,7,STONE)
B(0,4,8,STONE)
B(0,4,9,STONE)
B(0,4,10,STONE)
B(0,4,11,Leaves:7)
B(0,5,-10,STONE)
B(0,5,-9,STONE)
B(0,5,-8,STONE)
B(0,5,-7,STONE)
B(0,5,-6,STONE)
B(0,5,-5,STONE)
B(0,5,-4,STONE)
B(0,5,-3,LOG_2)
B(0,5,-2,STONE)
B(0,5,-1,LOG)
B(0,5,0,LOG)
B(0,5,1,STONE)
B(0,5,2,STONE)
B(0,5,3,STONE)
B(0,5,4,STONE)
B(0,5,5,STONE)
B(0,5,6,STONE)
B(0,5,7,STONE)
B(0,5,8,quark:basalt:0)
B(0,5,9,STONE)
B(0,5,10,quark:basalt:0)
B(0,6,-8,quark:basalt:0)
B(0,6,-7,STONE)
B(0,6,-6,STONE)
B(0,6,-5,STONE)
B(0,6,-4,LOG_2)
B(0,6,-3,STONE)
B(0,6,-2,STONE)
B(0,6,-1,STONE)
B(0,6,0,STONE)
B(0,6,1,STONE)
B(0,6,2,STONE)
B(0,6,3,LOG)
B(0,6,4,LOG)
B(0,6,5,STONE)
B(0,6,6,STONE)
B(0,6,7,STONE)
B(0,6,8,quark:basalt:0)
B(0,7,-7,quark:basalt:0)
B(0,7,-6,quark:basalt:0)
B(0,7,-5,quark:basalt:0)
B(0,7,-4,STONE)
B(0,7,-3,LOG_2:1)
B(0,7,-2,LOG)
B(0,7,-1,STONE)
B(0,7,0,LOG)
B(0,7,1,LOG_2)
B(0,7,2,LOG:1)
B(0,7,3,STONE)
B(0,7,4,STONE)
B(0,7,5,STONE)
B(0,7,6,STONE)
B(0,7,7,quark:basalt:0)
B(0,7,8,quark:basalt:0)
B(0,8,-7,quark:basalt:0)
B(0,8,-6,quark:basalt:0)
B(0,8,-5,quark:basalt:0)
B(0,8,-4,quark:basalt:0)
B(0,8,-3,STONE)
B(0,8,-2,LOG_2:1)
B(0,8,-1,STONE)
B(0,8,0,STONE)
B(0,8,1,LOG)
B(0,8,2,LOG)
B(0,8,3,STONE)
B(0,8,4,STONE)
B(0,8,5,STONE)
B(0,8,6,quark:basalt:0)
B(0,8,7,quark:basalt:0)
B(0,8,8,quark:basalt:0)
B(0,9,-7,Leaves:7)
B(0,9,-6,STONE)
B(0,9,-5,STONE)
B(0,9,-4,STONE)
B(0,9,-3,STONE)
B(0,9,-2,STONE)
B(0,9,-1,LOG:1)
B(0,9,0,LOG:2)
B(0,9,1,STONE)
B(0,9,2,STONE)
B(0,9,3,STONE)
B(0,9,4,STONE)
B(0,9,5,STONE)
B(0,9,6,quark:basalt:0)
B(0,9,7,quark:basalt:0)
B(0,10,-5,STONE)
B(0,10,-4,STONE)
B(0,10,-3,LOG:1)
B(0,10,-2,STONE)
B(0,10,-1,STONE)
B(0,10,0,STONE)
B(0,10,1,LOG:2)
B(0,10,2,STONE)
B(0,10,3,LOG_2)
B(0,10,4,STONE)
B(0,10,5,STONE)
B(0,11,-5,STONE)
B(0,11,-4,STONE)
B(0,11,-3,STONE)
B(0,11,-2,LOG:2)
B(0,11,-1,LOG_2)
B(0,11,0,STONE)
B(0,11,1,STONE)
B(0,11,2,LOG_2)
B(0,11,3,STONE)
B(0,11,4,STONE)
B(0,11,5,STONE)
B(0,12,-5,STONE)
B(0,12,-4,STONE)
B(0,12,-3,STONE)
B(0,12,-2,LOG:1)
B(0,12,-1,STONE)
B(0,12,0,LOG:1)
B(0,12,1,LOG_2)
B(0,12,2,STONE)
B(0,12,3,STONE)
B(0,12,4,STONE)
B(0,12,5,STONE)
B(0,12,6,Leaves:7)
B(0,13,-5,STONE)
B(0,13,-4,STONE)
B(0,13,-3,STONE)
B(0,13,-2,STONE)
B(0,13,-1,LOG_2)
B(0,13,0,STONE)
B(0,13,1,LOG_2:1)
B(0,13,2,LOG)
B(0,13,3,STONE)
B(0,13,4,STONE)
B(0,13,5,STONE)
B(0,14,-5,STONE)
B(0,14,-4,STONE)
B(0,14,-3,STONE)
B(0,14,-2,STONE)
B(0,14,-1,LOG:1)
B(0,14,0,STONE)
B(0,14,1,STONE)
B(0,14,2,STONE)
B(0,14,3,quark:basalt:0)
B(0,14,4,STONE)
B(0,14,5,STONE)
B(0,15,-5,STONE)
B(0,15,-4,STONE)
B(0,15,-3,STONE)
B(0,15,-2,STONE)
B(0,15,-1,STONE)
B(0,15,0,LOG:2)
B(0,15,1,STONE)
B(0,15,2,STONE)
B(0,15,3,STONE)
B(0,15,4,STONE)
B(0,15,5,STONE)
B(0,16,-5,STONE)
B(0,16,-4,STONE)
B(0,16,-3,STONE)
B(0,16,-2,STONE)
B(0,16,-1,LOG)
B(0,16,0,LOG:1)
B(0,16,1,STONE)
B(0,16,2,LOG)
B(0,16,3,STONE)
B(0,16,4,STONE)
B(0,16,5,STONE)
B(0,16,6,Leaves:7)
B(0,17,-5,STONE)
B(0,17,-4,STONE)
B(0,17,-3,STONE)
B(0,17,-2,STONE)
B(0,17,-1,STONE)
B(0,17,0,LOG:2)
B(0,17,1,STONE)
B(0,17,2,STONE)
B(0,17,3,STONE)
B(0,17,4,STONE)
B(0,17,5,STONE)
B(0,18,-6,quark:basalt:0)
B(0,18,-5,quark:basalt:0)
B(0,18,-4,STONE)
B(0,18,-3,STONE)
B(0,18,-2,STONE)
B(0,18,-1,STONE)
B(0,18,0,STONE)
B(0,18,1,STONE)
B(0,18,2,STONE)
B(0,18,3,STONE)
B(0,18,4,STONE)
B(0,18,5,STONE)
B(0,18,6,quark:basalt:0)
B(0,19,-7,quark:basalt:0)
B(0,19,-6,quark:basalt:0)
B(0,19,-5,STONE)
B(0,19,-4,LOG:2)
B(0,19,-3,LOG)
B(0,19,-2,STONE)
B(0,19,-1,STONE)
B(0,19,0,LOG_2)
B(0,19,1,STONE)
B(0,19,2,STONE)
B(0,19,3,STONE)
B(0,19,4,STONE)
B(0,19,5,quark:basalt:0)
B(0,19,6,quark:basalt:0)
B(0,19,7,quark:basalt:0)
B(0,20,-8,quark:basalt:0)
B(0,20,-7,quark:basalt:0)
B(0,20,-6,quark:basalt:0)
B(0,20,-5,STONE)
B(0,20,-4,STONE)
B(0,20,-3,LOG:1)
B(0,20,-2,LOG)
B(0,20,-1,LOG)
B(0,20,0,STONE)
B(0,20,1,STONE)
B(0,20,2,STONE)
B(0,20,3,LOG_2:1)
B(0,20,4,STONE)
B(0,20,5,quark:basalt:0)
B(0,20,6,quark:basalt:0)
B(0,20,7,quark:basalt:0)
B(0,21,-9,STONE)
B(0,21,-8,STONE)
B(0,21,-7,STONE)
B(0,21,-6,STONE)
B(0,21,-5,LOG_2)
B(0,21,-4,STONE)
B(0,21,-3,LOG:2)
B(0,21,-2,LOG:1)
B(0,21,-1,STONE)
B(0,21,0,LOG_2)
B(0,21,1,STONE)
B(0,21,2,STONE)
B(0,21,3,STONE)
B(0,21,4,STONE)
B(0,21,5,STONE)
B(0,21,6,quark:basalt:0)
B(0,21,7,quark:basalt:0)
B(0,22,-10,STONE)
B(0,22,-9,STONE)
B(0,22,-8,STONE)
B(0,22,-7,STONE)
B(0,22,-6,STONE)
B(0,22,-5,LOG:1)
B(0,22,-4,STONE)
B(0,22,-3,STONE)
B(0,22,-2,LOG_2)
B(0,22,-1,LOG)
B(0,22,0,STONE)
B(0,22,1,LOG)
B(0,22,2,LOG:2)
B(0,22,3,LOG:2)
B(0,22,4,LOG:1)
B(0,22,5,STONE)
B(0,22,6,STONE)
B(0,22,7,quark:basalt:0)
B(0,22,8,STONE)
B(0,23,-11,STONE)
B(0,23,-10,STONE)
B(0,23,-9,STONE)
B(0,23,-8,STONE)
B(0,23,-7,STONE)
B(0,23,-6,STONE)
B(0,23,-5,STONE)
B(0,23,-4,LOG:2)
B(0,23,-3,STONE)
B(0,23,-2,LOG:2)
B(0,23,-1,LOG_2:1)
B(0,23,0,STONE)
B(0,23,1,STONE)
B(0,23,2,LOG)
B(0,23,3,STONE)
B(0,23,4,STONE)
B(0,23,5,LOG:2)
B(0,23,6,LOG:1)
B(0,23,7,STONE)
B(0,23,8,STONE)
B(0,23,9,STONE)
B(0,23,10,Leaves:7)
B(0,24,-12,STONE)
B(0,24,-11,STONE)
B(0,24,-10,STONE)
B(0,24,-9,STONE)
B(0,24,-8,STONE)
B(0,24,-7,STONE)
B(0,24,-6,STONE)
B(0,24,-5,STONE)
B(0,24,-4,LOG_2)
B(0,24,-3,STONE)
B(0,24,-2,STONE)
B(0,24,-1,STONE)
B(0,24,0,STONE)
B(0,24,1,STONE)
B(0,24,2,STONE)
B(0,24,3,STONE)
B(0,24,4,STONE)
B(0,24,5,STONE)
B(0,24,6,LOG:2)
B(0,24,7,STONE)
B(0,24,8,STONE)
B(0,24,9,STONE)
B(0,24,10,STONE)
B(0,25,-13,STONE)
B(0,25,-12,STONE)
B(0,25,-11,STONE)
B(0,25,-10,STONE)
B(0,25,-9,STONE)
B(0,25,-8,STONE)
B(0,25,-7,STONE)
B(0,25,-6,STONE)
B(0,25,-5,LOG:1)
B(0,25,-4,LOG_2:1)
B(0,25,-3,STONE)
B(0,25,-2,STONE)
B(0,25,-1,STONE)
B(0,25,0,STONE)
B(0,25,1,LOG)
B(0,25,2,STONE)
B(0,25,3,STONE)
B(0,25,4,LOG:1)
B(0,25,5,STONE)
B(0,25,6,STONE)
B(0,25,7,STONE)
B(0,25,8,STONE)
B(0,25,9,STONE)
B(0,25,10,STONE)
B(0,25,11,quark:basalt:0)
B(0,26,-13,STONE)
B(0,26,-12,STONE)
B(0,26,-11,STONE)
B(0,26,-10,STONE)
B(0,26,-9,STONE)
B(0,26,-8,STONE)
B(0,26,-7,LOG)
B(0,26,-6,STONE)
B(0,26,-5,STONE)
B(0,26,-4,LOG_2)
B(0,26,-3,LOG)
B(0,26,-2,STONE)
B(0,26,-1,LOG)
B(0,26,0,LOG)
B(0,26,1,STONE)
B(0,26,2,STONE)
B(0,26,3,LOG:2)
B(0,26,4,STONE)
B(0,26,5,STONE)
B(0,26,6,STONE)
B(0,26,7,STONE)
B(0,26,8,STONE)
B(0,26,9,STONE)
B(0,26,10,quark:basalt:0)
B(0,26,11,quark:basalt:0)
B(0,27,-12,STONE)
B(0,27,-11,STONE)
B(0,27,-10,STONE)
B(0,27,-9,STONE)
B(0,27,-8,STONE)
B(0,27,-7,LOG_2:1)
B(0,27,-6,LOG:2)
B(0,27,-5,LOG:1)
B(0,27,-4,STONE)
B(0,27,-3,STONE)
B(0,27,-2,STONE)
B(0,27,-1,STONE)
B(0,27,0,LOG:2)
B(0,27,1,STONE)
B(0,27,2,STONE)
B(0,27,3,STONE)
B(0,27,4,STONE)
B(0,27,5,STONE)
B(0,27,6,LOG)
B(0,27,7,STONE)
B(0,27,8,STONE)
B(0,27,9,STONE)
B(0,27,10,STONE)
B(1,0,-12,STONE)
B(1,0,-11,STONE)
B(1,0,-10,STONE)
B(1,0,-9,STONE)
B(1,0,-8,STONE)
B(1,0,-7,STONE)
B(1,0,-6,STONE)
B(1,0,-5,STONE)
B(1,0,-4,STONE)
B(1,0,-3,STONE)
B(1,0,-2,STONE)
B(1,0,-1,STONE)
B(1,0,0,STONE)
B(1,0,1,STONE)
B(1,0,2,STONE)
B(1,0,3,STONE)
B(1,0,4,STONE)
B(1,0,5,STONE)
B(1,0,6,STONE)
B(1,0,7,STONE)
B(1,0,8,STONE)
B(1,0,9,STONE)
B(1,0,10,STONE)
B(1,0,11,STONE)
B(1,0,12,quark:basalt:0)
B(1,0,13,quark:basalt:0)
B(1,1,-11,STONE)
B(1,1,-10,STONE)
B(1,1,-9,STONE)
B(1,1,-8,STONE)
B(1,1,-7,STONE)
B(1,1,-6,LOG_2:1)
B(1,1,-5,STONE)
B(1,1,-4,STONE)
B(1,1,-3,STONE)
B(1,1,-2,LOG:2)
B(1,1,-1,LOG)
B(1,1,0,STONE)
B(1,1,1,LOG)
B(1,1,2,LOG_2)
B(1,1,3,LOG_2:1)
B(1,1,4,STONE)
B(1,1,5,STONE)
B(1,1,6,STONE)
B(1,1,7,STONE)
B(1,1,8,STONE)
B(1,1,9,STONE)
B(1,1,10,quark:basalt:0)
B(1,1,11,quark:basalt:0)
B(1,1,12,quark:basalt:0)
B(1,2,-10,STONE)
B(1,2,-9,STONE)
B(1,2,-8,STONE)
B(1,2,-7,STONE)
B(1,2,-6,STONE)
B(1,2,-5,STONE)
B(1,2,-4,STONE)
B(1,2,-3,LOG)
B(1,2,-2,LOG_2:1)
B(1,2,-1,STONE)
B(1,2,0,LOG_2)
B(1,2,1,LOG:2)
B(1,2,2,STONE)
B(1,2,3,STONE)
B(1,2,4,LOG:1)
B(1,2,5,STONE)
B(1,2,6,STONE)
B(1,2,7,STONE)
B(1,2,8,STONE)
B(1,2,9,STONE)
B(1,2,10,quark:basalt:0)
B(1,2,11,STONE)
B(1,2,12,quark:basalt:0)
B(1,3,-10,STONE)
B(1,3,-9,STONE)
B(1,3,-8,STONE)
B(1,3,-7,LOG:1)
B(1,3,-6,LOG)
B(1,3,-5,STONE)
B(1,3,-4,STONE)
B(1,3,-3,STONE)
B(1,3,-2,LOG_2)
B(1,3,-1,STONE)
B(1,3,0,STONE)
B(1,3,1,LOG:2)
B(1,3,2,LOG:1)
B(1,3,3,LOG:2)
B(1,3,4,STONE)
B(1,3,5,STONE)
B(1,3,6,STONE)
B(1,3,7,STONE)
B(1,3,8,STONE)
B(1,3,9,STONE)
B(1,3,10,STONE)
B(1,3,11,Leaves:7)
B(1,4,-10,STONE)
B(1,4,-9,STONE)
B(1,4,-8,STONE)
B(1,4,-7,STONE)
B(1,4,-6,STONE)
B(1,4,-5,STONE)
B(1,4,-4,STONE)
B(1,4,-3,LOG:2)
B(1,4,-2,STONE)
B(1,4,-1,STONE)
B(1,4,0,LOG)
B(1,4,1,STONE)
B(1,4,2,STONE)
B(1,4,3,STONE)
B(1,4,4,STONE)
B(1,4,5,STONE)
B(1,4,6,STONE)
B(1,4,7,STONE)
B(1,4,8,STONE)
B(1,4,9,STONE)
B(1,5,-9,STONE)
